Workbook

Sheet KONTROL PANELİ
A1: KVK Md. 32/7 ve 32/8 — İmalat ve İhracat İndirimli Kurumlar Vergisi Çalışma Kağıdı
A2: Mükellef: | D2: VKN: | F2: Dönem:
A4: ÖN KONTROL | C4: CEVAP
A5: Sanayi sicil belgesi geçerli mi? (32/7 için)
A6: Sanayi sicil kapsamı imalat faaliyeti aktif mi?
A7: İhracat faaliyeti belgelenmiş mi? (32/8 için)
A8: İhracat + imalat matrahı toplamı KV matrahını aşmıyor mu?
A9: 32/A ile çakışma varsa matrahlar ayrıştırıldı mı?
A11: ÖZET TABLO — DİĞER SAYFALARA BAĞLANTILI
A12: No | B12: Kalem | C12: Tutar (TL)
A13: 1 | B13: KV Matrahı (Toplam) | C13: ='GELİR TABLOSU'!C90
A14: 2 | B14: İmalat Faaliyeti Matrahı (32/7) | C14: ='GELİR TABLOSU'!E90
A15: 3 | B15: İhracat Faaliyeti Matrahı (32/8) | C15: ='GELİR TABLOSU'!D90
A16: 4 | B16: Diğer Faaliyetler Matrahı | C16: ='GELİR TABLOSU'!F90
A17: 5 | B17: 32/7 KV Tasarrufu (1 puan) | C17: =HESAPLAMA!E14
A18: 6 | B18: 32/8 KV Tasarrufu (5 puan) | C18: =HESAPLAMA!D22
A19: 7 | B19: Toplam KV Tasarrufu | C19: =HESAPLAMA!C27
A20: 8 | B20: Ödenecek KV (tahmini) | C20: =HESAPLAMA!C33

Sheet GELİR TABLOSU
A1: GELİR TABLOSU — FAALİYET BAZINDA DAĞILIM
A2: Her kalem Toplam / İhracat / İmalat / Diğer sütunlarına ayrılarak dağıtılır
A3: Hesap Kodu | B3: Hesap Adı | C3: Toplam (TL) | D3: İhracat Faaliyeti | E3: İmalat Faaliyeti | F3: Diğer Faaliyetler | G3: Kontrol (C-D-E-F)
A4: A — BRÜT SATIŞLAR (Hesap 60)
A5: 600 | B5: 1-Yurtiçi Satışlar | G5: =C5-D5-E5-F5
A6: 601 | B6: 2-Yurtdışı Satışlar | G6: =C6-D6-E6-F6
A7: 602 | B7: 3-Diğer Gelirler | G7: =C7-D7-E7-F7
B8: A — BRÜT SATIŞLAR TOPLAMI | C8: =SUM(C5:C7) | D8: =SUM(D5:D7) | E8: =SUM(E5:E7) | F8: =SUM(F5:F7) | G8: =C8-D8-E8-F8
A10: B — SATIŞ İNDİRİMLERİ (-) (Hesap 61)
A11: 610 | B11: 1-Satıştan İadeler (-) | G11: =C11-D11-E11-F11
A12: 611 | B12: 2-Satış İskontoları (-) | G12: =C12-D12-E12-F12
A13: 612 | B13: 3-Diğer İndirimler (-) | G13: =C13-D13-E13-F13
B14: B — SATIŞ İNDİRİMLERİ TOPLAMI | C14: =SUM(C11:C13) | D14: =SUM(D11:D13) | E14: =SUM(E11:E13) | F14: =SUM(F11:F13) | G14: =C14-D14-E14-F14
B16: C — NET SATIŞLAR | C16: =C8-C14 | D16: =D8-D14 | E16: =E8-E14 | F16: =F8-F14 | G16: =C16-D16-E16-F16
A18: D — SATIŞLARIN MALİYETİ (-) (Hesap 62)
A19: 620 | B19: 1-Satılan Mamuller Maliyeti | G19: =C19-D19-E19-F19
A20: 621 | B20: 2-Satılan Ticari Mal Maliyeti | G20: =C20-D20-E20-F20
A21: 622 | B21: 3-Satılan Hizmet Maliyeti | G21: =C21-D21-E21-F21
A22: 623 | B22: 4-Diğer Satışların Maliyeti | G22: =C22-D22-E22-F22
B23: D — SATIŞLARIN MALİYETİ TOPLAMI | C23: =SUM(C19:C22) | D23: =SUM(D19:D22) | E23: =SUM(E19:E22) | F23: =SUM(F19:F22) | G23: =C23-D23-E23-F23
B25: BRÜT SATIŞ KARI / ZARARI | C25: =C16-C23 | D25: =D16-D23 | E25: =E16-E23 | F25: =F16-F23 | G25: =C25-D25-E25-F25
A27: E — FAALİYET GİDERLERİ (-) (Hesap 63)
A28: 630 | B28: 1-Ar-Ge Giderleri (-) | G28: =C28-D28-E28-F28
A29: 631 | B29: 2-Pazarlama, Satış ve Dağıtım Giderleri (-) | G29: =C29-D29-E29-F29
A30: 632 | B30: 3-Genel Yönetim Giderleri (-) | G30: =C30-D30-E30-F30
B31: Müşterek Genel Giderler (hasılat payına göre dağıtım) | C31: =D31+E31+F31 | G31: =C31-D31-E31-F31
B32: Müşterek Gider Niteliğindeki Amortismanlar | C32: =D32+E32+F32 | G32: =C32-D32-E32-F32
B33: E — FAALİYET GİDERLERİ TOPLAMI | C33: =SUM(C28:C32) | D33: =SUM(D28:D32) | E33: =SUM(E28:E32) | F33: =SUM(F28:F32) | G33: =C33-D33-E33-F33
B35: FAALİYET KARI / ZARARI | C35: =C25-C33 | D35: =D25-D33 | E35: =E25-E33 | F35: =F25-F33 | G35: =C35-D35-E35-F35
A37: F — DİĞER FAALİYETLERDEN GELİR VE KARLAR (Hesap 64)
A38: 640 | B38: 1-İştiraklerden Temettü Gelirleri | G38: =C38-D38-E38-F38
A39: 641 | B39: 2-Bağlı Ortaklıklardan Temettü Gelirleri | G39: =C39-D39-E39-F39
A40: 642 | B40: 3-Faiz Gelirleri (ihracat/imalat kaynaklı) | G40: =C40-D40-E40-F40
A41: 643 | B41: 4-Komisyon Gelirleri | G41: =C41-D41-E41-F41
A42: 644 | B42: 5-Konusu Olmayan Karşılıklar | G42: =C42-D42-E42-F42
A43: 645 | B43: 6-Menkul Kıymet Satış Karları | G43: =C43-D43-E43-F43
A44: 646 | B44: 7-Kambiyo Karları (faaliyete kaynaklı) | G44: =C44-D44-E44-F44
A45: 647 | B45: 8-Reeskont Faiz Gelirleri | G45: =C45-D45-E45-F45
A46: 649 | B46: 9-Diğer Gelir ve Karlar | G46: =C46-D46-E46-F46
B47: F — DİĞER FAALİYET GELİRLERİ ARA TOPLAM | C47: =SUM(C38:C46) | D47: =SUM(D38:D46) | E47: =SUM(E38:E46) | F47: =SUM(F38:F46) | G47: =C47-D47-E47-F47
...

Sheet HESAPLAMA
A1: KVK 32/7 ve 32/8 — İndirimli Kurumlar Vergisi Hesaplama Tablosu
A3: 1. MATRAH ÖZETİ
B4: Kalem | C4: Toplam (TL) | D4: İhracat | E4: İmalat | F4: Diğer
B5: KV Matrahı (Toplam) | C5: ='GELİR TABLOSU'!C90
B6: İhracat Faaliyeti Matrahı (32/8) | D6: ='GELİR TABLOSU'!D90
B7: İmalat Faaliyeti Matrahı (32/7) | E7: ='GELİR TABLOSU'!E90
B8: Diğer Faaliyetler Matrahı | F8: ='GELİR TABLOSU'!F90
A10: 2. KVK 32/7 — İMALAT FAALİYETİ İNDİRİMLİ KV
B11: İmalat Faaliyeti Matrahı (32/7) | E11: =E7
B12: Normal KV Oranı (%25) | E12: 0.25
B13: Normal KV (İmalat) | E13: =E11*E12
B14: 1 Puan İndirim Tutarı | E14: =E11*0.01
B15: İndirimli KV (%24) | E15: =E13-E14
B16: 32/7 KV TASARRUFU (1 Puan) | E16: =E14
A18: 3. KVK 32/8 — İHRACAT FAALİYETİ İNDİRİMLİ KV
B19: İhracat Faaliyeti Matrahı (32/8) | D19: =D6
B20: Normal KV Oranı (%25) | D20: 0.25
B21: Normal KV (İhracat) | D21: =D19*D20
B22: 5 Puan İndirim Tutarı | D22: =D19*0.05
B23: İndirimli KV (%20) | D23: =D21-D22
B24: 32/8 KV TASARRUFU (5 Puan) | D24: =D22
A26: 4. KONSOLİDASYON — TOPLAM KV HESABI
B27: Toplam KV Tasarrufu (32/7 + 32/8) | C27: =E14+D22
B28: Kalan Matrah (Diğer Faaliyetler) | C28: =C5-E11-D19
B29: Kalan Matrah Normal KV (%25) | C29: =C28*0.25
B30: 32/7 İndirimli KV | C30: =E15
B31: 32/8 İndirimli KV | C31: =D23
B32: Hesaplanan Toplam KV | C32: =C29+E15+D23
B33: TAHMİNİ ÖDENECEK KV | C33: =C32
A35: 5. UYUMLULUK KONTROLLERİ
B36: İhracat + İmalat Matrah Toplamı ≤ KV Matrahı? | C36: =IF(D19+E11<=C5,"✓ OK — Toplam matrah sınırı aşılmadı","✗ UYARI: İhracat+İmalat toplamı KV matrahını aşıyor!")
B37: 32/7 (İmalat) Matrahı > 0? | C37: =IF(E11>0,"✓ Uygulanabilir — İmalat matrahı mevcut","— Uygulanmıyor (İmalat matrahı sıfır)")
B38: 32/8 (İhracat) Matrahı > 0? | C38: =IF(D19>0,"✓ Uygulanabilir — İhracat matrahı mevcut","— Uygulanmıyor (İhracat matrahı sıfır)")

Sheet BELGE LİSTESİ
A1: KVK 32/7 ve 32/8 — Belge Kontrol Listesi
A2: No | B2: Belge Adı | C2: Kapsam | D2: Zorunlu mu? | E2: Mevcut mu? | F2: Tarih | G2: Notlar
A3: 1 | B3: Sanayi Sicil Belgesi (güncel, bakanlık onaylı) | C3: 32/7 | D3: Zorunlu
A4: 2 | B4: NACE / Faaliyet Kodu Teyidi (imalat sektörü) | C4: 32/7 | D4: Zorunlu
A5: 3 | B5: İmalat Faaliyeti Gelir Tablosu Dağılımı | C5: 32/7 | D5: Zorunlu
A6: 4 | B6: Matrah Ayrıştırma Hesap Tablosu (bu dosya) | C6: 32/7 | D6: Zorunlu
A7: 5 | B7: İhracat Gümrük Beyannameleri (dönem) | C7: 32/8 | D7: Zorunlu
A8: 6 | B8: İhracat Hasılat Özet Tablosu | C8: 32/8 | D8: Zorunlu
A9: 7 | B9: Döviz Alım Belgeleri (DAB) | C9: 32/8 | D9: Zorunlu
A10: 8 | B10: İhracat Matrahı Ayrıştırma Hesabı | C10: 32/8 | D10: Zorunlu
A11: 9 | B11: Kurumlar Vergisi Beyannamesi (KV1) | C11: Her ikisi | D11: Zorunlu
A12: 10 | B12: 32/A YTB varsa — Konsolidasyon Notu ve Matrah Tablosu | C12: Her ikisi | D12: Gerekirse

Sheet DENETÇİ NOTLARI
A1: KVK 32/7 ve 32/8 — Denetçi Notları ve Temel Prensipler
A3: KVK 32/7 — İMALAT FAALİYETİ İNDİRİMLİ KV TEMEL PRENSİPLERİ
A4: Sanayi sicil belgesine sahip, Sanayi ve Teknoloji Bakanlığı'nca belirlenen imalat sanayii sektörlerinde faaliyette bulunan kurumlar bu kapsamdaki kazançlarına 1 puan indirim uygular. Normal oran: %25 → İndirimli oran: %24. İndirim yalnızca imalat faaliyetinden elde edilen kazanç kısmına uygulanır. Tüm ticari kazanca değil, ayrıştırılmış imalat matrahına uygulanır.
A6: KVK 32/8 — İHRACAT FAALİYETİ İNDİRİMLİ KV TEMEL PRENSİPLERİ
A7: İhracat faaliyetinden elde edilen kazançlara 5 puan indirim uygulanır. Normal oran: %25 → İndirimli oran: %20. İndirim, sadece fiilen ihracat gelirinden elde edilen kazançla sınırlıdır. İhracat hasılatının gümrük beyannamesi ve döviz alım belgeleriyle belgelenmiş olması zorunludur.
A9: MATRAH AYRIŞTIRMA PRENSİPLERİ
A10: Faaliyet bazında matrah tespiti için gelir tablosundaki her kalem ilgili faaliyet kolonu altında takip edilmelidir. İhracat, imalat ve diğer faaliyetlere direkt bağlanamayan ortak (müşterek) giderler net satışlar içindeki faaliyet payına göre dağıtılmalıdır. KKEG (Kanunen Kabul Edilmeyen Giderler) tüm faaliyetlere ortak kabul edilir.
A12: 32/A İLE BİRLİKTE UYGULAMA
A13: KVK 32/A (Yatırım Teşvik Belgesi — İndirimli KV) ile 32/7 ve 32/8 aynı vergilendirme döneminde birlikte uygulanabilir. Ancak herhangi bir matrahın birden fazla indirime konu edilmemesi zorunludur. Her üç indirim kapsamındaki matrahların toplamı toplam KV matrahını aşmamalıdır. Matrahlar net biçimde ayrıştırılmalı ve belgelenmelidir.
A15: YİAKV ETKİSİ (YURT İÇİ ASGARİ KURUMLAR VERGİSİ)
A16: KVK 32/7 ve 32/8 kapsamındaki indirimler YİAKV matrahını etkilemez. YİAKV hesaplamasında ticari bilanço karı esas alınır ve bu indirimler düşülmez. Dolayısıyla uygulanan indirimli KV oranının YİAKV oranının altında kalmaması gerekmektedir; aksi hâlde YİAKV uygulanır.
A18: DENETİM NOKTALARI — ÖZET
A19: 1. Sanayi sicil belgesi geçerlilik tarihi kontrol edilmeli (32/7). 2. İhracat belgelerinin döneme ait olduğu teyit edilmeli (32/8). 3. Gelir tablosu faaliyet dağılımı muhasebe kayıtlarıyla uyumlu olmalı. 4. Müşterek gider dağıtım oranı tutarlı uygulanmalı. 5. HESAPLAMA sayfasında kontrol formülleri ✓ OK göstermeli. 6. BELGE LİSTESİ sayfasındaki tüm zorunlu belgeler 'Mevcut' işaretli olmalı.
