Workbook

Sheet KONTROL PANELİ
B2: KVK Md. 32/A — Yatırıma Katkı Tutarı (YKT) ve İndirimli KV Çalışma Kağıdı
B4: MÜKELLEf BİLGİLERİ
B5: Mükellef Unvanı
B6: Vergi Kimlik Numarası (VKN)
B7: Dönem Yılı
B9: ÖN KONTROL TABLOSU
B10: No | C10: Kontrol Konusu | G10: Durum
B11: 1 | C11: YTB(ler) geçerli ve iptal/revize edilmemiş
B12: 2 | C12: Finans/sigortacılık/adi ortaklık kapsamı dışı
B13: 3 | C13: Her YTB için kazanç ayrıştırması yapıldı
B14: 4 | C14: Çapraz YTB YKT uygulanmadı
B15: 5 | C15: YİAKV değerlendirmesi yapıldı
B16: 6 | C16: YMM raporu yükümlülüğü kontrol edildi (49 No'lu Sirkül)
B18: YTB ÖZET TABLOSU (Tüm YTB'lerin Özeti)
B19: YTB No | C19: Durum | D19: Yatırım Tutarı (TL) | E19: YKT (TL) | F19: Önceki Kümülatif Kullanım (TL) | G19: Bu Dönem Kullanım (TL) | H19: Bu Dönem KV Tasarrufu (TL) | I19: Kalan YKT (TL)
B20: =IFERROR('YTB-1'!A3,"YTB-1") | C20: =IFERROR('YTB-1'!A4,"") | D20: =IFERROR('YTB-1'!A5,0) | E20: =IFERROR('YTB-1'!A6,0) | F20: =IFERROR('YTB-1'!A7,0) | G20: =IFERROR('YTB-1'!A8,0) | H20: =IFERROR('YTB-1'!A9,0) | I20: =IFERROR('YTB-1'!A10,0)
B21: =IFERROR('YTB-2'!A3,"YTB-2") | C21: =IFERROR('YTB-2'!A4,"") | D21: =IFERROR('YTB-2'!A5,0) | E21: =IFERROR('YTB-2'!A6,0) | F21: =IFERROR('YTB-2'!A7,0) | G21: =IFERROR('YTB-2'!A8,0) | H21: =IFERROR('YTB-2'!A9,0) | I21: =IFERROR('YTB-2'!A10,0)
B22: =IFERROR('YTB-3'!A3,"YTB-3") | C22: =IFERROR('YTB-3'!A4,"") | D22: =IFERROR('YTB-3'!A5,0) | E22: =IFERROR('YTB-3'!A6,0) | F22: =IFERROR('YTB-3'!A7,0) | G22: =IFERROR('YTB-3'!A8,0) | H22: =IFERROR('YTB-3'!A9,0) | I22: =IFERROR('YTB-3'!A10,0)
B23: =IFERROR('YTB-4'!A3,"YTB-4") | C23: =IFERROR('YTB-4'!A4,"") | D23: =IFERROR('YTB-4'!A5,0) | E23: =IFERROR('YTB-4'!A6,0) | F23: =IFERROR('YTB-4'!A7,0) | G23: =IFERROR('YTB-4'!A8,0) | H23: =IFERROR('YTB-4'!A9,0) | I23: =IFERROR('YTB-4'!A10,0)
B24: =IFERROR('YTB-5'!A3,"YTB-5") | C24: =IFERROR('YTB-5'!A4,"") | D24: =IFERROR('YTB-5'!A5,0) | E24: =IFERROR('YTB-5'!A6,0) | F24: =IFERROR('YTB-5'!A7,0) | G24: =IFERROR('YTB-5'!A8,0) | H24: =IFERROR('YTB-5'!A9,0) | I24: =IFERROR('YTB-5'!A10,0)
B25: =IFERROR('YTB-6'!A3,"YTB-6") | C25: =IFERROR('YTB-6'!A4,"") | D25: =IFERROR('YTB-6'!A5,0) | E25: =IFERROR('YTB-6'!A6,0) | F25: =IFERROR('YTB-6'!A7,0) | G25: =IFERROR('YTB-6'!A8,0) | H25: =IFERROR('YTB-6'!A9,0) | I25: =IFERROR('YTB-6'!A10,0)
B26: =IFERROR('YTB-7'!A3,"YTB-7") | C26: =IFERROR('YTB-7'!A4,"") | D26: =IFERROR('YTB-7'!A5,0) | E26: =IFERROR('YTB-7'!A6,0) | F26: =IFERROR('YTB-7'!A7,0) | G26: =IFERROR('YTB-7'!A8,0) | H26: =IFERROR('YTB-7'!A9,0) | I26: =IFERROR('YTB-7'!A10,0)
B27: =IFERROR('YTB-8'!A3,"YTB-8") | C27: =IFERROR('YTB-8'!A4,"") | D27: =IFERROR('YTB-8'!A5,0) | E27: =IFERROR('YTB-8'!A6,0) | F27: =IFERROR('YTB-8'!A7,0) | G27: =IFERROR('YTB-8'!A8,0) | H27: =IFERROR('YTB-8'!A9,0) | I27: =IFERROR('YTB-8'!A10,0)
B28: =IFERROR('YTB-9'!A3,"YTB-9") | C28: =IFERROR('YTB-9'!A4,"") | D28: =IFERROR('YTB-9'!A5,0) | E28: =IFERROR('YTB-9'!A6,0) | F28: =IFERROR('YTB-9'!A7,0) | G28: =IFERROR('YTB-9'!A8,0) | H28: =IFERROR('YTB-9'!A9,0) | I28: =IFERROR('YTB-9'!A10,0)
B29: =IFERROR('YTB-10'!A3,"YTB-10") | C29: =IFERROR('YTB-10'!A4,"") | D29: =IFERROR('YTB-10'!A5,0) | E29: =IFERROR('YTB-10'!A6,0) | F29: =IFERROR('YTB-10'!A7,0) | G29: =IFERROR('YTB-10'!A8,0) | H29: =IFERROR('YTB-10'!A9,0) | I29: =IFERROR('YTB-10'!A10,0)
B30: TOPLAM | D30: =SUM(D20:D29) | E30: =SUM(E20:E29) | F30: =SUM(F20:F29) | G30: =SUM(G20:G29) | H30: =SUM(H20:H29) | I30: =SUM(I20:I29)
B32: DÖNEM SONU BEYANNAME SONUÇLARI
B33: Toplam Bu Dönem KV Tasarrufu (Beyanname 710/720) | I33: =H30
B34: Tüm YTB'ler Kalan YKT Toplamı (Devreden) | I34: =J30
B36: ℹ️ KULLANIM: Her YTB için ayrı bir YTB-X sayfası kullanın. Daha fazla YTB için mevcut bir YTB sayfasını kopyalayıp adını değiştirin (YTB-6, YTB-7, ...) ve formülleri güncelleyin.

Sheet YTB-1
A1: YTB-1
A2: YTB-1 — KVK Md.32/A İndirimli KV Çalışma Kağıdı
A3: =C16
A4: =C26
A5: =C20 | B5: A0.1 YTB geçerli mi? (İptal veya revize edilmemiş) | D5: EVET veya HAYIR seçin
A6: =C22 | B6: A0.2 Sektör uygun mu? (Finans/sigorta/adi ortaklık değil) | D6: EVET veya HAYIR seçin
A7: =C71 | B7: A0.3 Bu YTB'den elde edilen kazanç bu YTB'ye mi uygulanıyor? | D7: EVET veya HAYIR seçin
A8: =C77 | B8: A0.4 Yatırım/işletme dönemi doğru tespit edildi mi? | D8: EVET veya HAYIR seçin
A9: =C76 | B9: A0.5 Önceki dönem YKT kümülatif kullanımı doğru girildi mi? | D9: EVET veya HAYIR seçin
A10: =C79 | B10: A0.6 Çapraz YTB YKT uygulaması yok mu? | D10: EVET veya HAYIR seçin
B11: A0.7 YİAKV uyarlaması değerlendirildi mi? | D11: EVET veya HAYIR seçin
B12: A0.8 YMM raporu yükümlülüğü kontrol edildi mi? | D12: EVET veya HAYIR seçin
B13: A0.9 Ön Koşul Sonucu | C13: =IF(AND(C5="EVET",C6="EVET",C7="EVET",C8="EVET",C9="EVET",C10="EVET",C11="EVET",C12="EVET"),"✓ Hesaplanabilir","✗ Ön Koşul Eksik") | D13: Tüm koşullar EVET ise hesaplama yapılabilir
A15: BÖLÜM A — YTB KİMLİK BİLGİLERİ (Girdi)
B16: A.1 YTB Numarası | D16: Örn: 2023/B-123456
B17: A.2 YTB Düzenleme Tarihi | D17: GG.AA.YYYY formatında
B18: A.3 Yatırım Bölgesi (1-6) | D18: Bölge1→0% / Bölge2→10% / Bölge3→20% / Bölge4→30% / Bölge5→50% / Bölge6→80%
B19: A.4 Yatırım Türü | D19: Komple Yeni / Tevsi / Modernizasyon / Diğer
B20: A.5 Toplam Yatırım Tutarı (TL) | D20: YTB'de belirtilen toplam yatırım tutarı
B21: A.6 YKT Oranı (%) | D21: YTB'den gelen yatırıma katkı oranı
B22: A.7 YKT Tutarı (TL) | C22: =IF(C20*C21/100=0,0,C20*C21/100) | D22: =A.5 × A.6 / 100
B23: A.8 Vergi İndirim Oranı (%) | D23: YTB'den gelen vergi indirimi oranı
B24: A.9 Normal KV Oranı (%) | C24: 25 | D24: Varsayılan 25 (2024+); daha önce 20
B25: A.10 İndirimli KV Oranı (%) | C25: =C24*(1-C23/100) | D25: =A.9 × (1 - A.8/100)
B26: A.11 Dönem Durumu | D26: Yatırım / İşletme / Tamamlandı-İşletme Devam
B27: A.12 Tamamlama Vizesi Tarihi (Opsiyonel) | D27: İşletme dönemine geçişi belgeleyiniz
A29: BÖLÜM B — YATIRIM DÖNEMİNDE DİĞER FAALİYET KAZANCI İNDİRİMİ
A30: ⚠ Bu bölüm yalnızca A.11 = "Yatırım Döneminde" ise uygulanır. İşletme dönemindeyse Bölüm D kullanınız.
B31: B.1 Dönem Başı Kümülatif Yatırım Harcaması (TL) | D31: Önceki dönemlerde yapılan yatırım harcamaları toplamı
B32: B.2 Bu Dönem Yatırım Harcaması (TL) | D32: Cari dönemde gerçekleşen yatırım harcaması
B33: B.3 Kümülatif Toplam Harcama (TL) | C33: =C31+C32 | D33: =B.1 + B.2
B34: B.4 Bölge Limit Oranı (%) | C34: =SWITCH(C18,1,0,2,10,3,20,4,30,5,50,6,80,0) | D34: Bölgeye göre otomatik: B1→0, B2→10, B3→20, B4→30, B5→50, B6→80
B35: B.5 YKT × Bölge Limiti (TL) | C35: =C22*C34/100 | D35: =A.7 × B.4 / 100
B36: B.6 Azami Kullanılabilir Limit (TL) | C36: =MIN(C35,C33) | D36: =MIN(B.5, B.3)
B37: B.7 Önceki Dönemler Kümülatif YKT Kullanımı (TL) | D37: Bir önceki yıl beyannamesinden alınır
B38: B.8 Bu Dönem Kullanılabilir YKT (TL) | C38: =MAX(0,C36-C37) | D38: =MAX(0, B.6 - B.7)
B39: B.9 Diğer Faaliyet Kazancı Matrahı (TL) | D39: Yatırım dönemi diğer faaliyet kazancı
B40: B.10 İndirimli Matrah — Yatırım Dönemi (TL) | C40: =IF(C39>0,MIN(C39,IF(C24>0,C38/(C24/100),0)),0) | D40: =MIN(B.9, B.8 / (A.9/100)) — max indirimli matrah
B41: B.11 Normal KV (TL) | C41: =C40*C24/100 | D41: =B.10 × A.9/100
B42: B.12 İndirimli KV (TL) | C42: =C40*C25/100 | D42: =B.10 × A.10/100
...

Sheet YTB-2
A1: YTB-2
A2: YTB-2 — KVK Md.32/A İndirimli KV Çalışma Kağıdı
A3: =C16
A4: =C26
A5: =C20 | B5: A0.1 YTB geçerli mi? (İptal veya revize edilmemiş) | D5: EVET veya HAYIR seçin
A6: =C22 | B6: A0.2 Sektör uygun mu? (Finans/sigorta/adi ortaklık değil) | D6: EVET veya HAYIR seçin
A7: =C71 | B7: A0.3 Bu YTB'den elde edilen kazanç bu YTB'ye mi uygulanıyor? | D7: EVET veya HAYIR seçin
A8: =C77 | B8: A0.4 Yatırım/işletme dönemi doğru tespit edildi mi? | D8: EVET veya HAYIR seçin
A9: =C76 | B9: A0.5 Önceki dönem YKT kümülatif kullanımı doğru girildi mi? | D9: EVET veya HAYIR seçin
A10: =C79 | B10: A0.6 Çapraz YTB YKT uygulaması yok mu? | D10: EVET veya HAYIR seçin
B11: A0.7 YİAKV uyarlaması değerlendirildi mi? | D11: EVET veya HAYIR seçin
B12: A0.8 YMM raporu yükümlülüğü kontrol edildi mi? | D12: EVET veya HAYIR seçin
B13: A0.9 Ön Koşul Sonucu | C13: =IF(AND(C5="EVET",C6="EVET",C7="EVET",C8="EVET",C9="EVET",C10="EVET",C11="EVET",C12="EVET"),"✓ Hesaplanabilir","✗ Ön Koşul Eksik") | D13: Tüm koşullar EVET ise hesaplama yapılabilir
A15: BÖLÜM A — YTB KİMLİK BİLGİLERİ (Girdi)
B16: A.1 YTB Numarası | D16: Örn: 2023/B-123456
B17: A.2 YTB Düzenleme Tarihi | D17: GG.AA.YYYY formatında
B18: A.3 Yatırım Bölgesi (1-6) | D18: Bölge1→0% / Bölge2→10% / Bölge3→20% / Bölge4→30% / Bölge5→50% / Bölge6→80%
B19: A.4 Yatırım Türü | D19: Komple Yeni / Tevsi / Modernizasyon / Diğer
B20: A.5 Toplam Yatırım Tutarı (TL) | D20: YTB'de belirtilen toplam yatırım tutarı
B21: A.6 YKT Oranı (%) | D21: YTB'den gelen yatırıma katkı oranı
B22: A.7 YKT Tutarı (TL) | C22: =IF(C20*C21/100=0,0,C20*C21/100) | D22: =A.5 × A.6 / 100
B23: A.8 Vergi İndirim Oranı (%) | D23: YTB'den gelen vergi indirimi oranı
B24: A.9 Normal KV Oranı (%) | C24: 25 | D24: Varsayılan 25 (2024+); daha önce 20
B25: A.10 İndirimli KV Oranı (%) | C25: =C24*(1-C23/100) | D25: =A.9 × (1 - A.8/100)
B26: A.11 Dönem Durumu | D26: Yatırım / İşletme / Tamamlandı-İşletme Devam
B27: A.12 Tamamlama Vizesi Tarihi (Opsiyonel) | D27: İşletme dönemine geçişi belgeleyiniz
A29: BÖLÜM B — YATIRIM DÖNEMİNDE DİĞER FAALİYET KAZANCI İNDİRİMİ
A30: ⚠ Bu bölüm yalnızca A.11 = "Yatırım Döneminde" ise uygulanır. İşletme dönemindeyse Bölüm D kullanınız.
B31: B.1 Dönem Başı Kümülatif Yatırım Harcaması (TL) | D31: Önceki dönemlerde yapılan yatırım harcamaları toplamı
B32: B.2 Bu Dönem Yatırım Harcaması (TL) | D32: Cari dönemde gerçekleşen yatırım harcaması
B33: B.3 Kümülatif Toplam Harcama (TL) | C33: =C31+C32 | D33: =B.1 + B.2
B34: B.4 Bölge Limit Oranı (%) | C34: =SWITCH(C18,1,0,2,10,3,20,4,30,5,50,6,80,0) | D34: Bölgeye göre otomatik: B1→0, B2→10, B3→20, B4→30, B5→50, B6→80
B35: B.5 YKT × Bölge Limiti (TL) | C35: =C22*C34/100 | D35: =A.7 × B.4 / 100
B36: B.6 Azami Kullanılabilir Limit (TL) | C36: =MIN(C35,C33) | D36: =MIN(B.5, B.3)
B37: B.7 Önceki Dönemler Kümülatif YKT Kullanımı (TL) | D37: Bir önceki yıl beyannamesinden alınır
B38: B.8 Bu Dönem Kullanılabilir YKT (TL) | C38: =MAX(0,C36-C37) | D38: =MAX(0, B.6 - B.7)
B39: B.9 Diğer Faaliyet Kazancı Matrahı (TL) | D39: Yatırım dönemi diğer faaliyet kazancı
B40: B.10 İndirimli Matrah — Yatırım Dönemi (TL) | C40: =IF(C39>0,MIN(C39,IF(C24>0,C38/(C24/100),0)),0) | D40: =MIN(B.9, B.8 / (A.9/100)) — max indirimli matrah
B41: B.11 Normal KV (TL) | C41: =C40*C24/100 | D41: =B.10 × A.9/100
B42: B.12 İndirimli KV (TL) | C42: =C40*C25/100 | D42: =B.10 × A.10/100
...

Sheet YTB-3
A1: YTB-3
A2: YTB-3 — KVK Md.32/A İndirimli KV Çalışma Kağıdı
A3: =C16
A4: =C26
A5: =C20 | B5: A0.1 YTB geçerli mi? (İptal veya revize edilmemiş) | D5: EVET veya HAYIR seçin
A6: =C22 | B6: A0.2 Sektör uygun mu? (Finans/sigorta/adi ortaklık değil) | D6: EVET veya HAYIR seçin
A7: =C71 | B7: A0.3 Bu YTB'den elde edilen kazanç bu YTB'ye mi uygulanıyor? | D7: EVET veya HAYIR seçin
A8: =C77 | B8: A0.4 Yatırım/işletme dönemi doğru tespit edildi mi? | D8: EVET veya HAYIR seçin
A9: =C76 | B9: A0.5 Önceki dönem YKT kümülatif kullanımı doğru girildi mi? | D9: EVET veya HAYIR seçin
A10: =C79 | B10: A0.6 Çapraz YTB YKT uygulaması yok mu? | D10: EVET veya HAYIR seçin
B11: A0.7 YİAKV uyarlaması değerlendirildi mi? | D11: EVET veya HAYIR seçin
B12: A0.8 YMM raporu yükümlülüğü kontrol edildi mi? | D12: EVET veya HAYIR seçin
B13: A0.9 Ön Koşul Sonucu | C13: =IF(AND(C5="EVET",C6="EVET",C7="EVET",C8="EVET",C9="EVET",C10="EVET",C11="EVET",C12="EVET"),"✓ Hesaplanabilir","✗ Ön Koşul Eksik") | D13: Tüm koşullar EVET ise hesaplama yapılabilir
A15: BÖLÜM A — YTB KİMLİK BİLGİLERİ (Girdi)
B16: A.1 YTB Numarası | D16: Örn: 2023/B-123456
B17: A.2 YTB Düzenleme Tarihi | D17: GG.AA.YYYY formatında
B18: A.3 Yatırım Bölgesi (1-6) | D18: Bölge1→0% / Bölge2→10% / Bölge3→20% / Bölge4→30% / Bölge5→50% / Bölge6→80%
B19: A.4 Yatırım Türü | D19: Komple Yeni / Tevsi / Modernizasyon / Diğer
B20: A.5 Toplam Yatırım Tutarı (TL) | D20: YTB'de belirtilen toplam yatırım tutarı
B21: A.6 YKT Oranı (%) | D21: YTB'den gelen yatırıma katkı oranı
B22: A.7 YKT Tutarı (TL) | C22: =IF(C20*C21/100=0,0,C20*C21/100) | D22: =A.5 × A.6 / 100
B23: A.8 Vergi İndirim Oranı (%) | D23: YTB'den gelen vergi indirimi oranı
B24: A.9 Normal KV Oranı (%) | C24: 25 | D24: Varsayılan 25 (2024+); daha önce 20
B25: A.10 İndirimli KV Oranı (%) | C25: =C24*(1-C23/100) | D25: =A.9 × (1 - A.8/100)
B26: A.11 Dönem Durumu | D26: Yatırım / İşletme / Tamamlandı-İşletme Devam
B27: A.12 Tamamlama Vizesi Tarihi (Opsiyonel) | D27: İşletme dönemine geçişi belgeleyiniz
A29: BÖLÜM B — YATIRIM DÖNEMİNDE DİĞER FAALİYET KAZANCI İNDİRİMİ
A30: ⚠ Bu bölüm yalnızca A.11 = "Yatırım Döneminde" ise uygulanır. İşletme dönemindeyse Bölüm D kullanınız.
B31: B.1 Dönem Başı Kümülatif Yatırım Harcaması (TL) | D31: Önceki dönemlerde yapılan yatırım harcamaları toplamı
B32: B.2 Bu Dönem Yatırım Harcaması (TL) | D32: Cari dönemde gerçekleşen yatırım harcaması
B33: B.3 Kümülatif Toplam Harcama (TL) | C33: =C31+C32 | D33: =B.1 + B.2
B34: B.4 Bölge Limit Oranı (%) | C34: =SWITCH(C18,1,0,2,10,3,20,4,30,5,50,6,80,0) | D34: Bölgeye göre otomatik: B1→0, B2→10, B3→20, B4→30, B5→50, B6→80
B35: B.5 YKT × Bölge Limiti (TL) | C35: =C22*C34/100 | D35: =A.7 × B.4 / 100
B36: B.6 Azami Kullanılabilir Limit (TL) | C36: =MIN(C35,C33) | D36: =MIN(B.5, B.3)
B37: B.7 Önceki Dönemler Kümülatif YKT Kullanımı (TL) | D37: Bir önceki yıl beyannamesinden alınır
B38: B.8 Bu Dönem Kullanılabilir YKT (TL) | C38: =MAX(0,C36-C37) | D38: =MAX(0, B.6 - B.7)
B39: B.9 Diğer Faaliyet Kazancı Matrahı (TL) | D39: Yatırım dönemi diğer faaliyet kazancı
B40: B.10 İndirimli Matrah — Yatırım Dönemi (TL) | C40: =IF(C39>0,MIN(C39,IF(C24>0,C38/(C24/100),0)),0) | D40: =MIN(B.9, B.8 / (A.9/100)) — max indirimli matrah
B41: B.11 Normal KV (TL) | C41: =C40*C24/100 | D41: =B.10 × A.9/100
B42: B.12 İndirimli KV (TL) | C42: =C40*C25/100 | D42: =B.10 × A.10/100
...

Sheet YTB-4
A1: YTB-4
A2: YTB-4 — KVK Md.32/A İndirimli KV Çalışma Kağıdı
A3: =C16
A4: =C26
A5: =C20 | B5: A0.1 YTB geçerli mi? (İptal veya revize edilmemiş) | D5: EVET veya HAYIR seçin
A6: =C22 | B6: A0.2 Sektör uygun mu? (Finans/sigorta/adi ortaklık değil) | D6: EVET veya HAYIR seçin
A7: =C71 | B7: A0.3 Bu YTB'den elde edilen kazanç bu YTB'ye mi uygulanıyor? | D7: EVET veya HAYIR seçin
A8: =C77 | B8: A0.4 Yatırım/işletme dönemi doğru tespit edildi mi? | D8: EVET veya HAYIR seçin
A9: =C76 | B9: A0.5 Önceki dönem YKT kümülatif kullanımı doğru girildi mi? | D9: EVET veya HAYIR seçin
A10: =C79 | B10: A0.6 Çapraz YTB YKT uygulaması yok mu? | D10: EVET veya HAYIR seçin
B11: A0.7 YİAKV uyarlaması değerlendirildi mi? | D11: EVET veya HAYIR seçin
B12: A0.8 YMM raporu yükümlülüğü kontrol edildi mi? | D12: EVET veya HAYIR seçin
B13: A0.9 Ön Koşul Sonucu | C13: =IF(AND(C5="EVET",C6="EVET",C7="EVET",C8="EVET",C9="EVET",C10="EVET",C11="EVET",C12="EVET"),"✓ Hesaplanabilir","✗ Ön Koşul Eksik") | D13: Tüm koşullar EVET ise hesaplama yapılabilir
A15: BÖLÜM A — YTB KİMLİK BİLGİLERİ (Girdi)
B16: A.1 YTB Numarası | D16: Örn: 2023/B-123456
B17: A.2 YTB Düzenleme Tarihi | D17: GG.AA.YYYY formatında
B18: A.3 Yatırım Bölgesi (1-6) | D18: Bölge1→0% / Bölge2→10% / Bölge3→20% / Bölge4→30% / Bölge5→50% / Bölge6→80%
B19: A.4 Yatırım Türü | D19: Komple Yeni / Tevsi / Modernizasyon / Diğer
B20: A.5 Toplam Yatırım Tutarı (TL) | D20: YTB'de belirtilen toplam yatırım tutarı
B21: A.6 YKT Oranı (%) | D21: YTB'den gelen yatırıma katkı oranı
B22: A.7 YKT Tutarı (TL) | C22: =IF(C20*C21/100=0,0,C20*C21/100) | D22: =A.5 × A.6 / 100
B23: A.8 Vergi İndirim Oranı (%) | D23: YTB'den gelen vergi indirimi oranı
B24: A.9 Normal KV Oranı (%) | C24: 25 | D24: Varsayılan 25 (2024+); daha önce 20
B25: A.10 İndirimli KV Oranı (%) | C25: =C24*(1-C23/100) | D25: =A.9 × (1 - A.8/100)
B26: A.11 Dönem Durumu | D26: Yatırım / İşletme / Tamamlandı-İşletme Devam
B27: A.12 Tamamlama Vizesi Tarihi (Opsiyonel) | D27: İşletme dönemine geçişi belgeleyiniz
A29: BÖLÜM B — YATIRIM DÖNEMİNDE DİĞER FAALİYET KAZANCI İNDİRİMİ
A30: ⚠ Bu bölüm yalnızca A.11 = "Yatırım Döneminde" ise uygulanır. İşletme dönemindeyse Bölüm D kullanınız.
B31: B.1 Dönem Başı Kümülatif Yatırım Harcaması (TL) | D31: Önceki dönemlerde yapılan yatırım harcamaları toplamı
B32: B.2 Bu Dönem Yatırım Harcaması (TL) | D32: Cari dönemde gerçekleşen yatırım harcaması
B33: B.3 Kümülatif Toplam Harcama (TL) | C33: =C31+C32 | D33: =B.1 + B.2
B34: B.4 Bölge Limit Oranı (%) | C34: =SWITCH(C18,1,0,2,10,3,20,4,30,5,50,6,80,0) | D34: Bölgeye göre otomatik: B1→0, B2→10, B3→20, B4→30, B5→50, B6→80
B35: B.5 YKT × Bölge Limiti (TL) | C35: =C22*C34/100 | D35: =A.7 × B.4 / 100
B36: B.6 Azami Kullanılabilir Limit (TL) | C36: =MIN(C35,C33) | D36: =MIN(B.5, B.3)
B37: B.7 Önceki Dönemler Kümülatif YKT Kullanımı (TL) | D37: Bir önceki yıl beyannamesinden alınır
B38: B.8 Bu Dönem Kullanılabilir YKT (TL) | C38: =MAX(0,C36-C37) | D38: =MAX(0, B.6 - B.7)
B39: B.9 Diğer Faaliyet Kazancı Matrahı (TL) | D39: Yatırım dönemi diğer faaliyet kazancı
B40: B.10 İndirimli Matrah — Yatırım Dönemi (TL) | C40: =IF(C39>0,MIN(C39,IF(C24>0,C38/(C24/100),0)),0) | D40: =MIN(B.9, B.8 / (A.9/100)) — max indirimli matrah
B41: B.11 Normal KV (TL) | C41: =C40*C24/100 | D41: =B.10 × A.9/100
B42: B.12 İndirimli KV (TL) | C42: =C40*C25/100 | D42: =B.10 × A.10/100
...

Sheet YTB-5
A1: YTB-5
A2: YTB-5 — KVK Md.32/A İndirimli KV Çalışma Kağıdı
A3: =C16
A4: =C26
A5: =C20 | B5: A0.1 YTB geçerli mi? (İptal veya revize edilmemiş) | D5: EVET veya HAYIR seçin
A6: =C22 | B6: A0.2 Sektör uygun mu? (Finans/sigorta/adi ortaklık değil) | D6: EVET veya HAYIR seçin
A7: =C71 | B7: A0.3 Bu YTB'den elde edilen kazanç bu YTB'ye mi uygulanıyor? | D7: EVET veya HAYIR seçin
A8: =C77 | B8: A0.4 Yatırım/işletme dönemi doğru tespit edildi mi? | D8: EVET veya HAYIR seçin
A9: =C76 | B9: A0.5 Önceki dönem YKT kümülatif kullanımı doğru girildi mi? | D9: EVET veya HAYIR seçin
A10: =C79 | B10: A0.6 Çapraz YTB YKT uygulaması yok mu? | D10: EVET veya HAYIR seçin
B11: A0.7 YİAKV uyarlaması değerlendirildi mi? | D11: EVET veya HAYIR seçin
B12: A0.8 YMM raporu yükümlülüğü kontrol edildi mi? | D12: EVET veya HAYIR seçin
B13: A0.9 Ön Koşul Sonucu | C13: =IF(AND(C5="EVET",C6="EVET",C7="EVET",C8="EVET",C9="EVET",C10="EVET",C11="EVET",C12="EVET"),"✓ Hesaplanabilir","✗ Ön Koşul Eksik") | D13: Tüm koşullar EVET ise hesaplama yapılabilir
A15: BÖLÜM A — YTB KİMLİK BİLGİLERİ (Girdi)
B16: A.1 YTB Numarası | D16: Örn: 2023/B-123456
B17: A.2 YTB Düzenleme Tarihi | D17: GG.AA.YYYY formatında
B18: A.3 Yatırım Bölgesi (1-6) | D18: Bölge1→0% / Bölge2→10% / Bölge3→20% / Bölge4→30% / Bölge5→50% / Bölge6→80%
B19: A.4 Yatırım Türü | D19: Komple Yeni / Tevsi / Modernizasyon / Diğer
B20: A.5 Toplam Yatırım Tutarı (TL) | D20: YTB'de belirtilen toplam yatırım tutarı
B21: A.6 YKT Oranı (%) | D21: YTB'den gelen yatırıma katkı oranı
B22: A.7 YKT Tutarı (TL) | C22: =IF(C20*C21/100=0,0,C20*C21/100) | D22: =A.5 × A.6 / 100
B23: A.8 Vergi İndirim Oranı (%) | D23: YTB'den gelen vergi indirimi oranı
B24: A.9 Normal KV Oranı (%) | C24: 25 | D24: Varsayılan 25 (2024+); daha önce 20
B25: A.10 İndirimli KV Oranı (%) | C25: =C24*(1-C23/100) | D25: =A.9 × (1 - A.8/100)
B26: A.11 Dönem Durumu | D26: Yatırım / İşletme / Tamamlandı-İşletme Devam
B27: A.12 Tamamlama Vizesi Tarihi (Opsiyonel) | D27: İşletme dönemine geçişi belgeleyiniz
A29: BÖLÜM B — YATIRIM DÖNEMİNDE DİĞER FAALİYET KAZANCI İNDİRİMİ
A30: ⚠ Bu bölüm yalnızca A.11 = "Yatırım Döneminde" ise uygulanır. İşletme dönemindeyse Bölüm D kullanınız.
B31: B.1 Dönem Başı Kümülatif Yatırım Harcaması (TL) | D31: Önceki dönemlerde yapılan yatırım harcamaları toplamı
B32: B.2 Bu Dönem Yatırım Harcaması (TL) | D32: Cari dönemde gerçekleşen yatırım harcaması
B33: B.3 Kümülatif Toplam Harcama (TL) | C33: =C31+C32 | D33: =B.1 + B.2
B34: B.4 Bölge Limit Oranı (%) | C34: =SWITCH(C18,1,0,2,10,3,20,4,30,5,50,6,80,0) | D34: Bölgeye göre otomatik: B1→0, B2→10, B3→20, B4→30, B5→50, B6→80
B35: B.5 YKT × Bölge Limiti (TL) | C35: =C22*C34/100 | D35: =A.7 × B.4 / 100
B36: B.6 Azami Kullanılabilir Limit (TL) | C36: =MIN(C35,C33) | D36: =MIN(B.5, B.3)
B37: B.7 Önceki Dönemler Kümülatif YKT Kullanımı (TL) | D37: Bir önceki yıl beyannamesinden alınır
B38: B.8 Bu Dönem Kullanılabilir YKT (TL) | C38: =MAX(0,C36-C37) | D38: =MAX(0, B.6 - B.7)
B39: B.9 Diğer Faaliyet Kazancı Matrahı (TL) | D39: Yatırım dönemi diğer faaliyet kazancı
B40: B.10 İndirimli Matrah — Yatırım Dönemi (TL) | C40: =IF(C39>0,MIN(C39,IF(C24>0,C38/(C24/100),0)),0) | D40: =MIN(B.9, B.8 / (A.9/100)) — max indirimli matrah
B41: B.11 Normal KV (TL) | C41: =C40*C24/100 | D41: =B.10 × A.9/100
B42: B.12 İndirimli KV (TL) | C42: =C40*C25/100 | D42: =B.10 × A.10/100
...

Sheet BELGE LİSTESİ
B2: KVK Md.32/A — Zorunlu Belge Listesi ve Kontrol Tablosu
B4: Belge | C4: Zorunluluk | D4: Mevcut mu? | E4: Tarih / No | F4: Not
B5: YTB aslı veya noter onaylı sureti | C5: Zorunlu | F5: Her YTB için ayrı
B6: Tamamlama vizesi belgesi | C6: İşletme döneminde zorunlu | F6: İşletme dönemine geçişte
B7: Yatırım harcamaları özet tablosu | C7: Zorunlu | F7: Her dönem güncel
B8: Kazanç ayrıştırma tablosu (Tevsi için) | C8: Tevsi yatırımlarda zorunlu | F8: C bölümünü destekler
B9: YMM tasdik raporu (49 No'lu Sirkül kapsamı) | C9: Gerekiyorsa zorunlu | F9: Sirkül koşullarını kontrol edin
B10: ATİK değerleme belgesi (Tevsi götürü usul) | C10: Tevsi götürü usulde zorunlu | F10: Dönem sonu değerlemesi
B11: Önceki dönemler kümülatif YKT kullanım tablosu | C11: Zorunlu | F11: F.2 için kaynak belge

Sheet DENETÇİ NOTLARI
B2: DENETÇİ NOTLARI — KVK Md.32/A Uygulama Rehberi
B4: KVK 32/A TEMEL PRENSİPLER
B5: • YTB, Ekonomi/Sanayi/Ticaret Bakanlığı'nca verilen Yatırım Teşvik Belgesi'dir. • İndirimli KV, YTB'de belirtilen katkı ve indirim oranları çerçevesinde uygulanır. • Her YTB bağımsız değerlendirilir; YKT bir YTB'den diğerine aktarılamaz. • YKT tamamen kullanılıncaya veya YTB süresi doluncaya kadar devam eder.
B7: YATIRIM vs İŞLETME DÖNEMİ FARKI
B8: • Yatırım Dönemi: YTB onay tarihi → Tamamlama vizesi. Bu dönemde YALNIZCA diğer faaliyet kazancından (Bölüm B) indirim yapılabilir; bölge limiti uygulanır. • İşletme Dönemi: Tamamlama vizesinden sonra. Bu dönemde YTB kazancından (Bölüm D) indirim yapılır; bölge limiti UYGULANMAZ. • Yatırım döneminde indirilemeyen kümülatif miktar işletme dönemine devrolur.
B10: TEVSİ İÇİN MATRAH TESPİTİ
B11: • Tevsi yatırımında kazanç tespiti için iki yöntem vardır: 1. Gerçek Usul: İşletme içi kayıtlardan doğrudan tespit (daha güvenilir). 2. Götürü - Oransal: (YTB ATİK / Toplam ATİK) × KV Matrahı. • Yöntem seçimi tutarlı uygulanmalıdır; dönem içinde değiştirilemez. • ATİK değerleri dönem sonu itibarıyla, yeniden değerleme sonrası alınır.
B13: ÇAPRAZ YTB UYGULAMA YASAĞI
B14: • Bir YTB'den elde edilen kazanç yalnızca o YTB için YKT indiriminde kullanılabilir; başka bir YTB'nin YKT'sine mahsup edilemez. • Birden fazla YTB varsa her biri için bağımsız kazanç ayrıştırması şarttır. • Çapraz uygulama cezai tarhiyat riskine yol açar.
B16: YDO ENDEKSLEMESİ KURALI
B17: • Tamamlama vizesi alındıktan sonra devreden kalan YKT, her yıl Yeniden Değerleme Oranı (YDO) ile artırılır. • YDO: Maliye Bakanlığı her yıl Kasım/Aralık aylarında ilan eder. 2024 yılı: %63,93 — 2025 yılı: %3,30 (tahmini) • Endekslenmiş tutar beyannamede gösterilmeli ve desteklenmelidir.
B19: 49 NO'LU SİRKÜLERE GÖRE YMM RAPORU ZORUNLULUĞU
... B23: • Yurt İçi Asgari Kurumlar Vergisi (YİAKV), indirimli KV uygulamasını dolaylı olarak sınırlayabilir. KV, YİAKV'nin altına düşemez. • YİAKV hesabında indirimli KV öncesi matrah dikkate alınır. • İki hesaplama paralel yapılmalı ve yüksek olan beyannamede kullanılmalıdır. • 2024+ dönemleri için YİAKV etkisi özellikle dikkatle değerlendirilmelidir.
