Workbook

Sheet VERİ GİRİŞİ
A1: 404 – KÜLTÜR VE TURİZM AMAÇLI BAĞIŞ VE YARDIMLAR | KVK Mad. 10/1-d | YMM TASDİK
A2: Beyanname 404 | GİB KV Beyan Rehberi Mart 2026 (No:606) | ✗ YİAKV MATRAHINDA DÜŞÜLEMEZ
A3: KVK Md.10/1-d KAPSAMI — KÜLTÜR VE TURİZM AMAÇLI BAĞIŞ VE YARDIMLAR: ★ İNDİRİM ORANI ALICIYA GÖRE DEĞİŞİR — En kritik özellik: %100: Kültür ve Turizm Bakanlığı'na doğrudan / diğer kamu idarelerine doğrudan / Bakanlık onaylı proje kapsamında yapılan bağış ve yardımlar. %50: Kamu yararına çalışan dernekler (KYD) veya Cumhurbaşkanlığı/Bakanlar Kurulu kararıyla vergi muafiyeti tanınan vakıflar aracılığıyla yapılan bağış ve yardımlar. 402/403/417'den FARK: Orada KYD/muafiyet vakfı alıcı olsa da tamamı indirilir. 404'te KYD/vakıf alıcıda yalnızca %50 indirilir — en sık karıştırılan nokta. KAPSAM: Tarihi miras, müze, kütüphane, sanat, sinema/tiyatro/opera, turizm altyapısı. ★ YİAKV: DÜŞÜLEMEZ — E.11 bilgi satırı.
A4: ✗ YİAKV: 404 DÜŞÜLEMEZ — E.11. ★ ORAN UYARISI: 460/461 (Sponsorluk %100/%50) ile karıştırılmamalı. 404 karşılıksız bağış; 460/461 ise karşılıklı sponsorluk. Karşılık varsa → Sponsorluk (460/461). Karşılık yoksa → 404.
A6: A0. KAPSAM VE NİTELİK UYGUNLUK ÖN KONTROLÜ — KVK Md.10/1-d KÜLTÜR/TURİZM BAĞIŞI
B7: Kontrol Sorusu | F7: Yanıt | H7: YMM Tasdik Notu
A8: A0.1 ★ Bağış KVK Md.10/1-d kapsamında kültür/turizm amaçlı mı? | F8: EVET | G8: Kapsam: Tarihi/kültürel miras, müze, kütüphane, güzel sanatlar, sinema/tiyatro/opera/bale/konser, turizm altyapısı. Genel eğlence veya ticari etkinlik → Kapsam dışı.
A9: A0.2 ★ İŞLEM KAŞILISIZ BAĞIŞ MI? (Sponsorluk değil) | F9: EVET-Karşılıksız Bağış | G9: Karşılıksız → 404. Karşılıklı (reklam/tanıtım/isim hakkı) → 460/461 (Sponsorluk). Bu ayrım hayati — hatalı kod tarhiyat riski doğurur.
A10: A0.3 ★ Alıcı ve indirim oranı belirlendi mi? | F10: %100 (Kültür ve Turizm Bakanlığı/Kamu) | G10: ORAN KRİTİK: Bakanlık/kamu idaresi → %100. KYD dernek/muafiyet vakfı → %50. 402/403'ten farklı — burada KYD/vakıf için %50 uygulanır.
A11: A0.4 ★ Bağış FİİLEN yapıldı mı? (Nakdi: Banka — Ayni: Teslim belgesi) | F11: EVET | G11: Nakdi: Banka dekontu. Ayni: İmzalı teslim tutanağı.
A12: A0.5 Alıcıdan resmi makbuz alındı mı? | F12: EVET | G12: Makbuz zorunludur.
A13: A0.6 KYD/Muafiyet vakıfsa (%50 oranı için) statü belgesi temin edildi mi? | F13: EVET | G13: KYD: Bakanlık kararı. Muafiyet vakfı: CB/BK kararı. %100 için gerekmez.
A14: A0.7 ✗ YİAKV E.11'de bilgi satırı olarak gösterildi mi? | F14: EVET | G14: 404 YİAKV matrahından düşülemez — E.11 bilgi.
A15: A0.8 YMM Tasdik Raporu gereksinimi değerlendirildi mi? | F15: EVET | G15: >=500.000 TL → YMM raporu.
A16: A0.9 Tasdik Uygunluk Sonucu | F16: =IF(AND(F8="EVET",F9="EVET-Karşılıksız Bağış",F10<>"",F11="EVET",F12="EVET"),"OK - Hesaplanabilir","HATA - Ön koşul eksik") -> OK - Hesaplanabilir | G16: ★ A0.1 kapsam | A0.2 karşılıksız | A0.3 oran (%100/%50) | A0.4 fiili | A0.5 makbuz.
A18: A. GENEL BİLGİLER
A19: Kurumun Unvanı | G19: Tam ticaret unvanı
A20: VKN | G20: 10 haneli VKN
A21: Hesap Dönemi | G21: 01.01.2025 – 31.12.2025
A22: KV Oranı (%) | G22: 2025: %25
A23: Alıcı Kurum | G23: Kültür ve Turizm Bakanlığı / KYD Dernek / Muafiyet Vakfı
A24: Alıcı Statüsü ve Oran | G24: Kamu idaresi → %100 | KYD/Vakıf → %50
A25: Dosya Referansı | G25: YMM-2025/404-01
A28: B. BAĞIŞ ÖZET PARAMETRELERİ — KVK Md.10/1-d
B29: Parametre | E29: Değer | G29: Açıklama | H29: Kaynak
A30: B.1 Konu / Kapsam | E30: Tarihi Miras/Müze/Sanat/Turizm | F30: KVK Md.10/1-d kapsamında kültür/turizm faaliyeti alanı. | H30: Proje/Protokol
A31: B.2 ★ Alıcı Statüsü ve İndirim Oranı | E31: %100 (Kültür ve Turizm Bakanlığı/Kamu) | F31: ORAN KRİTİK: Bakanlık/kamu → %100. KYD/muafiyet vakfı → %50. | H31: Statü belgesi
A32: B.3 Alıcı Kurum Adı | F32: Kültür ve Turizm Bakanlığı / Kamu idaresi / KYD dernek / Muafiyet vakfı. | H32: Belge
A33: B.4 Bağış Tarihi | F33: Fiilen yapılan bağışın tarihi. | H33: Banka/Tutanak
A34: B.5 ★ Nakdi Bağış Tutarı (TL) | F34: Banka yoluyla yapılan nakdi bağış. | H34: Banka dekontu
A35: B.6 Ayni Bağış Değeri (TL — Maliyet/Net Defter Değeri) | F35: Ayni bağış varsa maliyet/net defter değeri. | H35: Stok/sabit kıymet
A36: B.7 ★ BRÜT BAĞIŞ TOPLAMI (B.5 + B.6) | E36: =C34+C35 -> 0 | F36: Nakdi + Ayni brüt toplam. | H36: Formül
A38: C. BAĞIŞ TABLOSU — KVK Md.10/1-d | ★ SÜTUN 6: %100 veya %50 ORAN SEÇİNİZ
A39: ★ SÜTUN 6 (ORAN) ZORUNLU: Her satır için alıcı statüsüne göre %100 veya %50 seçin. Bakanlık/kamu idaresi doğrudan → %100. KYD dernek / Muafiyet vakfı → %50. Sütun 7 (İndirim) orana göre otomatik hesaplanır.
A40: Bağış Tarihi | B40: Konu / Alıcı / Proje | C40: Nakdi (TL) | D40: Ayni Değer (TL) | E40: Brüt Toplam (TL) | F40: ★ ORAN | G40: İndirim (TL) | H40: Makbuz/Belge No
E41: =IF(OR(C41>0,D41>0),C41+D41,0) -> 0 | F41: %100 (Bakanlık/Kamu İdaresi Doğrudan) | G41: =IF(F41="%100 (Bakanlık/Kamu İdaresi Doğrudan)",E41,IF(F41="%50 (KYD Dernek veya Muafiyet Vakfı)",E41*0.5,0)) -> 0
E42: =IF(OR(C42>0,D42>0),C42+D42,0) -> 0 | F42: %50 (KYD Dernek veya Muafiyet Vakfı) | G42: =IF(F42="%100 (Bakanlık/Kamu İdaresi Doğrudan)",E42,IF(F42="%50 (KYD Dernek veya Muafiyet Vakfı)",E42*0.5,0)) -> 0
E43: =IF(OR(C43>0,D43>0),C43+D43,0) -> 0 | F43: %100 (Bakanlık/Kamu İdaresi Doğrudan) | G43: =IF(F43="%100 (Bakanlık/Kamu İdaresi Doğrudan)",E43,IF(F43="%50 (KYD Dernek veya Muafiyet Vakfı)",E43*0.5,0)) -> 0
E44: =IF(OR(C44>0,D44>0),C44+D44,0) -> 0 | F44: %50 (KYD Dernek veya Muafiyet Vakfı) | G44: =IF(F44="%100 (Bakanlık/Kamu İdaresi Doğrudan)",E44,IF(F44="%50 (KYD Dernek veya Muafiyet Vakfı)",E44*0.5,0)) -> 0
E45: =IF(OR(C45>0,D45>0),C45+D45,0) -> 0 | F45: %100 (Bakanlık/Kamu İdaresi Doğrudan) | G45: =IF(F45="%100 (Bakanlık/Kamu İdaresi Doğrudan)",E45,IF(F45="%50 (KYD Dernek veya Muafiyet Vakfı)",E45*0.5,0)) -> 0
...

Sheet HESAPLAMALAR & KONTROL
A1: 404 – KÜLTÜR/TURİZM BAĞIŞLARI KVK Md.10/1-d | HESAPLAMALAR VE DENETİM
A2: %100 Kamu / %50 KYD-Vakıf | KVK Md.10/1-d | Beyanname 404 | ✗ YİAKV E.11
A4: A. TASDİK ÖZETİ
A5: A0 Uygunluğu | E5: ='VERİ GİRİŞİ'!F16 -> OK - Hesaplanabilir | F5: OK ise devam
A6: Alıcı Statüsü/Oran (B.2) | E6: ='VERİ GİRİŞİ'!E31 -> %100 (Kültür ve Turizm Bakanlığı/Kamu) | F6: Kamu %100 / KYD-Vakıf %50
A7: %100 Brüt Bağış (D.1.1) | E7: ='VERİ GİRİŞİ'!E52 -> 0 | F7: Bakanlık/kamu idaresi satırları
A8: %100 İndirim (D.1.2) | E8: ='VERİ GİRİŞİ'!E53 -> 0
A9: %50 Brüt Bağış (D.2.1) | E9: ='VERİ GİRİŞİ'!E56 -> 0 | F9: KYD/muafiyet vakfı satırları
A10: %50 İndirim (D.2.2) | E10: ='VERİ GİRİŞİ'!E57 -> 0 | F10: %50 brüt × %50
A11: 404 TOPLAM İNDİRİM (D.3) | E11: ='VERİ GİRİŞİ'!E59 -> 0 | F11: =E8+E10 -> 0
A12: YİAKV | E12: ✗ DÜŞÜLEMEZ (E.11 Bilgi) | F12: Bağış/yardım tümü YİAKV dışı
A14: B. KVK Md.10/1-d KAPSAMI VE %100/%50 İNDİRİM ORANI TABLOSU
A15: KVK Md.10/1-d — KÜLTÜR VE TURİZM AMAÇLI BAĞIŞ VE YARDIMLAR: KAPSAM — FAAALİYET ALANLARI: • Kültürel miras koruma ve restorasyon (tarihi yapı, alan, eser) • Müze, kütüphane, arşiv kurulumu ve faaliyeti • Güzel sanatlar (resim, heykel, el sanatları, fotoğrafçılık) • Sinema, tiyatro, opera, bale, konser • Kültür/sanat yayıncılığı ve festivaller • Turizm altyapısı ve tanıtım faaliyetleri İNDİRİM ORANI TABLOSU (EN KRİTİK NOKTA): ┌─────────────────────────────────────────────────────────┐ │ ALICI │ ORAN │ AÇIKLAMA │ │ Kültür ve Turizm Bakanlığı │ %100 │ Tamamı │ │ Diğer kamu idaresi (doğrudan) │ %100 │ Tamamı │ │ Bakanlık onaylı proje │ %100 │ Tamamı │ │ KYD Dernek │ %50 │ Yarısı │ │ Muafiyet Vakfı │ %50 │ Yarısı │ └─────────────────────────────────────────────────────────┘ 402/403/417'DEN FARKI: Orada KYD/vakıf için de %100. 404'te KYD/vakıf için sadece %50.
A17: C. 404 (KVK Md.10/1-d) ile 460/461 (SPONSORLUK) KARŞILAŞTIRMASI
A18: 404 (BAĞIŞ) vs 460/461 (SPONSORLUK) — EN KARIŞTIRILAN KOD ÇIFTI: 404 — KVK Md.10/1-d (BAĞIŞ/YARDIM): Karşılıksız — reklam, tanıtım, isim hakkı, bilet vb. HİÇBİR KARŞILIK YOK. İndirim: Kamu/Bakanlık %100, KYD/vakıf %50. 460/461 — KVK Md.10/1-b (SPONSORLUK): Karşılıklı — logodan isim hakkına, biletiyle katılıma kadar karşılık var. İndirim: Amatör spor %100, Profesyonel spor %50. 460/461 kültür etkinlikleri için de uygulanabilir (karşılıklıysa). AYIRT EDİCİ TEST: 'Bu ödemede karşılık (reklam/logo/bilet/isim hakkı) var mı?' EVET → 460/461 (Sponsorluk). HAYIR → 404 (Bağış/Yardım). Yanlış kod seçimi → Yanlış oran uygulaması → Tarhiyat riski.
A20: D. DENETİM KONTROL LİSTESİ (K1–K13)
B21: Kontrol | F21: Açıklama
A22: K1 | B22: ★ Bağış KVK Md.10/1-d kapsamında kültür/turizm amaçlı mı? | F22: Tarihi miras/müze/sanat/turizm kapsamında.
A23: K2 | B23: ★ İşlem karşılıksız bağış mı? (Sponsorluk değil) | F23: Karşılıklıysa → 460/461.
A24: K3 | B24: ★ Her satır için %100 veya %50 oran seçildi mi? | F24: C tablosu F sütunu dolu olmalı.
A25: K4 | B25: ★ %100 satırlarda alıcı kamu idaresi/Bakanlık mı? | F25: KYD/vakıf için %100 uygulanamaz.
A26: K5 | B26: ★ %50 satırlarda KYD/muafiyet belgesi var mı? | F26: KYD: Bakanlık kararı. Vakıf: CB kararı.
A27: K6 | B27: ★ Bağış fiilen yapıldı mı? (Banka / teslim) | F27: Taahhüt → Kapsam dışı.
A28: K7 | B28: ★ Alıcıdan resmi makbuz alındı mı? | F28: Makbuz zorunlu.
A29: K8 | B29: D.3 = D.1.2 + D.2.2 mutabık mı? | F29: İki oran toplamı beyanname 404.
A30: K9 | B30: ★ İndirim matrahı aşıyor mu? (Devredilemez!) | F30: Aşan kısım beyanname notu.
A31: K10 | B31: ✗ YİAKV E.11'de bilgi satırı olarak gösterildi mi? | F31: 404 DÜŞÜLEMEZ — E.11 bilgi.
A32: K11 | B32: Ayni bağış varsa maliyet/net defter değeri esas alındı mı? | F32: Piyasa değeri değil. KDV istisnası.
A33: K12 | B33: Beyanname 404 'Kazancın Bulunması Halinde' bölümünde mi? | F33: Zarar döneminde uygulanamaz.
A34: K13 | B34: YMM Tasdik Raporu (49 No.lu Tebliğ) değerlendirildi mi? | F34: >=500.000 TL → YMM raporu.

Sheet MUHASEBE KAYITLARI
A1: 404 – KÜLTÜR/TURİZM BAĞIŞLARI KVK Md.10/1-d | MUHASEBE KAYITLARI
A2: KAYIT 1 — NAKDİ BAĞIŞ %100 (KÜLTÜR VE TURİZM BAKANLIĞI'NA DOĞRUDAN)
B3: Tarih | C3: Hesap | D3: Not | E3: Dr | F3: Kr | H3: Ref
A4: Dr | B4: [Tarih] | C4: 689 Diğer Olağan Dışı Gid. | D4: KVK Md.10/1-d bağışı — Bakanlık/kamu — gider | E4: [Tutar] | F4: — | G4: Makbuz
A5: KAYIT 2 — NAKDİ BAĞIŞ %50 (KYD DERNEK veya MUAFİYET VAKFI ARACILIĞIYLA)
B6: Tarih | C6: Hesap | D6: Not | E6: Dr | F6: Kr | H6: Ref
A7: Dr | B7: [Tarih] | C7: 689 Diğer Olağan Dışı Gid. | D7: KVK Md.10/1-d bağışı — KYD/vakıf — gider | E7: [Brüt] | F7: — | G7: Makbuz
A8: KAYIT 3 — DÖNEM SONU: KKEG + BEYANNAME 404 İNDİRİMİ
B9: Tarih | C9: Hesap | D9: Not | E9: Dr | F9: Kr | H9: Ref
A10: Dr | B10: [Dönem Sonu] | C10: 951 KKEG | D10: 404 bağış gideri KKEG'e (brüt) — indirim kısmı beyan | E10: [Brüt] | F10: — | G10: Beyanname
A11: DÖNEM SONU MUHASEBE NOTU — BEYANNAME 404: %100 BAĞIŞ (Bakanlık/Kamu): Bağış [Brüt] TL → KKEG → Matrahı artırır → Beyanname 404'te [Brüt] TL × %100 = [Brüt] TL indirim → Matrahtan düşülür. Net KV etkisi: Sıfır (indirim = KKEG). %50 BAĞIŞ (KYD/Vakıf): Bağış [Brüt] TL → KKEG → Matrahı artırır → Beyanname 404'te [Brüt] TL × %50 = [%50] TL indirim → Kalan %50'si kalıcı KKEG. Net KV etkisi: [Brüt × %50 × KV Oranı] TL ek KV yükü. YİAKV: ✗ DÜŞÜLEMEZ — E.11. Ayni bağışta KDV istisnası (KDVK Md.17/2-b).

Sheet DENETCİ NOTLARI
A1: 404 – KÜLTÜR/TURİZM BAĞIŞLARI KVK Md.10/1-d | DENETÇİ NOTLARI
A2: GİB KV Beyan Rehberi 2026 | KVK Md.10/1-d | %100/%50 Oran | 460/461 Farkı | YİAKV E.11
A3: Kod | B3: Konu | C3: Mesleki Değerlendirme / Tasdik Standardı | D3: Mevzuat / Kaynak
A4: N1 | B4: KVK Md.10/1-d — Kapsam ve %100/%50 Oran Tablosu | C4: KVK MADDE 10/1-d — KÜLTÜR VE TURİZM AMAÇLI BAĞIŞ VE YARDIMLAR: KAPSAM: • Kültürel miras koruma ve restorasyon • Müze, kütüphane, arşiv • Güzel sanatlar, sinema, tiyatro, opera, bale, konser • Kültür/sanat yayıncılığı ve festivaller • Turizm altyapısı ve tanıtım İNDİRİM ORANI: %100 → Kültür ve Turizm Bakanlığı'na doğrudan %100 → Diğer kamu idarelerine doğrudan %100 → Bakanlık onaylı proje kapsamında %50 → KYD dernek aracılığıyla %50 → Muafiyet vakfı aracılığıyla YİAKV: ✗ DÜŞÜLEMEZ (E.11) | BEYANNAME: 404 | D4: KVK Md.10/1-d | GİB KV Beyan Reh. 2026 (No:606)
A5: N2 | B5: ★ %100 ile %50 Oran Uygulamasının Sayısal Etkisi | C5: ORAN UYGULAMASI — SAYISAL KARŞILAŞTIRMA (örnek 1.000.000 TL bağış): SENARYO A — Kültür ve Turizm Bakanlığı'na 1.000.000 TL (%100): KKEG: +1.000.000 TL (matrahı artırır) 404 İndirimi: -1.000.000 TL (%100) Net etki: 0 TL ek KV yükü SENARYO B — KYD Kültür Derneğine 1.000.000 TL (%50): KKEG: +1.000.000 TL (matrahı artırır) 404 İndirimi: -500.000 TL (%50) Kalıcı KKEG: +500.000 TL Ek KV: 500.000 × %25 = 125.000 TL YMM UYARISI: %50 yerine %100 uygulamak → Eksik tarhiyat riski. %100 yerine %50 uygulamak → Mükellefi zarara uğratmak. Alıcı statüsü makbuzla belgelenmeli. | D5: KVK Md.10/1-d | GİB Beyan Rehberi
A6: N3 | B6: ★ 460/461 (Sponsorluk) ile 404 (Bağış) Ayrımı — Karıştırma Riski | C6: EN KARIŞTIRILAN KOD ÇİFTİ: 404 — KVK Md.10/1-d (BAĞIŞ/YARDIM): ✓ Karşılıksız — reklam, logo, isim hakkı, bilet yok. ✓ Kültür ve turizm amaçlı. ✓ Oran: Kamu %100, KYD/vakıf %50. 460 — KVK Md.10/1-b (PROFESYONELSPONSOLUK): ✓ Karşılıklı — logolu afiş, biletle katılım, isim hakkı vb. ✓ Profesyonel spor olayları için %50. 461 — KVK Md.10/1-b (AMATÖR SPONSORLUK): ✓ Karşılıklı — amatör spor ve kültür etkinlikleri %100. AYIRT EDİCİ TEST: 'Bu ödemede şirkete bir karşılık (logo, bilet, isim) verilecek mi?' EVET → Sponsorluk (460/461). HAYIR → Bağış/Yardım (404). Kültür etkinliği hem 404 hem 461 kapsamında olabilir. Belirleyici: Karşılık var mı? | D6: KVK Md.10/1-b | KVK Md.10/1-d | GİB Özelge
A7: N4 | B7: 402/403/417 ile 404 Oran Farkı — Kritik Bağlam | C7: BAĞIŞ KODLARINDA ORAN KARŞILAŞTIRMASI: 402 (KVK Md.10/1-c) — Okul/hastane/yurt inşaatı: Kamu → %100 | KYD → %100 | Muafiyet vakfı → %100 403 (KVK Md.10/1-5) — Eğitim/sağlık/gençlik/yurt: Kamu → %100 | KYD → %100 | Muafiyet vakfı → %100 417 (KVK Md.10/1-5) — İbadethane: Kamu → %100 | KYD → %100 | Muafiyet vakfı → %100 404 (KVK Md.10/1-d) — Kültür/turizm: Kamu → %100 | KYD → %50 | Muafiyet vakfı → %50 ★ 402/403/417'de KYD/vakıf için de tamamı indirilirken 404'te KYD/vakıf için sadece %50 indirilir. Bu farkı bilmeden 404 bağışında %100 uygulamak ciddi hata. | D7: KVK Md.10/1-c | KVK Md.10/1-5 | KVK Md.10/1-d
A8: N5 | B8: YİAKV ve 49 No.lu Tebliğ Tasdik Dil Standardı | C8: YİAKV (KVK Md.32/C) VE 404 BAĞIŞI: ✗ 404 (KVK Md.10/1-d): DÜŞÜLEMEZ → YİAKV E.11 KULLANIN (%100 — Bakanlık): '...KVK'nın 10. maddesinin (d) bendi kapsamında Kültür ve Turizm Bakanlığı'na [Tarih] tarihinde banka yoluyla ödenen [Tutar] TL bağışın tamamı (%100) olan [Tutar] TL matrahtan indirilmiştir. Söz konusu tutar YİAKV matrahından indirilmemiştir.' KULLANIN (%50 — KYD/Vakıf): '...KVK Md.10/1-d kapsamında [KYD/Vakıf Adı]'na ödenen [Brüt] TL bağışın %50'si olan [İndirim] TL matrahtan indirilmiştir. Söz konusu tutar YİAKV matrahından indirilmemiştir.' KULLANMAYIN: '...KYD derneğine bağış %100 indirilmiştir.' (→ %50 olmalı) '...Sponsorluk 404 kapsamında.' (Karşılıklıysa → 460/461) '...404 YİAKV matrahından düşülmüştür.' (YANLIŞ) | D8: 49 No.lu Tebliğ | KVK Md.10/1-d | SM-SMMM-YMM K. Md.12
A9: GİB KV BEYAN REHBERİ MART 2026 (No:606) KAPANIŞ (404): KVK Md.10/1-d — Kültür/turizm bağışı. Oran: Bakanlık/kamu %100, KYD/muafiyet vakfı %50. 402/403/417'den farklı — orada KYD için de %100; burada %50. 460/461 sponsorlukla karıştırılmamalı (karşılık testi). ✗ YİAKV E.11. YMM: SM-SMMM-YMM K. Md.12.

Sheet BELGE LISTESI
A1: 404 – KÜLTÜR/TURİZM BAĞIŞLARI KVK Md.10/1-d | BELGE LİSTESİ | YMM TASDİK
A2: Makbuz | KYD/Muafiyet Belgesi | Banka Dekontu | Karşılıksızlık Kanıtı | YİAKV E.11
A4: KATEGORİ 1 — ZORUNLU BELGELER
B5: No | C5: Belge | D5: Açıklama | E5: Temin
B6: 1 | C6: ★ Alıcıdan Resmi Bağış Makbuzu | D6: Kültür ve Turizm Bakanlığı, kamu idaresi, KYD dernek veya muafiyet vakfından resmi makbuz. Bağışın karşılıksız niteliği makbuzda açık olmalı. Zorunlu. | E6: Bakanlık / Kamu İdaresi / KYD / Muafiyet Vakfı
B7: 2 | C7: ★ %50 İçin: KYD Dernek veya Muafiyet Vakfı Statü Belgesi | D7: KYD: İlgili bakanlık kararı veya Resmî Gazete. Muafiyet vakfı: Cumhurbaşkanlığı/BK kararı. %100 (kamu idaresi) için bu belge gerekmez. | E7: İlgili Bakanlık / Resmî Gazete
B8: 3 | C8: ★ Nakdi Bağış — Banka EFT/Havale Dekontu | D8: Her nakdi ödeme için ayrı banka dekontu. | E8: Banka / Şirket hesabı
B9: 4 | C9: ★ Bağışın Karşılıksız Niteliğini Gösteren Belge | D9: Ödeme karşılığında reklam, logo, bilet, isim hakkı verilmediğini gösteren protokol, yazışma veya beyan. 404 ile 460/461 ayrımında kilit belge. | E9: İç onay / Yazışma
B10: 5 | C10: Ayni Bağış — Teslim Tutanağı + Maliyet Notu | D10: Ayni bağış (eser, ekipman, materyal) için teslim tutanağı ve maliyet/defter değeri. KDV hesaplanmaz (KDVK Md.17/2-b). | E10: Teslim sırasında
B11: 6 | C11: KV Beyannamesi 404 Satırı + YİAKV E.11 Bilgi | D11: Beyanname 404 = D.3 (D.1.2 + D.2.2) tutarı. YİAKV E.11 = 402+403+404+417+diğer bağış kodları dönem toplamı. | E11: GİB e-Beyanname + YİAKV ÇK
A13: KATEGORİ 2 — YMM TASDİK KONTROL SORULARI
B14: No | C14: Kontrol Sorusu | D14: Beklenen Sonuç | E14: YMM Aksiyonu
B15: S1 | C15: ★ Bağış KVK Md.10/1-d kapsamında kültür/turizm amaçlı mı? | D15: Kapsam içi faaliyet alanı. | E15: YMM kontrolü
B16: S2 | C16: ★ İşlem karşılıksız mı? (Sponsorluk değil) | D16: Karşılıklıysa → 460/461. | E16: YMM kontrolü
B17: S3 | C17: ★ Her satır için %100 veya %50 oran seçildi mi? | D17: C tablosu F sütunu eksiksiz. | E17: YMM kontrolü
B18: S4 | C18: ★ %100 satırlarda alıcı kamu idaresi/Bakanlık mı? | D18: KYD/vakıf için %100 yasak. | E18: YMM kontrolü
B19: S5 | C19: ★ %50 satırlarda statü belgesi temin edildi mi? | D19: KYD kararı / Muafiyet kararı. | E19: YMM kontrolü
B20: S6 | C20: ★ Bağış fiilen yapıldı mı? (Banka / teslim) | D20: Taahhüt → Kapsam dışı. | E20: YMM kontrolü
B21: S7 | C21: ★ Alıcıdan resmi makbuz alındı mı? | D21: Makbuz zorunlu. | E21: YMM kontrolü
B22: S8 | C22: Bağışın karşılıksız niteliği belgelendi mi? | D22: Logo/reklam/bilet yokluğu kanıtı. | E22: YMM kontrolü
B23: S9 | C23: D.3 = D.1.2 + D.2.2 doğru mu? | D23: İki oran toplamı beyanname 404. | E23: YMM kontrolü
B24: S10 | C24: ★ İndirim matrahı aşıyor mu? (Devredilmez!) | D24: Aşan kısım beyanname notu. | E24: YMM kontrolü
B25: S11 | C25: ✗ YİAKV E.11'de bilgi satırı var mı? | D25: 404 DÜŞÜLEMEZ — E.11. | E25: YMM kontrolü
B26: S12 | C26: YMM Tasdik Raporu değerlendirildi mi? | D26: >=500.000 TL → Rapor. | E26: YMM kontrolü
A28: GİB KV BEYAN REHBERİ MART 2026 (No:606) | 404 KVK Md.10/1-d KÜLTÜR/TURİZM BAĞIŞI SON NOT: İNDİRİM ORANI: Bakanlık/kamu idaresi → %100 | KYD dernek/muafiyet vakfı → %50. 402/403/417'den FARK: Orada KYD/vakıf için de %100; 404'te %50. 460/461 SPONSORLUKTAN FARK: Karşılıksız → 404. Karşılıklı (logo/bilet) → 460/461. Matrahı aşan kısım devredilemez. ✗ YİAKV E.11 (402+403+404+417+diğer tüm kodlar). YMM müteselsil sorumluluk: SM-SMMM-YMM Kanunu Md.12.
