Workbook

Sheet VERİ GİRİŞİ
A1: 409 - AR-GE INDIRIMI (KVK Md. 10/1-a) | COK PROJELI | TEK/COK PROJE UNIFIED | YMM TASDIK CALISMA KAGIDI
A2: KVK Md. 10/1-a | Ar-Ge Merkezi belgesi gerekmez | Devreden indirim: YDO artisi YOK (410'dan fark) | Beyanname Satir 409 | Maks. 5 Proje | C8 = Aktif Proje Sayisi
A3: KULLANIM: C8 = 1 -> Tek Proje (sadece C sutunu). C8 = 2-5 -> Cok Proje (C-G sutunlari). Kullanilmayan proje sutunlari gri olur. Beyanname 409 tutari KONSOLIDASYON sayfasi B.3 satirindan alinir.
A5: MODUL KIMLIGI VE VERSIYON
A6: Modul Kodu | C6: 409 - KVK Md. 10/1-a Ar-Ge Indirimi | Cok Projeli Unified Versiyon | H6: KVK 10/1-a | 5746 Md.3 (410) ve Md.3/A (454)'ten farkli rejim
A7: Calisma Kagidi Versiyonu | C7: v1.0 | 1 No.lu KV GT | 49 No.lu Teblig (30.12.2025) | H7: Devreden indirim YDO artisi YOK
A8: Aktif Proje Sayisi (1-5) | C8: 1 | D8: 1=Tek Proje (C sutunu) | 2-5=Cok Proje (C-G) | H8: C8 = 1 Tek Proje | C8 = 2-5 Cok Proje
A10: A0. KAPSAM VE NITELIK UYGUNLUK KONTROLU - TUM PROJELER ICIN ORTAK
A11: UYARI: KVK Md. 10/1-a kapsaminda Ar-Ge Merkezi belgesi veya STB proje onayi GEREKMEZ. Ancak faaliyetlerin isletme bunyesinde ve muhasiren yeni teknoloji/bilgi arayisina yonelik olmasi sarttir. KRITIK FARK (410'a gore): Devreden indirim YDO ile artirilmaz - artirimsiz devredilir. Ayni harcama icin hem 409 hem de 410/454 birlikte kullanilamaz.
A12: Kontrol Sorusu | C12: Yanit | D12: Aciklama / YMM Tasdik Notu
A13: A0.1 Ar-Ge faaliyetleri munhasiran yeni teknoloji ve bilgi arayisina yonelik mi? | C13: EVET | D13: Mevcut bilgi veya tekniklerle cozulebilir faaliyetler kapsam disindir. Rutin gelistirme, pazarlanabilir urun testleri kapsama girmez.
A14: A0.2 Ar-Ge faaliyetleri ISLETME BUNYESINDE mi gerceklestiriliyor? | C14: EVET | D14: KVK 10/1-a kapsaminda faaliyetlerin isletme bunyesinde yurutulmesi zorunludur. Disaridan alinan hizmetler sinirli olabilir. 5746 Md. 3/A (454) ise proje bazli-ozkaynakla yapilana uygulanir - bu farkldir.
A15: A0.3 Harcamalar diger faaliyetlerden ayri muhasebeleştiriliyor mu? | C15: EVET | D15: KVK 10/1-a kapsaminda Ar-Ge harcamalari, diger faaliyetlerden ayristirilarak muhasebeleştirilmeli ve indirim tutarinin dogru hesaplanmasina imkan verilmelidir. 1 No.lu KV GT'de bu ayirim zorunlu tutulmustur.
A16: A0.4 Ayni harcamalar icin 5746 Md. 3 (410) veya Md. 3/A (454) uygulanmakta mi? | C16: HAYIR | D16: CIFTE INDIRIM YASAGI: Ayni Ar-Ge harcamasi icin hem KVK 10/1-a (409) hem de 5746 (410 veya 454) birlikte kullanilamaz. Mükellef hangi kanun kapsaminda yararlanacagini secmeli ve tutarli sekilde uygulamalidir.
A17: A0.5 Devreden Ar-Ge indirimi var mi? (YDO artisi YOK - artirimsiz devredilir) | C17: HAYIR | D17: KVK 10/1-a'da devreden indirim YDO ile artIRILMAZ - aynen devredilir. 410 (5746) ve ayni kodun farklidir. Onceki yildan gelen tutar D.4 satirina dogrudan yazilir.
A18: A0.6 YiAKV (KVK Md. 32/C) etkisi analiz edildi mi? | C18: EVET | D18: 409 kodlu Ar-Ge indirimi 'Kazancin Bulunmasi Halinde Indirilecek' bolumundedir. YiAKV matrahina etkisi donem mevzuati cercevesinde ayrica analiz edilmelidir.
A19: A0.7 49/41 No.lu Teblig: YMM tasdik raporu yukumlulugu var mi? | C19: EVET | D19: 49 No.lu Teblig: Tek satir >=500.000 TL veya toplam >=1.000.000 TL -> YMM raporu zorunlu. 41 No.lu Teblig Ar-Ge indirimi tasdik sarti da ayrica degerlendirilmeli.
A20: A0.8 Tasdik Uygunluk Sonucu | C20: =IF(AND(C13="EVET",C14="EVET",C15="EVET",C16="HAYIR",C18="EVET",C19="EVET"),"OK - Hesaplanabilir","HATA - On kosul eksik") -> OK - Hesaplanabilir | D20: Zorunlu: A0.1/A0.2/A0.3 (EVET) + A0.4 (HAYIR - cifte indirim yok) + A0.6/A0.7 (EVET). A0.4=EVET ise cifte indirim riski - modulu kullanamazsiniz.
A21: Tasdik Engelleyici | C21: =IF(C20="HATA - On kosul eksik","BU MODUL KULLANILAMAZ - A0 kontrolunu tamamlayin","") | D21: Hata giderildiginde uyari kalkar.
A23: A. MUKELLEF BİLGİLERİ (Tum Projeler Icin Ortaktir)
A24: Alan | C24: Bilgi | I24: Aciklama
A25: Mukellef Unvani | I25: Ticaret sicilindeki tam unvan
A26: Vergi Kimlik No | I26: 10 haneli VKN
A27: Hesap Donemi | I27: 01.01.…… - 31.12.……
A28: Uygulanan Rejim | I28: KVK 10/1-a - 5746 Md.3 (410) degil
A29: KV Orani (%) | I29: Genel: %25 (2025); Finans: %30
A31: B. PROJE BILGILERI (C-G: Proje 1-5 | Kullanilmayan sutunlar gri olur)
B32: Proje Bilgisi | C32: Proje 1 | D32: Proje 2 | E32: Proje 3 | F32: Proje 4 | G32: Proje 5 | H32: Toplam | I32: Not
A33: P.1 | B33: Proje Adi / Baslik | I33: Kisa tanimlayici
A34: P.2 | B34: Ar-Ge Projesi Niteligi (KVK 10/1-a kapsami) | I34: Proje icerigi ve nitelik aciklamasi
A35: P.3 | B35: Proje Baslangic - Bitis Tarihi | I35: GG.AA.YYYY - GG.AA.YYYY
A37: C. AR-GE HARCAMA TURLERI — KVK Md. 10/1-a (1 No.lu KV GT) | C-G: Proje 1-5 | H: Toplam
A38: KVK 10/1-a kapsami: Muhasebede Ar-Ge hesabina atilan her tutar otomatik indirime girmez. Her harcama: (a) Muhasebede kayitli, (b) KVK 10/1-a kapsaminda uygun, (c) Proje ile dogrudan iliskili. Finansman giderleri (H.6) kapsam disidir. NOT: 5746'dan farkli olarak destek personeli %10 ve dis hizmet %20 limiti bu kapsam icin acikca belirlenmemistir.
A39: Kod | B39: Harcama Turu (KVK 10/1-a / 1 No.lu KV GT) | C39: Proje 1 (TL) | D39: Proje 2 (TL) | E39: Proje 3 (TL) | F39: Proje 4 (TL) | G39: Proje 5 (TL) | H39: Toplam (TL) | I39: KVK 10/1-a Kapsam Notu
A40: H.1 | B40: Ar-Ge Personeli Ucret Giderleri (Ar-Ge faaliyetine dogrudan tahsis edilen) | H40: =SUM(C40:G40) -> 0 | I40: Ar-Ge personelininin Ar-Ge faaliyetine ayirilen surede tahakkuk eden ucretleri. Kismi calismada: Ar-Ge suresi/Toplam sure orani uygulanir. KVK 10/1-a'da 5746 gibi GV stopaj terkini yoktur.
A41: H.2 | B41: Malzeme ve Hammadde Giderleri (Ar-Ge'ye ozgu tuketilen) | H41: =SUM(C41:G41) -> 0 | I41: Dogrudan Ar-Ge projesi icin tüketilen malzeme ve hammadde. Genel uretimdeki malzeme bu kapsamda yer almaz.
A42: H.3 | B42: Amortisman Giderleri (Ar-Ge'de kullanilan ATiK'lere isabet eden) | H42: =SUM(C42:G42) -> 0 | I42: Tamamen Ar-Ge'de kullanilan ATiK'ler icin hesaplanan amortismanlar. Kismen kullanilanlar: gün sayisi oraninda dahil edilir.
A43: H.4 | B43: Disaridan Alinan Fayda ve Hizmetler (Universite, Arastirma Kurumu vb.) | H43: =SUM(C43:G43) -> 0 | I43: Universite, arastirma merkezi vb. kuruluslardan alinan Ar-Ge hizmetleri. KVK 10/1-a'da 5746'daki gibi acik bir %20 siniri yoktur; ancak faaliyetlerin isletme bunyesinde oldugu ozunde korunmalidir.
A44: H.5 | B44: Genel Giderler (Ar-Ge faaliyetine isabet eden orantili pay) | H44: =SUM(C44:G44) -> 0 | I44: Kira, enerji, su, haberlesme gibi genel giderlerin Ar-Ge'ye isabet eden payi. Makul ve belgelenebilir dagilim anahtari kullanilmalidir.
A45: H.6 | B45: Vergi, Resim ve Harclara (Proje ile Dogrudan Iliskili) | H45: =SUM(C45:G45) -> 0 | I45: Ar-Ge projesiyle dogrudan ilgili vergi ve harclar.
...

Sheet KONSOLIDASYON & BEYANNAME
A1: 409 - AR-GE INDIRIMI (KVK Md. 10/1-a) | KONSOLIDASYON & BEYANNAME SONUC SAYFASI
A2: Tum projelerin D.5 degerleri birlestirilir -> Toplam kullanilabilir -> Kazanc limiti -> Beyanname 409 tutari ve devreden hesaplanir.
A3: =IF('VERİ GİRİŞİ'!C8=1,"TEK PROJE MODU: Proje 1 (C sutunu). Beyanname 409 = B.3 = MIN(D.5 Proje1, Donem Kazanci).","COK PROJE MODU: "&'VERİ GİRİŞİ'!C8&" proje aktif. Tum D.5 toplami kazanc limitiyle sinirlandirilir.") -> TEK PROJE MODU: Proje 1 (C sutunu). Beyanname 409 = B.3 = MIN(D.5 Proje1, Donem Kazanci).
A5: BOLUM 1 — PROJE BAZINDA KULLANILABILIR INDIRIM (VERİ GİRİŞİ'nden)
B6: Kalem | C6: Proje 1 | D6: Proje 2 | E6: Proje 3 | F6: Proje 4 | G6: Proje 5 | H6: TOPLAM | I6: YMM Notu
A7: K.1 | B7: D.3 - Temel Ar-Ge Indirimi (Cari Donem %100) | C7: ='VERİ GİRİŞİ'!C54 -> 0 | D7: ='VERİ GİRİŞİ'!D54 -> 0 | E7: ='VERİ GİRİŞİ'!E54 -> 0 | F7: ='VERİ GİRİŞİ'!F54 -> 0 | G7: ='VERİ GİRİŞİ'!G54 -> 0 | H7: =SUM(C7:G7) -> 0 | I7: Proje harcamasinin %100'u
A8: K.2 | B8: D.4 - Devreden Indirim (Artirimsiz - YDO YOK) | C8: ='VERİ GİRİŞİ'!C55 -> 0 | D8: ='VERİ GİRİŞİ'!D55 -> 0 | E8: ='VERİ GİRİŞİ'!E55 -> 0 | F8: ='VERİ GİRİŞİ'!F55 -> 0 | G8: ='VERİ GİRİŞİ'!G55 -> 0 | H8: =SUM(C8:G8) -> 0 | I8: KVK 10/1-a: YDO artisi uygulanmaz
A9: K.3 | B9: D.5 - PROJE KULLANILABILIR TOPLAM (K.1+K.2) | C9: ='VERİ GİRİŞİ'!C56 -> 0 | D9: ='VERİ GİRİŞİ'!D56 -> 0 | E9: ='VERİ GİRİŞİ'!E56 -> 0 | F9: ='VERİ GİRİŞİ'!F56 -> 0 | G9: ='VERİ GİRİŞİ'!G56 -> 0 | H9: =SUM(C9:G9) -> 0 | I9: Proje bazinda kullanilabilir azami tutar
A11: BOLUM 2 — DONEM KAZANC LIMITİ VE BU DONEM KULLANILACAK TOPLAM INDIRIM
A12: KVK 10/1-a Ar-Ge indirimi 'Kazancin Bulunmasi Halinde Indirilecek' bolumudir. Tum projelerin kullnilabilir indirimi toplanir, donem kazanciyla sinirlandirilir. KRITIK: Devreden indirim YDO ile artirilmaz - bir sonraki yilda artirimsiz devredilir.
A13: Kalem | C13: Tutar (TL) | H13: Not
A14: B.1 | B14: TOPLAM KULLANILABILIR INDIRIM (Tum Projelerin D.5 Toplami) | C14: =H9 -> 0 | H14: Tum projelerin kumulatif kullanilabilir indirimi
A15: B.2 | B15: Donem Kurum Kazanci (KKEG Sonrasi / Beyanname 409 Oncesi) | H15: ONEMLI: Ticari kar degil - KKEG+, gecmis yil zararlari sonrasi, 409 dusulmeden onceki tutari giriniz
A16: B.3 | B16: BU DONEM TOPLAM KULLANILACAK INDIRIM (Min B.1, B.2) | C16: =MIN(C14,C15) -> 0 | H16: KV Beyannamesi Satir 409 - 'Kazancin Bulunmasi Halinde Indirilecek'
A17: B.4 | B17: Sonraki Doneme Devreden TOPLAM (B.1 - B.3) - YDO artisi OLMAYACAK | C17: =MAX(0,C14-C16) -> 0 | H17: KVK 10/1-a: Bu tutar YDO ile artIRILMAZ - proje bazinda D.4 olarak aktarilir
A19: BOLUM 3 — PROJE BAZINDA INDIRIM KULLANIM DAGILIMI (Pro-Rata)
A20: Kazanc yeterli ise her proje D.5 tutarini tam kullanir. Kazanc yetersiz ise dagitim pro-rata veya YMM tercihine gore belirlenir. Beyannamede yalnizca B.3 (toplam) gosterilir. H sutunu = sonraki yila devreden (YDO artisi OLMAYACAK - D.4 olarak aktarilir).
B21: Proje | C21: Kullanilan | H21: Sonraki Yil Devreden | I21: Not
A22: P1 | B22: Proje 1 - Kullanilan ve Devreden | C22: =IFERROR(MIN(C9,C16*(C9/H9)),0) -> 0 | H22: =MAX(0,C9-C22) -> 0 | I22: Devreden = sonraki yil D.4 satirina yazilir. YDO ile artirilmaz - KVK 10/1-a kurali.
A23: P2 | B23: Proje 2 - Kullanilan ve Devreden | C23: =IFERROR(MIN(D9,C16*(D9/H9)),0) -> 0 | H23: =MAX(0,D9-C23) -> 0 | I23: Devreden = sonraki yil D.4 satirina yazilir. YDO ile artirilmaz - KVK 10/1-a kurali.
A24: P3 | B24: Proje 3 - Kullanilan ve Devreden | C24: =IFERROR(MIN(E9,C16*(E9/H9)),0) -> 0 | H24: =MAX(0,E9-C24) -> 0 | I24: Devreden = sonraki yil D.4 satirina yazilir. YDO ile artirilmaz - KVK 10/1-a kurali.
A25: P4 | B25: Proje 4 - Kullanilan ve Devreden | C25: =IFERROR(MIN(F9,C16*(F9/H9)),0) -> 0 | H25: =MAX(0,F9-C25) -> 0 | I25: Devreden = sonraki yil D.4 satirina yazilir. YDO ile artirilmaz - KVK 10/1-a kurali.
A26: P5 | B26: Proje 5 - Kullanilan ve Devreden | C26: =IFERROR(MIN(G9,C16*(G9/H9)),0) -> 0 | H26: =MAX(0,G9-C26) -> 0 | I26: Devreden = sonraki yil D.4 satirina yazilir. YDO ile artirilmaz - KVK 10/1-a kurali.
A27: CTR | B27: Dagilim Kontrol: Toplam Kullanilan = B.3 ile Uyumlu | C27: =SUM(C22:C26) -> 0 | H27: =ROUND(C27-C16,0) -> 0 | I27: H sutunu 0 ise dagilim dogru

Sheet HESAPLAMALAR & KONTROL
A1: 409 - AR-GE INDIRIMI (KVK Md. 10/1-a) | HESAPLAMALAR VE DENETIM KONTROL PANELI
A2: =IF('VERİ GİRİŞİ'!C8=1,"TEK PROJE | Proje 1 C sutunu -> KONSOLIDASYON B.3 = Beyanname 409","COK PROJE: "&'VERİ GİRİŞİ'!C8&" proje -> D.5 toplami -> KONSOLIDASYON B.3 = Beyanname 409") -> TEK PROJE | Proje 1 C sutunu -> KONSOLIDASYON B.3 = Beyanname 409
A4: TASDIK OZET - KONSOLIDASYON SAYFASINDAN
A5: A0 Tasdik Uygunlugu | D5: ='VERİ GİRİŞİ'!C20 -> OK - Hesaplanabilir | G5: VERİ GİRİŞİ A0.8 - OK ise hesap kullanilabilir
A6: Toplam Kapsam Ici Harcama (TL) | D6: ='VERİ GİRİŞİ'!H47 -> 0 | G6: Tum projelerin H toplami
A7: Toplam Kullanilabilir Indirim (D.5) | D7: ='KONSOLIDASYON & BEYANNAME'!H9 -> 0 | G7: K.3 - Tum proje D.5 toplami
A8: Bu Donem Kullanilacak Indirim | D8: ='KONSOLIDASYON & BEYANNAME'!C16 -> 0 | G8: B.3 - Beyanname 409
A9: Sonraki Doneme Devreden (YDO ARTISI YOK) | D9: ='KONSOLIDASYON & BEYANNAME'!C17 -> 0 | G9: B.4 - Artirimsiz devreder
A11: DENETIM VE TASDIK KONTROL LISTESI (K1-K8) — KVK Md. 10/1-a
A12: Kontrol | C12: Yasal Dayanak | D12: YMM Tasdik Notu | E12: Deg. | F12: Sonuc
A13: K1. Ar-Ge faaliyeti munhasiran yeni teknoloji/bilgi arayisina yonelik mi? Proje gerekliligi tevsik edildi mi? | C13: KVK Md. 10/1-a | 1 No.lu KV GT | D13: Mevcut bilgi veya tekniklerle cozulebilir faaliyetler kapsam disidir. Proje tanimi, teknik belgeler ve faaliyet icerigi tasdik dosyasinda bulunmalidir. | E13: Uygun / Eksik / Risk
A14: K2. Faaliyetler isletme bunyesinde mi? Disaridan alinan hizmetlerin orantisi makul mu? | C14: KVK Md. 10/1-a | 1 No.lu KV GT | D14: KVK 10/1-a'da faaliyetlerin isletme bunyesinde olmasi esastir. Disaridan alinan hizmetlerin orantisi ve niteligi belgelenmelidir. | E14: Uygun / Eksik / Risk
A15: K3. Ayni harcama icin 5746 (410/454) ile cifte indirim uygulanmiyor mu? | C15: KVK Md. 10/1-a | 5746 Kanunu | D15: CIFTE INDIRIM YASAGI: Ayni Ar-Ge harcamasi icin hem 409 hem de 410/454 birlikte kullanilamaz. Secilen rejim tutarli sekilde uygulanmalidir. | E15: Uygun / Eksik / Risk
A16: K4. Harcamalar diger faaliyetlerden ayri muhasebeleştirildi mi? | C16: 1 No.lu KV GT Bolum 10.1 | D16: Ar-Ge harcamalari, isletmenin diger faaliyetlerine ait harcamalardan ayristirilarak muhasebeleştirilmeli ve proje bazinda izlenmelidir. | E16: Uygun / Eksik / Risk
A17: K5. D.4 Devreden indirim YDO ile artirilmadan kullanildi mi? | C17: KVK Md. 10/1-a | 1 No.lu KV GT | D17: KRITIK FARK: KVK 10/1-a'da devreden indirim YDO ile artirilmaz. 410 (5746) ile bu fark cok onemlidir. Onceki yil bakiyesi dogrudan kullanilir. | E17: Uygun / Eksik / Risk
A18: K6. Finansman giderleri kapsam disinda tutuldu mu? | C18: KVK Md. 10/1-a | 1 No.lu KV GT | D18: Faiz ve diger finansman giderleri Ar-Ge harcamasi sayilmaz. H.7 satirinda yer alirlar ve indirim toplamina dahil edilmez. | E18: Uygun / Eksik / Risk
A19: K7. YiAKV (KVK Md. 32/C) matrahina etkisi analiz edildi mi? | C19: KVK Md. 32/C | D19: 409 kodu 'Kazancin Bulunmasi Halinde Indirilecek' bolumdedir. YiAKV matrahina etkisi donem mevzuati cercevesinde ayrica analiz edilmelidir. | E19: Uygun / Eksik / Risk
A20: K8. 49/41 No.lu Teblig tasdik raporu yukumlulugu degerlendirildi mi? | C20: 49 No.lu Teblig (30.12.2025) | 41 No.lu Teblig | D20: Tek satir >=500.000 TL veya toplam >=1.000.000 TL -> YMM tasdik raporu zorunlu. Tam tasdik yaptIranlar ayrica rapor gerektirmez. | E20: Uygun / Eksik / Risk

Sheet DENETCI NOTLARI
A1: 409 - AR-GE INDIRIMI (KVK Md. 10/1-a) | YMM MESLEKI DEGERLENDIRME VE TASDIK NOTLARI
A2: -> 409 KVK 10/1-a | Devreden indirim YDO artisi YOK | 410/5746 ile cifte indirim yasak

Sheet BELGE LISTESI
A1: 409 - AR-GE INDIRIMI (KVK Md. 10/1-a) | TASDIK BELGE LISTESI VE DENETIM KANITI ENVANTER
A2: -> 409 KVK 10/1-a | Devreden indirim YDO artisi YOK | 410/5746 ile cifte indirim yasak

Sheet MUHASEBE KAYITLARI
A1: 409 - AR-GE INDIRIMI (KVK Md. 10/1-a) | MUHASEBE KAYITLARI CALISMA KAGIDI
A2: -> 409 KVK 10/1-a | Devreden indirim YDO artisi YOK | 410/5746 ile cifte indirim yasak
