Workbook

Sheet VERİ GİRİŞİ
A1: 410 – AR-GE İNDİRİMİ (5746 s.K. Md. 3) | ÇOK PROJELİ ÇALIŞMA KÂĞIDI (Maks. 5 Proje) | YMM TASDİK
A2: 5746 s.K. Md. 3 | Ar-Ge Merkezi Belgeli | Her Proje Ayrı İzlenir | Sonuç → KONSOLİDASYON sayfası | Beyanname Satır 410
A3: ℹ️ KULLANIM: Mükellef aynı dönemde 5'e kadar Ar-Ge projesi ile bu çalışma kâğıdını kullanabilir. Her projenin harcamaları C–G sütunlarına ayrı ayrı girilir. H sütunu otomatik toplam alır. Proje bazında D.6 (kullanılabilir indirim) hesaplanır; dönem kazanç limiti ise KONSOLİDASYON sayfasında uygulanır.
A5: MODÜL KİMLİĞİ VE VERSİYON
A6: Modül Kodu | C6: 410 — 5746 s.K. Md. 3 (Ar-Ge Merkezi) | Çok Projeli Versiyon | Maks. 5 Proje
A7: Çalışma Kâğıdı Versiyonu | C7: v2.0 — Çok Projeli | 7555 s.K. (24.07.2025) + 7263 s.K. GSF Yükümlülüğü
A8: Hazırlama Tarihi
A10: A0. KAPSAM VE NİTELİK UYGUNLUK KONTROLÜ — TÜM PROJELER İÇİN ORTAK ÖN KONTROL
A11: ⚠️ Bu blok tüm projeler için ortaktır. STB 'Ar-Ge Merkezi Belgesi' tüm projelerin ön koşuludur. Mükellef aynı Ar-Ge merkezinde birden fazla projeyi eş zamanlı yürütüyor olabilir. Her proje için A0 yeniden doldurulmaz — bir kez 'EVET' verilen kontroller tüm projeler için geçerlidir.
A12: Tasdik Uygunluk Kontrol Soruları | C12: Yanıt | D12: Açıklama / Tasdik Notu
A13: A0.1 Ar-Ge faaliyetleri münhasıran yeni teknoloji ve bilgi arayışına yönelik mi? | C13: EVET | D13: Kapsam dışı faaliyetler (pazarlanabilir ürün geliştirme, rutin iyileştirme vb.) indirime konu edilemez.
A14: A0.2 STB 'Ar-Ge Merkezi Belgesi' geçerli ve koşullar sağlanıyor mu? | C14: EVET | D14: 410 kodu için Ar-Ge Merkezi Belgesi zorunlu önkoşuldur. Belge geçersizse tüm projeler için modül kullanılamaz.
A15: A0.3 En az 15 TZE Ar-Ge personeli koşulu sağlanıyor mu? (Bazı sektörlerde 30) | C15: EVET | D15: BKK ile 15 (genel) / 30 (bazı NACE). Bu koşulun kaybedilmesi belge iptaline yol açar.
A16: A0.4 Her projedeki harcamalar 'Ar-Ge projesi' kapsamında ve ayrı izlenebilir mi? | C16: EVET | D16: Her proje ayrı proje kodu altında ve ayrı hesapta izlenmelidir. Proje bazı muhasebe zorunludur.
A17: A0.5 Sipariş bazlı Ar-Ge var mı? (Varsa proje bazında belirtiniz — H.8/H.9) | C17: HAYIR | D17: Sipariş alan merkez %50 / sipariş veren %50 dağılımı her proje için ayrı uygulanır.
A18: A0.6 Artırımlı indirim için 5 göstergeden biri ≥%20 artış sağlandı mı? | C18: EVET | D18: ≥%20 artış → artış tutarının %50'si ek indirim (31.12.2028). Proje veya merkez bazında değerlendirilebilir.
A19: A0.7 Devreden Ar-Ge indirimi var mı? (Proje bazında D.5a-D.5b sütunlarına giriniz) | C19: HAYIR | D19: Her projenin devreden indirimi VERİ GİRİŞİ D.5a satırına ayrı ayrı girilir. YDO artışı otomatik hesaplanır.
A20: A0.8 Md. 3/14 GSF: Herhangi bir projede kullanılan indirim ≥ 1.000.000 TL mi? | C20: HAYIR | D20: GSF yükümlülüğü KONSOLİDASYON sayfasında toplam bazında otomatik kontrol edilir.
A21: A0.9 YİAKV etkisi: Ar-Ge indirimleri YİAKV matrahına etkisi analiz edildi mi? | C21: EVET | D21: Kazancın Bulunması Halinde bölümündeki indirimin YİAKV matrahına etkisi dönem mevzuatıyla analiz edilmeli.
A22: A0.10 49/41 No.lu Tebliğ: YMM tasdik raporu yükümlülüğü değerlendirildi mi? | C22: EVET | D22: Tek satır ≥500K TL veya toplam ≥1M TL → YMM raporu zorunlu. Toplam bazında değerlendirilir.
A23: A0.11 Tasdik Uygunluk Sonucu | C23: =IF(AND(C13="EVET",C14="EVET",C15="EVET",C16="EVET",C21="EVET",C22="EVET"),"✅ OK – Hesaplanabilir","⛔ HATA – Ön koşul eksik") -> ✅ OK – Hesaplanabilir | D23: Zorunlu: A0.1/A0.2/A0.3/A0.4/A0.9/A0.10. Diğerleri bilgi amaçlı.
A24: Tasdik Engelleyici Uyarı | C24: =IF(C23="⛔ HATA – Ön koşul eksik","⛔ BU MODÜL KULLANILAMAZ — A0 Kontrolünü Tamamlayın","") | D24: Hata giderildiğinde uyarı otomatik kalkar.
A26: A. MÜKELLEF VE AR-GE MERKEZİ BİLGİLERİ (Tüm Projeler için Ortaktır)
A27: Alan | C27: Bilgi / Giriş | I27: Açıklama
A28: Mükellef Unvanı | I28: Ticaret sicilindeki tam unvan
A29: Vergi Kimlik No
A30: Hesap Dönemi | I30: 01.01.…… – 31.12.……
A31: Ar-Ge Merkezi Belge No | I31: STB belgesi
A32: Ar-Ge Merkezi Belge Geçerlilik | I32: Süre dolmuşsa modül kullanılamaz
A33: TZE Ar-Ge Personeli Sayısı | I33: Min 15 (bazı NACE: 30) — tüm projeler toplamında
A34: Dönem Başı YDO Oranı (%) | I34: VUK YDO — devreden indirim güncellemesi için
A35: KV Oranı (%) | I35: Genel: %25 (2025); Finans: %30
A37: B. PROJE BİLGİLERİ — Her Sütuna Bir Proje (Proje 1–5)
B38: Proje Bilgisi | C38: PROJE 1 | D38: PROJE 2 | E38: PROJE 3 | F38: PROJE 4 | G38: PROJE 5 | H38: TOPLAM / BİLGİ | I38: Not
A39: P.1 | B39: Proje Adı / Başlığı | I39: Kısa tanımlayıcı ad
A40: P.2 | B40: STB/TÜBİTAK Proje No | I40: Proje referans numarası
A41: P.3 | B41: Proje Başlangıç – Bitiş Tarihi | I41: GG.AA.YYYY – GG.AA.YYYY
A43: C. AR-GE HARCAMA TÜRLERİ — PROJE BAZINDA (C–G: Proje 1–5 | H: Toplam | I: Kural)
A44: 5746 Md. 3 kapsamı: Muhasebede Ar-Ge hesabına atılan her tutar indirime girmez. Her gider kalemi: (a) Muhasebede kayıtlı, (b) 5746 açısından uygun, (c) Proje kapsamında doğrudan ilişkili. Finansman giderleri (H.10) kapsam dışıdır.
A45: Kod | B45: Harcama Türü | C45: Proje 1 (TL) | D45: Proje 2 (TL) | E45: Proje 3 (TL) | F45: Proje 4 (TL) | G45: Proje 5 (TL) | H45: Toplam (TL) | I45: 5746 Md. 3 Kural / Not
...

Sheet KONSOLİDASYON & BEYANNAME
A1: 410 – AR-GE İNDİRİMİ | KONSOLİDASYON & BEYANNAME SONUÇ SAYFASI
A2: Tüm projelerin D.6 değerleri bu sayfada birleştirilir → Toplam kullanılabilir indirim belirlenir → Kazanç limiti uygulanır → Beyanname 410 tutarı ve devreden tutarlar hesaplanır.
A3: ℹ️ Bu sayfa VERİ GİRİŞİ sayfasındaki formüllere bağlıdır. Sarı hücreler (Dönem Kurum Kazancı) manuel girilir. Geri kalan tüm değerler otomatik hesaplanır.
A4: =IF(COUNTA('VERİ GİRİŞİ'!C39:G39)=1,"TEK PROJE MODU: Yalnizca Proje 1 (C sutunu) aktif. Beyanname 410 = B.3 = MIN(D.6 Proje1, Donem Kazanci)","COK PROJE MODU: "&COUNTA('VERİ GİRİŞİ'!C39:G39)&" aktif proje - Tum D.6 toplami B.3 ile sinirlanir") -> COK PROJE MODU: 0 aktif proje - Tum D.6 toplami B.3 ile sinirlanir
A5: BÖLÜM 1 — PROJE BAZINDA KULLANILABİLİR İNDİRİM TABLOSU (VERİ GİRİŞİ'nden)
B6: Kalem | C6: Proje 1 | D6: Proje 2 | E6: Proje 3 | F6: Proje 4 | G6: Proje 5 | H6: TOPLAM | I6: YMM Notu
A7: K.1 | B7: D.3 — Temel Ar-Ge İndirimi (Cari Dönem %100) | C7: ='VERİ GİRİŞİ'!C63 -> 0 | D7: ='VERİ GİRİŞİ'!D63 -> 0 | E7: ='VERİ GİRİŞİ'!E63 -> 0 | F7: ='VERİ GİRİŞİ'!F63 -> 0 | G7: ='VERİ GİRİŞİ'!G63 -> 0 | H7: =SUM(C7:G7) -> 0 | I7: Proje harcamasının %100'ü
A8: K.2 | B8: D.4 — Artırımlı İndirim (≥%20 Artış, %50 Ek) | C8: ='VERİ GİRİŞİ'!C64 -> 0 | D8: ='VERİ GİRİŞİ'!D64 -> 0 | E8: ='VERİ GİRİŞİ'!E64 -> 0 | F8: ='VERİ GİRİŞİ'!F64 -> 0 | G8: ='VERİ GİRİŞİ'!G64 -> 0 | H8: =SUM(C8:G8) -> 0 | I8: Şart sağlanıyorsa artış tutarının %50'si
A9: K.3 | B9: D.5 — Devreden İndirim (YDO Güncellenmiş) | C9: ='VERİ GİRİŞİ'!C68 -> 0 | D9: ='VERİ GİRİŞİ'!D68 -> 0 | E9: ='VERİ GİRİŞİ'!E68 -> 0 | F9: ='VERİ GİRİŞİ'!F68 -> 0 | G9: ='VERİ GİRİŞİ'!G68 -> 0 | H9: =SUM(C9:G9) -> 0 | I9: Önceki dönem bakiye, VUK YDO ile artırılmış
A10: K.4 | B10: D.6 — PROJE KULLANILABİLİR TOPLAM (K.1+K.2+K.3) | C10: ='VERİ GİRİŞİ'!C69 -> 0 | D10: ='VERİ GİRİŞİ'!D69 -> 0 | E10: ='VERİ GİRİŞİ'!E69 -> 0 | F10: ='VERİ GİRİŞİ'!F69 -> 0 | G10: ='VERİ GİRİŞİ'!G69 -> 0 | H10: =SUM(C10:G10) -> 0 | I10: Proje bazında azami kullanılabilir indirim
A12: BÖLÜM 2 — DÖNEM KAZANÇ LİMİTİ VE BU DÖNEM KULLANILACAK TOPLAM İNDİRİM
A13: Ar-Ge indirimi 'Kazancın Bulunması Halinde' bölümündedir. Tüm projelerin kullanılabilir indirim toplamı, dönem kurum kazancıyla sınırlıdır. Kazancı aşan kısım sonraki dönemlere devredilir.
A14: Kalem | C14: Tutar (TL) | H14: Not
A15: B.1 | B15: TOPLAM KULLANILABİLİR İNDİRİM (Tüm Projelerin D.6 Toplamı) | C15: =H10 -> 0 | H15: Tüm projelerin kullanılabilir indirimi — K.4 toplam
A16: B.2 | B16: Dönem Kurum Kazancı (KKEG Sonrası / 410 İndirimi Öncesi) | H16: ⚠️ Ticari kâr değil — KKEG+, geçmiş yıl zararları sonrası, 410 düşülmeden önceki tutar giriniz | I16: Manuel giriş
A17: B.3 | B17: BU DÖNEM TOPLAM KULLANILACAK İNDİRİM (Min: B.1, B.2) | C17: =MIN(C15,C16) -> 0 | H17: KV Beyannamesi Satır 410 — 'Kazancın Bulunması Halinde İndirilecek'
A18: B.4 | B18: Sonraki Dönemlere Devreden TOPLAM (B.1 – B.3) | C18: =MAX(0,C15-C17) -> 0 | H18: Bu tutar proje bazında D.5a olarak sonraki yıla aktarılır (YDO ile artırılacak)
A19: B.5 | B19: Vergi Tasarrufu (B.3 × KV Oranı) | C19: =C17*'VERİ GİRİŞİ'!C35/100 -> 0 | H19: Bilgi amaçlı — KV oranını VERİ GİRİŞİ A bölümünden alarak formülize edebilirsiniz | I19: Hesaplama
A21: BÖLÜM 3 — PROJE BAZINDA İNDİRİM KULLANIM DAĞILIMI
A22: Kazanç yeterliyse her proje D.6 tutarını tam kullanır. Kazanç yetersizse dağılım YMM tarafından belirlenir (genellikle pro-rata veya proje önceliğine göre). Bu tablo bilgi amaçlıdır — beyannamede yalnızca B.3 (toplam) gösterilir.
B23: Proje | C23: P1 Kullanılan | D23: P2 | E23: P3 | F23: P4 | G23: P5 | H23: Toplam | I23: Not
A24: D.1 | B24: Proje 1 — Kullanılan İndirim | C24: =IFERROR(MIN(C10,C17*(C10/H10)),0) -> 0 | H24: =MAX(0,C10-C24) -> 0 | I24: Pro-rata dağılım — YMM başka yöntem belirleyebilir. H sütunu = proje bazında sonraki yıla devreden (D.5a olarak aktarın).
A25: D.2 | B25: Proje 2 — Kullanılan İndirim | C25: =IFERROR(MIN(D10,C17*(D10/H10)),0) -> 0 | H25: =MAX(0,D10-C25) -> 0 | I25: Pro-rata dağılım — YMM başka yöntem belirleyebilir. H sütunu = proje bazında sonraki yıla devreden (D.5a olarak aktarın).
A26: D.3 | B26: Proje 3 — Kullanılan İndirim | C26: =IFERROR(MIN(E10,C17*(E10/H10)),0) -> 0 | H26: =MAX(0,E10-C26) -> 0 | I26: Pro-rata dağılım — YMM başka yöntem belirleyebilir. H sütunu = proje bazında sonraki yıla devreden (D.5a olarak aktarın).
A27: D.4 | B27: Proje 4 — Kullanılan İndirim | C27: =IFERROR(MIN(F10,C17*(F10/H10)),0) -> 0 | H27: =MAX(0,F10-C27) -> 0 | I27: Pro-rata dağılım — YMM başka yöntem belirleyebilir. H sütunu = proje bazında sonraki yıla devreden (D.5a olarak aktarın).
A28: D.5 | B28: Proje 5 — Kullanılan İndirim | C28: =IFERROR(MIN(G10,C17*(G10/H10)),0) -> 0 | H28: =MAX(0,G10-C28) -> 0 | I28: Pro-rata dağılım — YMM başka yöntem belirleyebilir. H sütunu = proje bazında sonraki yıla devreden (D.5a olarak aktarın).
A29: ✅ | B29: Dağılım Kontrol: Toplam Kullanılan = B.3 ile Uyumlu | C29: =SUM(C24:C28) -> 0 | H29: =ROUND(C29-C17,0) -> 0 | I29: H sütunu 0 ise dağılım doğru — fark varsa manuel ayarla
A31: BÖLÜM 4 — GİRİŞİM SERMAYESİ FONU (GSF) — TOPLAM BAZINDA KONTROL (5746 Md. 3/14)
A32: G.1 | B32: Bu Dönem Toplam Kullanılan İndirim (B.3) | C32: =C17 -> 0 | H32: Beyanname 410 satırı
A33: G.2 | B33: GSF Yükümlülüğü (B.3 ≥ 1M TL ise %2, max 20M TL) | C33: =IF(C17>=1000000,MIN(C17*0.02,20000000),0) -> 0 | H33: Yıl sonuna kadar GSYF/GSYO'ya aktarılmalı. Aktarılmazsa → B.3'ün %20'si reddedilir.
A34: G.3 | B34: GSF Aktarım Yükümlülüğü Var mı? | C34: =IF(C17>=1000000,"EVET — Yıl Sonuna Kadar Aktarın","HAYIR — Yükümlülük Yok") -> HAYIR — Yükümlülük Yok | H34: EVET ise aktarım kanıtı belge listesine eklenmelidir
A35: G.4 | B35: Aktarılmazsa Reddedilecek Tutar (B.3 × %20) | C35: =IF(C17>=1000000,C17*0.2,0) -> 0 | H35: Bu tutar nedeniyle vergi ziyaı cezasız tarhiyat yapılır

Sheet HESAPLAMALAR & KONTROL
A1: 410 — HESAPLAMALAR & KONTROL | OTOMATİK SINIR TESTLERİ VE DENETİM KONTROL LİSTESİ
A3: TASDİK ÖZET — KONSOLİDASYON SAYFASINDAN
A4: A0.11 Tasdik Uygunluk | D4: ='VERİ GİRİŞİ'!C23 -> ✅ OK – Hesaplanabilir | G4: VERİ GİRİŞİ A0.11
A5: Toplam Kapsam İçi Harcama (TL) | D5: ='VERİ GİRİŞİ'!H56 -> 0 | G5: Tüm projelerin H toplamı
A6: Toplam Kullanılabilir İndirim (D.6) | D6: ='KONSOLİDASYON & BEYANNAME'!H10 -> 0 | G6: K.4 — Tüm proje D.6 toplamı
A7: Bu Dönem Kullanılacak İndirim | D7: ='KONSOLİDASYON & BEYANNAME'!C17 -> 0 | G7: B.3 — Beyanname 410 satırı
A8: Toplam Sonraki Dönem Devreden | D8: ='KONSOLİDASYON & BEYANNAME'!C18 -> 0 | G8: B.4 — Tüm projeler toplamı
A9: GSF Yükümlülüğü (Toplam) | D9: ='KONSOLİDASYON & BEYANNAME'!C33 -> 0 | G9: G.2 — %2 fon aktarım zorunluluğu
A11: OTOMATİK KONTROL 1 — H.4 DIŞ HİZMETLER %20 SINIRI (Proje Bazında ve Toplam)
B12: Kalem | C12: Proje 1 | D12: Proje 2 | E12: Proje 3 | F12: Proje 4 | G12: Proje 5 | H12: TOPLAM | I12: Kural
A13: C1.a | B13: H.4 Dış Hizmet Tutarı (TL) | C13: ='VERİ GİRİŞİ'!C49 -> 0 | D13: ='VERİ GİRİŞİ'!D49 -> 0 | E13: ='VERİ GİRİŞİ'!E49 -> 0 | F13: ='VERİ GİRİŞİ'!F49 -> 0 | G13: ='VERİ GİRİŞİ'!G49 -> 0 | H13: =SUM(C13:G13) -> 0 | I13: Her proje sütunu VERİ GİRİŞİ'nden
A14: C1.b | B14: Toplam Ar-Ge Harcaması (TL) | C14: ='VERİ GİRİŞİ'!C56 -> 0 | D14: ='VERİ GİRİŞİ'!D56 -> 0 | E14: ='VERİ GİRİŞİ'!E56 -> 0 | F14: ='VERİ GİRİŞİ'!F56 -> 0 | G14: ='VERİ GİRİŞİ'!G56 -> 0 | H14: =SUM(C14:G14) -> 0 | I14: Her proje sütunu C(A) satırından
A15: C1.c | B15: H.4 / Toplam Oran (%) | C15: =IFERROR(C13/C14*100,0) -> 0 | D15: =IFERROR(D13/D14*100,0) -> 0 | E15: =IFERROR(E13/E14*100,0) -> 0 | F15: =IFERROR(F13/F14*100,0) -> 0 | G15: =IFERROR(G13/G14*100,0) -> 0 | I15: Oran %20'yi aşmamalıdır
A16: C1.d | B16: H.4 %20 Sınırı Sonucu | C16: =IF(IFERROR(C13/C14,0)<=0.2,"✅ UYGUN","⚠️ AŞIYOR") -> ✅ UYGUN | D16: =IF(IFERROR(D13/D14,0)<=0.2,"✅ UYGUN","⚠️ AŞIYOR") -> ✅ UYGUN | E16: =IF(IFERROR(E13/E14,0)<=0.2,"✅ UYGUN","⚠️ AŞIYOR") -> ✅ UYGUN | F16: =IF(IFERROR(F13/F14,0)<=0.2,"✅ UYGUN","⚠️ AŞIYOR") -> ✅ UYGUN | G16: =IF(IFERROR(G13/G14,0)<=0.2,"✅ UYGUN","⚠️ AŞIYOR") -> ✅ UYGUN | I16: UYGUN / AŞIYOR
A18: OTOMATİK KONTROL 2 — DESTEK PERSONELİ %10 TZE SINIRI (Toplam Merkez Bazında)
A19: Toplam TZE Ar-Ge Personeli (manuel giriş — VERİ GİRİŞİ A bölümünden) | G19: Min 15 (genel) / 30 (bazı NACE sektörü)
A20: Destek Personeli TZE (manuel giriş — tüm personel bazında) | G20: Tüm projelerdeki destek personeli toplamı
A21: İzin Verilen Azami Destek Personeli (%10) | D21: =C19*0.1 -> 0 | G21: TZE Ar-Ge × %10
A22: Sınır Aşımı | D22: =MAX(0,C20-C21) -> 0 | G22: Pozitif ise H.2 düzeltilmeli
A23: Destek Personeli %10 Sonucu | D23: =IF(C20<=C21,"✅ UYGUN — %10 sınırı içinde","⚠️ SINIRI AŞIYOR") -> ✅ UYGUN — %10 sınırı içinde | G23: Aşan kısım tüm projelerin H.2'sinden orantılı düşülmeli

Sheet DENETÇİ NOTLARI
A1: 410 – AR-GE İNDİRİMİ (5746 s.K. Md. 3) | ÇOK PROJELİ | YMM MESLEKİ DEĞERLENDİRME VE TASDİK NOTLARI
A2: → Bu sayfa tek proje versiyonundaki içerikle aynı yapıda tutulmalıdır (v1.0 DENETÇİ NOTLARI referans alınız).

Sheet BELGE LİSTESİ
A1: 410 – AR-GE İNDİRİMİ (5746 s.K. Md. 3) | ÇOK PROJELİ | TASDİK BELGE LİSTESİ VE DENETİM KANITI ENVANTERİ
A2: → Bu sayfa tek proje versiyonundaki içerikle aynı yapıda tutulmalıdır (v1.0 DENETÇİ NOTLARI referans alınız).

Sheet MUHASEBE KAYITLARI
A1: 410 – AR-GE İNDİRİMİ (5746 s.K. Md. 3) | ÇOK PROJELİ | MUHASEBE KAYITLARI ÇALIŞMA KÂĞIDI
A2: → Bu sayfa tek proje versiyonundaki içerikle aynı yapıda tutulmalıdır (v1.0 DENETÇİ NOTLARI referans alınız).
