Workbook

Sheet VERİ GİRİŞİ
A1: 450 – DİĞER İNDİRİMLER | GİB KV Beyanname Catch-All Kodu | YMM TASDİK
A2: Beyanname 450 | GİB KV Beyan Rehberi Mart 2026 (No:606) | Kazancın Bulunması Halinde
A3: BEYANNAME 450 — DİĞER İNDİRİMLER: GİB kurumlar vergisi beyannamesinde ayrı bir kod numarası verilmemiş ancak mevzuatta öngörülen indirim kalemlerinin beyan edileceği genel (catch-all) satırdır. ★ KULLANIM KOŞULLARI (ÜÇÜ BİRDEN ZORUNLU): ① MEVZUAT DAYANAĞI: Her indirim kalemi için açık yasal dayanak (KVK maddesi, geçici madde, özel kanun, ÇVÖA veya özelge) mutlaka belirtilmeli. ② BELGE: İndirimi kanıtlayan belge(ler) tasdik dosyasında bulunmalı. ③ TEKRAR ETMEME: 450'de yer alan indirim, beyannamede başka bir kodda (402, 404, 414 vb.) zaten beyan edilmemiş olmalı. ★ YMM MÜTESELSİL SORUMLULUĞU: Dayanaksız veya belgesiz indirim → Tarhiyat riski. ★ YİAKV: Her indirim kalemi için YİAKV durumu ayrı ayrı değerlendirilmeli.
A4: ★ UYARI: 450 kodu '450 — Diğer İndirimler' başlığı altında catch-all niteliğindedir. Standart kodlarda (402-467) karşılığı olan bir indirim 450'ye yazılırsa mükerrerlik veya kod hatası oluşur. Önce standart kodlar kontrol edilmeli — 450 sadece kapsam dışı kalanlar için.
A6: A0. KAPSAM VE NİTELİK UYGUNLUK ÖN KONTROLÜ — BEYANNAME 450 DİĞER İNDİRİMLER
B7: Kontrol Sorusu | E7: Yanıt | G7: YMM Tasdik Notu
A8: A0.1 ★ Bu indirim standart kodlarda (402–467) karşılığı OLMAYAN bir kalem mi? | E8: EVET | F8: İndirim 402 (eğitim/sağlık), 404 (kültür/turizm), 414 (sağlık hizm.), 416 (diğer hizm.), 452 (korumalı işyeri), 467 (İFM) vb. standart kodlara girmiyorsa 450 kullanılır. Standart kodda karşılığı varsa önce o kod kullanılmalı.
A9: A0.2 ★ Her indirim kalemi için AÇIK MEVZUAT DAYANAĞI belirlendi mi? | E9: EVET | F9: KVK maddesi, geçici maddesi, özel kanun, ÇVÖA veya GİB özelgesi ile dayanak gösterilmeli. Dayanaksız indirim → Tarhiyat ve ceza riski.
A10: A0.3 ★ İndirim hakkı beyan dönemine ait mi? (Devir/zamanlaama kontrolü) | E10: EVET | F10: İndirim hakkının cari döneme ait olduğu teyit edilmeli. Geçmiş dönem indirimleri mahsuplaşma veya düzeltme beyannamesiyle ele alınmalı.
A11: A0.4 Her indirim kalemi için destekleyici BELGE temin edildi mi? | E11: EVET | F11: Fatura, sözleşme, özelge, mahkeme kararı, teknik hesaplama vb. ilgili belge zorunludur.
A12: A0.5 ✗/✓ YİAKV durumu her kalem için ayrı ayrı değerlendirildi mi? | E12: EVET | F12: 450'deki her kalem için YİAKV matrahına etkisi (E.11 veya korumalı) ayrıca belirlenmeli.
A13: A0.6 YMM Tasdik Raporu gereksinimi değerlendirildi mi? | E13: EVET | F13: >=500.000 TL → YMM raporu.
A14: A0.7 Tasdik Uygunluk Sonucu | E14: =IF(AND(E8="EVET",E9="EVET",E10="EVET",E11="EVET"),"OK - Hesaplanabilir","HATA - Ön koşul eksik") -> OK - Hesaplanabilir | F14: ★ A0.1 standart kod kontrolü | A0.2 mevzuat dayanak | A0.3 dönem | A0.4 belge.
A16: A. GENEL BİLGİLER
A17: Kurumun Unvanı | F17: Tam ticaret unvanı
A18: VKN | F18: 10 haneli VKN
A19: Hesap Dönemi | F19: 01.01.2025 – 31.12.2025
A20: KV Oranı (%) | F20: 2025: %25
A21: Toplam 450 İndirim Kalemi Sayısı | F21: Beyanname 450'ye dahil edilen farklı indirim türü sayısı
A22: Dosya Referansı | F22: YMM-2025/450-01
A25: B. DİĞER İNDİRİM KALEMLERİ TABLOSU — BEYANNAME 450
A26: Her indirim kalemi için ayrı satır. SÜTUN 2: İndirim türü/açıklaması. SÜTUN 3: Mevzuat dayanağı (KVK Md./Geç.Md./Kanun No.). SÜTUN 4: İndirim tutarı. SÜTUN 5: YİAKV durumu. SÜTUN 6: Belge referansı. ★ Dayanaksız satır bırakılmamalı.
A27: No | B27: İndirim Açıklaması | C27: Mevzuat Dayanağı | D27: İndirim Tutarı (TL) | E27: YİAKV Durumu | F27: Belge Referansı | G27: YMM Notu
A28: 1 | E28: YMM Teyidi Gerekli
A29: 2 | E29: YMM Teyidi Gerekli
A30: 3 | E30: YMM Teyidi Gerekli
A31: 4 | E31: YMM Teyidi Gerekli
A32: 5 | E32: YMM Teyidi Gerekli
A33: 6 | E33: YMM Teyidi Gerekli
A34: 7 | E34: YMM Teyidi Gerekli
A35: 8 | E35: YMM Teyidi Gerekli
A36: BEYANNAME 450 TOPLAMI | D36: =SUM(D28:D35) -> 0 | E36: ← Beyanname 450 — Kazancın Bulunması Halinde | Devredilmez
A38: C. YİAKV AYRIMI — 450 İNDİRİM KALEMLERİ SINIFLANDIRMASI
A39: 450'deki her indirim kalemi için YİAKV matrahına etkisi ayrı değerlendirilmeli. Korumalı kalemler YİAKV matrahından düşülür — E.11 kalemleri düşülemez. Her kalem için GİB Rehberi No:607 ve ilgili mevzuat incelenmeli.
A40: No | B40: İndirim Kalemi | C40: Mevzuat | D40: YİAKV Durumu | E40: Tutar (TL) | F40: Etki | G40: YMM Notu
A41: 1 | B41: ='VERİ GİRİŞİ'!B28 -> 0 | C41: ='VERİ GİRİŞİ'!C28 -> 0 | D41: YMM Teyidi Gerekli | E41: ='VERİ GİRİŞİ'!D28 -> 0
A42: 2 | B42: ='VERİ GİRİŞİ'!B29 -> 0 | C42: ='VERİ GİRİŞİ'!C29 -> 0 | D42: YMM Teyidi Gerekli | E42: ='VERİ GİRİŞİ'!D29 -> 0
A43: 3 | B43: ='VERİ GİRİŞİ'!B30 -> 0 | C43: ='VERİ GİRİŞİ'!C30 -> 0 | D43: YMM Teyidi Gerekli | E43: ='VERİ GİRİŞİ'!D30 -> 0
A44: 4 | B44: ='VERİ GİRİŞİ'!B31 -> 0 | C44: ='VERİ GİRİŞİ'!C31 -> 0 | D44: YMM Teyidi Gerekli | E44: ='VERİ GİRİŞİ'!D31 -> 0
A45: 5 | B45: ='VERİ GİRİŞİ'!B32 -> 0 | C45: ='VERİ GİRİŞİ'!C32 -> 0 | D45: YMM Teyidi Gerekli | E45: ='VERİ GİRİŞİ'!D32 -> 0
...

Sheet HESAPLAMALAR & KONTROL
A1: 450 – DİĞER İNDİRİMLER | HESAPLAMALAR VE DENETİM
A2: Catch-All Kod | Mevzuat Dayanak Zorunlu | Kalem Bazı YİAKV | Beyanname 450
A4: A. TASDİK ÖZETİ
A5: A0 Uygunluğu | D5: ='VERİ GİRİŞİ'!E14 -> OK - Hesaplanabilir | E5: OK ise devam
A6: Kalem Sayısı | D6: ='VERİ GİRİŞİ'!E21 -> 0 | E6: Beyanname 450 kalem adedi
A7: 450 TOPLAM İNDİRİM | D7: ='VERİ GİRİŞİ'!D36 -> 0 | E7: B Tablosu toplamı
A9: B. 450 KODUNUN KULLANIM AMACI VE SINIRI
A10: BEYANNAME 450 — DİĞER İNDİRİMLER CATCH-ALL KODU: KULLANILMASI GEREKEN DURUMLAR: • Mevzuatta açıkça öngörülmüş ancak standart beyanname kodunda (402-467) ayrı satırı bulunmayan indirimler • GİB özelgesiyle teyit edilmiş özel indirim hakları • Kanun geçici maddesi kapsamı ve süreli indirimler • ÇVÖA kapsamında vergi muafiyeti/indirimlerinin yansıması KULLANILMAMASI GEREKEN DURUMLAR: ✗ Standart kodda (402-467) karşılığı olan indirim → İlgili koda yazılmalı ✗ Mevzuat dayanağı belirsiz indirim → 450 dahil edilemez ✗ Aynı tutarın başka kodda beyan edilmesi → Mükerrer indirim ✗ Gider niteliğindeki tutarlar → 450 değil doğrudan gider kalemi YMM MÜTESELSİL SORUMLULUĞU: 450'ye dahil edilen her kalem için YMM'nin: ① Yasal dayanağı teyit etmesi ② Belgeyi incelemesi ③ YİAKV etkisini değerlendirmesi ④ Standart kodda karşılığı olmadığını doğrulaması zorunludur.
A12: C. DENETİM KONTROL LİSTESİ (K1–K10)
B13: Kontrol | D13: Açıklama | F13: Sonuç
A14: K1 | B14: ★ Her kalem için standart kod kontrolü yapıldı mı? | D14: 402-467 kodlarında karşılığı varsa 450 değil. | F14: Uygun/Eksik/Risk
A15: K2 | B15: ★ Her kalem için mevzuat dayanağı belirlendi mi? | D15: B tablosu Sütun 3 dolu olmalı. | F15: Uygun/Eksik/Risk
A16: K3 | B16: ★ Her kaleme ait belge tasdik dosyasında mı? | D16: Belgesiz kalem → 450'ye dahil edilemez. | F16: Uygun/Eksik/Risk
A17: K4 | B17: ★ Her kalem cari döneme ait mi? | D17: Dönem dışı indirim → Düzeltme beyannamesi. | F17: Uygun/Eksik/Risk
A18: K5 | B18: ★ YİAKV durumu kalem bazında değerlendirildi mi? | D18: C tablosu sütun 4 teyit edilmeli. | F18: Uygun/Eksik/Risk
A19: K6 | B19: Mükerrer indirim riski kontrol edildi mi? | D19: Aynı tutar başka kodda beyan edilmemiş. | F19: Uygun/Eksik/Risk
A20: K7 | B20: B tablosu toplamı D.1 ile mutabık mı? | D20: D36 = D.1 eşitliği. | F20: Uygun/Eksik/Risk
A21: K8 | B21: ★ İndirim matrahı aşıyor mu? (Devredilemez!) | D21: Aşan kısım beyanname notu. | F21: Uygun/Eksik/Risk
A22: K9 | B22: Beyanname 450 'Kazancın Bulunması Halinde'? | D22: Zarar → uygulanamaz. | F22: Uygun/Eksik/Risk
A23: K10 | B23: YMM Tasdik Raporu değerlendirildi mi? | D23: >=500.000 TL → YMM raporu. | F23: Uygun/Eksik/Risk

Sheet MUHASEBE KAYITLARI
A1: 450 – DİĞER İNDİRİMLER | MUHASEBE KAYITLARI
A2: NOT: 450 Diğer İndirimler — Muhasebe Kaydı İndirim Türüne Göre Değişir
A3: MUHASEBE KAYDI GENEL ÇERÇEVE: 450 kapsamındaki indirimler, türlerine göre farklı muhasebe etkisi yaratabilir: ① Gider niteliğinde değilse (saf beyanname indirimi): Gelir tablosunu etkilemez — sadece beyanname. ② Gider niteliğindeyse: İlgili gider hesabına (689/770 vb.) kaydedilir, KKEG'e alınır, beyanname 450 indirimi olarak matrahtan düşülür. Her indirim türü için muhasebe kaydı ve KKEG etkisi ayrı değerlendirilmelidir.
B4: Senaryo | C4: Muhasebe Etkisi | D4: Beyanname Etkisi | E4: Dr/Kr | G4: Ref
A5: → | B5: Saf Beyanname İndirimi (Gider değil) | C5: Gelir tablosu etkilenmez | D5: Matrahtan direkt indirim | E5: — Muhasebe kaydı yok — | G5: Beyanname 450
A6: → | B6: Gider + Beyanname İndirimi | C6: 689/770 → KKEG → 450 indirimi | D6: KKEG tutarı matrahtan düşülür | E6: Dr: 951 KKEG | Kr: 952 Karş. | G6: Beyanname 450
A7: → | B7: ÇVÖA Kapsamı Mahsup | C7: Yurt dışı vergi → Mahsup | D7: Beyanname üzerinde mahsup | E7: — Muhasebe etkisi ayrı — | G7: ÇVÖA Protokolü

Sheet DENETCİ NOTLARI
A1: 450 – DİĞER İNDİRİMLER | DENETÇİ NOTLARI
A2: Catch-All Kod | Mevzuat Dayanak | Standart Kod Kontrolü | YİAKV Kalem Bazı | 49 No.lu Tebliğ
A3: Kod | B3: Konu | C3: Mesleki Değerlendirme / Tasdik Standardı | D3: Mevzuat / Kaynak
A4: N1 | B4: Beyanname 450 — Catch-All Kodun Kapsamı ve Sınırları | C4: BEYANNAME 450 — DİĞER İNDİRİMLER: GİB kurumlar vergisi beyannamesinde 402-467 arası standart kodlarda karşılığı bulunmayan ancak mevzuatta öngörülmüş indirimler için kullanılan genel satırdır. KULLANIM ALANINA GİREN ÖRNEKLER: • Özel kanunlarla tanınan ve standart kodda olmayan indirimler • GİB özelgesiyle teyit edilmiş spesifik indirim hakları • Geçici madde kapsamı süreli indirimler • ÇVÖA kapsamı vergi mahsup/indirim unsurları KULLANIM DIŞI: ✗ 402-467 standart kodlarda karşılığı olan her kalem ✗ Mevzuat dayanağı belirsiz indirimler ✗ Gider niteliğindeki tutarların doğrudan beyanı | D4: GİB KV Beyan Reh. 2026 (No:606) | VUK | KVK
A5: N2 | B5: ★ Mevzuat Dayanak Zorunluluğu — YMM Müteselsil Sorumluluğu | C5: 450'NİN EN KRİTİK KURALI — MEVZUAT DAYANAĞI: Her indirim kalemi için açık yasal dayanak ZORUNLUDUR: KABUL EDİLEN DAYANAKLAR: ① KVK madde/fıkra referansı (ör. KVK Md.10/1-x) ② Kanun geçici maddesi (ör. KVK Geç. Md.61) ③ Özel kanun numarası ve ilgili maddesi ④ GİB özelge tarihi ve sayısı ⑤ ÇVÖA adı, madde ve fıkrası KABUL EDİLMEYEN DAYANAKLAR: ✗ 'Genel uygulama', 'sektör standardı', 'muhasebe prensibi' ✗ Dayanak gösterilmeksizin yazılan tutar YMM SORUMLULUĞU: Dayanaksız 450 kalemi → Tarhiyat + Vergi ziyaı cezası SM-SMMM-YMM Kanunu Md.12 → Müteselsil sorumluluk | D5: VUK Md.341 | KVK Md.30 | SM-SMMM-YMM K. Md.12
A6: N3 | B6: Standart Kod Kontrolü — 402-467 Önceliği | C6: STANDART KOD KONTROL LİSTESİ — 450 ÖNCESI: Aşağıdaki kategorilerde indirim varsa önce ilgili kod kullanılmalı: BAĞIŞ/YARDIM KODLARI (✗ YİAKV E.11): 402 Eğitim/Sağlık/Yurt | 403 Gençlik/İzci/Yurt | 404 Kültür/Turizm 417 İbadethane | 419 Kapadokya | 451 CB Kampanya 462 Kızılay | 463 Yeşilay | 464-483 Özel Kanunlu Bağışlar İNDİRİM KODLARI: 406 Yatırım İndirimi | 414-416 Yurt Dışı Hizmet | 452 Korumalı İşyeri 453 Nakdi Sermaye | 455/283 Ar-Ge | 456/457 Teknokent | 467 İFM SPONSORLUK: 460/461 Spor Sponsorluğu | 466 UAB Bu kodların hiçbirine girmeyen meşru indirim → 450 | D6: GİB KV Beyan Reh. 2026 (No:606) | KVK Md.10
A7: N4 | B7: YİAKV — Kalem Bazında Ayrı Değerlendirme | C7: YİAKV (KVK Md.32/C) VE 450 DİĞER İNDİRİMLER: 450'deki her kalem için YİAKV etkisi AYRI DEĞERLENDİRİLMELİDİR. OLASI DURUMLAR: ① Kalem KVK Md.32/C f.2'de açıkça sayılan korumalı kalemse: → YİAKV matrahından düşülebilir (kalem bazında teyit) ② Kalem E.11 kapsamındaysa: → YİAKV matrahından düşülemez ③ Durum belirsizse: → GİB Rehberi No:607 + özelge araştırması zorunlu KARŞILAŞTIRMALI REFERANS: 406 Yatırım İndirimi → ✗ E.11 (düşülemez) 467 İFM Kazancı → ✓ (g) bendi (düşülebilir) 450 kalemleri → Kalem bazında ayrı teyit YMM: B ve C tablolarında her satır için YİAKV durumu doldurulmalı. | D7: KVK Md.32/C | GİB Rehberi No:607
A8: N5 | B8: 49 No.lu Tebliğ + YMM Tasdik Dil Standardı | C8: KULLANIN (her kalem için ayrı paragraf): '...[Mevzuat Dayanağı (KVK Md./Kanun No./Özelge)] kapsamında [İndirim Konusu Açıklaması] nedeniyle [Tutar] TL, kurumlar vergisi matrahından Diğer İndirimler (Beyanname 450) kapsamında indirilmiştir. [YİAKV durumu belirtilmeli].' KULLANMAYIN: '...Çeşitli indirimler kapsamında toplam [X] TL.' (Ayrıntısız) '...Mevzuat gereği indirim.' (Madde belirtilmemiş) '...Standart kodda (ör. 462) yer alan tutarlar ayrıca 450'ye.' (Mükerrerlik) KRİTİK RİSKLER: (1) Standart koda sahip indirimi 450'ye yazmak. (2) Mevzuat dayanağı göstermemek. (3) Belgesiz indirim dahil etmek. (4) YİAKV etkisini değerlendirmemek. | D8: 49 No.lu Tebliğ | SM-SMMM-YMM K. Md.12
A9: GİB KV BEYAN REHBERİ MART 2026 (No:606) KAPANIŞ (450): Diğer İndirimler — 402-467 standart kodlarına girmeyen, mevzuata dayalı indirimler. Her kalem için: Mevzuat dayanağı + Belge + Standart kod dışı teyit + YİAKV kalem bazı değerlendirme. Dayanaksız veya belgesiz kalem → Tarhiyat riski. YMM: SM-SMMM-YMM K. Md.12.

Sheet BELGE LISTESI
A1: 450 – DİĞER İNDİRİMLER | BELGE LİSTESİ | YMM TASDİK
A2: Mevzuat Dayanağı Belgesi | Özelge | İndirim Hesabı | Standart Kod Dışı Teyit | YİAKV
A4: KATEGORİ 1 — HER KALEM İÇİN ZORUNLU BELGELER
B5: No | C5: Belge | D5: Açıklama | E5: Temin
B6: 1 | C6: ★ Mevzuat Dayanak Belgesi (Her Kalem İçin Ayrı) | D6: KVK maddesi metni, özel kanun maddesi, GİB özelgesi veya ÇVÖA ilgili maddesi. Her indirim kalemi için ayrı mevzuat dayanağı belgesi. Zorunlu. | E6: Mevzuat / GİB Özelge Arşivi
B7: 2 | C7: ★ İndirim Hakkını Kanıtlayan Dayanak Belge | D7: Fatura, sözleşme, hesap özeti, teknik hesaplama raporu, mahkeme kararı vb. İndirim tutarını doğrulayan her türlü resmi belge. Zorunlu. | E7: Şirket Arşivi / Muhasebe
B8: 3 | C8: ★ Standart Kod Dışı Teyit Notu | D8: İndirim kaleminin 402-467 arası standart kodlarda yer almadığını gösteren YMM değerlendirme notu. Her kalem için ayrı. Zorunlu. | E8: YMM Değerlendirme Notu
B9: 4 | C9: ★ YİAKV Kalem Bazında Değerlendirme Notu | D9: Her kalem için YİAKV matrahına etkisinin değerlendirildiği GİB Rehberi No:607 kapsamında YMM notu. Zorunlu. | E9: YMM Değerlendirme Notu
B10: 5 | C10: KV Beyannamesi 450 Satırı + Kalem Detayı | D10: Beyanname 450 = B Tablosu Toplamı. Her kaleme ait açıklama ve tutar ayrıca tasdik dosyasında bulunmalı. | E10: GİB e-Beyanname + Dosya
A12: KATEGORİ 2 — YMM TASDİK KONTROL SORULARI
B13: No | C13: Kontrol Sorusu | D13: Beklenen Sonuç | E13: YMM Aksiyonu
B14: S1 | C14: ★ Her kalem standart kodda (402-467) karşılığı olmayan bir kalem mi? | D14: Standart kod önceliği kontrol. | E14: YMM kontrolü
B15: S2 | C15: ★ Her kalem için mevzuat dayanağı belirlendi mi? | D15: B Tablosu sütun 3 dolu. | E15: YMM kontrolü
B16: S3 | C16: ★ Her kaleme ait belge mevcut mu? | D16: Belgesiz kalem → Çıkar. | E16: YMM kontrolü
B17: S4 | C17: ★ Her kalem cari döneme ait mi? | D17: Dönem dışı → Düzeltme beyannamesi. | E17: YMM kontrolü
B18: S5 | C18: ★ YİAKV kalem bazında değerlendirildi mi? | D18: C Tablosu sütun 4 dolu. | E18: YMM kontrolü
B19: S6 | C19: Mükerrer indirim kontrolü yapıldı mı? | D19: Başka kodda beyan edilmemiş. | E19: YMM kontrolü
B20: S7 | C20: ★ İndirim matrahı aşıyor mu? (Devredilmez!) | D20: Aşan kısım beyanname notu. | E20: YMM kontrolü
B21: S8 | C21: Beyanname 450 'Kazancın Bulunması Halinde'? | D21: Zarar → uygulanamaz. | E21: YMM kontrolü
B22: S9 | C22: YMM Tasdik Raporu değerlendirildi mi? | D22: >=500.000 TL → Rapor. | E22: YMM kontrolü
A24: GİB KV BEYAN REHBERİ MART 2026 (No:606) | 450 DİĞER İNDİRİMLER CATCH-ALL KODU: 402-467 standart kodlarına girmeyen mevzuata dayalı indirimler. Her kalem için: ① Standart kod dışı teyit ② Mevzuat dayanağı ③ Belge ④ YİAKV kalem bazı. Dayanaksız veya belgesiz kalem 450'ye dahil edilemez — tarhiyat ve ceza riski. YMM müteselsil sorumluluk: SM-SMMM-YMM Kanunu Md.12.
