Workbook

Sheet VERİ GİRİŞİ
A1: 454 – AR-GE İNDİRİMİ (5746 s.K. Md. 3 / Md. 3/A) | KVK Md. 10/1-a | YMM TASDİK ÇALIŞMA KÂĞIDI
A2: 5746 s.K. Md. 3 (Ar-Ge Merkezi) | 5746 s.K. Md. 3/A (Proje Bazlı) | KVK Md. 10/1-a | Kazancın Bulunması Halinde İndirilecek | Devreden İndirim: YDO ile Artırılır | 31.12.2028 Uygulama Süresi | Beyanname Satırı 454
A3: KULLANIM: Sarı zemin hücrelere veri giriniz. A0 eksiksiz tamamlanmadan hesap bölümlerine geçilmemelidir. Her proje için ayrı takip yapılmalıdır. Siparişe dayalı Ar-Ge'de dağıtım oranı dikkat gerektirir.
A5: MODÜL KİMLİĞİ VE VERSİYON
A6: Modül Kodu / İndirim Türü | C6: 454 — 5746 s.K. Ar-Ge İndirimi | KVK Md. 10/1-a | D6: 5746 Md. 3 / Md. 3/A | KVK 10/1-a | GVK 89/9
A7: Çalışma Kâğıdı Versiyonu | C7: v1.0 | D7: 7555 s.K. (24.07.2025) üst sınır değişikliği dahil
A8: Hazırlama / Güncelleme Tarihi | D8: GG.AA.YYYY
A10: A0. KAPSAM VE NİTELİK UYGUNLUK KONTROLÜ — Tasdik Öncesi Zorunlu Ön Kontrol
A11: ⚠️ YMM UYARISI: Bu çalışma kâğıdı 5746 sayılı Kanun Md. 3 (Ar-Ge Merkezi) veya Md. 3/A (Proje Bazlı) kapsamında Ar-Ge indirimi uygulamak isteyen mükellefler için hazırlanmıştır. İndirim 'Kazancın Bulunması Halinde İndirilecek' bölümündedir — zarar durumunda kullanılamaz. Devreden indirim sonraki yıla VUK Yeniden Değerleme Oranı kadar artırılarak devredilir. A0 tamamlanmadan tasdik dosyasına eklenemez.
A12: Tasdik Uygunluk Kontrol Soruları | C12: Yanıt | D12: Açıklama / Tasdik Notu
A13: A0.1 Ar-Ge faaliyeti münhasıran yeni teknoloji ve bilgi arayışına yönelik mi? (Ürün geliştirme değil) | C13: EVET | D13: İndirim yalnızca yeni teknoloji ve bilgi arayışına yönelik Ar-Ge faaliyeti için geçerlidir. Halihazırda bilinen veya mevcut teknikler/çalışmalar kapsam dışıdır. Ürün geliştirme veya prototip testleri pazarlanabilir aşamaya geldiğinde Ar-Ge sona erer.
A14: A0.2 5746 Md. 3 (Ar-Ge Merkezi) mi yoksa Md. 3/A (Proje Bazlı/Özkaynakla) mi? — Modül seçildi mi? | C14: Md. 3 (Ar-Ge Merkezi) | D14: Md. 3: Sanayi ve Teknoloji Bakanlığı 'Ar-Ge Merkezi Belgesi' zorunludur (en az 15 TZE personel). Md. 3/A: Proje bazlı — Bakanlık Ar-Ge/yenilik projesi olarak değerlendirmesi şartı aranır. Her iki modülde de indirim oranı %100'dür.
A15: A0.3 Md. 3 seçildiyse: Ar-Ge Merkezi belgesi (STB onaylı) geçerli ve koşullar sağlanıyor mu? | C15: EVET | D15: Ar-Ge Merkezi belgesi STB'den alınmış ve geçerliliğini korumalıdır. En az 15 tam zaman eşdeğer Ar-Ge personeli koşulu sağlanmalıdır (bazı NACE sektörlerde 30). Şartların ihlali indirimi sona erdirir.
A16: A0.4 Md. 3/A seçildiyse: Proje STB tarafından Ar-Ge/yenilik projesi olarak değerlendirildi mi? | C16: EVET | D16: Md. 3/A kapsamında projenin Sanayi ve Teknoloji Bakanlığı'nca değerlendirilmesi zorunludur. Bakanlık değerlendirmesi olmadan indirim uygulanamaz.
A17: A0.4b Siparişe dayalı Ar-Ge'de mükellefin rolü nedir? (H.8 ve H.9 çakışmasını önlemek için belirtin) | C17: Yok / Uygulanamaz | D17: Sipariş Alan seçildiyse: H.8 kullanılır (kendi yaptığınız harcamanın %50'si), H.9 boş bırakılır. Sipariş Veren seçildiyse: H.9 kullanılır (ödediğiniz harcamanın %50'si), H.8 boş bırakılır. GV stopaj terkini ve SGK desteği yalnızca sipariş alan Ar-Ge merkezine aittir.
A18: A0.5 Siparişe dayalı Ar-Ge var mı? (Sipariş veren %50, alan %50 dağılımı uygulandı mı?) | C18: HAYIR | D18: Siparişe dayalı yürütülen Ar-Ge faaliyetlerinde: Sipariş alan Ar-Ge merkezi %50, sipariş veren %50 indirim alır. Her iki tarafta da belgelenmiş sözleşme zorunludur.
A19: A0.6 Artırımlı indirim hakkı değerlendirildi mi? (≥%20 artış — ek %50 indirim — 31.12.2028'e kadar) | C19: EVET | D19: Önceki yıla göre 5 göstergeden herhangi birinde ≥%20 artış sağlayan Ar-Ge/Tasarım merkezlerinde artış tutarının %50'si ek indirim konusu yapılabilir (31.12.2028'e kadar). Göstergeler: Ar-Ge/ciro payı, patent sayısı, uluslararası destekli proje sayısı, lisansüstü araştırmacı oranı, toplam araştırmacı oranı.
A20: A0.7 Devreden Ar-Ge indirimi var mı? (Önceki yıldan — YDO ile artırılarak devreder mi?) | C20: HAYIR | D20: Kazanç yetersizliği nedeniyle kullanılamayan Ar-Ge indirimi sonraki yıla devreder. 5746 kapsamında devredilen tutar VUK Yeniden Değerleme Oranı kadar artırılır. KVK 10/1-a'da ise artırım olmadan devreder.
A21: A0.8 YİAKV (KVK Md. 32/C) etkisi: Ar-Ge indirimi YİAKV matrahından düşülebilir mi? Analiz edildi mi? | C21: EVET | D21: Ar-Ge indirimi 'Kazancın Bulunması Halinde' bölümünde olduğundan YİAKV matrahına etkisi dönem mevzuatı çerçevesinde ayrıca analiz edilmelidir. Kesin hüküm verilemez; GİB KV Rehberi ve güncel tebliğler teyit edilmelidir.
A22: A0.9 49 No.lu Tebliğ kapsamında YMM tasdik raporu yükümlülüğü var mı? | C22: EVET | D22: 49 No.lu SMMM-YMM Kanunu Tebliği (30.12.2025): Tek satır ≥500.000 TL VEYA toplam ≥1.000.000 TL → YMM tasdik raporu zorunludur. 41 No.lu Tebliğ tasdik şartı da değerlendirilmeli. Tam tasdik yaptıranlar ayrıca rapor gerekmez.
A23: A0.10 Tasdik Uygunluk Sonucu (9 Ön Kontrol) | C23: =IF(AND(C13="EVET",C14<>"",OR(AND(C14="Md. 3 (Ar-Ge Merkezi)",C15="EVET"),AND(C14="Md. 3/A (Proje Bazlı / Özkaynakla)",C16="EVET")),C21="EVET",C22="EVET"),"✅ OK – Hesaplanabilir","⛔ HATA – Ön koşul eksik") -> ✅ OK – Hesaplanabilir | D23: Temel şartlar sağlanmadan tasdik dosyasına eklenemez.
A24: Tasdik Engelleyici Uyarı | C24: =IF(C23="⛔ HATA – Ön koşul eksik","⛔ BU MODÜL KULLANILAMAZ — A0 Kontrolünü Tamamlayın","") | D24: Hata giderildiğinde uyarı otomatik kalkar.
A26: A. MÜKELLEF, YMM VE DÖNEM BİLGİLERİ
A27: Alan | C27: Giriş | D27: Açıklama
A28: Mükellef Unvanı | D28: Ticaret sicilindeki tam unvan
A29: Vergi Kimlik Numarası | D29: 10 haneli VKN
A30: Hesap Dönemi | D30: 01.01.…… – 31.12.……
A31: Ar-Ge Merkezi Belge No (varsa) | D31: STB tarafından verilen belge numarası ve tarihi
A32: Ar-Ge Merkezi Belge Geçerlilik Tarihi | D32: Belgenin geçerlilik tarihi — süresi dolmuşsa indirim uygulanamaz
A33: Çalışma Kâğıdı Hazırlayan | D33: Tasdiki yapan YMM / sorumlu
A34: KV Oranı (%) | D34: KVK Md. 32: %25 (2025 genel); %30 finans
A35: Yeniden Değerleme Oranı (%) | D35: VUK kapsamında o yıl açıklanan oran — devreden indirim için kullanılır
A37: C. AR-GE HARCAMA TÜRLERİ VE İNDİRİME ESAS TUTAR TESPİTİ (Proje/Merkez Bazında)
A38: Ar-Ge harcamaları, işletmenin diğer faaliyetlerine ait harcamalardan ayrı olarak muhasebeleştirilmeli ve indirim tutarının doğru hesaplanmasına imkân verecek şekilde izlenmelidir. Her proje için ayrı takip yapılması tavsiye edilir.
A39: Harcama Türü Kodu | B39: Harcama Türü Açıklaması | C39: Tutar (TL) | D39: Açıklama / YMM Kontrol Notu
A40: H.1 | B40: Personel Giderleri — Ar-Ge Personeli (Tam Zamanlı ve Kısmi) | D40: Ar-Ge faaliyetine doğrudan katılan araştırmacı ve teknik personel ücretleri. Kısmi çalışmada, Ar-Ge'ye ayrılan süre/toplam çalışma süresi oranı uygulanır. GV stopaj terkinine esas ücretler muhtasar beyanname ekinde ayrıca gösterilir.
A41: H.2 | B41: Personel Giderleri — Destek Personeli (TZE Ar-Ge personelinin %10'u sınırı) | D41: Ar-Ge faaliyetlerine katılan yönetici, laborant, sekreter, işçi ve benzeri destek personeli. Tam zaman eşdeğer Ar-Ge personelinin %10'unu aşamaz.
A42: H.3 | B42: Genel Giderler (Kira, Su, Enerji, Bakım-Onarım, Haberleşme) | D42: Ar-Ge merkezi/proje alanının kira, su, enerji, bakım-onarım ve haberleşme giderleri. Yalnızca Ar-Ge faaliyetinin devamlılığını sağlamaya yönelik olanlar.
A43: H.4 | B43: Dışarıdan Sağlanan Fayda ve Hizmetler | D43: Üniversiteler, araştırma kurumları veya diğer kuruluşlardan sağlanan hizmetler. Toplam Ar-Ge harcamasının %20'sini aşmamalıdır.
A44: H.5 | B44: Vergi, Resim ve Harçlar (Damga Vergisi dahil) | D44: Ar-Ge projesiyle doğrudan ilgili vergi, resim ve harçlar. Damga vergisi istisna kapsamındaysa bu satır sıfır olabilir.
...

Sheet HESAPLAMALAR & KONTROL
A1: 454 – AR-GE İNDİRİMİ (5746 s.K. Md. 3 / Md. 3/A) | HESAPLAMALAR VE DENETİM KONTROL PANELİ
A2: 5746 s.K. Md. 3 / Md. 3/A | KVK Md. 10/1-a | GVK Md. 89/9 | KV Beyannamesi Satır 454 — Tasdik Çalışma Kâğıdı
A4: TASDİK ÖZET TABLOSU — Hızlı Değerlendirme Paneli
A5: Tasdik Uygunluk Kontrolü | C5: ='VERİ GİRİŞİ'!C23 -> ✅ OK – Hesaplanabilir | D5: VERİ GİRİŞİ A0.10 — OK ise hesap kullanılabilir
A6: Modül Türü (Md.3 / Md.3/A) | C6: ='VERİ GİRİŞİ'!C14 | D6: Seçilen modül türü
A7: Cari Dönem Ar-Ge Harcaması (TL) | C7: ='VERİ GİRİŞİ'!C50 -> 0 | D7: C bölümü A toplamı — finansman gideri hariç
A8: Temel İndirim Tutarı (TL) | C8: ='VERİ GİRİŞİ'!C57 -> 0 | D8: D.3 satırı — %100 × harcama
A9: Artırımlı İndirim (TL) | C9: ='VERİ GİRİŞİ'!C58 -> 0 | D9: D.4 satırı — ≥%20 artış varsa ek %50
A10: Devreden İndirim (TL) | C10: ='VERİ GİRİŞİ'!C59 -> 0 | D10: D.5 satırı — önceki yıldan, YDO artırımlı
A11: BU DÖNEM KULLANILAN İNDİRİM (TL) | C11: ='VERİ GİRİŞİ'!C62 -> 0 | D11: D.8 satırı — Beyanname Satır 454
A12: Sonraki Yıla Devreden (TL) | C12: ='VERİ GİRİŞİ'!C63 -> 0 | D12: D.9 satırı — 5746'da YDO ile artırılacak
A14: DENETİM VE TASDİK KONTROL LİSTESİ (K1–K12)
A15: Kontrol Maddesi | C15: Yasal Dayanak | D15: YMM Tasdik Notu | E15: Değ. | F15: Sonuç
A16: K1. 5746 / KVK modülü doğru belirlendi mi? (Md. 3: Merkez Belgesi | Md. 3/A: Proje Onayı | KVK 10/1-a: Genel) | C16: 5746 s.K. Md. 3 | Md. 3/A | KVK Md. 10/1-a | D16: 5746 Md. 3: STB 'Ar-Ge Merkezi Belgesi' zorunlu. 5746 Md. 3/A: Proje STB tarafından Ar-Ge/yenilik projesi olarak değerlendirilmeli. KVK 10/1-a: Ar-Ge merkezi belgesi gerekmez, münhasır yeni teknoloji arayışı yeterli. | E16: ☐ UYGUN ☐ EKSİK ☐ RİSK | F16: ✅/❌/⚠
A17: K2. Ar-Ge Merkezi belgesinin geçerliliği ve personel koşulu teyit edildi mi? | C17: 5746 s.K. Md. 2 | STB Yönetmeliği | D17: En az 15 TZE Ar-Ge personeli koşulu sağlanmalı (bazı NACE sektörlerde 30). Belgenin iptal edilmediği veya şartların ihlal edilmediği teyit edilmeli. Belge tarihi ve süresi tasdik dosyasında yer almalıdır. | E17: ☐ UYGUN ☐ EKSİK ☐ RİSK | F17: ✅/❌/⚠
A18: K3. Ar-Ge faaliyeti münhasıran yeni teknoloji ve bilgi arayışına yönelik mi? | C18: 5746 s.K. Md. 2 | KVK Md. 10/1-a | 1 S.No.lu KV GT | D18: Ürün pazarlanabilir aşamaya geldiğinde Ar-Ge projesi sona erer. Mevcut bilgi ve tekniklerle çözülebilir faaliyetler kapsam dışıdır. Proje tanımı ve STB değerlendirmesi tasdik dosyasında yer almalıdır. | E18: ☐ UYGUN ☐ EKSİK ☐ RİSK | F18: ✅/❌/⚠
A19: K4. Harcama türleri doğru sınıflandırıldı mı? (Finansman gideri 5746'da hariç) | C19: 6 S.No.lu 5746 GT | KVK Md. 10/1-a | D19: 5746 kapsamında finansman giderleri (faiz) Ar-Ge harcaması sayılmaz. KVK 10/1-a'da bu ayrım farklı olabilir. Destek personeli %10 TZE sınırı kontrol edilmeli. | E19: ☐ UYGUN ☐ EKSİK ☐ RİSK | F19: ✅/❌/⚠
A20: K5. Kısmi çalışan personelin Ar-Ge payı (süre oranı) doğru hesaplandı mı? | C20: 5746 GT | Uygulama Yönetmeliği | D20: Kısmi çalışma halinde, personelin Ar-Ge faaliyetlerine ayırdığı süre/toplam süre oranı uygulanarak ücret hesaplanmalıdır. Her personel için çalışma süresi belgesi tasdik dosyasında bulunmalıdır. | E20: ☐ UYGUN ☐ EKSİK ☐ RİSK | F20: ✅/❌/⚠
A21: K6. Siparişe dayalı Ar-Ge varsa %50 / %50 dağılımı doğru uygulandı mı? | C21: 5746 s.K. Md. 3/3. fıkra | D21: Sipariş alan Ar-Ge merkezi harcamaların %50'si, sipariş veren %50'si indirim konusu yapar. İki taraflı sözleşme zorunludur. Sipariş verenler GV stopaj terkini ve SGK desteğinden yararlanamaz. | E21: ☐ UYGUN ☐ EKSİK ☐ RİSK | F21: ✅/❌/⚠
A22: K7. Artırımlı indirim kriterleri değerlendirildi mi? (5 göstergeden biri ≥%20 artış) | C22: 5746 s.K. Md. 3/7. fıkra | 31.12.2028 uzatması | D22: 5 göstergeden birinde ≥%20 artış: (a) Ar-Ge/ciro payı, (b) patent sayısı, (c) uluslararası destekli proje, (d) lisansüstü araştırmacı oranı, (e) toplam araştırmacı oranı. Artış tutarının %50'si ek indirim konusu yapılabilir. | E22: ☐ UYGUN ☐ EKSİK ☐ RİSK | F22: ✅/❌/⚠
A23: K8. Devreden Ar-Ge indirimi YDO ile artırılarak devredildi mi? | C23: 5746 s.K. Md. 3/2. fıkra | VUK YDO | D23: 5746 kapsamında devreden tutar sonraki yılda VUK Yeniden Değerleme Oranı kadar artırılır. KVK 10/1-a kapsamında devredilen tutar artırımsız devreder. İki kanundan yararlanılıyorsa her biri ayrı izlenmelidir. | E23: ☐ UYGUN ☐ EKSİK ☐ RİSK | F23: ✅/❌/⚠
A24: K9. GV stopaj terkini doğru hesaplandı ve muhtasar beyanname ekinde gösterildi mi? | C24: 5746 s.K. Md. 3/A | 4 S.No.lu 5746 GT | 7555 s.K. (24.07.2025) | D24: Doktoralı: %95, YL: %90, Diğerleri: %80. 7555 s.K. ile brüt asgari ücretin 40 katı üst sınırı getirildi. Personel bazında hesaplama zorunludur; muhtasar beyanname Tablo-1 (20/c) satırında gösterilmeli. | E24: ☐ UYGUN ☐ EKSİK ☐ RİSK | F24: ✅/❌/⚠
A25: K10. SGK işveren hissesi desteği doğru uygulandı mı? (%50 Hazine karşılar) | C25: 5746 s.K. Md. 3/A | SGK mevzuatı | D25: Kamu personeli hariç, Ar-Ge ve destek personelinin SGK işveren hissesinin %50'si Hazine karşılar. SGK beyannamesinde ayrıca beyan edilir; KV beyannamesini etkilemez. | E25: ☐ UYGUN ☐ EKSİK ☐ RİSK | F25: ✅/❌/⚠
A26: K11. YİAKV (KVK Md. 32/C) matrahında Ar-Ge indirimi etkisi analiz edildi mi? | C26: KVK Md. 32/C | GİB KV Rehberi 2025 | D26: Ar-Ge indirimi 'Kazancın Bulunması Halinde' bölümünde yer aldığından YİAKV matrahına etkisi dönem mevzuatı çerçevesinde ayrıca analiz edilmeli. Kesin hüküm verilemez; GİB rehberi ve tebliğler teyit edilmelidir. | E26: ☐ UYGUN ☐ EKSİK ☐ RİSK | F26: ✅/❌/⚠
A27: K12. 49 No.lu Tebliğ eşiği aşıldı mı? (500K TL / 1M TL) YMM raporu gerekiyor mu? | C27: 49 No.lu SMMM-YMM K. Tebliği (30.12.2025) | 41 No.lu Tebliğ | D27: Tek satır ≥500.000 TL veya toplam ≥1.000.000 TL → YMM tasdik raporu zorunludur. 41 No.lu Tebliğ kapsamındaki tasdik şartı da ayrıca değerlendirilmeli. Tam tasdik yaptıranlar ayrıca rapor gerekmez. | E27: ☐ UYGUN ☐ EKSİK ☐ RİSK | F27: ✅/❌/⚠
A29: OTOMATİK KONTROL 1 — H.4 DIŞ HİZMETLER %20 SINIRI (6 S.No.lu 5746 GT)
A30: H.4 Dış Hizmet Tutarı (TL) | C30: ='VERİ GİRİŞİ'!C42 -> 0 | D30: VERİ GİRİŞİ H.4 satırından otomatik alınır
A31: Toplam Ar-Ge Harcaması (TL) | C31: ='VERİ GİRİŞİ'!C50 -> 0 | D31: VERİ GİRİŞİ C bölümü A toplamı
A32: H.4 / Toplam Oran (%) | C32: =IFERROR(C30/C31*100,0) -> 0 | D32: Bu oran %20'yi aşmamalıdır (6 Seri No.lu 5746 GT)
A33: H.4 %20 Sınırı Sonucu | C33: =IF(IFERROR(C30/C31,0)<=0.2,"✅ UYGUN — %20 sınırı içinde","⚠️ SINIRI AŞIYOR — H.4 düşülmeli") -> ✅ UYGUN — %20 sınırı içinde | D33: Sınır aşılıyorsa: H.4 tutarını Toplam × %20 ile sınırlandırınız
A35: OTOMATİK KONTROL 2 — DESTEK PERSONELİ %10 TZE SINIRI (5746 s.K. Md. 2)
A36: Toplam Tam Zaman Eşdeğer (TZE) Ar-Ge personeli sayısını VERİ GİRİŞİ'nden okuyamıyoruz — bu kontrol için aşağıdaki 2 hücreyi doldurunuz.
A37: Toplam TZE Ar-Ge Personeli Sayısı (girişi yapınız) | D37: Ar-Ge merkezinde tam zaman eşdeğer (TZE) olarak çalışan Ar-Ge personeli sayısı. Kısmi çalışmada oransal hesap yapılır.
A38: Destek Personeli TZE Sayısı (girişi yapınız) | D38: Ar-Ge faaliyetlerine katılan destek personelinin TZE sayısı (yönetici, laborant, sekreter vb.)
A39: İzin Verilen Azami Destek Personeli (%10 Üst Sınır) | C39: =IFERROR(C37*0.1,0) -> 0 | D39: TZE Ar-Ge personeli × %10 = azami destek personeli sayısı
A40: Sınır Aşımı (Aşan TZE kişi sayısı) | C40: =MAX(0,C38-C39) -> 0 | D40: Pozitif değer = aşım var; bu kişilerin giderleri H.2'den çıkarılmalıdır
A41: Destek Personeli %10 Sınırı Sonucu | C41: =IF(C38<=C39,"✅ UYGUN — %10 sınırı içinde","⚠️ SINIRI AŞIYOR — H.2 tutarını düzeltin") -> ✅ UYGUN — %10 sınırı içinde | D41: Sınır aşılıyorsa H.2 personel gideri tutarını azaltınız
A43: YİAKV VE DEVREDEN İNDİRİM UYARI NOTU
A44: Ar-Ge indirimi 'Kazancın Bulunması Halinde İndirilecek' bölümündedir — 310 (TGB/4691) 'Zarar Olsa Dahi' bölümünden farklıdır. Devreden indirim: 5746 kapsamında YDO ile artırılır; KVK 10/1-a'da artırımsız devredilir. YİAKV matrahına etkisi dönem mevzuatı çerçevesinde ayrıca analiz edilmeli — kesin hüküm verilemez.

Sheet MUHASEBE KAYITLARI
A1: 454 – AR-GE İNDİRİMİ (5746 s.K.) | MUHASEBE KAYITLARI ÇALIŞMA KÂĞIDI
A2: TDHP Esaslarına Göre — Ar-Ge harcamaları 263/750 hesaplarında izlenir. İndirim ticari kârı etkilemez — beyanname üzerinde matrah azaltıcı unsurdur. Muhasebe sorumluluğu mükellefte, tasdik sorumluluğu YMM'dedir.
A3: HESAP STANDARDI: 263 Araştırma ve Geliştirme Giderleri (aktif) | 750 Ar-Ge Giderleri (gider) | 193 Peşin Ödenen Vergiler | 190 Devreden Ar-Ge İndirimi (kayıt dışı izleme)
A5: KAYIT 1 — AR-GE HARCAMASININ AKTİFLEŞTİRİLMESİ (263 Ar-Ge Giderleri — Proje Süresince)
A6: Tarih | B6: Hesap No / Açıklama | D6: Not | E6: Borç (TL) | F6: Alacak (TL) | G6: Ref
C7: [1. hesap / açıklama]
C8: [2. hesap / açıklama]
A9: 263 AR-GE GİDERLERİ ← 100/102/320/etc. | Harcama yapıldıkça proje aktifleştirilir. Doğrudan giderleme imkânı varsa 750 AR-GE GİDERLERİ hesabı kullanılır.
A11: KAYIT 2 — PROJE TAMAMLANDIĞINDA AMORTİSMAN KAYDEDME (İktisadi Kıymet Oluşmuşsa)
A12: Tarih | B12: Hesap No / Açıklama | D12: Not | E12: Borç (TL) | F12: Alacak (TL) | G12: Ref
C13: [1. hesap / açıklama]
C14: [2. hesap / açıklama]
A15: 268 BİRİKMİŞ AMORTİSMAN ← 770/760 | 5746: Aktifleştirilen Ar-Ge harcamaları proje bittikten sonra 263→268 amortisman yoluyla itfa edilir. İktisadi kıymet oluşmazsa doğrudan gider yazılır.
A17: KAYIT 3 — GV STOPAJ TERKİNİ (Muhtasar Beyanname — Aylık/Dönemsel)
A18: Tarih | B18: Hesap No / Açıklama | D18: Not | E18: Borç (TL) | F18: Alacak (TL) | G18: Ref
C19: [1. hesap / açıklama]
C20: [2. hesap / açıklama]
A21: 360 ÖDENECEK VERGİ → Terkin: Tahakkuk eden GV stopajından terkine tabi tutar muhtasar beyanname Tablo-1 (20/c) satırında gösterilir; terkin sonrası kalan vergi (21) satırında beyan edilir.
A23: NOT — BEYANNAME ETKİSİ: Ar-Ge indirimi ticari kârı etkilemez; KV beyannamesinde 'Kazancın Bulunması Halinde İndirilecek' bölümünde Satır 454'te gösterilir. KVK 10/1-a (artırımsız) ile 5746 (YDO artırımlı) kapsamındaki devreden indirimler ayrı izlenmelidir.

Sheet BELGE LİSTESİ
A1: 454 – AR-GE İNDİRİMİ (5746 s.K.) | TASDİK BELGE LİSTESİ VE DENETİM KANITI ENVANTERİ
A2: KVK Md. 17 / 3568 s.K. Kapsamında YMM Tasdik Dosyası — Zorunlu ve Destekleyici Belgeler
B3: No | C3: Belge / Denetim Kanıtı | D3: İçerik ve YMM Tasdik Kontrol Notu | E3: Temin Kaynağı
A4: KATEGORİ 1 — ZORUNLU TASDİK BELGELERİ (Eksiklik Tasdik Kapsamından Çıkarılma Gerekçesi Oluşturur)
B5: ✅ 1 | C5: Ar-Ge Merkezi Belgesi (STB Onaylı — Md. 3 İçin) | D5: Sanayi ve Teknoloji Bakanlığı tarafından verilen 'Ar-Ge Merkezi Belgesi'. Belge tarihi, geçerlilik süresi ve faaliyet konusu YMM tarafından bağımsız olarak doğrulanmalıdır. Md. 3/A kullanıyorsa bu satır N/A; proje onay belgesi ile değiştirilir. | E5: STB / Mükellef arşivi
B6: ✅ 2 | C6: Ar-Ge Proje Tanımı ve STB/TÜBİTAK Değerlendirme Belgesi | D6: 5746 Md. 3 için: Ar-Ge projelerinin listesi ve kısa tanımları. 5746 Md. 3/A için: Projenin Bakanlık tarafından Ar-Ge/yenilik projesi olarak değerlendirildiğini gösteren belge — bu olmadan indirim uygulanamaz. | E6: STB / TÜBİTAK
B7: ✅ 3 | C7: Ar-Ge Harcama Özeti ve Muhasebe Hesap Dökümü | D7: Harcama türleri (H.1-H.9) bazında dökümü. 263 / 750 hesap ekstresi ile uyumu teyit edilmeli. Finansman giderlerinin ayrıştırılmış olduğu belgelenmelidir. | E7: Muhasebe / ERP
B8: ✅ 4 | C8: Personel Listesi — Tam Zamanlı Ar-Ge, Kısmi ve Destek Personeli Dökümü | D8: Her personel için: tam/kısmi zamanlı ayrımı, Ar-Ge'ye ayrılan süre oranı, eğitim durumu. TZE (tam zaman eşdeğer) personel sayısı hesabı ve %10 destek personeli sınırı kontrolü. En az 15 TZE şartının sağlandığını belgeler. | E8: İK/Bordro sistemi
B9: ✅ 5 | C9: GV Stopaj Terkini Hesaplama Tablosu (Personel Bazında) ve Muhtasar Beyanname | D9: Her personel için: öğrenim durumu, terkin oranı, aylık ücret, 40×asgari ücret üst sınırı. Muhtasar beyanname Tablo-1 (20/c) satırı ile mutabakat. 7555 s.K. (24.07.2025) üst sınırının doğru uygulandığı teyit edilmeli. | E9: Bordro / muhtasar beyanname
B10: ✅ 6 | C10: Devreden Ar-Ge İndirimi Tablosu (Önceki Yıldan Gelenler) | D10: 5746 kapsamı: Önceki yıldan gelen tutar ve YDO artışı hesabı. KVK 10/1-a kapsamı: Artırımsız devreden tutar. İki kanun altında izleme ayrı ayrı yapılmış olmalıdır. | E10: YMM çalışma notu / önceki beyanname
B11: ✅ 7 | C11: KV Beyannamesi Satır 454 — Tutarlılık Kontrolü | D11: Beyanname 454 satırı ile bu çalışma kâğıdı D.8 tutarı mutabık olmalıdır. 'Kazancın Bulunması Halinde İndirilecek' bölümüne yazıldığı teyit edilmeli. Fark varsa yazılı gerekçe hazırlanmalıdır. | E11: GİB e-Beyanname
B12: ✅ 8 | C12: Ar-Ge Faaliyet Raporu / Proje Çıktıları (Proje Gerçekliği Kanıtı) | D12: Ar-Ge faaliyetinin münhasıran yeni teknoloji ve bilgi arayışına yönelik olduğunu kanıtlayan proje ilerleme raporları, deney kayıtları veya teknik belgeler. Bu belge olmadan 'Ar-Ge faaliyeti' iddiası savunulamaz. | E12: Ar-Ge departmanı
A13: KATEGORİ 2 — KRİTİK DESTEK BELGELERİ
B14: ➕ 9 | C14: Siparişe Dayalı Ar-Ge Varsa: Sözleşme ve %50/%50 Dağılım Hesabı | D14: Sipariş alan/veren arasındaki sözleşme ve harcama dağılım tablosu. Sipariş veren tarafın GV stopajı terkini ve SGK desteğinden yararlanamayacağı teyit edilmeli. | E14: Hukuk arşivi
B15: ➕ 10 | C15: Artırımlı İndirim İçin Önceki Yıl Karşılaştırma Tablosu (5 Gösterge) | D15: ≥%20 artış sağlanan gösterge(ler)in önceki yıl ve cari yıl değerleri. Artış oranı ve ek indirim tutarı hesabı. Artış yok ise bu belge N/A. | E15: Ar-Ge / YMM hesabı
B16: ➕ 11 | C16: SGK İşveren Hissesi Desteği Hesabı ve SGK Beyannamesi | D16: %50 Hazine desteğine konu olan personel listesi ve prim hesabı. SGK sisteminde '05746' kodu ile bildirimin yapıldığı teyit edilmeli. | E16: SGK / bordro
B17: ➕ 12 | C17: YİAKV Matrah Hesaplama Notu | D17: Ar-Ge indirimi tutarının YİAKV matrahına etkisi dönem mevzuatı çerçevesinde analiz edilmeli. YMM tarafından hazırlanmalı; GİB KV Rehberi dayanağı belirtilmeli. | E17: YMM çalışma notu
B18: ➕ 13 | C18: 49 No.lu Tebliğ Eşiği Kontrol Notu ve YMM Tasdik Raporu Yükümlülüğü | D18: 454 satırı ≥500K TL veya toplam ≥1M TL ise YMM tasdik raporu ibraz edilmelidir. 41 No.lu Tebliğ kapsamındaki tasdik şartı da ayrıca değerlendirilmelidir. | E18: YMM
A19: ⚠️ TASDİK KURALI: Ar-Ge indirimi 'Kazancın Bulunması Halinde İndirilecek' bölümündedir — zarar durumunda kullanılamaz. 4691/TGB (310 kodu) ile karıştırılmamalıdır. 5746 kapsamında devreden indirim YDO ile artırılır; KVK 10/1-a'da artırımsız devredilir. Bu ayrımın tasdik raporunda net gösterilmesi zorunludur.
A21: TASDİK DOSYASI HAZIRLIK KONTROL ÖZETİ
A22: 454 — Ar-Ge İndirimi (5746 s.K. Md. 3 / Md. 3/A) — Tasdik Hazırlık Kontrol Listesi □ A0 kontrol bloğu (9 soru) tamamlandı ve 'OK' sonucu alındı □ Ar-Ge Merkezi belgesi (STB) veya proje onay belgesi temin edildi □ Ar-Ge faaliyetinin münhasır yeni teknoloji arayışına yönelik olduğu belgelendi □ Harcama türleri (H.1-H.9) doğru sınıflandırıldı; finansman giderleri ayrıştırıldı □ TZE Ar-Ge personeli sayısı (en az 15) ve %10 destek sınırı doğrulandı □ Kısmi çalışan personel süre oranı hesabı yapıldı □ Siparişe dayalı Ar-Ge varsa %50/%50 dağılım doğrulandı □ Artırımlı indirim kriterleri (5 gösterge — ≥%20 artış) değerlendirildi □ Devreden indirim: 5746'da YDO ile artırılarak, KVK 10/1-a'da artırımsız aktarıldı □ GV stopaj terkini personel bazında hesaplandı (7555 s.K. üst sınırı kontrol edildi) □ YİAKV matrahına etkisi analiz edildi ve belgelendi □ 49/41 No.lu Tebliğ eşikleri kontrol edildi; gerekiyorsa YMM raporu hazırlandı □ Beyanname 454 satırı = D.8 tutarı mutabakatı tamamlandı

Sheet DENETÇİ NOTLARI
A1: 454 – AR-GE İNDİRİMİ (5746 s.K. Md. 3 / Md. 3/A) | YMM MESLEKİ DEĞERLENDİRME VE TASDİK NOTLARI
A2: 5746 s.K. | KVK Md. 10/1-a | GVK Md. 89/9 | Yasal Dayanak • Tasdik Kapsamı • Risk Analizi • YİAKV • İnceleme Notları
A3: 📌 YMM TASDİK YAZIM DİLİ STANDARDI: ✅ KULLANIN: değerlendirilmelidir | ayrıca test edilmelidir | uygun koşullar sağlandığında | belgelenmelidir ❌ KULLANMAYIN: uygulanır | kesin olarak | tamamı indirim konusu yapılır — YMM sorumluluğu doğurur
A5: I. HUKUK VE MEVZUAT DEĞERLENDİRMESİ (Ana Tasdik Tespiti)
A6: Yasal Dayanak: • 5746 s.K. Md. 3 (Ar-Ge Merkezi): Ar-Ge merkezlerinde gerçekleştirilen Ar-Ge ve yenilik harcamalarının %100'ü (siparişe dayalılarda %50) kurum/ticari kazancın tespitinde indirim konusu yapılabilir. Sanayi ve Teknoloji Bakanlığı'ndan 'Ar-Ge Merkezi Belgesi' zorunludur. • 5746 s.K. Md. 3/A (Proje Bazlı / Özkaynakla): İşletmelerin özkaynakları ile gerçekleştirdikleri münhasıran yeni teknoloji ve bilgi arayışına yönelik Ar-Ge harcamalarının %100'ü, projenin Sanayi ve Teknoloji Bakanlığı tarafından Ar-Ge/yenilik projesi olarak değerlendirilmesi şartıyla indirim konusu yapılabilir. • KVK Md. 10/1-a: Münhasıran yeni teknoloji ve bilgi arayışına yönelik Ar-Ge harcamalarının %100'ü kurum kazancından indirilir. 5746 kapsamında yararlanılıyorsa bu madde ayrıca değerlendirmeye alınmayabilir; tercih edilmesi halinde farklılıklar gözetilmelidir. • GVK Md. 89/9: Gelir vergisi mükelleflerine paralel düzenleme. • Uygulama süresi: 31.12.2028'e kadar uzatılmıştır.
A8: II. KRİTİK FARK: 5746 Md.3 / Md.3/A / KVK 10/1-a VE 310 (TGB/4691) KARŞILAŞTIRMASI
A9: BEYANNAME KONUMU: 454 kodu (Ar-Ge): 'Kazancın Bulunması Halinde İndirilecek' bölümü 310 kodu (TGB): 'Zarar Olsa Dahi İndirilecek' bölümü Bu iki kodu karıştırmak en sık yapılan hatalardan biridir! DEVREDEN İNDİRİM FARKI: 5746 kapsamında: Kazanç yetersizliği nedeniyle devreden tutar sonraki yılda VUK Yeniden Değerleme Oranı kadar artırılarak kullanılır. KVK 10/1-a kapsamında: Devredilen tutar artırımsız devredilir. İki kanundan aynı anda yararlanılıyorsa her biri ayrı izlenmeli ve raporlanmalıdır. ARTIRMA FARKI: 5746 Md. 3: Artırımlı indirim hakkı vardır (≥%20 artış — %50 ek indirim — 31.12.2028'e kadar). KVK 10/1-a: Artırımlı indirim yoktur. SİPARİŞE DAYALI: 5746 Md. 3: Sipariş alan %50 + sipariş veren %50 dağılımı uygulanır. Sipariş verenler GV stopaj terkini ve SGK desteğinden yararlanamaz.
A11: III. TASDİK RİSK ANALİZİ — KRİTİK RİSKLER
A12: RİSK 1 — AR-GE MERKEZİ BELGESİ KOŞULLARININ İHLALİ: En az 15 TZE Ar-Ge personeli şartının kaybedildiği, belgenin iptal edildiği veya şartların ihlal edildiği hallerde indirimin geri alınması ve vergi ziyaı riski doğar. RİSK 2 — ‘YENİ TEKNOLOJİ ARAŞTIRILMASI’ KAPSAMINI AŞMA: Halihazırda bilinen veya mevcut tekniklerle çözülebilir faaliyetler kapsam dışıdır. Ürün geliştirme ve test aşamasının pazarlanabilir aşamayı geçtiği andan itibaren yapılan harcamalar Ar-Ge sayılmaz. RİSK 3 — FİNANSMAN GİDERİNİN DAHIL EDİLMESİ: 5746 kapsamında finansman giderleri (faiz, kredi masrafları) Ar-Ge harcaması sayılmaz. Bu giderlerin H.1-H.9 hesabına dahil edilmesi tarhiyat riskine yol açar. RİSK 4 — GV STOPAJ TERKİNİ HATALARI: Personel öğrenim durumu yanlış belirlenmesi, 40×asgari ücret üst sınırı (7555 s.K.) uygulanmaması veya kısmi çalışmada süre oranının yanlış hesaplanması. RİSK 5 — DEVREDEN İNDİRİM YDO ARTIŞI: 5746 kapsamındaki devreden indirimin YDO ile artırılmadan kullanılması veya KVK 10/1-a ile 5746 kapsamlarının karıştırılması.
A14: IV. YİAKV ETKİ ANALİZİ (KVK Md. 32/C)
A15: Ar-Ge indirimi (454 kodu) 'Kazancın Bulunması Halinde İndirilecek' bölümündedir. Bu bölümdeki indirimlerin YİAKV matrahına etkisi dönem mevzuatı çerçevesinde ayrıca analiz edilmelidir. Güncel Değerlendirme (2025): • 4691/TGB (310 kodu — 'Zarar Olsa Dahi') için YİAKV kuralı farklıdır. • Ar-Ge indirimi için GİB KV Rehberi ve ilgili dönem mevzuatı teyit edilmelidir. • Kesin hüküm verilemez — YMM tarafından ayrı tabloda hesaplanmalı ve belgelenmelidir.
A17: V. MEVZUAT DAYANAKLARI VE GÜNCEL KAYNAKLAR
... A21: 1. ÖNCELİKLİ BELGE: Ar-Ge Merkezi Belgesi (tarih, geçerlilik, personel sayısı). Belge ve koşul ihlali varsa indirimden geriye dönük yararlanılamaz. 2. 'AR-GE' OLUP OLMADIĞI NOTU: Projenin gerçekten yeni teknoloji arayışına yönelik olduğunu kanıtlayan teknik belgeler (proje raporu, deney kayıtları) tasdik dosyasında bulunmalıdır. Bu kanıt olmadan 'Ar-Ge' iddiası inceleme sürecinde zayıf kalır. 3. GV STOPAJ VE SGK: Personel bazında hesaplama, 40×asgari ücret üst sınırı kontrolü ve muhtasar beyanname (20/c) uyumu YMM tarafından bağımsız olarak doğrulanmalıdır. 4. 454 vs 310 KARIŞIKLIĞI: Ar-Ge indirimi (454) zarar durumunda KULLANILAMAZ. TGB istisnası (310) zarar olsa da uygulanır. Bu ayrım beyanname dolumunda kritiktir. 5. YMM SORUMLULUK NOTU: Bu çalışma kâğıdındaki veriler mükellef beyanına dayanmaktadır. Ar-Ge faaliyetinin niteliği, personel listesi, harcama dökümü ve merkez belgesi YMM tarafından 3568 sayılı Kanun çerçevesinde bağımsız olarak test edilmiştir.
