Workbook

Sheet VERİ GİRİŞİ
A1: 467 – İSTANBUL FİNANS MERKEZİ (İFM) KAZANÇ İNDİRİMİ | KVK Mad. 10/1-i | 7412 S.K. | YMM TASDİK
A2: Beyanname 467 | GİB KV Beyan Rehberi Mart 2026 (No:606) | Kazancın Bulunması Halinde | YİAKV Teyidi
A3: KVK Md.10/1-i — İSTANBUL FİNANS MERKEZİ (İFM) KAZANÇ İNDİRİMİ: 7412 sayılı İstanbul Finans Merkezi Kanunu kapsamında İFM'de faaliyette bulunan kurumların (katılımcıların) yurt dışı kaynaklı finansal hizmet kazançlarına kademeli indirim. ★ KADEMELİ İNDİRİM ORANI (GİB Rehberi No:606): 2022–2031 Arası: Net Kazancın %100'ü — Bu dönemde kazanç üzerinden hiç KV ödenmez. 2032 ve Sonrası: Net Kazancın %75'i — Teşvik süresiz, oran azalır. ★ KAPSAM KOŞULLARI (DÖRDÜ BİRDEN ZORUNLU): ① KATILIMCI BELGESİ: İFM Başkanlığı'ndan alınmış geçerli katılımcı belgesi ② BÖLGEDE FAALİYET: İFM bölgesinde fiilen faaliyette bulunmak ③ PERSONEL: Bölgede fiilen personel istihdam etmek ④ HİZMET TÜRÜ: Finansal hizmet — yurt dışı kaynaklı kazanç ★ YİAKV: GİB Rehberi No:607 kapsamında durumu YMM tarafından teyit edilmeli.
A4: ★ ORAN DİKKATİ: 2025 dönemi için %100 (2022-2031 bandı). 2032'de %75'e iner. ★ 416 ile KARIŞTIRILMASIN: 416 Diğer Hizmetler %50 — 467 İFM %100/%75 ve katılımcı belgesi zorunlu. ✓ YİAKV (KVK Md.32/C f.2 bent g): 467 YİAKV MATRAHINDA DÜŞÜLEBİLİR — KVK Md.32/C 2. fıkrasının (g) bendi kapsamında KORUMAL KALEMDİR. Asgari vergi yükü DOĞURMAZ.
A6: A0. KAPSAM VE NİTELİK UYGUNLUK ÖN KONTROLÜ — KVK Md.10/1-i İFM KAZANÇ İNDİRİMİ
B7: Kontrol Sorusu | E7: Yanıt | G7: YMM Tasdik Notu
A8: A0.1 ★ Kurum İFM Başkanlığı'ndan geçerli KATİLIMCI BELGESİ aldı mı? | E8: EVET | F8: 7412 s.K. kapsamında İFM Başkanlığı'nın verdiği katılımcı belgesi zorunludur. Belge olmadan 467 uygulanamaz.
A9: A0.2 ★ Kurum İFM bölgesinde FİİLEN faaliyette bulunuyor mu? | E9: EVET | F9: İFM bölgesinde fiziksel ofis ve fiili faaliyet zorunludur. Sadece tescil yeterli değil.
A10: A0.3 ★ İFM bölgesinde FİİLEN PERSONEL istihdam ediliyor mu? | E10: EVET | F10: Bölgede çalışan personel varlığı zorunludur. SGK kayıtları ile teyit edilmeli.
A11: A0.4 ★ Kazanç YURT DIŞI KAYNAKLI finansal hizmetlerden mi elde ediliyor? | E11: EVET | F11: İndirim yalnızca yurt dışı kaynaklı finansal hizmet kazançlarına uygulanır. Yurt içi müşteriye verilen hizmet → Kapsam dışı.
A12: A0.5 ★ Dönem oran tespiti yapıldı mı? (2022-2031: %100 | 2032+: %75) | E12: 2022-2031 (İndirim Oranı: %100) | F12: GİB Rehberi No:606: 2022-2031 arası %100, 2032 ve sonrası %75. 2025 dönemi için %100 uygulanır.
A13: A0.6 ✓ YİAKV: KVK Md.32/C f.2 (g) bendi — 467 DÜŞÜLEBILIR (Korumalı Kalem) | E13: EVET — Korumalı | F13: KVK Md.32/C f.2 (g): 467 YİAKV matrahından düşülebilir. Asgari vergi yükü doğurmaz.
A14: A0.7 YMM Tasdik Raporu gereksinimi değerlendirildi mi? | E14: EVET | F14: >=500.000 TL → YMM raporu.
A15: A0.8 Tasdik Uygunluk Sonucu | E15: =IF(AND(E8="EVET",E9="EVET",E10="EVET",E11="EVET"),"OK - Hesaplanabilir","HATA - Ön koşul eksik") -> OK - Hesaplanabilir | F15: ★ A0.1 katılımcı belgesi | A0.2 fiili faaliyet | A0.3 personel | A0.4 yurt dışı kaynak | A0.5 oran.
A17: A. GENEL BİLGİLER
A18: Kurumun Unvanı | F18: Tam ticaret unvanı
A19: VKN | F19: 10 haneli VKN
A20: Hesap Dönemi | F20: 01.01.2025 – 31.12.2025
A21: KV Oranı (%) | F21: 2025: %25
A22: Katılımcı Belgesi No | F22: İFM Başkanlığı'ndan alınan katılımcı belgesi numarası
A23: Katılımcı Belgesi Tarihi | F23: Katılımcı belgesinin düzenleme tarihi
A24: Uygulanan İndirim Oranı | F24: 2025 için: %100 (2022-2031 bandı)
A25: Dosya Referansı | F25: YMM-2025/467-01
A28: B. İFM KAZANÇ İNDİRİM HESABI — KVK Md.10/1-i | KADEMELİ ORAN
A29: B.1 2022–2031 DÖNEMİ — İNDİRİM ORANI: %100 (2025 DÖNEMİ BU BANTTA)
B30: Parametre | D30: Değer (TL) | F30: Açıklama | G30: Kaynak
A31: B.1.1 ★ Yurt Dışı Kaynaklı Finansal Hizmet Brüt Geliri | D31: İFM'den yurt dışı kaynaklı finansal hizmet brüt geliri. | F31: Fatura/Hesap
A32: B.1.2 ★ İlişkili Maliyet/Giderler | D32: Yurt dışı hizmetle doğrudan ilişkili giderler. | F32: Gider kaydı
A33: B.1.3 ★ İNDİRİME ESAS NET KAZANÇ (B.1.1 - B.1.2) | C33: =MAX(0,C31-C32) -> 0 | D33: Net kazanç. %100 bu tutara uygulanır — brüt değil! | F33: Formül
A34: B.1.4 İndirim Oranı (2022-2031) | C34: %100 | D34: GİB Rehberi No:606 — 2022-2031 arası. | F34: Rehber No:606
A35: B.1.5 ★ BEYANNAME 467 (2022-2031 Dönemi) | C35: =MAX(0,C31-C32)*1 -> 0 | D35: Net Kazanç × %100 = Beyanname 467 (2025 için). | F35: Formül
A37: B.2 2032 VE SONRASI DÖNEMİ — İNDİRİM ORANI: %75 (BİLGİ AMAÇLI — 2025 DÖNEMI UYGULANMAZ)
B38: Parametre | D38: Değer (TL) | F38: Açıklama | G38: Kaynak
A39: B.2.1 Yurt Dışı Kaynaklı Finansal Hizmet Brüt Geliri (2032+) | D39: 2032 ve sonrası için ayrı satır — 2025 dönemi kullanılmaz. | F39: Fatura/Hesap
A40: B.2.2 İlişkili Maliyet/Giderler (2032+) | D40: 2032 sonrası gider payı. | F40: Gider kaydı
A41: B.2.3 Net Kazanç (2032+) | C41: =MAX(0,C39-C40) -> 0 | D41: Net kazanç. %75 uygulanır. | F41: Formül
A42: B.2.4 İndirim Oranı (2032+) | C42: %75 | D42: GİB Rehberi No:606 — 2032 ve sonrası. | F42: Rehber No:606
A43: B.2.5 BEYANNAME 467 (2032+ Dönemi) | C43: =MAX(0,C39-C40)*0.75 -> 0 | D43: Net Kazanç × %75. (2025 için bu bölüm 0) | F43: Formül
A45: C. İFM FİNANSAL HİZMET KAZANÇ TABLOSU (BEYANNAME 467)
A46: Her finansal hizmet kalemi veya müşteri grubu için ayrı satır. 2025 dönemi için Sütun 5 = Net Kazanç × %100. Yurt dışı kaynaklı hizmetler — yurt içi müşteri satırları dahil edilmemeli.
...

Sheet HESAPLAMALAR & KONTROL
A1: 467 – İFM KAZANÇ İNDİRİMİ KVK Md.10/1-i | HESAPLAMALAR VE DENETİM
A2: 7412 s.K. İFM | Katılımcı Belgesi | 2025:%100 / 2032+:%75 | Net Kazanç | Beyanname 467
A4: A. TASDİK ÖZETİ
A5: A0 Uygunluğu | D5: ='VERİ GİRİŞİ'!E15 -> OK - Hesaplanabilir | E5: OK ise devam
A6: Katılımcı Belgesi (A0.1) | D6: ='VERİ GİRİŞİ'!E8 -> EVET | E6: İFM Başkanlığı belgesi
A7: Cari Dönem Oranı (A0.5) | D7: ='VERİ GİRİŞİ'!E12 -> 2022-2031 (İndirim Oranı: %100) | E7: 2025: %100
A8: Net Kazanç (D.3) | D8: ='VERİ GİRİŞİ'!C60 -> 0 | E8: Max(0,Brüt-Gider)
A9: 467 İNDİRİM (D.5) | D9: ='VERİ GİRİŞİ'!C62 -> 0
A10: YİAKV Durumu | D10: ✓ DÜŞÜLEBILIR — (g) bendi | E10: KVK Md.32/C f.2 (g): Korumalı kalem — İFM kazancı üzerinden asgari vergi yükü yok
A12: B. KVK Md.10/1-i İFM KAPSAMI — KADEMELİ ORAN VE 416 İLE KARŞILAŞTIRMA
A13: KVK MADDE 10/1-i — İFM KAZANÇ İNDİRİMİ (7412 S.K.): KAPSAM: İFM'de katılımcı belgesiyle faaliyette bulunan kurumların yurt dışı kaynaklı finansal hizmetlerden elde ettikleri kazançlara indirim. KADEMELİ İNDİRİM TABLOSU (GİB Rehberi No:606): ┌─────────────────┬────────────────────────────────────────────────┐ │ Dönem │ İndirim Oranı │ ├─────────────────┼────────────────────────────────────────────────┤ │ 2022–2031 │ %100 — Net kazanç üzerinden sıfır KV │ │ 2032 ve sonrası │ %75 — Net kazancın %75'i matrahtan düşülür │ └─────────────────┴────────────────────────────────────────────────┘ 467 (İFM) ile 416 (Diğer Hizmetler/KVK Md.10/1-ğ) KARŞILAŞTIRMASI: 416: Mimarlık/Mühendislik/Yazılım vb. yurt dışı hizmet → %50 sabit oran Bakanlık izni yok | Geniş hizmet kapsamı | Kişi + Kuruluş alıcı 467: Finansal hizmetlere özgü → %100/%75 kademeli oran (daha avantajlı!) Katılımcı belgesi + fiili faaliyet + personel şartı İFM bölgesinde olmak zorunlu HESAPLAMA ESASI: Net Kazanç (Brüt − Gider) × Oran
A15: C. DENETİM KONTROL LİSTESİ (K1–K12)
B16: Kontrol | D16: Açıklama | F16: Sonuç
A17: K1 | B17: ★ Katılımcı belgesi İFM Başkanlığı'ndan alındı mı? | D17: Belge olmadan 467 uygulanamaz. | F17: Uygun/Eksik/Risk
A18: K2 | B18: ★ İFM bölgesinde fiili faaliyet var mı? | D18: Kayıt değil, fiili faaliyet şart. | F18: Uygun/Eksik/Risk
A19: K3 | B19: ★ Bölgede personel istihdam ediliyor mu? | D19: SGK teyidi. | F19: Uygun/Eksik/Risk
A20: K4 | B20: ★ Hizmet yurt dışı kaynaklı mı? | D20: Yurt içi müşteri → Kapsam dışı. | F20: Uygun/Eksik/Risk
A21: K5 | B21: ★ Net kazanç hesabı doğru mu? (Brüt − Gider) | D21: Brüt gelire oran uygulanamaz. | F21: Uygun/Eksik/Risk
A22: K6 | B22: ★ Cari dönem oranı doğru seçildi mi? (2025: %100) | D22: 2032+ öncesi → %100. | F22: Uygun/Eksik/Risk
A23: K7 | B23: C tablosu her satırda dönem oranı seçildi mi? | D23: A sütunu dropdown dolu olmalı. | F23: Uygun/Eksik/Risk
A24: K8 | B24: C tablosu F toplamı D.5 ile mutabık mı? | D24: F54 = D.5 eşitliği. | F24: Uygun/Eksik/Risk
A25: K9 | B25: ★ İndirim matrahı aşıyor mu? (Devredilemez!) | D25: Aşan kısım beyanname notu. | F25: Uygun/Eksik/Risk
A26: K10 | B26: YİAKV ilişkisi YMM tarafından değerlendirildi mi? | D26: GİB Rehberi No:607 incelendi. | F26: Uygun/Eksik/Risk
A27: K11 | B27: Beyanname 467 'Kazancın Bulunması Halinde'? | D27: Zarar → uygulanamaz. | F27: Uygun/Eksik/Risk
A28: K12 | B28: YMM Tasdik Raporu değerlendirildi mi? | D28: >=500.000 TL → Rapor. | F28: Uygun/Eksik/Risk

Sheet MUHASEBE KAYITLARI
A1: 467 – İFM KAZANÇ İNDİRİMİ KVK Md.10/1-i | MUHASEBE KAYITLARI
A2: KAYIT 1 — İFM FİNANSAL HİZMET GELİRİ VE MALİYET KAYDI
B3: Tarih | C3: Hesap | D3: Not | E3: Dr | F3: Kr | G3: Ref
A4: Kr | B4: [Dönem] | C4: 600/601 Satışlar | D4: Yurt dışı kaynaklı İFM finansal hizmet geliri | E4: — | F4: [Brüt] | G4: Fatura/Hesap
A5: KAYIT 2 — DÖNEM SONU: BEYANNAME 467 İNDİRİMİ
B6: Tarih | C6: Hesap | D6: Not | E6: Dr | F6: Kr | G6: Ref
A7: Not | B7: [Dönem Sonu] | C7: — Beyanname Üzerinde İndirim — | D7: KVK Md.10/1-i indirimi gelir tablosunu etkilemez — muhasebe kaydı gerekmez | E7: [Net×Oran] | F7: — | G7: Beyanname 467
A8: DÖNEM SONU — BEYANNAME 467 (2025 DÖNEMİ: %100): 467 indirimi GELİR TABLOSUNU ETKİLEMEZ — muhasebe kaydı gerekmez. Net Kazanç × %100 (2025 için) → KV beyannamesi 467 satırı. YİAKV: GİB Rehberi No:607 kapsamında durum YMM tarafından teyit edilmeli. Matrahı aşan kısım devredilmez. 2032'den itibaren oran %75'e iner.

Sheet DENETCİ NOTLARI
A1: 467 – İFM KAZANÇ İNDİRİMİ KVK Md.10/1-i | DENETÇİ NOTLARI
A2: 7412 s.K. | 2022-2031:%100 / 2032+:%75 | Katılımcı Belgesi | 416 Farkı | YİAKV Teyidi
A3: Kod | B3: Konu | C3: Mesleki Değerlendirme / Tasdik Standardı | D3: Mevzuat / Kaynak
A4: N1 | B4: KVK Md.10/1-i — İFM Kapsam ve Kademeli Oran | C4: KVK MADDE 10/1-i — İSTANBUL FİNANS MERKEZİ KAZANÇ İNDİRİMİ: 7412 sayılı İFM Kanunu kapsamında İFM bölgesinde katılımcı belgesiyle faaliyette bulunan kurumların yurt dışı kaynaklı finansal hizmet kazançlarına kademeli indirim uygulanır. KADEMELİ ORAN (GİB Rehberi No:606): 2022–2031: Net kazancın %100'ü — KV yükü yok 2032+: Net kazancın %75'i — Teşvik süresiz, oran azalır ZORUNLU KOŞULLAR: ① İFM Başkanlığı katılımcı belgesi ② İFM bölgesinde fiili faaliyet ③ Bölgede personel istihdamı ④ Yurt dışı kaynaklı finansal hizmet kazancı YİAKV: GİB Rehberi No:607 kapsamında YMM teyidi gerekli. | D4: KVK Md.10/1-i | 7412 s.K. | GİB KV Beyan Reh. 2026 (No:606)
A5: N2 | B5: ★ 467 (İFM) ile 416 (Diğer Hizmetler) Karşılaştırması | C5: 467 (İFM) vs 416 (KVK Md.10/1-ğ) — TEMEL FARKLAR: 416 — DİĞER HİZMETLER (KVK Md.10/1-ğ): • Hizmet: Mimarlık, Mühendislik, Yazılım, Tasarım, Çağrı Merkezi vb. • Oran: Net kazancın %50'si — sabit • Bakanlık izni: Yok • Alıcı: Yurt dışı gerçek kişi veya kuruluş • İFM bölgesi şartı: Yok 467 — İFM (KVK Md.10/1-i): • Hizmet: Finansal hizmetler (bankacılık, sigorta, sermaye piyasası vb.) • Oran: %100 (2022-2031) / %75 (2032+) — çok daha avantajlı! • Katılımcı belgesi: ZORUNLU • İFM bölgesinde fiili faaliyet + personel: ZORUNLU • Alıcı: Yurt dışı kaynaklı AYNILIKLARI: Her ikisinde de Net Kazanç esası (brüt gelir değil). Her ikisinde de devredilmez, kazancın bulunması halinde. | D5: KVK Md.10/1-ğ | KVK Md.10/1-i | GİB Reh. No:606
A6: N3 | B6: Katılımcı Belgesi ve Fiili Faaliyet Koşulları | C6: KATİLIMCI BELGESİ VE FAALİYET KOŞULLARI: KATİLIMCI BELGESİ: • İFM Yönetim Başkanlığı tarafından verilir • 7412 sayılı Kanun kapsamında • Belge alınmadan 467 uygulanamaz • Belge tarihinden önceki dönem gelirleri kapsam dışı FİİLİ FAALİYET KOŞULU: • İFM bölgesinde fiili ofis ve operasyon zorunlu • Sadece tescil veya adres kaydı yeterli değil • Fiili faaliyet belgesi/kanıtı gerekebilir PERSONEL İSTİHDAMI: • İFM bölgesinde çalışan personel şart • SGK işyeri kaydı + prim ödeme belgesi ile teyit YMM: Her üç koşulun da dönem boyunca sağlandığı belgelenmeli. | D6: 7412 s.K. | GİB Özelge | İFM Yönetim Başkanlığı
A7: N4 | B7: ✓ YİAKV DÜŞÜLEBILIR — KVK Md.32/C f.2 (g) Bendi — Korumalı Kalem | C7: KVK Md.32/C f.2 BENT (g) — İFM KAZANÇ İNDİRİMİ KORUMAL KALEMDİR: KVK'nın 32/C maddesinin 2. fıkrasının (g) bendi: 'İstanbul Finans Merkezi Bölgesinde faaliyette bulunan kurumların elde ettikleri kazançlarda indirim' YİAKV matrahından DÜŞÜLEBİLECEK istisnalar arasında AÇIKÇA SAYILMIŞTIR. YİAKV HESAPLAMA SİSTEMATİĞİ (GİB Rehberi No:607): Ticari Bilanço Kârı + KKEG = Ara Toplam - 467 Kodu (İFM Kazanç İndirimi) ← BURADA DÜŞÜLEBİLİR = YİAKV Matrahı × %10 = Asgari Vergi SAYISAL ÖRNEK: Ticari Bilanço Kârı: 10.000.000 TL + KKEG: 1.000.000 TL = Ara Toplam: 11.000.000 TL - 467 İFM İndirimi: -8.000.000 TL ← Düşülebilir! = YİAKV Matrahı: 3.000.000 TL × %10 YİAKV: 300.000 TL 406 (Yatırım İndirimi) ile KARŞILAŞTIRMA: 406: ✗ YİAKV E.11 — DÜŞÜLEMEZ → Asgari vergi yükü doğurur 467: ✓ KVK Md.32/C (g) — DÜŞÜLEBİLİR → Asgari vergi yükü DOĞURMAZ İFM TEŞVİKİNİN RUHU: Kanun koyucu İFM'deki finansal hizmet ihracatını stratejik alan olarak gördüğünden bu kazancı YİAKV dışında tutarak teşvikin etkisini korumuştur. | D7: KVK Md.32/C f.2 (g) | GİB Rehberi No:607 | KVK Md.10/1-i
A8: N5 | B8: 49 No.lu Tebliğ + YMM Tasdik Dil Standardı | C8: KULLANIN (2025 Dönemi — %100): '...Kurumlar Vergisi Kanunu'nun 10. maddesinin (i) bendi kapsamında, 7412 sayılı İstanbul Finans Merkezi Kanunu'na göre İFM'de faaliyette bulunan ve [Katılımcı Belgesi No] numaralı katılımcı belgesine sahip şirketimizin yurt dışı kaynaklı finansal hizmetlerden elde ettiği [Net Kazanç] TL net kazancın %100'ü olan [Tutar] TL kurumlar vergisi matrahından indirilmiştir.' KULLANMAYIN: '...Katılımcı belgesi olmadan İFM indirimi uygulandı.' (Geçersiz) '...Yurt içi müşteri geliri 467 kapsamında.' (Kapsam dışı) '...Brüt gelirin %100'ü 467 kapsamında.' (Net kazanç olmalı) KRİTİK RİSKLER: (1) Katılımcı belgesi olmadan 467 uygulamak. (2) Yurt içi müşteri gelirini 467'ye dahil etmek. (3) Brüt gelire oran uygulamak (net kazanç olmalı). (4) Dönem oranını yanlış seçmek (2025: %100, 2032: %75). | D8: 49 No.lu Tebliğ | KVK Md.10/1-i | SM-SMMM-YMM K. Md.12
A9: GİB KV BEYAN REHBERİ MART 2026 (No:606/607) KAPANIŞ (467): KVK Md.10/1-i — İFM'de katılımcı belgesiyle yurt dışı finansal hizmet. Oran: 2022-2031 %100 | 2032+ %75. Net kazanç × oran. ✓ YİAKV: KVK Md.32/C f.2 (g) bendi — KORUMAL KALEMDİR, asgari vergi yükü doğurmaz. 406 ile farklı: 406 ✗ E.11 | 467 ✓ (g) bendi.

Sheet BELGE LISTESI
A1: 467 – İFM KAZANÇ İNDİRİMİ KVK Md.10/1-i | BELGE LİSTESİ | YMM TASDİK
A2: Katılımcı Belgesi | Yurt Dışı Müşteri Faturası | Personel SGK | Gelir Ayrımı | YİAKV Teyidi
A4: KATEGORİ 1 — ZORUNLU BELGELER
B5: No | C5: Belge | D5: Açıklama | E5: Temin
B6: 1 | C6: ★ İFM Katılımcı Belgesi | D6: İFM Yönetim Başkanlığı tarafından düzenlenen katılımcı belgesi. 467'nin temel koşulu. Belgenin dönem boyunca geçerli olduğu teyit edilmeli. Zorunlu. | E6: İFM Yönetim Başkanlığı
B7: 2 | C7: ★ Yurt Dışı Müşteri Faturası ve Sözleşme | D7: Her yurt dışı kaynaklı finansal hizmet için fatura ve sözleşme. Müşterinin yurt dışı kaynaklı olduğu anlaşılmalı. Zorunlu. | E7: Muhasebe / Sözleşme Arşivi
B8: 3 | C8: ★ İFM Personeli SGK Hizmet Dökümü | D8: İFM bölgesinde çalışan personelin SGK işyeri kaydı ve prim ödeme belgesi. Personel istihdamı koşulunun kanıtı. Zorunlu. | E8: SGK e-Devlet
B9: 4 | C9: ★ Yurt İçi / Yurt Dışı Gelir-Gider Ayrışım Notu | D9: Karma faaliyette yurt dışı kaynaklı gelir ve ilgili gider payının ayrıştırıldığı YMM hesaplama notu. Net kazanç hesabının dayanağı. Zorunlu. | E9: YMM Hesaplama Notu
B10: 5 | C10: Fiili Faaliyet Belgesi (Gerektiğinde) | D10: İFM bölgesinde fiilen faaliyette bulunulduğunu gösteren kira sözleşmesi, adres teyit belgesi veya GİB/SGK işyeri kaydı. | E10: Kiralama / SGK
B11: 6 | C11: KV Beyannamesi 467 Satırı + YİAKV Değerlendirme | D11: Beyanname 467 = Net Kazanç × %100 (2025). YİAKV durumu için GİB Rehberi No:607 kapsamında YMM değerlendirme notu. | E11: GİB e-Beyanname + YMM Notu
A13: KATEGORİ 2 — YMM TASDİK KONTROL SORULARI
B14: No | C14: Kontrol Sorusu | D14: Beklenen Sonuç | E14: YMM Aksiyonu
B15: S1 | C15: ★ Katılımcı belgesi geçerli ve dönem kapsamında mı? | D15: Belge tarihleri kontrol. | E15: YMM kontrolü
B16: S2 | C16: ★ İFM bölgesinde fiili faaliyet var mı? | D16: Ofis/faaliyet kanıtı. | E16: YMM kontrolü
B17: S3 | C17: ★ Bölgede personel istihdam ediliyor mu? | D17: SGK teyidi. | E17: YMM kontrolü
B18: S4 | C18: ★ Hizmetler yurt dışı kaynaklı mı? | D18: Yurt içi müşteri → Kapsam dışı. | E18: YMM kontrolü
B19: S5 | C19: ★ Net kazanç hesabı doğru mu? (Brüt − Gider) | D19: Brüt gelire oran → Hatalı. | E19: YMM kontrolü
B20: S6 | C20: ★ Cari dönem oranı doğru mu? (2025: %100) | D20: C tablosu A sütunu teyidi. | E20: YMM kontrolü
B21: S7 | C21: ★ İndirim matrahı aşıyor mu? (Devredilmez!) | D21: Aşan kısım beyanname notu. | E21: YMM kontrolü
B22: S8 | C22: YİAKV ilişkisi değerlendirildi mi? | D22: GİB Rehberi No:607 teyidi. | E22: YMM kontrolü
B23: S9 | C23: Beyanname 467 'Kazancın Bulunması Halinde'? | D23: Zarar → uygulanamaz. | E23: YMM kontrolü
B24: S10 | C24: YMM Tasdik Raporu değerlendirildi mi? | D24: >=500.000 TL → Rapor. | E24: YMM kontrolü
A26: GİB KV BEYAN REHBERİ MART 2026 (No:606/607) | 467 İFM KAZANÇ İNDİRİMİ: Katılımcı belgesi + İFM fiili faaliyet + personel + yurt dışı kaynaklı finansal hizmet zorunludur. Oran: 2022-2031 %100 | 2032+ %75. NET kazanç × oran (brüt gelir değil). ✓ YİAKV: KVK Md.32/C f.2 (g) bendi — KORUMAL KALEMDİR. Asgari vergi yükü DOĞURMAZ. 406 (Yatırım İnd.) ile karşılaştır: 406 → ✗ E.11 (YİAKV yükü var) | 467 → ✓ (g) bendi (yük yok). Matrahı aşan devredilmez. YMM: SM-SMMM-YMM Kanunu Md.12.
