Workbook

Sheet VERİ GİRİŞİ
A1: 300 – DİĞER FON VUK 279 DEĞER ARTIŞ KAZANCI İSTİSNASI | KVK Md. 5/1-a-5 | YMM TASDİK ÇALIŞMA KÂĞIDI
A2: KVK Md.5/1-a-5 | 7456 s.K. Md.19 ile Mülga (15.07.2023) | GEÇİŞ UYGULAMASI: 15.07.2023 Öncesi İktisap Edilen Fonlar İçin | Zarar Olsa Dahi İndirilecek — Beyanname Satır 300
A3: KRİTİK UYARI (7456 s.K.): 15.07.2023 tarihinden itibaren yeni iktisap edilen fonların değerleme farkları bu istisnadan yararlanamaz. Aynı fonda karma tarihli alım varsa tarihe göre ayrıştırma zorunludur. GSYF değerleme farkı bu forma dahil edilmez (298/386 satırı).
A4: RENK KODLARI: Sarı = Manuel giriş | Yeşil = Otomatik hesaplama | Kırmızı çerçeve = Kritik alan | Mavi banner = Bölüm başlığı
A6: A0. KAPSAM VE NİTELİK UYGUNLUK ÖN KONTROLÜ
B7: Kontrol Sorusu | E7: Yanıt | G7: YMM Tasdik Notu
A8: A0.1 İstisna uygulanacak fon(lar)ın iktisap tarihi 15.07.2023'ten ÖNCE mi? | E8: EVET | F8: KRİTİK: 15.07.2023 sonrası iktisap edilen payların değerleme farkı istisna dışı. Karma tarihli alımlarda pay adedi bazında ayrıştırma zorunludur.
A9: A0.2 Fon türü doğru mu? (GSYF bu formda değil — 298/386 satırı) | E9: EVET | F9: 5/1-a-5: Sadece 3. ve 4. alt bentlere kaynak teşkil eden diğer fonlar. GSYF (5/1-a-3) değerleme farkı → 298 veya 386 satırı. Bu ayrım kritiktir.
A10: A0.3 VUK 279 değerleme yöntemi doğru uygulandı mı? (Portföy bileşimi teyit edildi mi?) | E10: EVET | F10: Portföy %51+ hisse senedi → Alış bedeli (değerleme farkı = 0). Diğer durum → Borsa rayici/ilanı edilen fiyat kullanılır. Portföy bileşimi fon bilgi formuyla teyit edilmelidir.
A11: A0.4 Dönem başı ve dönem sonu değerler muhasebe ve fon belgesiyle uyumlu mu? | E11: EVET | F11: Dönem başı: Bir önceki dönem sonu değeri / açılış bakiyesi. Dönem sonu: Fon yöneticisi 31.12 ilanı veya borsa rayici. 118/245 hesap kartı ile uyum zorunludur.
A12: A0.5 Negatif değerleme farkı (düşüş) var mı? KKEG değerlendirmesi yapıldı mı? | E12: HAYIR-Risk Yok | F12: Değerleme düşüşü → 659 gider kaydı. Bu tutarın KKEG mi yoksa indirilebilir gider mi olduğu ayrıca değerlendirilmelidir. İstisna yalnızca artışlar için geçerlidir.
A13: A0.6 YİAKV matrahında 300 satırı doğru konumlandırıldı mı? | E13: EVET | F13: KVK 5/1-a-5 istisnası 'Zarar Olsa Dahi İndirilecek' bölümündedir. YİAKV matrahından düşülüp düşülemeyeceği dönem mevzuatıyla analiz edilmeli.
A14: A0.7 YMM Tasdik Raporu gereksinimi değerlendirildi mi? (49 No.lu Tebliğ) | E14: EVET | F14: 49 No.lu Tebliğ (30.12.2025): Tek satır >=500.000 TL veya toplam >=1.000.000 TL → YMM raporu. Tam tasdik sözleşmesi olanlar ayrıca rapor düzenlemez.
A15: A0.8 Tasdik Uygunluk Sonucu | E15: =IF(AND(E8="EVET",E9="EVET",E10="EVET",E11="EVET",E13="EVET",E14="EVET"),"OK - Hesaplanabilir","HATA - Ön koşul eksik") -> OK - Hesaplanabilir | F15: A0.1 (iktisap tarihi) ve A0.2 (fon türü) kritik. Karma tarihte A0.1=Karma seçilmeli.
A17: A. MÜKELLEF VE DÖNEM BİLGİLERİ
A18: Mükellef Unvanı | F18: İstisna uygulayan kurumun tam adı
A19: Vergi Kimlik Numarası | F19: 10 haneli VKN
A20: Hesap Dönemi | F20: Örn: 01.01.2025 – 31.12.2025
A21: Genel KV Oranı (%) | F21: 2025: %25 | Finans/Bankacılık: %30
A23: B. VUK 279 DEĞERLEME FARKI HESAP TABLOSU — İstisna Kapsamı Fonlar (15.07.2023 Öncesi İktisap)
A24: KAPSAM: KVK 5/1-a-3 ve 5/1-a-4 kapsamındaki diğer yatırım fonlarının 15.07.2023 öncesi iktisap edilen payları. Her satır bir fon veya aynı fondaki 15.07.2023 öncesi payları temsil eder. GSYF ve 15.07.2023 sonrası alınan paylar bu tabloya dahil edilmez.
B25: Fon Adı / Tanımlayıcı | C25: İktisap Tarihi | D25: Dönem Başı Değer (TL) | E25: Dönem Sonu VUK 279 (TL) | F25: Değerleme Farkı (TL) | G25: YMM Notu
B26: Fon-1 | F26: =IF(AND(E26>0,D26>0),MAX(0,E26-D26),0) -> 0 | G26: İktisap tarihi ve fon türü teyit edilmeli.
B27: Fon-2 | F27: =IF(AND(E27>0,D27>0),MAX(0,E27-D27),0) -> 0 | G27: İktisap tarihi ve fon türü teyit edilmeli.
B28: Fon-3 | F28: =IF(AND(E28>0,D28>0),MAX(0,E28-D28),0) -> 0 | G28: İktisap tarihi ve fon türü teyit edilmeli.
B29: Fon-4 | F29: =IF(AND(E29>0,D29>0),MAX(0,E29-D29),0) -> 0 | G29: İktisap tarihi ve fon türü teyit edilmeli.
B30: Fon-5 | F30: =IF(AND(E30>0,D30>0),MAX(0,E30-D30),0) -> 0 | G30: İktisap tarihi ve fon türü teyit edilmeli.
B31: Fon-6 | F31: =IF(AND(E31>0,D31>0),MAX(0,E31-D31),0) -> 0 | G31: İktisap tarihi ve fon türü teyit edilmeli.
B32: Fon-7 | F32: =IF(AND(E32>0,D32>0),MAX(0,E32-D32),0) -> 0 | G32: İktisap tarihi ve fon türü teyit edilmeli.
B33: Fon-8 | F33: =IF(AND(E33>0,D33>0),MAX(0,E33-D33),0) -> 0 | G33: İktisap tarihi ve fon türü teyit edilmeli.
B34: B — DEĞERLEME FARKI TOPLAMI (İstisna Tutarı) | D34: =SUM(D26:D33) -> 0 | E34: =SUM(E26:E33) -> 0 | F34: =SUM(F26:F33) -> 0
A36: C. KAPSAM DIŞI DEĞERLEME FARKLARI — Vergiye Tabi (Kontrol Tablosu)
A37: Bu tablodaki fonlar 300 satırına YAZILMAZ — vergiye tabi gelirdir. 15.07.2023 sonrası iktisap edilenler, portföyünde döviz/altın olanlar (VUK 279 kapsamı dışı) veya GSYF'ler bu tabloya alınır.
B38: Fon Adı / Tanımlayıcı | C38: Kapsam Dışı Neden | D38: Dönem Başı (TL) | E38: Dönem Sonu (TL) | F38: Fark (TL) | G38: YMM Notu
B39: KD-1 | F39: =IF(AND(E39>0,D39>0),E39-D39,0) -> 0 | G39: Vergiye tabi — beyanname matrahına dahil
B40: KD-2 | F40: =IF(AND(E40>0,D40>0),E40-D40,0) -> 0 | G40: Vergiye tabi — beyanname matrahına dahil
B41: KD-3 | F41: =IF(AND(E41>0,D41>0),E41-D41,0) -> 0 | G41: Vergiye tabi — beyanname matrahına dahil
B42: KD-4 | F42: =IF(AND(E42>0,D42>0),E42-D42,0) -> 0 | G42: Vergiye tabi — beyanname matrahına dahil
B43: C — KAPSAM DIŞI TOPLAM (Vergiye Tabi — 300 Satırına Yazılmaz) | F43: =SUM(F39:F42) -> 0
A45: D. İSTİSNA TUTARI — KV BEYANNAMESİ SATIR 300
...

Sheet HESAPLAMALAR & KONTROL
A1: 300 – DİĞER FON VUK 279 | HESAPLAMALAR VE DENETİM KONTROL PANELİ
A2: KVK Md.5/1-a-5 | 7456 s.K. Mülga | 15.07.2023 Öncesi İktisap | Zarar Olsa Dahi İndirilecek | Beyanname Satır 300
A4: A. TASDIK ÖZETİ — VERİ GİRİŞİNDEN OTOMATİK
A5: A0 Tasdik Uygunluğu | D5: ='VERİ GİRİŞİ'!E15 -> OK - Hesaplanabilir | E5: A0.8 OK ise devam
A6: İstisna Kapsamı Fon Sayısı | D6: =COUNTIF('VERİ GİRİŞİ'!F26:F33,">0") -> 0 | E6: B tablosunda fark>0 olan fon adedi
A7: Toplam Dönem Başı Değer (B Tablosu) | D7: ='VERİ GİRİŞİ'!D34 -> 0 | E7: Kümülatif dönem başı
A8: Toplam Dönem Sonu VUK 279 Değeri (B Tablosu) | D8: ='VERİ GİRİŞİ'!E34 -> 0 | E8: Kümülatif dönem sonu
A9: TOPLAM İSTİSNA TUTARI (Beyanname 300) | D9: ='VERİ GİRİŞİ'!F34 -> 0 | E9: B tablosu toplam — Beyanname 300. Satır
A10: Kapsam Dışı (Vergiye Tabi) Fark (C Tablosu) | D10: ='VERİ GİRİŞİ'!F43 -> 0 | E10: Beyanname matrahında yer alır
A12: B. DENETİM KONTROL LİSTESİ (K1–K10)
B13: Kontrol | D13: Kontrol Açıklaması | F13: Sonuç | G13: YMM Aksiyonu
A14: K1 | B14: İktisap tarihi kriteri her fon için ayrı ayrı teyit edildi mi? | D14: 15.07.2023'ten önceki paylar için değerleme farkı istisna dahili. Sonraki tarihli paylar için vergiye tabidir. Banka/MKK alış dekontu ile her fon ayrı ayrı belgelenmelidir. | F14: Uygun / Eksik / Risk
A15: K2 | B15: Fon türü ayrıştırması yapıldı mı? (GSYF / Diğer ayrımı) | D15: GSYF (5/1-a-3) değerleme farkı → 298 veya 386 satırı. Bu form 5/1-a-5 kapsamındaki diğer fonlar için. Tek formda iki fon türü karıştırılmamalıdır. | F15: Uygun / Eksik / Risk
A16: K3 | B16: VUK 279 değerleme yöntemi fon portföy bileşimiyle uyumlu mu? | D16: Portföy %51+ hisse senedi → Alış bedeli (değerleme farkı sıfır). Diğer durumlar → Borsa rayici veya ilan edilen fiyat. Fon bilgi formu/izahname ile teyit edilmeli. | F16: Uygun / Eksik / Risk
A17: K4 | B17: Dönem başı değer (01.01) ile muhasebe açılış bakiyesi uyumlu mu? | D17: Bir önceki dönem VUK 279 değerlemesi bu dönem başı değeri olmalıdır. 118/245 hesap kartı açılış bakiyesi ile VERİ GİRİŞİ D sütunu uyumlu olmalı. | F17: Uygun / Eksik / Risk
A18: K5 | B18: Dönem sonu VUK 279 değeri belgelenmiş mi? (31.12 ilanı var mı?) | D18: Fon yöneticisi 31.12 tarihli birim pay değer ilanı veya borsa rayici alınmalıdır. KAP, borsa veya aracı kurum verisi kayıt olarak dosyaya eklenmelidir. | F18: Uygun / Eksik / Risk
A19: K6 | B19: Değerleme düşüşü varsa KKEG değerlendirmesi yapıldı mı? | D19: Değerleme kaybı (C6<0): 659 gider kaydı yapılır. Bu tutarın KKEG olup olmadığı ayrıca değerlendirilmelidir. İstisna yalnızca artışlar için geçerlidir — düşüşlerde istisna uygulanamaz. | F19: Uygun / Eksik / Risk
A20: K7 | B20: Muhasebe 649 hesabı ile beyanname 300 satırı uyumlu mu? | D20: VUK 279 değerleme artışı dönem içinde 649 hesabına gelir kaydedilmeli. KKEG olarak matrahı eklenip 300 satırında istisna olarak düşülmelidir. 649 toplamı ile D.1 (Beyanname 300 tutarı) uyumlu olmalıdır. | F20: Uygun / Eksik / Risk
A21: K8 | B21: Karma tarihli alım ayrıştırması tam ve doğru yapıldı mı? | D21: Aynı fonda 15.07.2023 öncesi ve sonrası alım varsa: Pay adedi bazında ayrıştırma yapılmalı. Her alım partisi için ayrı değerleme farkı hesabı zorunludur. | F21: Uygun / Eksik / Risk
A22: K9 | B22: Beyanname 300 satırı 'Zarar Olsa Dahi' bölümünde doğru konumlandırıldı mı? | D22: 300 satırı 'Zarar Olsa Dahi İndirilecek İstisna ve İndirimler' bölümündedir. Kazancın bulunması halinde bölümünde değildir. Bu ayrım kritiktir. | F22: Uygun / Eksik / Risk
A23: K10 | B23: YİAKV matrahında 300 istisnasının etkisi analiz edildi mi? | D23: KVK 5/1-a-5 istisnasının YİAKV matrahını etkileyip etkilemediği dönem mevzuatı çerçevesinde analiz edilmeli ve YİAKV çalışma kâğıdına yansıtılmalıdır. | F23: Uygun / Eksik / Risk
A25: C. BEYANNAME SATIR EŞLEŞTİRME VE MUTABAKAT
B26: Beyanname Satırı | D26: Tutar (TL) | F26: Açıklama
A27: Satır 300 | C27: ='VERİ GİRİŞİ'!F46 -> 0 | D27: KVK 5/1-a-5 — Zarar Olsa Dahi İndirilecek — 15.07.2023 öncesi VUK 279 değerleme farkı
A28: DİKKAT: 298/386 | C28: GSYF değerleme farkı ayrı satır | D28: GSYF değer artışı 5/1-a-3 kapsamında — 298 veya 386 satırı kullanılır. Bu forma dahil edilmez.

Sheet MUHASEBE KAYITLARI
A1: 300 – DİĞER FON VUK 279 DEĞER ARTIŞ KAZANCI | MUHASEBE KAYITLARI ÇALIŞMA KÂĞIDI
A2: KVK Md.5/1-a-5 | VUK Md.279 | Örnek Muhasebe Fişleri
A3: NOT: Rehber niteliğindedir. Şirkete özgü muhasebe planı ve VUK 279 değerleme sonuçlarına göre uyarlanmalıdır.
A5: KAYIT 1 — DÖNEM SONU VUK 279 DEĞERLEME KAYDI (DEĞER ARTIŞI — İSTİSNA KAPSAMINDA)
A6: Fon Adı: [___] | VUK 279 Değerleme Tarihi: 31.12.20XX | Değerleme Artışı: [TL]
B7: Tarih | C7: Hesap Adı / Kodu | D7: Muhasebe Notu | E7: Dr (TL) | F7: Kr (TL) | G7: Referans
A8: Dr | B8: 31.12.20XX | C8: 118 Diğer Menkul Kıymetler (veya 245 Bağlı MK) | D8: VUK 279 dönem sonu değerleme artışı | E8: [Artış Tutarı] | F8: — | G8: VUK Md.279
A9: Kr | B9: 31.12.20XX | C9: 649 Diğer Olağandışı Gelir | D9: Değerleme geliri — 5/1-a-5 istisna (15.07.2023 öncesi iktisap) | E9: — | F9: [Artış Tutarı] | G9: KV 300. Satır
A10: YIL SONU AKIŞ (Beyanname Döngüsü): 1. Değerleme artışı 649 hesabına gelir kaydedilir → Ticari kâr artar. 2. Yılsonu: KKEG tablosuna eklenir (hesaplama matrahını artırır). 3. KV Beyannamesi: 300. satırda 'Zarar Olsa Dahi İndirilecek' olarak istisna düşülür. YMM notu: 649 toplamı ile beyanname 300 tutarı uyumlu olmalıdır.
A12: KAYIT 2 — DÖNEM SONU VUK 279 DEĞERLEME KAYDI (DEĞER DÜŞÜŞÜ — KKEG DEĞERLENDİRMESİ GEREKİR)
B13: Tarih | C13: Hesap Adı / Kodu | D13: Muhasebe Notu | E13: Dr (TL) | F13: Kr (TL) | G13: Referans
A14: Dr | B14: 31.12.20XX | C14: 659 Diğer Olağandışı Gider | D14: VUK 279 dönem sonu değerleme düşüşü | E14: [Düşüş Tutarı] | F14: — | G14: KKEG mi? Analiz et
A15: Kr | B15: 31.12.20XX | C15: 118 Diğer Menkul Kıymetler | D15: Menkul kıymet değer azalışı | E15: — | F15: [Düşüş Tutarı] | G15: VUK Md.279
A16: DİKKAT — KKEG DEĞERLENDİRMESİ: Değerleme düşüşünün vergi açısından kabul edilip edilmeyeceği tartışmalıdır. Genel eğilim: VUK 279 değerleme kaybı → KKEG olarak değerlendirilmekte. YMM notu: Dönemin özelge/muktezalarına bakılmalı; KKEG ise beyanname matrahına eklenmelidir.
A18: KAYIT 3 — FON SATIŞ/İADE KAYDI (Elden Çıkarma)
B19: Tarih | C19: Hesap Adı / Kodu | D19: Muhasebe Notu | E19: Dr (TL) | F19: Kr (TL) | G19: Referans
A20: Dr | B20: [Satış Tarihi] | C20: 102 Bankalar | D20: Satış/iade bedeli tahsilatı | E20: [Satış Bedeli] | F20: — | G20: Banka dekontu
A21: Kr | B21: [Satış Tarihi] | C21: 118 Diğer Menkul Kıymetler | D21: VUK 279 değerleme sonrası bilanço değeri | E21: — | F21: [Bilanço Değeri] | G21: 118 hesap kartı
A22: Kr/Dr | B22: [Satış Tarihi] | C22: 645 Menkul Kıymet Satış Kâr/Zararı | D22: Elden çıkarma kazancı/zararı (5/1-a-4 kapsam kontrolü) | E22: — | F22: [Fark] | G22: 5/1-a-4 analiz et
A23: SATIŞ SONRASI NOT: Fonun elden çıkarılmasından doğan kazanç 5/1-a-4 kapsamında ayrıca değerlendirilmelidir. Bu istisna (300 satırı) yalnızca elde tutma süresindeki VUK 279 değerleme artışları içindir.
A25: KV BEYANNAMESİ DÖNEM SONU İSTİSNA NOTU — Muhasebe Kaydı Gerekmez
A26: BEYANNAME AKIŞI (Muhasebe Kaydı Değil — Beyanname Üzeri İşlem): a) 649 hesabındaki VUK 279 değerleme artışları zaten ticari kâra dahildir. b) Yılsonu KKEG tablosunda: Bu tutarlar KKEG olarak eklenmiştir (veya doğrudan ticari kâr içindedir). c) KV Beyannamesi 300. Satır: 'Zarar Olsa Dahi İndirilecek' bölümünde istisna tutarı yazılır. Beyanname 300 = VERİ GİRİŞİ F34 = HESAPLAMALAR D9 = Muhasebe 649 (VUK 279 geliri toplamı) Bu üç tutarın birebir uyumlu olması YMM tasdik dosyasının tamamlanma koşuludur.

Sheet DENETCİ NOTLARI
A1: 300 – DİĞER FON VUK 279 | DENETÇİ NOTLARI VE MESLEKİ DEĞERLENDİRME
A2: KVK Md.5/1-a-5 | 7456 s.K. Mülga | Geçiş Uygulaması | VUK Md.279 | YMM Tasdik Notu Katalogu
A4: BÖLÜM 1 — YASAL DAYANAK VE TARİHSEL ÇERÇEVE
A5: Kod | B5: Konu | C5: Mesleki Değerlendirme | D5: Mevzuat
A6: N1 | B6: 5/1-a-5 İstisnasının Tarihsel Çerçevesi | C6: KVK Md.5/1-a-5: 5/1-a-3 ve 5/1-a-4 kapsamındaki fonların VUK 279 değerleme farklarını kapsıyordu. 7456 sayılı Kanun (15.07.2023): Bu bent mülga edilmiştir. GEÇİŞ UYGULAMASI: 15.07.2023'ten önce iktisap edilen paylar için değerleme farkı istisnası devam etmektedir. Yeni iktisaplarda: Değerleme farkı vergiye tabidir. Beyanname 300. Satır: 'Zarar Olsa Dahi İndirilecek' bölümünde yer alır. | D6: KVK Md.5/1-a-5 | 7456 s.K. Md.19 | 15.07.2023
A7: N2 | B7: VUK 279 Değerleme Yöntemi | C7: VUK Md.279: Hisse senedi ağırlıklı yatırım fonu katılma payları → Alış bedeli ile değerlenir. Hisse ağırlıklı: Portföyün en az %51'i BIST'te işlem gören hisse senedi. Hisse ağırlıklı değilse: Borsa rayici veya ilanı edilen fiyat. YMM notu: Portföy bileşimi fon bilgi formu/izahnamesinden her dönem teyit edilmelidir. Yöntemin yanlış uygulanması: Değerleme farkının hatalı hesaplanmasına yol açar. | D7: VUK Md.279 | Fon Mevzuatı
A8: N3 | B8: 15.07.2023 Tarihi — En Kritik Kontrol Noktası | C8: Bu tarih kesin sınırdır: ÖNCE iktisap → Değerleme farkı istisna (300 satırı) SONRA iktisap → Değerleme farkı vergiye tabi (matrahta kalır) KARMA DURUM (Aynı Fonda Farklı Tarihlerde Alım): Pay adedi bazında ayrıştırma zorunludur. Her alım partisi için ayrı değerleme farkı hesabı yapılmalıdır. Karma durumda belirsizlik: Hangi payın önce satıldığı (FIFO/ağırlıklı ortalama) önemlidir. | D8: 7456 s.K. Md.19 | KVK Md.5/1-a-5
A9: N4 | B9: GSYF Ayrımı — 298/386 ile Karıştırma Riski | C9: GSYF (Girişim Sermayesi Yatırım Fonu) 5/1-a-3 kapsamındadır. GSYF değerleme farkı → 298 veya 386 satırı (5/1-a-3 kapsamı). Diğer fonlar 5/1-a-5 kapsamı → 300 satırı. YANLIŞ UYGULAMA: GSYF'yi 300 satırına yazmak veya diğer fonları 298/386 satırına yazmak. Her iki hata da vergi incelemesinde tarhiyat ve ceza riskidir. | D9: KVK Md.5/1-a-3 ve 5/1-a-5
A11: BÖLÜM 2 — YMM TASDİK DEĞERLENDİRMESİ VE RİSK ANALİZİ
A12: Kod | B12: Konu | C12: Mesleki Değerlendirme | D12: Mevzuat
A13: N5 | B13: Değerleme Düşüşü — KKEG Riski | C13: Değerleme artışı: 649 Dr/Kr → İstisna (300 satırı) → Vergi dışı Değerleme düşüşü: 659 Dr → KKEG mi? Bu tartışmalıdır. Genel eğilim: VUK 279 değerleme kayıpları KKEG olarak değerlendirilmektedir. Ancak özelge bazlı farklı görüşler mevcuttur. YMM notu: Dönemin güncel mukteza/özelgelerine bakılmalı; KKEG ise beyanname matrahına eklenmelidir. Risk: Düşüşün yanlış sınıflandırılması tarhiyat riski doğurabilir. | D13: VUK Md.279 | Muktezalar
A14: N6 | B14: 49 No.lu Tebliğ — Tasdik Raporu | C14: 30.12.2025 tarihli 49 No.lu Tebliğ: Tek satır >=500.000 TL veya toplam >=1.000.000 TL → YMM tasdik raporu zorunlu. Tam tasdik sözleşmesi olanlar ayrıca rapor düzenlemez. YMM notu: Beyanname 300 satırı tutarını 49 No.lu eşikle karşılaştırın. Eşiği aşıyorsa rapor olmadan istisna kullanılması tarhiyat riskidir. | D14: 49 No.lu Tebliğ (30.12.2025) | YMM Kanunu Md.12
A15: N7 | B15: Muhasebe ile Beyanname Uyumu | C15: 3 kademe uyum kontrolü: 1. Muhasebe 649 (VUK 279 artış toplamı) 2. VERİ GİRİŞİ B Tablosu Toplam (F34) 3. KV Beyannamesi 300. Satır Bu üç tutarın birebir uyumlu olması tasdik dosyasının tamamlanma koşuludur. Uyumsuzluk: Kaynak belgelere inilmeli ve yazılı açıklama yapılmalıdır. | D15: KVK Md.5/1-a-5 | VUK Md.279
A16: N8 | B16: YİAKV ile İlişki | C16: KVK 32/C kapsamındaki YİAKV hesabında 300 satırındaki istisnanın etkisi analiz edilmelidir. 5/1-a-5 istisnası 'Zarar Olsa Dahi İndirilecek' bölümündedir. YİAKV matrahının hesaplanmasında bu istisnanın nasıl dikkate alınacağı dönem tebliğleri ve GİB açıklamalarıyla doğrulanmalıdır. YMM notu: YİAKV çalışma kâğıdına 300 satırı etkisini ayrı kalem olarak yansıtın. | D16: KVK Md.32/C | YİAKV Tebliğleri
A17: N9 | B17: YMM Tasdik Dil Standardı | C17: KULLANIN: '...iktisap tarihi teyit edilen paylar için değerleme farkı istisnadan yararlanabilecektir' '...VUK 279 yöntemi fon bilgi formuyla doğrulandığı ölçüde uygulanabilir' '...dönem mevzuatı çerçevesinde değerlendirilmelidir' KULLANMAYIN: '...tüm değerleme farkları istisna kapsamındadır' | '...kesin istisna alır' | '...sorunsuz' KRİTİK RİSK ALANLARI: (1) İktisap tarihi belgesi | (2) VUK 279 yöntem doğruluğu | (3) GSYF/Diğer fon ayrımı | (4) Karma tarihli ayrıştırma | (5) Değerleme düşüşü KKEG | D17: SM-SMMM-YMM Kanunu Md.12
A19: TARTIŞMALI KONU — GEÇİŞ DÖNEMİ: Aynı fonda 15.07.2023 öncesi ve sonrası alım varsa ve fon redemption (iade) geliyorsa hangi payın iade edildiği (FIFO vs. Ortalama Maliyet) değerleme farkı hesabını doğrudan etkiler. GİB'in bu konuda henüz netleşmiş bir görüşü bulunmamaktadır. Karma tarihli durumlarda ihtiyati yaklaşım önerilir.

Sheet BELGE LISTESI
A1: 300 – DİĞER FON VUK 279 DEĞER ARTIŞ KAZANCI | BELGE VE BİLGİ LİSTESİ | YMM TASDİK
A2: KVK Md.5/1-a-5 | 7456 s.K. Mülga | 15.07.2023 Öncesi İktisap | VUK Md.279 | Zarar Olsa Dahi İndirilecek | 49 No.lu Tebliğ YMM Raporu
A3: Kategori 1: Her fon için zorunlu belgeler. Kategori 2: Destekleyici belgeler. Kategori 3: YMM tasdik kontrol soruları. Her fon için ayrı belge klasörü oluşturulması önerilir.
A5: KATEGORİ 1 — ZORUNLU BELGELER (Her Fon İçin Ayrı Ayrı Temin Edilmeli)
B6: No | C6: Belge / Bilgi Adı | D6: Detay ve YMM Kontrol Noktaları | E6: Temin Yeri
B7: 1 | C7: Fon Alış Dekontu / MKK Hesap Ekstresi (İktisap Tarihi Belgesi) | D7: Her fon için iktisap tarihi (alış tarihi) belgesi zorunludur. 15.07.2023 öncesi alış tarihinin ispat belgesidir. Banka alış dekontu veya MKK (Merkezi Kayıt Kuruluşu) hesap ekstresi. YMM notu: İktisap tarihi bulunmayan veya belgelenemeyenler istisna kapsamında değerlendirilemez. | E7: Banka / aracı kurum alış dekontu / MKK hesap ekstresi
B8: 2 | C8: Dönem Başı Bilanço Değeri (01.01 — Muhasebe Kaydı) | D8: VUK 279 değerleme tablosunda dönem başı değeri olarak kullanılan tutar. Önceki dönem sonu VUK 279 değerinin bu dönem başı değeriyle tutarlı olduğu teyit edilmeli. 118/245 hesap kartı açılış bakiyesiyle uyumlu olmalıdır. YMM notu: Dönem başı tutarsızlığı tüm değerleme farkı hesabını etkiler. | E8: Muhasebe 118/245 hesap kartı — dönem başı bakiyesi
B9: 3 | C9: Dönem Sonu VUK 279 Değer Belgesi (31.12 — Fon Yöneticisi İlanı) | D9: Fon yöneticisinin 31.12 tarihli birim pay değer ilanı. KAP, Borsa İstanbul verisi veya aracı kurum portföy değerleme raporu. VUK 279 değerleme farkının (Dönem Sonu — Dönem Başı) doğru hesaplandığını teyit eder. YMM notu: 31.12 tarihli ve yetkili kaynaktan olmalıdır. | E9: KAP / fon yöneticisi / Borsa İstanbul veri sistemi / aracı kurum
B10: 4 | C10: Fon Bilgi Formu / İzahname (Portföy Bileşimi Teyidi) | D10: VUK 279 değerleme yöntemini (alış bedeli mi, borsa rayici mi?) belirleyen belge. Portföy %51+ BIST hisse senedi → Alış bedeli (değerleme farkı = 0). Aksi durumda: Borsa rayici/ilan fiyatı kullanılır. YMM notu: Portföy bileşimi dönem boyunca değişmiş olabilir; dönem başı ve sonu kontrol edilmeli. | E10: KAP / fon yöneticisi / SPK / Borsa İstanbul
B11: 5 | C11: Muhasebe 649 Hesap Kartı (VUK 279 Değerleme Gelirleri) | D11: Dönem içinde kaydedilen VUK 279 değerleme artışlarının muhasebe dökümü. 649 hesabı toplamının VERİ GİRİŞİ B Tablosu toplamıyla uyumlu olduğu teyit edilmeli. KKEG tablosu bağlantısı da kontrol edilmelidir. YMM notu: 649 ≠ Beyanname 300 durumunda açıklama zorunludur. | E11: Muhasebe programı — 649 hesap ekstresi
B12: 6 | C12: KV Beyannamesi Taslağı — 300. Satır (Nihai veya Taslak) | D12: Beyanname 300. satırındaki tutarın VERİ GİRİŞİ D.1 tutarıyla birebir uyumlu olduğu teyit edilmeli. 'Zarar Olsa Dahi İndirilecek' bölümünde doğru konumlandırıldığı kontrol edilmeli. YMM notu: Beyanname 300 < D.1 ise neden az kullanıldığı açıklanmalı. 300 > D.1 ise hata. | E12: GİB İnternet Vergi Dairesi / e-Beyanname sistemi
A14: KATEGORİ 2 — DESTEKLEYİCİ BELGELER (Duruma Göre Gerekli)
B15: No | C15: Belge / Bilgi Adı | D15: Detay ve YMM Kontrol Noktaları | E15: Temin Yeri
B16: 7 | C16: Karma Tarihli Alım Ayrıştırma Tablosu (15.07.2023 Öncesi/Sonrası) | D16: Aynı fonda 15.07.2023 öncesi ve sonrası alım varsa: Pay adedi bazında ayrıştırma tablosu zorunludur. Her alım partisi için ayrı maliyet bedeli, iktisap tarihi ve değerleme farkı hesabı yapılmalıdır. YMM notu: Hangi payın iade/satış için öncelikli sayılacağı (FIFO/ort.) belirlenmeli. | E16: Muhasebe / yatırım hesabı ekstresi / aracı kurum raporu
B17: 8 | C17: Değerleme Düşüşü KKEG Değerlendirme Notu | D17: Dönem sonu < Dönem başı ise değerleme kaybı oluşur. 659 gider kaydı yapılır. Bu tutarın KKEG olup olmadığı ayrıca analiz edilmelidir. Güncel özelge/mukteza araştırması yapılarak YMM görüşü dosyaya eklenmelidir. YMM notu: Değerleme kaybına ilişkin KKEG kararı yazılı olarak belgelenmeli. | E17: YMM görüş notu / Güncel mukteza araştırması
B18: 9 | C18: Önceki Dönem Beyannamesi ve Karşılaştırma Tablosu | D18: Önceki dönem 300 satırı ile cari dönem karşılaştırması. YKT bakiyesi olmadığı için devir tablosu gerekmez; ancak süreklilik teyidi yapılmalıdır. Önceki dönemde kullanılan istisnalar ve bu dönemki değişimler analiz edilmelidir. | E18: Geçmiş dönem KV beyannameleri / önceki dönem çalışma kâğıdı
B19: 10 | C19: YİAKV Matrah Hesaplama Tablosu | D19: KVK 32/C kapsamındaki yurt içi asgari kurumlar vergisi hesabında 300 satırı istisnasının etkisi analiz edilmelidir. YMM notu: YİAKV matrahında 5/1-a-5 istisnasının nasıl dikkate alındığı dönem mevzuatıyla doğrulanmalı. | E19: YİAKV çalışma kâğıdı / KVK 32/C Tebliğleri
B20: 11 | C20: KKEG Tablosu ve Beyanname Mutabakat Çalışması | D20: VUK 279 değerleme artışının KKEG olarak nasıl ele alındığı. 649 hesabı → KKEG tablosu → Beyanname matrahı → 300 satırı istisna bağlantısı. Bu zincirleme uyumun çalışma tablosu dosyaya eklenmelidir. | E20: Muhasebe çalışma kâğıdı / KKEG tablosu / Vergi hesabı
A22: KATEGORİ 3 — YMM TASDİK KONTROL SORULARI (Her Fon İçin Ayrı Uygulayın)
B23: No | C23: Kontrol Sorusu | D23: Beklenen Sonuç / Tasdik Standardı | E23: YMM Aksiyonu
B24: S1 | C24: Her fonun iktisap tarihi 15.07.2023'ten önce olduğu belgeyle teyit edildi mi? | D24: Alış tarihi belgesi (banka dekontu / MKK ekstresi) mevcut olmalı. Belgesiz hiçbir fon istisna kapsamında değerlendirilemez. Risk: Tarihin 15.07.2023 sonrası olması veya belge eksikliği → Tarhiyat. | E24: YMM kontrolü uygulayın
B25: S2 | C25: Fon portföyü VUK 279 değerleme yöntemini etkiliyor mu? (Alış bedeli / Borsa rayici ayrımı) | D25: Fon bilgi formu ile portföy bileşimi teyit edilmeli. %51+ BIST hisse → Alış bedeli (değerleme farkı = 0). Aksi → Borsa rayici/ilan. Risk: Yanlış yöntem uygulaması → Değerleme farkı hatalı hesaplanır. | E25: YMM kontrolü uygulayın
B26: S3 | C26: Bu form GSYF değerleme farkını dahil ediyor mu? (Dahil etmemeli!) | D26: GSYF (5/1-a-3) değerleme farkı → 298 veya 386 satırı. Bu forma dahil edilmemelidir. Kontrol: VERİ GİRİŞİ B tablosunda GSYF var mı? | E26: YMM kontrolü uygulayın
B27: S4 | C27: Değerleme farkı hesabı doğru mu? (Dönem Sonu − Dönem Başı ≥ 0 ise istisna) | D27: Formül: IF(Dönem Sonu > Dönem Başı, Dönem Sonu − Dönem Başı, 0). Negatif fark: İstisna yok — KKEG analizi gerekir. B tablosu F sütunu ile VERİ GİRİŞİ D.1 uyumlu mu? | E27: YMM kontrolü uygulayın
B28: S5 | C28: Muhasebe 649 toplamı ile beyanname 300 satırı tutarlı mı? | D28: 649 hesabı toplamı (VUK 279 artışları) = Beyanname 300 tutarı. Fark varsa: KKEG tablosu kontrolü yapılmalı ve açıklanmalıdır. 3 kademe uyum: 649 = B Tablosu = Beyanname 300. | E28: YMM kontrolü uygulayın
B29: S6 | C29: Kapsam dışı fonlar (C tablosu) matrahta doğru konumlandırıldı mı? | D29: 15.07.2023 sonrası iktisap / GSYF / döviz-altın portföyü → Vergiye tabi. Bu tutarlar beyanname matrahında kalmalıdır — 300 satırına yazılmamalıdır. C tablosu toplamı ile matrah arasındaki uyum kontrol edilmeli. | E29: YMM kontrolü uygulayın
B30: S7 | C30: Beyanname 300 satırı 'Zarar Olsa Dahi İndirilecek' bölümünde mi? | D30: 'Kazancın Bulunması Halinde' bölümüyle karıştırılmaması kritiktir. 300 satırı 'Zarar Olsa Dahi İndirilecek' bölümündedir. Yanlış bölüm: Tarhiyat riski. | E30: YMM kontrolü uygulayın
A32: SON NOT (YMM TASDİK HATIRLATMASI): 49 No.lu Tebliğ (30.12.2025): Tek satır >=500.000 TL veya toplam >=1.000.000 TL → YMM raporu zorunlu. Tam tasdik sözleşmesi olanlar ayrıca rapor düzenlemez. Mülga hüküm nedeniyle bu istisna geçici uygulamadır — her dönem kapsam değerlendirilmelidir. İktisap tarihi belgesi eksikliği en büyük tarhiyat riskidir. YMM tasdik hatası → Müteselsil sorumluluk (YMM Kanunu Md.12).
