Workbook

Sheet VERİ GİRİŞİ
A1: 310 – TEKNOLOJİ GELİŞTİRME BÖLGELERİNDE ELDE EDİLEN KAZANÇLAR İSTİSNASI
A2: 4691 s.K. Geçici Md.2 | KVK Satır 310 | Yazılım / Tasarım / Ar-Ge | 31.12.2028'e kadar (dönem mevzuatı ayrıca kontrol edilmelidir) | Zarar Olsa Dahi İndirilir
A3: RENK KODLARI: 🔵 Sarı zemin / mavi metin = Kullanıcı girişi ⚫ Siyah = Formül 🟢 Yeşil zemin = Sonuç 🔴 Turuncu zemin = Uyarı ℹ Mavi zemin = Bilgi
A4: A0. TEMEL NİTELİK TESPİTİ — Bu Dosyaya Uygunluk Kontrolü (Önce Doldurun)
A5: ⚠️ UYARI: Bu çalışma kağıdı yalnızca 4691 sayılı Kanun kapsamındaki TGB'de münhasıran yazılım / tasarım / Ar-Ge faaliyeti yürüten mükellefler için hazırlanmıştır. TGB dışı faaliyetler, kapsam dışı gelirler (faiz, kur farkı, ATİK satışı) ve özel durumlar (GMH satışı / CBKK) ayrıca değerlendirilmelidir.
A6: Temel Kontrol Soruları | C6: Yanıt | D6: Açıklama / Not
A7: A0.1 Faaliyet TGB içinde yürütülüyor mu? | C7: EVET | D7: Bölge dışında yürütülen faaliyetler istisna kapsamı dışındadır; özel düzenleme yoksa risk doğar.
A8: A0.2 Kazanç türü yazılım / tasarım / Ar-Ge mi? | C8: EVET | D8: Yalnızca bu üç faaliyet türü istisna kapsamındadır. Kapsam dışı gelirler C bölümünde ayrıştırılmalıdır.
A9: A0.3 İstisna şartları değerlendirildi mi? | C9: EVET | D9: Hasılat/gider ayrıştırması, zarar ring-fence ve belgeleme şartları sağlanmış olmalıdır.
A10: A0.4 YİAKV etkisi ayrıca test edildi mi? | C10: EVET | D10: 4691 s.K. istisnası YİAKV matrahından indirilemeyen istisnalar arasındadır. Ayrı hesap zorunludur.
A11: A0.5 Ana Senaryo Kontrol Sonucu | C11: =IF(AND(C7="EVET",C8="EVET",C9="EVET"),"✅ OK – Bu dosya uygun","⛔ HATA – Ön koşul sağlanmadı") -> ✅ OK – Bu dosya uygun | D11: Tüm kontrol soruları 'EVET' olmadan hesap sonuçlarının doğrudan kullanılmaması önerilir.
A14: A – MÜKELLEF VE DÖNEM BİLGİLERİ
A15: Mükellef Unvanı | D15: → | E15: Kurumlar vergisi mükellefi unvanı
A16: Vergi Kimlik Numarası | D16: → | E16: 10 haneli VKN
A17: Bağlı Bulunulan TGB Adı | D17: → | E17: Örn: Hacettepe Teknokent, İTÜ Arı Teknopark
A18: Yönetici Şirket | D18: → | E18: TGB yönetici şirketinin adı
A19: Hesap Dönemi | D19: → | E19: 01.01.…… – 31.12.…… (hesap dönemi girilecek)
A20: KV Oranı (%) | C20: 0.25 | D20: → | E20: 2025: %25 (genel); Finans: %30
A21: YİAKV Oranı | C21: 0.1 | D21: → | E21: 4691 s.K. istisnası, YİAKV matrahından indirilemeyen istisnalar kapsamında değerlendirilmelidir. Dönem mevzuatı ayrıca kontrol edilmelidir.
B24: Proje Adı / Kodu | C24: Hasılat (TL) | D24: Toplam Gider (TL) | E24: Bölge İçi Gider Payı | F24: İstisna Kazanç (TL) | G24: Not
B25: Proje-1 | C25: 0 | D25: 0 | E25: 1 | F25: =IF(C25-D25*E25>0, C25-D25*E25, 0) -> 0 | G25: Bölge içi faaliyet
B26: Proje-2 | C26: 0 | D26: 0 | E26: 1 | F26: =IF(C26-D26*E26>0, C26-D26*E26, 0) -> 0 | G26: Bölge içi faaliyet
B27: Proje-3 | C27: 0 | D27: 0 | E27: 1 | F27: =IF(C27-D27*E27>0, C27-D27*E27, 0) -> 0 | G27: Bölge içi faaliyet
B28: Proje-4 | C28: 0 | D28: 0 | E28: 1 | F28: =IF(C28-D28*E28>0, C28-D28*E28, 0) -> 0 | G28: Bölge içi faaliyet
B29: Proje-5 | C29: 0 | D29: 0 | E29: 1 | F29: =IF(C29-D29*E29>0, C29-D29*E29, 0) -> 0 | G29: Bölge içi faaliyet
B30: Proje-6 | C30: 0 | D30: 0 | E30: 1 | F30: =IF(C30-D30*E30>0, C30-D30*E30, 0) -> 0 | G30: Bölge içi faaliyet
B31: Proje-7 | C31: 0 | D31: 0 | E31: 1 | F31: =IF(C31-D31*E31>0, C31-D31*E31, 0) -> 0 | G31: Bölge içi faaliyet
B32: Proje-8 | C32: 0 | D32: 0 | E32: 1 | F32: =IF(C32-D32*E32>0, C32-D32*E32, 0) -> 0 | G32: Bölge içi faaliyet
A33: PROJE BAZLI İSTİSNA KAZANÇ TOPLAMI | C33: =SUM(F25:F32) -> 0
A35: C – KAPSAM DIŞI GELİRLER (İstisna kapsamında değerlendirilemez)
A36: Faiz gelirleri • Yabancı para kur farkları • ATİK satış kazançları • TGB dışı ticari faaliyetler → Bu gelirler istisna kazanca DAHİL EDİLEMEZ. Ayrı hesaplarda izlenmesi zorunludur (1 No.lu KVGT 10.4.2).
A37: Faiz Gelirleri (TGB hesaplarından) | C37: 0 | D37: TL | E37: Nakit değerlendirme faizleri → kapsam dışı
A38: Kur Farkı Gelirleri | C38: 0 | D38: TL | E38: Dövizli alacak/borç kur farkları → kapsam dışı
A39: ATİK Satış Kazançları | C39: 0 | D39: TL | E39: İktisadi kıymet elden çıkarma → kapsam dışı
A40: Diğer Kapsam Dışı Gelirler | C40: 0 | D40: TL | E40: TGB dışı ticari faaliyetler, lisans bedelleri (CBKK şartı olmadan)
A41: TOPLAM KAPSAM DIŞI GELİR (bilgi amaçlı) | C41: =SUM(C37:C40) -> 0
A43: D – GAYRİ MADDİ HAK SATIŞI (Cumhurbaşkanı Kararı Kapsamında — Patent/Eşdeğer Belge)
A44: DİKKAT: Bu bölüm YALNIZCA patentli/eşdeğer belgeli gayri maddi hak satış/devir/kiralama kazancı olan durumlarda doldurulur. Normal proje kazançlarından ayrıdır. Patent veya fonksiyonel olarak patente eşdeğer belge zorunludur. İstisna kısmı: Nitelikli Harcama Oranı (NHO) = Nitelikli Harcamalar ÷ Toplam Harcamalar × GMH Satış Kazancı Nitelikli harcama: Kurum bünyesindeki Ar-Ge + bağımsız araştırma harcamaları (yurt dışı ilişkili ≤%30 sınırı).
A45: Nitelikli Harcama Tutarı (TL) | C45: 0 | D45: TL | E45: Kurum bünyesindeki Ar-Ge + bağımsız araştırma harcamaları. Yurt dışı ilişkili kişi payı ≤%30.
A46: Toplam Harcama Tutarı (TL) | C46: 0 | D46: TL | E46: Nitelikli + niteliksiz (CBKK kapsamı dışı) tüm harcamalar
...

Sheet HESAPLAMALAR & KONTROL
A1: 310 – TEKNOLOJİ GELİŞTİRME BÖLGELERİ | HESAPLAMALAR & DENETİM KONTROL PANELİ
A2: 4691 s.K. Geçici Md.2 | 1 No.lu KVGT Bölüm 10.4 | KVK Beyanname Satır 310
A4: SINIFLANDIRMA KONTROLÜ (VERİ GİRİŞİ ÖN KONTROL SONUCU)
A5: Ön kontrol sonucu | C5: ='VERİ GİRİŞİ'!C11 -> ✅ OK – Bu dosya uygun | D5: Bu hücre '✅ OK' olmadan hesap sonuçlarının kullanılmaması önerilir.
A6: YİAKV Etkisi (Bilgi Amaçlı) | C6: =IF('VERİ GİRİŞİ'!C10="EVET","✅ TEST EDİLDİ","⚠ KONTROL GEREKİR") -> ✅ TEST EDİLDİ | D6: 4691 s.K. istisnası YİAKV matrahından indirilemeyen istisnalar arasındadır (KVK 32/C kapsamı dışı). Nihai YİAKV etkisi ayrıca hesaplanmalıdır.
A7: A – HESAPLAMA ÖZETİ (VERİ GİRİŞİ'NDEN OTOMATİK)
B8: Kalem | C8: Tutar | D8: Birim | E8: Açıklama
A9: Proje Bazlı İstisna Kazanç | C9: ='VERİ GİRİŞİ'!C33 -> 0 | D9: TL | E9: B Bölümü (VG satır 24)
A10: GMH Satışı İstisna Kısmı | C10: ='VERİ GİRİŞİ'!C49 -> 0 | D10: TL | E10: D Bölümü (VG satır 40)
A11: TOPLAM İSTİSNA (Satır 310) | C11: ='VERİ GİRİŞİ'!C54 -> 0 | D11: TL | E11: E Bölümü (VG satır 45)
A12: Hesaplanan Fon Tutarı | C12: ='VERİ GİRİŞİ'!C62 -> 0 | D12: TL | E12: F Bölümü (VG satır 53)
A13: Uygulanacak Fon (MIN sınırlı) | C13: ='VERİ GİRİŞİ'!C64 -> 0 | D13: TL | E13: F Bölümü (VG satır 55)
A14: YİAKV Teorik Taban Vergi (İstisna × YİAKV Oranı) | C14: ='VERİ GİRİŞİ'!C54*'VERİ GİRİŞİ'!C21 -> 0 | D14: TL | E14: Bilgi amaçlıdır; doğrudan beyanname satırı değildir. Nihai YİAKV hesabı ayrıca test edilmelidir.
A16: B – DENETİM KONTROL LİSTESİ (K1–K10)
B17: Kontrol Maddesi | C17: Yasal Dayanak | D17: Şart | E17: Giriş | F17: Sonuç
A18: K1 – Faaliyet TGB'de yürütüldü mü? | C18: Bölgede faaliyete geçiş tarihi sonrasında başlayan projeler. Tamamlanmış projeler kapsam dışı. (1 No.lu KVGT 10.4.1) | D18: Bölge içi | F18: ✅/❌
A19: K2 – Faaliyet yazılım / tasarım / Ar-Ge mi? | C19: Yalnızca bu üç faaliyet türü istisna kapsamında. Ticari satış, destek, danışmanlık (Ar-Ge dışı) → kapsam dışı. | D19: Faaliyet türü | F19: ✅/❌
A20: K3 – Hasılat, maliyet ve giderler ayrı hesapta izleniyor mu? | C20: Bölge içi ve bölge dışı faaliyetlerin hasılat/gider bazında net ayrıştırılması zorunlu. (1 No.lu KVGT 10.4.2) | D20: Muhasebe ayrımı | F20: ✅/❌
A21: K4 – İstisna kapsamı zararlar diğer faaliyetlere yüklendi mi? (Yüklenmemeli) | C21: İstisna faaliyetinin zararı diğer kazançlardan indirilemez. Tersine uygulama → vergi ziyaı riski. | D21: Zarar ring-fence | F21: ✅/❌
A22: K5 – Kapsam dışı gelirler (faiz/kur farkı) istisna dışı tutuldu mu? | C22: Nakit yönetimi gelirleri, kur farkları, ATİK satış kazançları → istisna kapsamı dışı. | D22: Kapsam dışı | F22: ✅/❌
A23: K6 – GMH satışı için patent/eşdeğer belge var mı? | C23: CBKK kapsamı GMH satışında patent veya fonksiyonel eşdeğer belge zorunludur. Belge yoksa NHO hesaplamasının uygulanması riski doğar; istisna kapsamı bu durumda ayrıca değerlendirilmelidir. | D23: Patent belgesi | F23: ✅/❌
A24: K7 – NHO (Nitelikli Harcama Oranı) doğru hesaplandı mı? | C24: Nitelikli harcama: Bağımsız Ar-Ge + kurum içi. Yurt dışı ilişkili kişi payı ≤%30. (CBK 2017/10821, 54 No.lu CBK) | D24: NHO kontrolü | F24: ✅/❌
A25: K8 – Fon yükümlülüğü oluştu mu ve zamanında yapıldı mı? | C25: İstisna ≥ 5.000.000 TL → %3 fon, 31 Aralık'a kadar GSYF/GSYO/Kuluçka merkezi yatırımı. Yapılmazsa → İstisnanın %20'si iptal (vergi ziyaısız tarh). | D25: Fon yatırım | F25: ✅/❌
A26: K9 – YİAKV matrahı ile normal KV matrahı ayrıştırıldı mı? | C26: KVK 32/C kapsamında asgari kurumlar vergisi hesabı yapılırken, 4691 s.K. kapsamındaki istisnanın matrahtan indirilemeyeceği yönünde değerlendirme riski bulunduğundan, normal KV ve YİAKV hesapları ayrı çalışma kağıtlarıyla test edilmelidir. | D26: YİAKV riski | F26: ✅/❌
A27: K10 – Beyanname 310 satırı 'Zarar Olsa Dahi İndirilecek' bölümünde mi? | C27: 4691 s.K. istisnası zarar olsa dahi indirilir. Beyanname doldurmada doğru bölüm seçilmeli. | D27: Beyanname formu | F27: ✅/❌
A29: C – YİAKV (YURT İÇİ ASGARİ KURUMLAR VERGİSİ) — ÖNEMLİ UYARI
A30: KVK 32/C kapsamında asgari kurumlar vergisi hesabı yapılırken, 4691 s.K. kapsamındaki istisnanın matrahtan indirilemeyeceği yönünde değerlendirme riski bulunduğundan, normal KV ve YİAKV hesapları ayrı çalışma kağıtlarıyla test edilmelidir. Asgari KV oranı: %10 (kurum kazancı × %10 ≤ KV olma zorunluluğu). TGB istisnası uygulanmış kurumlar için KV sıfırlanabilir ancak YİAKV ödenebilir. Dönem mevzuatı ayrıca kontrol edilmelidir.
A32: D – FON YÜKÜMLÜLÜK ÖZET TABLOSU
A33: İstisna Tutarı (Beyanname 310) | C33: ='VERİ GİRİŞİ'!C54 -> 0
A34: Hesaplanan Fon (%3, azami 100M TL) | C34: ='VERİ GİRİŞİ'!C64 -> 0
A35: Yatırım Son Tarihi | C35: Hesap döneminin son günü

Sheet MUHASEBE KAYITLARI
A1: 310 – MUHASEBE KAYITLARI REHBERİ | 4691 s.K. TGB İSTİSNASI
A2: ⚠️ Bu kayıtlar Tek Düzen Hesap Planı'na göre rehber niteliğindedir. Şirketin muhasebe politikasına ve muhasebe uzmanı görüşüne göre uyarlanmalıdır.
A4: KAYIT 1 – Ar-Ge / YAZILIM / TASARIM GELİRİ TAHAKKUKU (Dönem İçi)
B5: Tarih | C5: Hesap No / Açıklama | D5: Not | E5: Borç (TL) | F5: Alacak (TL) | G5: Ref
B6: Dönem içi | C6: 120 Alıcılar / uygun alacak hesabı | D6: Proje hizmet bedeli hakediş | E6: Brüt proje geliri | G6: Sözleşme / Hakediş
A7: Bölge içi yazılım/tasarım/Ar-Ge gelirleri ayrı hesap altında izlenmeli. 642 hesabı (faiz) ve 646 (kur farkı) ile karıştırılmamalı.
A9: KAYIT 2 – FONUN PASİFTE İZLENMESİ (İstisna ≥ 5.000.000 TL ise)
B10: Tarih | C10: Hesap No / Açıklama | D10: Not | E10: Borç (TL) | F10: Alacak (TL) | G10: Ref
B11: KV beyanname | C11: 590 Dönem Net Kârı (veya 689 Diğer Gider) | D11: Fon aktarımı | E11: İstisna × %3 | G11: 4691 Ek Md.3
C12: 549 Özel Fonlar | D12: Girişim sermayesi fon hesabı | F12: İstisna × %3 | G12: Hesap dönemi sonuna kadar yatırılacak
A13: Fon tutarı pasifte geçici bir hesapta izlenmeli; ilgili hesap döneminin sonuna kadar uygun yatırım araçlarına (GSYF/GSYO/Kuluçka merkezi) yönlendirilmelidir.
A15: KAYIT 3 – FON YATIRILDIĞINDA (GSYF Fonu Satın Alımı Örneği)
B16: Tarih | C16: Hesap No / Açıklama | D16: Not | E16: Borç (TL) | F16: Alacak (TL) | G16: Ref
B17: Yatırım tar. | C17: 242 İştirakler / 110 Hisse Senetleri / uygun finansal yatırım hesabı | D17: GSYF payı alımı | E17: Fon tutarı | G17: Yatırım belgesi
A18: Kuluçka merkezi girişimcisine sermaye konulmasında → 242 İştirakler kullanılır. GSYO'ya sermaye konulmasında da aynı hesap.
A20: KAYIT 4 – DÖNEM SONU: İSTİSNA NAZIM KAYDI (İsteğe Bağlı Takip)
B21: Tarih | C21: Hesap No / Açıklama | D21: Not | E21: Borç (TL) | F21: Alacak (TL) | G21: Ref
B22: Dönem sonu | C22: 950 Nazım Hesaplar – İstisna Kazanç Takibi | D22: İstisna kazanç takibi | E22: İstisna tutarı | G22: Beyanname 310
C23: 951 Karşılıklı Nazım Hesabı | F23: İstisna tutarı | G23: Mahsup
A24: Muhasebe kârı değişmez — istisna beyanname üzerinde uygulanır. KV karşılığı hesaplamasında istisna kazanç matrah dışı bırakılır.

Sheet DENETÇİ NOTLARI
A1: 310 – DENETÇİ NOTLARI VE RİSK ANALİZİ | 4691 s.K. TGB İSTİSNASI
A2: 4691 s.K. Geçici Md.2 | 1 No.lu KVGT Bölüm 10.4 | 7953 No.lu CBK (16.12.2023) | KVK 32/C YİAKV | Beyanname Satır 310 | İstisna süresi: 31.12.2028'e kadar (GİB 2026 Ticari Kazanç Rehberi; dönem mevzuatı kontrol edilmelidir)
A4: A – YASAL DAYANAK METNİ
A5: ► 4691 s.K. Geçici Madde 2 (Yürürlük: 31.12.2028'e kadar (GİB 2026 Ticari Kazanç Rehberi; dönem mevzuatı kontrol edilmelidir)): "Yönetici şirketlerin bu Kanun uygulaması kapsamında elde ettikleri kazançlar ile Bölgede faaliyet gösteren gelir ve kurumlar vergisi mükelleflerinin, münhasıran bu Bölgedeki yazılım, tasarım ve AR-GE faaliyetlerinden elde ettikleri kazançları ilgili süre (dönem mevzuatına göre kontrol edilmelidir) tarihine kadar gelir ve kurumlar vergisinden müstesnadır." Ek Madde 3 (7263 s.K. ile eklenmiş; 7953 No.lu CBK ile 01.01.2024'ten itibaren güncellenmiş): "1/1/2022 tarihinden itibaren [geçici 2. madde kapsamında] yıllık beyanname üzerinden istisna edilen kazanç tutarı 5.000.000 TL ve üzerinde olan mükellefler tarafından bu tutarın %3'ü pasifte geçici bir hesaba aktarılır. [Yıllık azami: 100.000.000 TL] [Süre: Yıl sonu] [Yaptırım: İstisnanın %20'si iptal]"
A7: B – KRİTİK RİSK TABLOSU
A8: ► RİSK 1 — YİAKV ÇARPAN ETKİSİ (01.01.2025+) 4691 s.K. kapsamındaki istisnanın YİAKV matrahındaki etkisi ayrıca değerlendirilmelidir. Normal kurumlar vergisi hesabı ile YİAKV hesabı ayrı test edilmelidir. KVK 32/C-2 fıkrası kapsamında indirilemeyen istisnalar listesinde 4691 s.K. Geçici Md.2 istisnasının bulunduğuna dair GİB değerlendirmesi mevcuttur. Bu nedenle TGB istisnası uygulayan kurumlar için YİAKV yükü doğabilir. Dönem mevzuatı ve GİB güncel rehberleri kontrol edilmelidir.
A9: ► RİSK 2 — BÖLGE DIŞI FAALİYET Faaliyetin bölge dışında yürütülen kısmı için özel düzenleme ve şartlar ayrıca test edilmelidir; uygun şartlar yoksa ilgili kazanç bakımından istisna riski doğar. Dönemsel özel düzenlemeler ve 4691 s.K. çerçevesindeki istisnai haller saklı kalmak kaydıyla, bölge dışı çalışma süreleri için istisna uygulaması genel kural olarak mümkün değildir; ancak mevzuat değişikliklerini takip edin.
A10: ► RİSK 3 — KAPSAM DIŞI GELİRLERİN İSTİSNAYA DAHİL EDİLMESİ Faiz, kur farkı, ATİK satış kazancı ve TGB dışı ticari faaliyetlerden elde edilen gelirler istisna kapsamı dışındadır. Bu gelirlerin 310 satırına yazılması vergi incelemesinde ceza riskidir. Çözüm: C bölümündeki kapsam dışı gelirler mutlaka ayrı hesapta izlenmeli.
A11: ► RİSK 4 — FON YÜKÜMLÜLÜĞÜNÜN YAPILMAMASI İstisna ≥ 5.000.000 TL iken fon yapılmazsa → İstisnanın %20'si iptal, vergi ziyaısız tarh. Hesap döneminin son günü itibarıyla uygun yatırım araçlarına yönlendirilmiş olması şarttır. Beyanname verildiği tarihe kadar fon karşılığı pasife alınmalı, yıl sonuna kadar yatırım tamamlanmalıdır. Kuluçka merkezi yatırımlarında işlemin hukuki niteliği ve tevsik şekli ayrıca incelenmelidir; yalnızca hisse devri niteliğindeki işlemlerde risk oluşabilir (GİB özelgesi 26.11.2025; dönem güncel uygulaması kontrol edilmelidir).
A12: ► RİSK 5 — GMH SATIŞINDA PATENT VE NHO HESAPLAMASI CBKK (Cumhurbaşkanı Kararı) kapsamındaki GMH satışında patent zorunludur. NHO = Nitelikli harcamalar / Toplam harcamalar. Yurt dışı ilişkili kişi harcama payı ≤%30 sınırı. Sınırı aşan kısım NHO'ya dahil edilmez → İstisna oranı düşer.
A13: ► RİSK 6 — İSTİSNA KAPSAMINDAKİ ZARARIN DİĞER FAALİYETLERE YÜKLENMESİ TGB istisna kapsamı faaliyetin zararla sonuçlanması halinde bu zarar diğer kazançlardan indirilemez. "Zarar ring-fence" prensibi. Aksine yapılan uygulama ceza riskidir.
A15: C – ÖNEMLİ ÖZELGELER VE KAYNAKLAR
A16: ► Güncel Mevzuat ve Kaynaklar: • 4691 sayılı Teknoloji Geliştirme Bölgeleri Kanunu, Geçici Md.2, Ek Md.3 • 1 Seri No.lu Kurumlar Vergisi Genel Tebliği, Bölüm 10.4 • 7953 No.lu Cumhurbaşkanı Kararı (16.12.2023 tarih, 32401 sayılı RG) — %2→%3 fon, 1M→2M alt sınır • 10803 No.lu Cumhurbaşkanı Kararı (31.12.2025 tarih, 33124 (5. Mükerrer) sayılı RG) → Fon alt sınırı: 2M→5M TL (01.01.2026 itibarıyla; 2025 dönemine ait beyannamelere uygulanır) Oran %3 ve üst sınır 100M TL değişmemiştir. • CBK 2017/10821 ve 54 No.lu CBK — NHO hesaplama esasları • GİB Özelge, 26.11.2025, E-38418978-125[4691-24] — Kuluçka merkezi sermaye şartı • 5520 KVK Md.32/C (7524 s.K. ile 02.08.2024) — YİAKV (01.01.2025+) • 4691 s.K. Uygulama Yönetmeliği Md.35/C — Fon yükümlülük esasları • KV Beyannamesi Satır 310: 'Teknoloji Geliştirme Bölgelerinde Elde Edilen Kazançlar' → 'Cari Yıla Ait Zarar, İstisna ve İndirimler' bölümü — Zarar olsa dahi indirilir

Sheet BELGE LİSTESİ
A1: 310 – GEREKLİ BELGE VE BİLGİ LİSTESİ (Denetim ve YMM Tasdik İçin)
A2: ✅ Zorunlu | ➕ Destekleyici | Tüm belgeler YMM denetim dosyasına eklenmeli.
B4: No | C4: Belge / Bilgi Adı | D4: Detay ve YMM Kontrol Noktaları | E4: Temin Yeri
A5: KATEGORİ 1 — ZORUNLU BELGELER
B6: ✅ 1 | C6: TGB Katılımcı Belgesi / Yönetici Şirket Onayı | D6: Firmanın TGB'de faaliyete geçiş tarihi ve kapsama alınan proje onaylarını gösterir. YMM: Faaliyet tarihinin projenin başlangıç tarihinden önce olduğunu teyit eder. | E6: Yönetici şirket / TGB
B7: ✅ 2 | C7: Yıllık Proje Listesi ve Hakediş Raporları | D7: Yürütülen yazılım/tasarım/Ar-Ge projelerinin adı, bütçesi, süresi, müşterisi. YMM: Her projenin istisna kapsamında olduğunu ve bölge içinde yürütüldüğünü doğrular. | E7: Proje yönetim sistemi
B8: ✅ 3 | C8: Bölge İçi Hasılat ve Gider Hesap Dökümü | D8: TGB faaliyetlerine özgü 600/601 hesap hareketleri, proje bazında ayrıştırılmış giderler. YMM: Kapsam dışı gelirlerin (faiz/kur farkı) ayrı hesaplarda olduğunu kontrol eder. | E8: Muhasebe / ERP
B9: ✅ 4 | C9: KV Beyannamesi ve 310 Satır Tutarı | D9: İstisna tutarının beyannamede 'Zarar Olsa Dahi İndirilecek İstisnalar' bölümünde gösterilmesi. YMM: Beyanname satır 310 = Çalışma kağıdı E bölümü toplamı. | E9: GİB e-Beyanname
B10: ✅ 5 | C10: Fon Yükümlülük Hesaplaması ve Aktarım Belgesi | D10: İstisna ≥ 5M TL ise: %3 fon hesaplaması, 549 Özel Fonlar hesabı dökümü, GSYF/GSYO/Kuluçka merkezi yatırım belgesi (ilgili hesap döneminin sonuna kadar). | E10: Muhasebe + yatırım belgesi
B11: ✅ 6 | C11: TGB Faaliyet Yeri Belgesi (Bölge İçi Faaliyet Teyidi) | D11: TGB yönetici şirketi onayı veya katılımcı belgesi. Faaliyetin münhasıran bölge içinde yürütüldüğünü belgeler. YMM: Bölge içi/dışı çalışma süreleri ve proje kayıtları ayrıca kontrol edilmelidir. Vergi incelemesinde en kritik belgedir. | E11: TGB yönetici şirketi
A13: KATEGORİ 2 — DESTEKLEYİCİ BELGELER
B14: ➕ 6 | C14: Patent / Fonksiyonel Eşdeğer Belge (GMH Satışı Varsa) | D14: CBKK kapsamında GMH satışından istisna uygulanıyorsa patent veya eşdeğer belge zorunlu. YMM: Belge tarihi ve proje ile ilişkisi. | E14: TPE / USPTO / EPO
B15: ➕ 7 | C15: NHO (Nitelikli Harcama Oranı) Hesaplama Tablosu | D15: Toplam harcamalar, nitelikli harcamalar, yurt dışı ilişkili kişi harcamaları ≤%30 sınırı. YMM: Hesaplamayı doğrular, ilişkili kişi sınırını kontrol eder. | E15: Proje finans kayıtları
B16: ➕ 8 | C16: Personel GV Stopajı İstisna Tablosu | D16: İstisna kapsamı personel listesi, çalışılan saat/proje dökümü, muhtasar beyanname terkin tutarları. YMM: personelin teşvik kapsamı, görev niteliği, çalışma düzeni ve ilgili dönemde geçerli sınır/şartları (1/8/2025 itibarıyla brüt asgari ücretin 40 katı üst sınırı dahil) kontrol eder. Dönem mevzuatı ayrıca teyit edilmelidir. | E16: İnsan kaynakları / bordro
B17: ➕ 9 | C17: SGK Prim İşveren Hissesi Devlet Katkısı Belgeleri | D17: SGK'dan alınan katkı makbuzları, SGK-4/a prim bildirgeleri. | E17: SGK e-Bildirge
B18: ➕ 10 | C18: YİAKV Matrah Hesaplama Tablosu | D18: YİAKV matrahı ve oranı, ilgili dönemin mevzuatına göre ayrıca test edilmelidir. YMM: Normal KV matrahı ile YİAKV matrahını ayrı çalışma kağıtlarıyla karşılaştırır ve tutarlılığı doğrular. | E18: Muhasebe çalışma kağıdı
A20: ⚠️ SON NOT: Kapsam dışı gelirler (faiz, kur farkı, ATİK satışı), GMH satışı (CBKK kapsamı) ve özel durumlar ayrı çalışma kağıdı gerektirebilir. VERİ GİRİŞİ A0 kontrolü 'OK' olmadan bu listenin kullanılması önerilmez.
A23: TASDİK DOSYASI HAZIRLIK KONTROL ÖZETİ
A24: 310 — 4691 s.K. Geçici Md. 2 TGB Kazanç İstisnası — Tasdik Hazırlık Kontrol Listesi □ A0 kontrol bloğu tamamlandı ve 'OK' sonucu alındı □ TGB katılımcı belgesi ve yönetici şirket onayı temin edildi □ Proje listesi ve hakediş raporları gözden geçirildi □ Kapsam dışı gelirler (faiz/kur farkı/ATİK) istisna hesabından ayrıştırıldı □ Zarar ring-fence kuralına uyum kontrol edildi □ Fon yükümlülüğü hesaplandı ve yatırım belgesi temin edildi (≥5.000.000 TL ise) □ GMH satışı varsa patent belgesi ve NHO tablosu hazırlandı □ YİAKV matrahı bu istisnayı DÜŞÜLMEDEN ayrı hesaplandı □ 64x hesabı ile beyanname 310 satırı mutabakatı tamamlandı □ DENETÇİ NOTLARI sayfası (I-IV bloklar) dolduruldu
