Workbook

Sheet VERİ GİRİŞİ
A1: 350 – DİĞER İNDİRİMLER VE İSTİSNALAR | KV BEYANNAMESİ 302–349 DIŞI TÜM İSTİSNA VE İNDİRİMLER | YMM TASDİK | BEYANNAME 350
A2: 350 Satırı = 302–349 ÖZEL SATIRLARINA girmeyen tüm istisna ve indirimlerin toplamı | Her kalem AYRI yasal dayanak ile belgelenmeli | YMM açısından setten en riskli satır | Kazancın Bulunması Halinde (ve bazı kalemler Zarar Olsa Dahi)
A3: ★ 350'NİN TEMEL KURALI: Her kalem için ayrı yasal dayanak + ayrı belge paketi zorunludur. 'Diğer İstisna' gerekçesiyle toplu tutar yazımı kabul edilemez. Önce 302–349 özel satırlarını kontrol edin — özel satır varsa 350'yi kullanmayın. Setimizde: TGB Yönetici Şirket → 311 | TUGS Gemi → 315 | Ürün Senedi → 349 (350 değil).
A4: EN SIK KULLANILAN 350 KALEMLERİ: (1) Serbest Bölge Kazancı (3218 s.K.) | (2) Teknokent Girişimci/Yazılım (4691 s.K. GVM Md.2) | (3) Ar-Ge ve Tasarım İndirimi (5746 s.K.) | (4) Girişim Sermayesi Fonu (KVK Md.10/1-g) | (5) Bağış ve Sponsorluk (KVK Md.10/1-b,c) | (6) Özel Okul/Hastane (KVK 5/1-ı) | (7) Diğer Özel Kanun İstisnaları
A6: A0. KAPSAM TEYİDİ
A7: Önce kontrol: Beyan edilmek istenen istisna/indirim için 302–349 arasında özel bir satır var mı?
B8: Kontrol Sorusu | F8: Yanıt | H8: YMM Notu
A9: A0.1 ★ Her kalem için 302–349 özel satırlarında daha uygun satır olmadığı teyit edildi mi? | F9: EVET | G9: Özel satır varsa 350 değil, o satır kullanılır.
A10: A0.2 ★ Her kalem için AYRI yasal dayanak ve belge mevcut mu? | F10: EVET | G10: Toplu tutar kabul edilemez — her kalem bağımsız belgelenmeli.
A11: A0.3 Her kalemin beyanname bölümü (KB Halinde / Zarar Olsa Dahi) doğru mu? | F11: EVET | G11: C tablosunda her kalem için bölüm seçilmeli.
A12: A0.4 YMM Tasdik Raporu (49 No.lu Tebliğ) değerlendirildi mi? | F12: EVET | G12: >=500.000 TL → YMM raporu.
A13: A0.5 Tasdik Uygunluk Sonucu | F13: =IF(AND(F9="EVET",F10="EVET",F11="EVET",F12="EVET"),"OK - Hesaplanabilir","HATA - Ön koşul eksik") -> OK - Hesaplanabilir | G13: Her kalem ayrı yasal dayanak + belge zorunlu.
A15: B. BEYANNAME 350'DE SIK KULLANILAN İSTİSNA VE İNDİRİMLER REFERANS TABLOSU
A16: Her kategori için C bölümündeki detay tablosunda ilgili satır doldurulur.
B17: Kategori | C17: Yasal Dayanak | D17: İstisna/İndirim Özeti | E17: Bölüm | F17: İstisna? | G17: İndirim? | H17: Özelge?
B18: Serbest Bölge Kazancı İstisnası | C18: 3218 s.K. Geçici Md.3 | D18: Üretim lisansı olanlar + İhracat faaliyeti. AB üyelik tarihine kadar (güncel kontrol şart). | E18: Kazancın Bulunması Halinde | F18: EVET | G18: - | H18: Önerilir
B19: Teknokent Girişimci — Ar-Ge/Yazılım/Tasarım | C19: 4691 s.K. GVM Md.2 | D19: TGB içinde yazılım/Ar-Ge/tasarım yapan kiracı firma kazancı. Yönetici şirket (311) DEĞİL. | E19: Kazancın Bulunması Halinde | F19: EVET | G19: - | H19: Önerilir
B20: Ar-Ge ve Tasarım İndirimi | C20: 5746 s.K. Md.3 | D20: Ar-Ge Merkezi belgeli harcamalar. %100 indirim. Zarar Olsa Dahi — Devreden takip. | E20: Zarar Olsa Dahi — İndirim | F20: - | G20: EVET | H20: Tavsiye
B21: Girişim Sermayesi Fonu İndirimi | C21: KVK Md.10/1-g | D21: Girişim sermayesi fonu/ortaklığına katılım. Sınır: %10 ve %20. | E21: Kazancın Bulunması Halinde | F21: - | G21: EVET | H21: Tavsiye
B22: Yatırım Ortaklığı Kazanç İstisnası | C22: KVK Md.5/1-d | D22: SPK kapsamlı Türkiye'de kurulu yatırım fonu ve ortaklıkları. | E22: Kazancın Bulunması Halinde | F22: EVET | G22: - | H22: Önerilir
B23: Özel Okul/Hastane/Rehab Merkezi İstisnası | C23: KVK Md.5/1-ı | D23: Özel eğitim, rehabilitasyon ve sağlık kurumu kazancı. İlk faaliyet tarihinden 5 yıl. | E23: Kazancın Bulunması Halinde | F23: EVET | G23: - | H23: Önerilir
B24: Sponsorluk Harcamaları İndirimi | C24: KVK Md.10/1-b | D24: Amatör spor %100, profesyonel spor %50. | E24: Kazancın Bulunması Halinde | F24: - | G24: EVET | H24: Değerlendirin
B25: Bağış ve Yardımlar İndirimi | C25: KVK Md.10/1-c,d,e,f | D25: Vakıf, okul, yurt, üniversite, hastane. Sınır: Kazancın %5 veya %10 (kuruma göre). | E25: Kazancın Bulunması Halinde | F25: - | G25: EVET | H25: Değerlendirin
B26: Diğer Özel Kanun İstisnaları | C26: Çeşitli Özel Kanunlar | D26: Yukarıdaki kategorilere girmeyen özel kanun istisnaları. Her biri ayrı yasal dayanak. | E26: Kazanç/Zarar Durumuna Göre | F26: ? | G26: ? | H26: Zorunlu
A28: C. DÖNEM 350 KALEMLERİ — KALEM BAZINDA VERİ GİRİŞİ
A29: Her satır bir ayrı istisna/indirim kalemine karşılık gelir. YMM tasdik dosyasının temel envanteri olarak kullanılır.
B30: No | C30: İstisna/İndirim Kalemi | D30: Yasal Dayanak | E30: Tutar (TL) | F30: Beyanname Bölümü | G30: Belge Türü | H30: YMM Durumu
A31: K1 | B31: Serbest Bölge Kazancı İstisnası | C31: 3218 s.K. Geçici Md.3 | E31: Kazancın Bulunması Halinde | F31: Üretim Lisansı + Faaliyet Belgesi | G31: Tamamlandı
A32: K2 | B32: Teknokent Girişimci Ar-Ge/Yazılım Kazancı | C32: 4691 s.K. GVM Md.2 | E32: Kazancın Bulunması Halinde | F32: TGB Kiracı Belgesi + Kazanç Tablosu | G32: Tamamlandı
A33: K3 | B33: Ar-Ge ve Tasarım İndirimi | C33: 5746 s.K. Md.3 | E33: Zarar Olsa Dahi — İndirim | F33: Ar-Ge Merkezi Belgesi + Harcama Listesi | G33: Tamamlandı
A34: K4 | B34: Girişim Sermayesi Fonu İndirimi | C34: KVK Md.10/1-g | E34: Kazancın Bulunması Halinde | F34: Fon/Ortaklık Belgesi + Sınır Hesabı | G34: Tamamlandı
A35: K5 | B35: Bağış ve Sponsorluk İndirimi | C35: KVK Md.10/1-b,c,d | E35: Kazancın Bulunması Halinde | F35: Sözleşme + Makbuz/Banka Dekontu | G35: Tamamlandı
A36: K6 | B36: [Diğer — Yasal Dayanak Giriniz] | C36: [Kanun Md. Fıkra] | F36: [Belge türü] | G36: Eksik Belge
A37: K7 | B37: [Diğer — Yasal Dayanak Giriniz] | C37: [Kanun Md. Fıkra] | F37: [Belge türü] | G37: Eksik Belge
A38: K8 | B38: [Diğer — Yasal Dayanak Giriniz] | C38: [Kanun Md. Fıkra] | F38: [Belge türü] | G38: Eksik Belge
A39: TOPLAM | B39: DÖNEM 350 TOPLAMI — Beyanname 350 Satırı | D39: =SUM(D31:D38) -> 0 | E39: K1+K2+...+K8 Toplamı → Beyanname 350
A41: D. YMM AÇISINDAN KRİTİK UYARILAR
A42: U1 | B42: Özel satır varsa 350 KULLANMA | D42: 302–349 uygun özel satır varsa 350'ye yazmak hatalıdır. GİB her kalemi tek tek açıklatabilir.
A43: U2 | B43: Her kalem ayrı yasal dayanak — toplu tutar yetmez | D43: Kalem kalem belgeleme zorunludur. Toplu tutar yazımı tarhiyat riski taşır.
A44: U3 | B44: Beyanname bölümü doğru seçilmeli (KB Halinde / Zarar Olsa Dahi) | D44: Ar-Ge indirimi zarar döneminde de uygulanır. Her kalemin kanununu kontrol edin.
...

Sheet HESAPLAMALAR & KONTROL
A1: 350 – DİĞER İNDİRİMLER VE İSTİSNALAR | HESAPLAMALAR VE DENETİM
A2: Beyanname 350 = 302–349 Dışındaki Tüm İstisna ve İndirimler | Kalem Bazında Şeffaf Belgeleme | Serbest Bölge | Teknokent | Ar-Ge | Girişim Sermayesi | Bağış
A4: A. TASDİK ÖZETİ
A5: A0 Tasdik Uygunluğu | D5: ='VERİ GİRİŞİ'!F13 -> OK - Hesaplanabilir | E5: OK ise devam
A6: K1 — Serbest Bölge (TL) | D6: ='VERİ GİRİŞİ'!D31 -> 0 | E6: Varsa tutar
A7: K2 — Teknokent Girişimci (TL) | D7: ='VERİ GİRİŞİ'!D32 -> 0 | E7: Varsa tutar
A8: K3 — Ar-Ge İndirimi (TL) | D8: ='VERİ GİRİŞİ'!D33 -> 0 | E8: Varsa tutar
A9: K4 — Girişim Sermayesi (TL) | D9: ='VERİ GİRİŞİ'!D34 -> 0 | E9: Varsa tutar
A10: K5 — Sponsorluk/Bağış (TL) | D10: ='VERİ GİRİŞİ'!D35 -> 0 | E10: Varsa tutar
A11: K6-K8 — Diğer (TL) | D11: =SUM('VERİ GİRİŞİ'!D36:D38) -> 0 | E11: Özel kalemler
A12: BEYANNAME 350 TOPLAMI (TL) | D12: ='VERİ GİRİŞİ'!D39 -> 0 | E12: = D39 Toplamı
A14: B. K1 — SERBEST BÖLGE KAZANCI DETAY (3218 s.K.)
A15: Geçici Md.3: Üretim lisansı koşulu. Finansal gelirler kapsam dışı. Güncel yürürlük kontrolü zorunlu.
B16: Parametre | D16: Değer / Seçim | F16: Açıklama | H16: Belge
A17: SB.1 Faaliyet Lisansı Geçerli mi? | C17: EVET | D17: Tarım Bakanlığı lisansı değil — SB faaliyet lisansı | G17: SB Bölge Müdürlüğü
A18: SB.2 Faaliyet Türü | C18: Üretim | D18: İstisna türe göre değişir | G18: Lisans belgesi
A19: SB.3 İstisna Kapsamındaki Kazanç (TL) | C19: ='VERİ GİRİŞİ'!D31 -> 0 | D19: Mali tablolar | G19: Kazanç hesabı
A20: SB.4 Kapsam Dışı Gelir — Faiz vb. (TL) | C20: 0
A22: C. K3 — AR-GE VE TASARIM İNDİRİMİ DETAY (5746 s.K.)
A23: Ar-Ge Merkezi belgesi zorunlu. %100 indirim. 'Zarar Olsa Dahi' — Devreden tutar sonraki yıllara taşınır.
B24: Parametre | D24: Değer (TL) | F24: Açıklama | H24: Belge
A25: ARG.1 Ar-Ge Merkezi Belgesi Geçerli mi? | C25: EVET | D25: Sanayi Bakanlığı onaylı Ar-Ge Merkezi belgesi | G25: Ar-Ge Merkezi Belgesi
A26: ARG.2 Dönem Ar-Ge Harcamaları (TL) | C26: ='VERİ GİRİŞİ'!D33 -> 0 | D26: Ar-Ge raporu | G26: Hesap kartı
A27: ARG.3 Ar-Ge İndirimi (%100) (TL) | C27: =C26 -> 0 | D27: Hesap tablosu
A28: ARG.4 Önceki Dönemden Devreden (TL) | C28: 0 | D28: Beyanname eki | G28: Önceki dönem KV
A29: ARG.5 Bu Dönem Uygulanabilecek (TL) | C29: =C27+C28 -> 0 | D29: Beyanname kontrolü
A31: D. ANA DENETİM KONTROL LİSTESİ (K1–K14)
B32: Kontrol | D32: Açıklama | F32: Sonuç
A33: K1 | B33: ★ Her kalem için 302–349 özel satırlarında uygun satır olmadığı teyit edildi mi? | D33: Özel satır varsa 350 kullanılmaz. | F33: =IF('VERİ GİRİŞİ'!F9="EVET","Uygun","Eksik") -> Uygun | G33: Uygun/Eksik/Risk
A34: K2 | B34: ★ Her kalem için ayrı yasal dayanak belgesi mevcut mu? | D34: Toplu tutar / 'diğer' gerekçesi kabul edilemez. | F34: =IF('VERİ GİRİŞİ'!F10="EVET","Uygun","Eksik") -> Uygun | G34: Uygun/Eksik/Risk
A35: K3 | B35: ★ Her kalemin beyanname bölümü (KB Halinde / Zarar Olsa Dahi) doğru mu? | D35: C tablosu sütun 5 kontrolü. | F35: =IF('VERİ GİRİŞİ'!F11="EVET","Uygun","Eksik") -> Uygun | G35: Uygun/Eksik/Risk
A36: K4 | B36: Serbest bölge kazancında finansal gelirler ayrıştırıldı mı? | D36: Faiz, kur farkı → Kapsam dışı. | F36: =IF(C19>0,IF(C20>0,"Kontrol","Uygun"),"Uygun") -> Uygun | G36: Uygun/Eksik/Risk
A37: K5 | B37: Teknokent girişimci ile 311 Yönetici Şirket karıştırılmadı mı? | D37: Kiracı → K2/350. Yönetici → 311. | F37: =IF(D7>0,"Kontrol","Uygun") -> Uygun | G37: Uygun/Eksik/Risk
A38: K6 | B38: Ar-Ge merkezi belgesi geçerli mi? Devreden takibi yapıldı mı? | D38: ARG.4 önceki dönem beyanname ekiyle uyumlu. | F38: =IF(C25="EVET","Uygun","Eksik") -> Uygun | G38: Uygun/Eksik/Risk
A39: K7 | B39: Girişim sermayesi fonu sınırı (%10 ve %20) aşılmadı mı? | D39: KVK Md.10/1-g sınır kontrol. | F39: =IF(D9>0,"Kontrol","Uygun") -> Uygun | G39: Uygun/Eksik/Risk
A40: K8 | B40: Bağış/sponsorluk oran sınırı (%5 veya %10) aşılmadı mı? | D40: KVK Md.10 oran sınır kontrol. | F40: =IF(D10>0,"Kontrol","Uygun") -> Uygun | G40: Uygun/Eksik/Risk
A41: K9 | B41: KVK Md.10 indirimleri sırası doğru mu? | D41: İstisna sonrası matrahtan indirim sırası. | F41: Kontrol | G41: Uygun/Eksik/Risk
A42: K10 | B42: 350 toplamı C tablosu D39 ile uyumlu mu? | D42: Beyanname 350 = D39. | F42: =IF(D12='VERİ GİRİŞİ'!D39,"Uygun","HATA") -> Uygun | G42: Uygun/Eksik/Risk
A43: K11 | B43: Tartışmalı kalemler için özelge alındı mı? | D43: Az emsal, yeni veya tartışmalı özel kanun kalemleri. | F43: Kontrol | G43: Uygun/Eksik/Risk
A44: K12 | B44: 350 zararla beyan döneminde doğru uygulandı mı? | D44: KB Halinde kalemler → Kazanç yoksa uygulanamaz. | F44: Kontrol | G44: Uygun/Eksik/Risk
...

Sheet MUHASEBE KAYITLARI
A1: 350 – DİĞER İNDİRİMLER VE İSTİSNALAR | MUHASEBE KAYITLARI
A2: Her 350 kalemi kendi kanun hükmüne göre muhasebeleştirilir.
A3: K1 — SERBEST BÖLGE KAZANCI (3218 s.K.)
B4: Tarih | C4: Hesap | D4: Not | E4: Dr | F4: Kr | G4: Ref
A5: Kr | B5: [Dönem] | C5: 645/679 Serbest Bölge Kazancı | D5: 3218 s.K. Geçici Md.3 istisna — Beyanname 350 K1 | E5: - | F5: [Tutar] | G5: 350 K1 — SB belgesi
A6: Kapsam dışı finansal gelirler (faiz, kur farkı) ayrı hesapta — 350 K1'e dahil edilmez.
A7: K2 — TEKNOKENT GİRİŞİMCİ (4691 s.K. GVM Md.2)
B8: Tarih | C8: Hesap | D8: Not | E8: Dr | F8: Kr | G8: Ref
A9: Kr | B9: [Dönem] | C9: 645/679 TGB Yazılım/Ar-Ge Kazancı | D9: 4691 GVM Md.2 — Beyanname 350 K2 (Yönetici Şirket DEĞİL → 311) | E9: - | F9: [Tutar] | G9: 350 K2 — TGB kiracı belgesi
A10: TGB Yönetici Şirket → 311 satırı (350 değil). TGB kiracısı (girişimci firma) → 350 K2.
A11: K3 — AR-GE VE TASARIM İNDİRİMİ (5746 s.K. Md.3)
B12: Tarih | C12: Hesap | D12: Not | E12: Dr | F12: Kr | G12: Ref
A13: Dr | B13: [Beyan] | C13: 770 Ar-Ge Gideri (Matrahtan İndirilecek) | D13: 5746 s.K. Md.3 — %100 indirim — Zarar Olsa Dahi — Beyanname 350 K3 | E13: - | F13: [Tutar] | G13: 350 K3 — Ar-Ge Merkezi belgesi
A14: Devreden kısım: Matrahı aşan Ar-Ge indirimi sonraki yıla devreder — yıllık takip zorunlu.
A15: K4 — GİRİŞİM SERMAYESİ FONU İNDİRİMİ (KVK Md.10/1-g)
B16: Tarih | C16: Hesap | D16: Not | E16: Dr | F16: Kr | G16: Ref
A17: Dr | B17: [Beyan] | C17: 549 Girişim Sermayesi Fonu | D17: KVK Md.10/1-g — %10 ve %20 sınırı — Beyanname 350 K4 | E17: - | F17: [Tutar] | G17: 350 K4 — Fon belgesi
A18: Fon 5 yıl içinde kullanılmalı. Amaç dışı kullanım → Vergi + gecikme zammı riski.

Sheet DENETCİ NOTLARI
A1: 350 – DİĞER İNDİRİMLER VE İSTİSNALAR | DENETÇİ NOTLARI
A2: 302–349 Dışı Tüm İstisna/İndirimler | SB | Teknokent | Ar-Ge | GS Fonu | 5/1-d Dağıtım Şartı | KOBİ Birleşme | GİB Rehberleri No:606,605
A3: Kod | B3: Konu | C3: Mesleki Değerlendirme | D3: Mevzuat
A4: N1 | B4: 350 Satırının Yapısı ve Ana Kurallar | C4: KV BEYANNAMESİ 350 'DİĞER' KAVRAMI: 302–349: Belirli istisnalara özgü satırlar. 350: Bu satırlara girmeyen TÜM istisna ve indirimlerin toplandığı catch-all satır. ANA KURAL — KALEM BAZINDA ŞEFFAFLIK: 350'ye yazılan her TL kanun/madde/fıkra bazında ayrıştırılmalıdır. GİB incelemesinde 350 kalemi tek tek açıklanmak zorunda kalınabilir. EN SIK YAPILAN HATALAR: ① Özel satırı olan istisnayı 350'ye yazmak (TGB Yönetici Şirket → 311, 350 değil) ② 350'ye toplu tutar yazıp kalem detayını belgede bırakmamak ③ 'Zarar Olsa Dahi' (Ar-Ge) ile 'Kazancın Bulunması Halinde' ayrımını karıştırmak ④ İstisna ve indirim sıralamasını yanlış yapmak BEYANNAME 350: = C tablosu K1+K2+...+K8 Toplamı (D39) Her dönem önceki dönemle karşılaştır — büyük fark → Not ekle. | D4: KVK Md.5,10 | 5746 s.K. | 3218 s.K. | 4691 s.K.
A5: N2 | B5: K1 Serbest Bölge + K2 Teknokent — Kritik Ayrımlar | C5: SERBEST BÖLGE (3218 s.K. Geçici Md.3): Yalnızca üretim lisansı olanlar → Üretim kazancı istisna. Alım-satım faaliyeti → Kapsam tartışmalı. Finansal gelirler (faiz, kur farkı) → Kesin kapsam dışı. Güncel yürürlük durumu kontrol edilmeli. TEKNOKENT GİRİŞİMCİ (4691 s.K. GVM Md.2): TGB içinde Ar-Ge, yazılım, tasarım yapan KİRACI firma → K2/350. TGB YÖNETİCİ ŞİRKET → 311 satırı (350 DEĞİL) — KARIŞTIRILMAMALI. İstisna belirli tarihe kadar — güncel kontrol zorunlu. YMM KULLANSIN: K1: '...3218 sayılı Kanun kapsamında [SB adı]’ndaki üretim faaliyetinden...' K2: '...4691 sayılı Kanun Geçici Madde 2 kapsamında TGB kiracısı sıfatıyla...' | D5: 3218 s.K. | 4691 s.K. | GİB Tebliğleri
A6: N3 | B6: K3 Ar-Ge İndirimi + K4 Girişim Sermayesi + Sıralama | C6: AR-GE VE TASARIM İNDİRİMİ (5746 s.K.): Ar-Ge Merkezi belgesi — Sanayi Bakanlığı onaylı — zorunlu. 'Zarar Olsa Dahi' — Matrahı aşan kısım sonraki yıllara devrede. Devreden tutar yıllık takip listesi — beyanname ekinde gösterilmeli. GİRİŞİM SERMAYESİ FONU: Sınır: Beyan edilen kazancın %10'u VE %20'yi aşamaz (ikisi birlikte). 549 fon hesabı — 5 yıl içinde kullanılmalı — amaç dışı kullanım → Vergi + ZZ riski. MATRAH HESABINDA DOĞRU SIRALAMA: Ticari Bilanço Kârı − KVK Md.5 İstisnaları (K1 SB, K2 TGB, K5 Okul/Hastane vb.) − KVK Md.10 İndirimleri (K3 Ar-Ge, K4 GS Fonu, K5 Bağış/Sponsorluk) = KV Matrahı (Kurumlar Vergisi Matrahı) YMM: '...beyan edilen kazancın %100'ü 5746 sayılı Kanun Md.3 kapsamında Ar-Ge indirimi olarak, toplam [XX] TL'si devreden indirim olarak beyan edilmiştir' | D6: 5746 s.K. | KVK Md.10 | 49 No.lu Tebliğ
A7: N4 | B7: ★ 5/1-d Dağıtım Şartı (1/1/2025+) + KOBİ Birleşme İndirimli Oran — GİB Rehberleri 2026 Güncellemeleri | C7: ★ KVK 5/1-d DAĞITIM ŞARTI (7524 s.K. Md.32 — 1/1/2025 tarihinden itibaren): GYO, GKO, GSYF ve SPK kapsamlı fon/ortaklıklar (emeklilik fonları HARİÇ), 5/1-d istisna kazançlarından yararlanabilmek için taşınmaz gelirlerinin en az %50'sini KV beyan ayını izleyen 2. ayın sonuna kadar kar payı olarak DAĞITMALIDIR. 350 SATIRI ÜZERINDEKI ETKİSİ: • Yatırım Ortaklığı/Fon Kazanç İstisnası (5/1-d) bir 350 kalemi olarak kullanılıyorsa: → Dağıtım şartı SAĞLANIYORSA: 5/1-d taşınmaz dışı kazancı 350'ye yazılabilir. → Dağıtım şartı SAĞLANAMIYORSA: Hem taşınmaz hem taşınmaz dışı istisna KALKAR — 350'ye hiçbir tutar yazılamaz. • 5/1-d dağıtım şartını sağlayan fon/ort.'dan alınan kâr payı → 5/1-a (301) istisnasına konu edilemez. Sağlayamayan fon/ort.'dan alınan → 5/1-a uygulanabilir. ★ KOBİ BİRLEŞME İNDİRİMLİ KV ORANI (KVK Md.32/f — KV Oran Rehberi 2026 — Yayın No:605): KOBİ niteliğindeki kurumların birleşmesinde birleşilen kuruma, üretim faaliyetinden elde edilen kazançlar üzerinden 5 yıl boyunca indirimli KV oranı uygulanmaktadır. YMM DİKKAT: Bu düzenleme 350 SATIRINDA DEĞİL — indirimli oran uygulaması olarak doğrudan vergi hesabında (KVK 32 kapsamında) değerlendirilir. İhracat/üretim indirimlerine benzer şekilde, matrah indirimi değil oran indirimi söz konusudur. | D7: 7524 s.K. Md.32 | KVK Md.5/1-d KV Beyan Rehberi Mart 2026 (No:606) KV Oran Rehberi Mart 2026 (No:605) KVK Md.32/f (KOBİ Birleşme)
A8: 350 SATIRI KAPANIŞ: YMM 350'yi tasdik ederken temel sorumluluk: (1) Her kalemin bağımsız yasal dayanağı var mı? (2) 302–349 özel satırlarında daha uygun satır yoktu mu? (3) KB Halinde/Zarar Olsa Dahi bölüm seçimi doğru mu? (4) Özelge gerektiren kalemler için özelge alındı mı? Şeffaflık = En iyi 350 tasdik savunması. YMM müteselsil sorumluluk: SM-SMMM-YMM Kanunu Md.12.

Sheet BELGE LISTESI
A1: 350 – DİĞER İNDİRİMLER VE İSTİSNALAR | BELGE LİSTESİ | YMM TASDİK
A2: Her 350 Kalemi İçin Ayrı Belge Paketi | Serbest Bölge / Teknokent / Ar-Ge / GS Fonu / Bağış | Kalem Bazında Şeffaflık | 49 No.lu Tebliğ
A4: KATEGORİ 1 — TEMEL ZORUNLU BELGELER
A5: Her kalem için (1) Yasal Dayanak Belgesi + (2) Kazanç/Harcama Hesabı + (3) Destekleyici Belge
B6: No | C6: Belge | D6: Detay | E6: Temin
B7: 1 | C7: ★ C Tablosu — Dönem 350 Kalem Envanteri | D7: VERİ GİRİŞİ C tablosu: Tüm kalemler yasal dayanak, tutar, bölüm ve YMM durumu ile eksiksiz doldurulmuş. YMM tasdik dosyasının 350 bölümü omurgası. | E7: VERİ GİRİŞİ C bölümü çıktısı
B8: 2 | C8: K1 Serbest Bölge — Faaliyet Lisansı + Kazanç Ayrıştırma | D8: 3218 s.K. kapsamında SB faaliyet lisansı. Kapsam içi (üretim) ve kapsam dışı (finansal gelir) kazanç ayrıştırma tablosu. | E8: SB Bölge Müdürlüğü + Bakanlık
B9: 3 | C9: K2 Teknokent Girişimci — TGB Kiracı Belgesi | D9: 4691 s.K. kapsamında TGB kiracısı olduğunu gösteren kira sözleşmesi/yerleşim belgesi. TGB'deki yazılım/Ar-Ge kazancı ayrıştırma tablosu. | E9: TGB Yönetici Şirketi belgesi
B10: 4 | C10: K3 Ar-Ge İndirimi — Ar-Ge Merkezi Belgesi + Devreden Takibi | D10: Sanayi Bakanlığı onaylı Ar-Ge Merkezi belgesi. Dönem Ar-Ge harcamaları listesi + Devreden Ar-Ge indirimi yıllık takip tablosu. | E10: Ar-Ge Merkezi Belgesi + Muhasebe ekstresi
B11: 5 | C11: K4 Girişim Sermayesi Fonu — Fon Belgesi + Sınır Hesabı | D11: Girişim sermayesi yatırım fonu/ortaklık belgesi (SPK kayıtlı). Sınır hesabı: %10 ve %20 kontrol. 549 fon hesabı açılışı. | E11: SPK kaydı + 549 hesap ekstresi
B12: 6 | C12: K5 Bağış/Sponsorluk — Sözleşme + Makbuz + Oran Sınırı | D12: Sözleşme/Makbuz/Banka dekontu. KVK Md.10 oran sınırı hesabı (%5 veya %10). | E12: Sözleşme + Makbuz
B13: 7 | C13: KV Beyannamesi Taslağı — 350. Satır | D13: 350 = C tablosu D39 ile uyumlu. Doğru bölüm seçimi kontrolü. | E13: GİB e-Beyanname sistemi
A15: KATEGORİ 2 — EK BELGELER
B16: No | C16: Belge | D16: Detay | E16: Temin
B17: 8 | C17: GİB Özelgesi (Tartışmalı Kalemler İçin) | D17: Az emsal, yeni veya tartışmalı özel kanun kalemleri için GİB özelgesi. Özellikle serbest bölge, yeni teknokent ve özel haller. | E17: GİB özelge başvuru sistemi
B18: 9 | C18: Önceki Dönem Beyanname ve Devreden İndirimler | D18: Ar-Ge devreden tutarı önceki dönem beyanname ekinden gelmeli. Önceki dönem 350 tutarı karşılaştırma referansı. | E18: Önceki dönem KV Beyannamesi
A20: KATEGORİ 3 — YMM TASDİK KONTROL SORULARI
B21: No | C21: Kontrol Sorusu | D21: Beklenen Sonuç | E21: YMM Aksiyonu
B22: S1 | C22: ★ 302–349 özel satırlarında daha uygun satır olmadığı teyit edildi mi? | D22: Özel satır varsa 350 kullanılmaz. | E22: YMM kontrolü
B23: S2 | C23: ★ Her kalem için ayrı yasal dayanak belgesi mevcut mu? | D23: Toplu tutar kabul edilemez. | E23: YMM kontrolü
B24: S3 | C24: ★ Her kalemin beyanname bölümü doğru mu? | D24: KB Halinde / Zarar Olsa Dahi ayrımı. | E24: YMM kontrolü
B25: S4 | C25: Serbest bölge finansal gelirler ayrıştırıldı mı? | D25: Faiz, kur farkı → Kapsam dışı. | E25: YMM kontrolü
B26: S5 | C26: Teknokent girişimci ile 311 Yönetici Şirket karıştırılmadı mı? | D26: Kiracı → K2/350. Yönetici → 311. | E26: YMM kontrolü
B27: S6 | C27: Ar-Ge indirimi Ar-Ge Merkezi belgesiyle desteklendi mi? | D27: Devreden yıllık takip belgesi. | E27: YMM kontrolü
B28: S7 | C28: GS Fonu sınırı (%10 ve %20) aşılmadı mı? | D28: KVK Md.10/1-g sınır kontrolü. | E28: YMM kontrolü
B29: S8 | C29: 350 toplamı C tablosu D39 ile uyumlu mu? | D29: D39 = Beyanname 350. | E29: YMM kontrolü
B30: S9 | C30: Matrah sıralaması (istisna → indirim) doğru mu? | D30: KVK 5 sonrası KVK 10. | E30: YMM kontrolü
B31: S10 | C31: YMM Tasdik Raporu (49 No.lu Tebliğ) değerlendirildi mi? | D31: >=500.000 TL → YMM raporu. | E31: YMM kontrolü
A33: SON NOT: 49 No.lu Tebliğ: >=500.000 TL → YMM raporu. Tam tasdik → ayrıca rapor yok. 350'nin setin diğer dosyalarından özgün yeri: Catch-all satır — tek bir istisnayı değil, 302–349 dışındaki TÜM istisna ve indirimlerin havuzunu kapsar. YMM sorumluluğu: Her kalem kendi yasal dayanağıyla, bağımsız belgelenmiş, doğru bölümde, özelge gerektirenlerde özelge alınmış olmalıdır. Şeffaflık = En iyi 350 tasdik savunması. YMM müteselsil sorumluluk: SM-SMMM-YMM Kanunu Md.12.
