Workbook

Sheet VERİ GİRİŞİ
A1: 370 – KVK GEÇİCİ MADDE 14/1-a | DEĞERLEMEDen DOĞAN KUR FARKI KAZANCI İSTİSNASI | KUR KORUMALI MEVDUAT (KKM) | YMM TASDİK ÇALIŞMA KÂĞIDI
A2: KVK Geçici Md.14/1-a | 31/12/2021 Bilanço Yabancı Para → TL KKM Dönüşümü | Dönüşüm Anındaki Kur Farkı Kazancı İstisnası | Beyanname 370 | ★ YİAKV MATRAHINDA DÜŞÜLEMEZ | GİB KV Beyan Rehberi Mart 2026 (No:606)
A3: ★★ YİAKV (KVK Md.32/C) KRİTİK: 370 kapsamındaki değerleme kazancı istisnası YİAKV matrahından DÜŞÜLEMEZ — asgari vergide matrahta kalır. (KV Beyan Rehberi 2026 No:606 | YİAKV Reh. No:607 Bölüm 3.3 | E.7 DÜŞÜLEMEZ listesi)
A5: A0. KAPSAM VE NİTELİK UYGUNLUK ÖN KONTROLÜ
B6: Kontrol Sorusu | E6: Yanıt | G6: YMM Tasdik Notu
A7: A0.1 Kurumun 31/12/2021 tarihli bilançosunda yabancı para (döviz tevdiat hesabı dahil) bakiyesi var mıydı? | E7: EVET | F7: KVK Geçici Md.14 kapsamı YALNIZCA 31/12/2021 bilanço yabancı para bakiyelerini kapsar. Sonradan edinilen yabancı paralar kapsam dışı.
A8: A0.2 ★ Bu yabancı paralar yasal süre içinde TL mevduat/katılım hesabına (KKM) dönüştürüldü mü? | E8: EVET | F8: Orijinal süre: 17/2/2022 – 31/3/2022. Cumhurbaşkanı kararlarıyla uzatıldı. Güncel dönüşüm son tarihi kontrol edilmeli. B bölümünde tarih doğrulaması zorunlu.
A9: A0.3 Dönüşüm esnasında kur farkı (değerleme) kazancı oluştu mu? | E9: EVET | F9: Bilanço tarihindeki kur ile dönüşüm günü kuru arasında pozitif fark varsa kazanç oluşur. Negatif fark olursa (TL değer kaybı döneminde) 370 tutarı sıfır olabilir.
A10: A0.4 KKM hesabının TL cinsinden açıldığı ve korumalı (garantili) olduğu teyit edildi mi? | E10: EVET | F10: Sadece TL mevduat veya TL katılım hesabı (KKM) kapsamda. Döviz korumalı hesap farklıdır — Geçici Md.14 koşullarına uygunluk bankadan teyit alınmalıdır.
A11: A0.5 370 (değerleme kazancı) ile 371 (faiz/kâr payı) doğru ayrıştırıldı mı? | E11: EVET | F11: 370: Dönüşüm anındaki tek seferlik kur farkı kazancı (değerleme). 371: KKM hesabından elde edilen faiz ve kâr payı geliri. Her ikisi de ayrı beyanname satırı — karıştırılmamalı. 371 için ayrı çalışma kâğıdı düzenleyin.
A12: A0.6 ★ 370 tutarının YİAKV matrahından DÜŞÜLMEDIĞI teyit edildi mi? | E12: EVET | F12: KVK Geçici Md.14 kapsamı kazançlar YİAKV matrahından DÜŞÜLEMEZ (E.7). Hatalı uygulama → YİAKV tarhiyatı + vergi ziyaı cezası + gecikme faizi. YİAKV çalışma kâğıdında da çift kontrol yapılmalıdır.
A13: A0.7 Dönüşüm tarihi ve tutarı banka belgesiyle teyit edildi mi? | E13: EVET | F13: Döviz dönüşüm dekontu + KKM hesap açılış belgesi zorunludur. Banka tarafından düzenlenen resmi belge olmadan istisna savunulamaz.
A14: A0.8 YMM Tasdik Raporu gereksinimi değerlendirildi mi? (49 No.lu Tebliğ) | E14: EVET | F14: >=500.000 TL → YMM raporu. KV beyannamesi ile birlikte veya 2 ay içinde elektronik. Tam tasdik sözleşmesi olanlar ayrıca rapor düzenlemez.
A15: A0.9 Tasdik Uygunluk Sonucu | E15: =IF(AND(E7="EVET",E8="EVET",E9="EVET",E12="EVET"),"OK - Hesaplanabilir","HATA - Ön koşul eksik") -> OK - Hesaplanabilir | F15: ★ A0.2 (dönüşüm tarihi), A0.6 (YİAKV düşülemez) kritik.
A17: A. GENEL BİLGİLER
A18: Kurumun Unvanı | F18: Tam ticaret unvanı — beyannamedeki ile aynı
A19: VKN | F19: 10 haneli VKN
A20: Hesap Dönemi | F20: Örn: 01.01.2025 – 31.12.2025
A21: KV Oranı (%) | F21: 2025: %25 | Banka/Finans: %30 | YİD/KÖİ: %30
A22: Dosya Referansı | F22: YMM-2025/370-01
A23: Bankacıyla İletişim Kişisi | F23: KKM koşulları için banka yetkilisi adı/iletişim
A25: B. DÖNÜŞÜM KOŞULLARI VE YASAL DAYANAĞA UYGUNLUK KONTROLÜ (KVK Geçici Md.14/1-a)
A26: Dönüşüm tarihinin Cumhurbaşkanı kararlarıyla belirlenen yasal süre içinde olduğu teyit edilmelidir. 31/12/2021 bilanço bakiyesini aşan dönüşümler kapsam dışıdır.
B27: Parametre | D27: Değer / Tarih | F27: Açıklama | G27: Yasal Dayanak
A28: B.1 31/12/2021 Bilançosundaki Toplam Yabancı Para Bakiyesi (TL karşılığı) | D28: 31/12/2021 TCMB kapanış kuru × Döviz miktarı. Bilanço ile mutabık olmalı. | F28: Bilanço
A29: B.2 Dönüşüme Konu Edilen Yabancı Para Miktarı (Döviz cinsinden, toplam) | D29: 31/12/2021 bakiyesini aşamaz. Aşan kısım kapsam dışı. | F29: Banka dekontu
A30: B.3 ★ Dönüşüm Tarihi (TL KKM hesabına geçiş tarihi) | D30: Yasal süre içinde olduğu banka belgesiyle kanıtlanmalıdır. | F30: Banka dekontu
A31: B.4 Dönüşüm Günü TCMB Döviz Alış Kuru (C. tablosunda her döviz için ayrı girilecek) | D31: TCMB resmi kuru — dönüşüm günü itibarıyla (tcmb.gov.tr) | F31: TCMB kur tablosu
A32: B.5 KKM Hesap Türü | C32: TL Mevduat (KKM) | D32: Yalnızca TL KKM (mevduat veya katılım) kapsamda. Döviz hesabı kapsamda değil. | F32: Banka belgesi
A33: B.6 KKM Hesap Vade Tarihi | D33: Hesap vadesi — 371 faiz hesabı için de referans | F33: Banka hesap cüzdanı
A34: B.7 Dönüşüm 31/12/2021 Bilançosu Bakiyesi İle Sınırlı mı? | C34: EVET | D34: Dönüşüm tutarı 31/12/2021 bakiyesini aşamaz. B.2 ≤ Bilanço bakiyesi. | F34: KVK Geç.Md.14/1
A36: C. PARA BİRİMİ BAZINDA DÖNÜŞÜM VE DEĞERLEME KAZANCI HESABI
A37: Her yabancı para birimi için ayrı satır doldurun. Değerleme Kazancı = (Dönüşüm Günü Kuru × Döviz Miktarı) − (31/12/2021 Kuru × Döviz Miktarı). Bilanço kuru: 31/12/2021 TCMB döviz alış kuru. Negatif fark → o döviz için 370 kazancı yok (0).
A38: Döviz | B38: 31/12/2021 Bakiye (Döviz) | C38: 31/12/2021 TCMB Kuru | D38: Bilanço TL Değeri | E38: Dönüşüm Günü Kuru | F38: Dönüşüm TL Tutarı | G38: Değerleme Kazancı (TL)
A39: USD | D39: =IF(B39>0,B39*C39,0) -> 0 | F39: =IF(B39>0,B39*E39,0) -> 0 | G39: =MAX(F39-D39,0) -> 0
A40: EUR | D40: =IF(B40>0,B40*C40,0) -> 0 | F40: =IF(B40>0,B40*E40,0) -> 0 | G40: =MAX(F40-D40,0) -> 0
A41: GBP | D41: =IF(B41>0,B41*C41,0) -> 0 | F41: =IF(B41>0,B41*E41,0) -> 0 | G41: =MAX(F41-D41,0) -> 0
A42: CHF | D42: =IF(B42>0,B42*C42,0) -> 0 | F42: =IF(B42>0,B42*E42,0) -> 0 | G42: =MAX(F42-D42,0) -> 0
A43: Diğer Döviz | D43: =IF(B43>0,B43*C43,0) -> 0 | F43: =IF(B43>0,B43*E43,0) -> 0 | G43: =MAX(F43-D43,0) -> 0
A44: TOPLAM | B44: Toplam Değerleme Kazancı (Tüm Dövizler) | F44: =SUM(F39:F43) -> 0 | G44: =SUM(G39:G43) -> 0
...

Sheet HESAPLAMALAR & KONTROL
A1: 370 – KVK GEÇİCİ MD.14/1-a DEĞERLEMEden DOĞAN KAZANÇ | HESAPLAMALAR VE DENETİM
A2: KVK Geçici Md.14/1-a | KKM Dönüşüm Kur Farkı Kazancı | Beyanname 370 | YİAKV MATRAHINDA DÜŞÜLEMEZ
A4: A. TASDİK ÖZETİ — VERİ GİRİŞİNDEN OTOMATİK
A5: A0 Tasdik Uygunluğu | D5: ='VERİ GİRİŞİ'!E15 -> OK - Hesaplanabilir | E5: OK ise devam
A6: KKM Hesap Türü (B.5) | D6: ='VERİ GİRİŞİ'!C32 -> TL Mevduat (KKM) | E6: TL Mevduat/Katılım
A7: Dönüşüm Süresi Uygunluğu (B.7) | D7: ='VERİ GİRİŞİ'!C34 -> EVET | E7: EVET = Uygun
A8: Toplam Brüt Kazanç (D.3) | D8: ='VERİ GİRİŞİ'!C52 -> 0 | E8: Değerleme kazancı toplamı
A9: Kapsam Dışı Ayrıştırma (D.4) | D9: ='VERİ GİRİŞİ'!C53 -> 0 | E9: Varsa orantılı ayrıştırma
A10: 370 İSTİSNA TUTARI (D.5) | D10: ='VERİ GİRİŞİ'!C54 -> 0
A11: ★ YİAKV'de DÜŞÜLEMEZ | D11: Evet — E.7 kapsamında | E11: Her zaman DÜŞÜLEMEZ
A13: B. PARA BİRİMİ BAZINDA DEĞERLEME KAZANCI ÖZET (VERİ GİRİŞİ C Tablosundan)
A14: Döviz | B14: 31/12/2021 Bakiye (Döviz) | C14: 31/12/2021 Kuru (TL) | D14: Bilanço TL | E14: Dönüşüm Kuru (TL) | F14: Dönüşüm TL | G14: Değerleme Kazancı (TL)
A15: USD | B15: ='VERİ GİRİŞİ'!B39 -> 0 | C15: ='VERİ GİRİŞİ'!C39 -> 0 | D15: ='VERİ GİRİŞİ'!D39 -> 0 | E15: ='VERİ GİRİŞİ'!E39 -> 0 | F15: ='VERİ GİRİŞİ'!F39 -> 0 | G15: ='VERİ GİRİŞİ'!G39 -> 0
A16: EUR | B16: ='VERİ GİRİŞİ'!B40 -> 0 | C16: ='VERİ GİRİŞİ'!C40 -> 0 | D16: ='VERİ GİRİŞİ'!D40 -> 0 | E16: ='VERİ GİRİŞİ'!E40 -> 0 | F16: ='VERİ GİRİŞİ'!F40 -> 0 | G16: ='VERİ GİRİŞİ'!G40 -> 0
A17: GBP | B17: ='VERİ GİRİŞİ'!B41 -> 0 | C17: ='VERİ GİRİŞİ'!C41 -> 0 | D17: ='VERİ GİRİŞİ'!D41 -> 0 | E17: ='VERİ GİRİŞİ'!E41 -> 0 | F17: ='VERİ GİRİŞİ'!F41 -> 0 | G17: ='VERİ GİRİŞİ'!G41 -> 0
A18: CHF | B18: ='VERİ GİRİŞİ'!B42 -> 0 | C18: ='VERİ GİRİŞİ'!C42 -> 0 | D18: ='VERİ GİRİŞİ'!D42 -> 0 | E18: ='VERİ GİRİŞİ'!E42 -> 0 | F18: ='VERİ GİRİŞİ'!F42 -> 0 | G18: ='VERİ GİRİŞİ'!G42 -> 0
A19: Diğer | B19: ='VERİ GİRİŞİ'!B43 -> 0 | C19: ='VERİ GİRİŞİ'!C43 -> 0 | D19: ='VERİ GİRİŞİ'!D43 -> 0 | E19: ='VERİ GİRİŞİ'!E43 -> 0 | F19: ='VERİ GİRİŞİ'!F43 -> 0 | G19: ='VERİ GİRİŞİ'!G43 -> 0
A20: TOPLAM | B20: Toplam Değerleme Kazancı → Beyanname 370 | F20: ='VERİ GİRİŞİ'!G44 -> 0 | G20: ='VERİ GİRİŞİ'!C54 -> 0
A22: C. DENETİM KONTROL LİSTESİ (K1–K12) — KVK GEÇİCİ MD.14/1-a
B23: Kontrol | D23: Açıklama / Yasal Dayanak | F23: Sonuç
A24: K1 | B24: ★ Dönüşüme konu yabancı para 31/12/2021 bilançosunda mevcut muydu? | D24: Bilanço yabancı para hesabı (döviz tevdiat dahil) teyit edilmeli. Sonradan edinilen döviz kapsam dışı. | F24: Uygun/Eksik/Risk
A25: K2 | B25: ★ Dönüşüm tarihi yasal süre içinde mi? (CB Kararlarıyla uzatılan son tarih kontrol edildi mi?) | D25: Orijinal: 17/2/2022 – 31/3/2022. Cumhurbaşkanı kararlarıyla uzatıldı. Güncel son tarih banka belgesiyle teyit. | F25: Uygun/Eksik/Risk
A26: K3 | B26: Dönüşüm tutarı 31/12/2021 bilançosu bakiyesini aşmıyor mu? | D26: Aşan kısım kapsam dışı — kapsam içi kısım orantılı hesaplanır. B.2 ≤ B.1 kontrol. | F26: Uygun/Eksik/Risk
A27: K4 | B27: ★ 31/12/2021 TCMB döviz kurları resmi kaynaktan alındı mı? | D27: TCMB resmi kapanış kuru (alış kuru). Bilanço değerlemesiyle uyumlu olmalı. tcmb.gov.tr. | F27: Uygun/Eksik/Risk
A28: K5 | B28: Dönüşüm günü TCMB döviz kurları resmi kaynaktan alındı mı? | D28: Dönüşüm tarihi TCMB resmi kuru. Banka dekontu ile çapraz kontrol edilmeli. | F28: Uygun/Eksik/Risk
A29: K6 | B29: Değerleme kazancı (D.3) muhasebe kayıtlarıyla mutabık mı? | D29: 680/679 hesabındaki kur farkı geliri ile C tablosu toplamı uyumlu olmalı. | F29: Uygun/Eksik/Risk
A30: K7 | B30: ★ 370 ve 371 (faiz/kâr payı) doğru ayrıştırıldı mı? | D30: 370: Dönüşüm anındaki tek seferlik kur farkı. 371: KKM hesabından süregelen faiz/kâr payı. Her ikisi ayrı satır. | F30: Uygun/Eksik/Risk
A31: K8 | B31: ★★ 370 istisnası YİAKV matrahından DÜŞÜLMEDI mi? | D31: KVK Geçici Md.14 kazançları YİAKV matrahından DÜŞÜLEMEZ (E.7). YİAKV çalışma kâğıdında E.7 satırında bu tutar DÜŞÜLEMEZ listesinde yer almalıdır. EN KRİTİK KONTROL. | F31: Uygun/Eksik/Risk
A32: K9 | B32: Beyanname 370 tutarı D.5 ile uyumlu mu? 'Kazancın Bulunması Halinde' bölümünde mi? | D32: 370 → Kazancın Bulunması Halinde İndirilecek. Zarar döneminde uygulanamaz. | F32: Uygun/Eksik/Risk
A33: K10 | B33: KKM hesap belgesi (banka dekontu + hesap açılış belgesi) dosyada mevcut mu? | D33: Döviz dönüşüm dekontu + KKM hesap açılışı — her ikisi zorunlu. Banka teyidi gerekebilir. | F33: Uygun/Eksik/Risk
A34: K11 | B34: Kapsam dışı kazanç (D.4) varsa orantılı ayrıştırma yapıldı mı? | D34: 31/12/2021 bakiyesini aşan dönüşüm tutarı kapsam dışı ve vergiye tabidir. | F34: Uygun/Eksik/Risk
A35: K12 | B35: YMM Tasdik Raporu (49 No.lu Tebliğ) değerlendirildi mi? | D35: >=500.000 TL → YMM raporu. KV beyannamesi ile birlikte veya 2 ay içinde elektronik gönderim. | F35: Uygun/Eksik/Risk

Sheet MUHASEBE KAYITLARI
A1: 370 – KVK GEÇİCİ MD.14/1-a DEĞERLEMEden DOĞAN KAZANÇ | MUHASEBE KAYITLARI
A2: KKM Dönüşüm Günü | Kur Farkı Değerleme Kaydı | İstisna Kaydı | YİAKV Uyarısı
A3: NOT: Aşağıdaki kayıtlar örnek niteliğindedir. Muhasebe politikasına ve kurlara göre uyarlanmalıdır.
A4: KAYIT 1 — DÖNÜŞÜM GÜNÜ: YABANCI PARA ÇIKIŞI VE TL KKM AÇILIŞI
B5: Tarih | C5: Hesap | D5: Not | E5: Dr | F5: Kr | G5: Ref
A6: Dr | B6: [Dönüşüm Tarihi] | C6: 108 Diğer Hazır Değerler / KKM Hesabı | D6: TL KKM hesabına dönüştürülen tutar (Dönüşüm günü kuru × Döviz miktarı) | E6: [Dönüşüm TL] | F6: — | G6: Banka dekontu
A7: Kr | B7: [Dönüşüm Tarihi] | C7: 100/102 Kasa veya 121 Döviz Hesabı | D7: Yabancı para çıkışı (bilanço değeri üzerinden) | E7: — | F7: [Bilanço TL] | G7: Döviz hesap kartı
A8: Kr | B8: [Dönüşüm Tarihi] | C8: 646 Kambiyo Kârları / 679 Diğer Olağandışı Kâr | D8: Dönüşüm anındaki kur farkı kazancı — KVK Geçici Md.14/1-a kapsamı → Beyanname 370 | E8: — | F8: [Kur Farkı] | G8: KV 370
A9: KUR FARKI = (Dönüşüm Günü Kuru − 31/12/2021 Kuru) × Döviz Miktarı. Bu fark 646/679 hesabına kaydedilir. Dönüşüm günü kuruna göre değerleme yapılmaktadır.
A10: KAYIT 2 — BEYANNAME DÖNEMİ: KUR FARKI KAZANCININ İSTİSNA OLARAK GÖSTERİLMESİ
A11: Muhasebe kaydı yapılmaz. KV Beyannamesinde 370 satırına istisna tutarı yazılır. Kaydı açıklayan not aşağıdadır.
A12: BEYANNAME AKIŞI — KVK GEÇİCİ MD.14/1-a: 1. Dönüşüm günü 646/679 hesabına kaydedilen kur farkı kazancı → Ticari kârda yer alır. 2. KV Beyannamesi 370. Satır: 'Kazancın Bulunması Halinde İndirilecek' bölümü → İstisna tutarı (D.5) buraya yazılır. 3. Genel KV matrahı: Ticari kâr + KKEG − (370 dahil izin verilen istisnalar). 4. ★★ YİAKV MATRAHI: 370 tutarı buradan ÇIKARILMAZ — asgari vergi matrahında kalır. YİAKV çalışma kâğıdı E.7 satırında: 'KKM Değerleme Kazancı (KVK Geçici Md.14) → DÜŞÜLEMEZ ✗'
A13: KAYIT 3 — 370 DEĞERLEME KAZANCI vs 371 FAİZ/KÂR PAYI AYRIMI
B14: Tarih | C14: Hesap | D14: Not | E14: Dr | F14: Kr | G14: Ref
A15: 370 | B15: [Dönüşüm Tarihi] | C15: 646/679 — KUR FARKI KAZANCI | D15: Dönüşüm anında bir kez oluşan kur farkı → Beyanname 370 (Geçici Md.14/1-a) | E15: — | F15: [Tutar] | G15: KV 370
A16: 371 | B16: [Faiz Tarihi] | C16: 642 Faiz Gelirleri / 644 Temettü ve Kâr Payları | D16: KKM hesabından dönem içinde tahakkuk eden faiz/kâr payı → Beyanname 371 (Geçici Md.14/1-b) | E16: — | F16: [Tutar] | G16: KV 371
A17: 370 genellikle TEK SEFERLİK dönüşüm yılında oluşur. 371 KKM hesabı yaşadığı sürece her dönem devam eder. Her ikisi de YİAKV matrahından DÜŞÜLEMEZ. Ayrı çalışma kâğıtları düzenlenmelidir.

Sheet DENETCİ NOTLARI
A1: 370 – KVK GEÇİCİ MD.14/1-a DEĞERLEMEden DOĞAN KAZANÇ | DENETÇİ NOTLARI
A2: GİB KV Beyan Rehberi Mart 2026 (Yayın No:606) | KVK Geçici Md.14 | 7352 s.K. | ★★ YİAKV MATRAHINDA DÜŞÜLEMEZ (E.7)
A3: Kod | B3: Konu | C3: Mesleki Değerlendirme / Tasdik Standardı | D3: Mevzuat / Kaynak
A4: N1 | B4: KVK Geçici Md.14/1-a — Yasal Çerçeve ve Güncel Durum (GİB No:606 Bölüm 2.2.15) | C4: KVK GEÇİCİ MADDE 14/1-a TANIMI: Kurumların 31/12/2021 tarihli bilançolarında yer alan yabancı paralarını, Cumhurbaşkanı Kararıyla belirlenen süre içinde TL mevduat veya TL katılım hesabına (Kur Korumalı Mevduat — KKM) dönüştürmeleri halinde, bu dönüşüm esnasında oluşan kur farkı kazancı (değerleme farkı) kurumlar vergisinden istisna edilmiştir. TEMEL KOŞULLAR: ① 31/12/2021 bilanço bakiyesi şartı: Yalnızca bu tarihteki yabancı para bakiyesi kapsam dahili. ② TL KKM hesabı: Yalnızca TL mevduat veya TL katılım hesabına dönüşüm. ③ Dönüşüm süresi: Cumhurbaşkanı Kararıyla belirlenen son tarih içinde. ④ Değerleme kazancı: Bilanço kuru ile dönüşüm günü kuru arasındaki pozitif fark. BEYANNAME: 370 | Kazancın Bulunması Halinde İndirilecek GİB KV Beyan Rehberi 2026 (Yayın No:606), Bölüm 2.2.15 kapsamında yer almaktadır. | D4: KVK Geçici Md.14/1-a | 7352 s.K. Md.8 | GİB KV Beyan Reh. 2026 (No:606)
A5: N2 | B5: ★ Değerleme Kazancı Hesaplama Yöntemi ve Teknik Detaylar | C5: DEĞERLEME KAZANCI HESABI: Her yabancı para birimi için ayrı ayrı hesaplanır: Değerleme Kazancı = (Dönüşüm Günü TCMB Kuru × Döviz Miktarı) − (31/12/2021 TCMB Kuru × Döviz Miktarı) TCMB KURU: Her iki tarih için de TCMB resmi döviz alış kuru esas alınır. KAPSAM SINIRI: Dönüşüm tutarı 31/12/2021 bilanço bakiyesini aşamaz. Aşan kısım kapsam dışıdır ve vergi matrahında kalır. Bu durumda orantılı hesaplama yapılır: İstisna Oranı = 31/12/2021 Bakiyesi / Toplam Dönüşüm Tutarı POZİTİF FAZ KOŞULU: Dönüşüm günü kuru 31/12/2021 kurundan düşükse (TL değer kazanmış dönem), değerleme kazancı negatif olabilir. Bu durumda 370 tutarı sıfırdır — istisna oluşmaz. MUHASEBE: 646 Kambiyo Kârları veya 679 hesabında izlenir. Ticari kâra dahildir. Beyannamede 370 satırıyla istisna olarak indirilir. | D5: KVK Geçici Md.14/1-a | TCMB Kur Tablosu | VUK Md.280
A6: N3 | B6: ★★ YİAKV ile İlişki — EN KRİTİK YMM KONTROL NOKTASI | C6: KVK GEÇİCİ MD.14 KAZANÇLARI YİAKV MATRAHINDA DÜŞÜLEMEZ: KVK Md.32/C (YİAKV) kapsamında asgari kurumlar vergisi hesaplamasında, KVK Geçici Md.14 kapsamındaki değerleme kazancı istisnası MATRAHTAN DÜŞÜLEMEZ. BEYANNAME AKIŞI: ① Ticari bilanço kârı + KKEG = YİAKV kazanç tabanı ② 370 tutarı bu tabanı AZALTMAZ — matrahta kalır ③ YİAKV × %10 = Ham asgari vergi ④ Genel KV ve YİAKV karşılaştırılır — büyük olan ödenir YİAKV ÇALIŞMA KÂĞIDI KONTROLÜ: E.7 satırı: 'KKM Değerleme + Faiz/Kâr Payı İstisnası (KVK Geçici Md.14) → YİAKV'de DÜŞÜLEMEZ ✗ | Beyanname 370/371' SIKLIKLA YAPILAN HATA: 370 tutarını YİAKV matrahından düşmek → Asgari vergi eksik hesaplanır → Tarhiyat + vergi ziyaı cezası + gecikme faizi riski. YMM müteselsil sorumluluğu kapsamındadır. | D6: KVK Md.32/C | YİAKV Rehberi (No:607) Bölüm 3.3 | GİB KV Beyan Reh. (No:606)
A7: N4 | B7: 370 (Değerleme Kazancı) ile 371 (Faiz/Kâr Payı) Ayrımı ve Birlikte Kullanım | C7: KVK GEÇİCİ MD.14 İKİ AYRI İSTİSNA: 370 — DEĞERLEMEden DOĞAN KAZANCbeyanname (Geçici Md.14/1-a): • OLUŞMA ZAMANI: Yalnızca dönüşüm anında, tek seferlik. • TUTAR: Bilanço kuru ile dönüşüm günü kuru arasındaki pozitif fark. • SONRAKI DÖNEMLER: 370 tutarı artık sıfırdır (hesap değerleme kürü değişmez). • MUHASEBE HESABI: 646 Kambiyo Kârları / 679 Diğer Olağandışı Kâr. 371 — FAİZ VE KÂR PAYI İSTİSNASI (Geçici Md.14/1-b): • OLUŞMA ZAMANI: KKM hesabı yaşadığı sürece her dönem süregelen gelir. • TUTAR: KKM hesabından tahakkuk eden faiz ve kâr payı. • SONRAKI DÖNEMLER: Hesap aktif olduğu sürece devam eder. • MUHASEBE HESABI: 642 Faiz Gelirleri / 644 Temettü ve Kâr Payları. HER İKİSİ DE YİAKV MATRAHINDA DÜŞÜLEMEZ. Ayrı çalışma kâğıtları (370 ve 371). | D7: KVK Geçici Md.14/1-a (Beyanname 370) | KVK Geçici Md.14/1-b (Beyanname 371)
A8: N5 | B8: 49 No.lu Tebliğ + YMM Tasdik Dil Standardı | C8: 49 No.lu Tebliğ: >=500.000 TL → YMM raporu. KV beyannamesi ile birlikte veya 2 ay içinde elektronik. KULLANIN: '...31/12/2021 tarihli bilançoda kayıtlı [Döviz Miktarı] ABD Doları'nın [Tarih] tarihinde TL kur korumalı mevduat hesabına dönüştürülmesi sonucunda KVK Geçici Madde 14/1-a kapsamında oluşan [Tutar] TL tutarındaki değerleme kazancı kurumlar vergisinden istisna edilmiştir. Söz konusu tutar beyanname 370. satırında gösterilmiş olup yurt içi asgari kurumlar vergisi matrahından indirilmemiştir.' KULLANMAYIN: '...370 tutarı YİAKV matrahından düşülmüştür.' (YANLIŞ — YİAKV matrahında kalır) '...31/12/2021 sonrası edinilen dövizler de 370 kapsamında istisnaya tabidir.' (Kapsam dışı) '...dönüşüm tutarı bilanço bakiyesini aştığından tamamına istisna uygulanmıştır.' (Hatalı) KRİTİK RİSK ALANLARI: (1) 370 tutarını YİAKV matrahından düşmek → EN SIK YAPILAN HATA. (2) 31/12/2021 sonrası edinilen dövizlerin dönüşümünü kapsama dahil etmek. (3) 370 ve 371'i aynı satıra yazmak veya karıştırmak. (4) Dönüşüm tarihinin yasal süre dışında olmasını gözden kaçırmak. | D8: 49 No.lu Tebliğ | KVK Geçici Md.14 | SM-SMMM-YMM K. Md.12
A9: GİB KV BEYAN REHBERİ MART 2026 (YAYIN NO:606) — BÖLÜM 2.2.15 KAPANIŞ: KVK Geçici Md.14 kapsamındaki istisnalar 2025 KV beyannamesi için günceldir. En kritik kontrol: 370 ve 371 tutarlarının YİAKV matrahından düşülmemesi. Bu hata vergi ziyaı cezası ve gecikme faiziyle sonuçlanır. YMM müteselsil sorumluluk: SM-SMMM-YMM Kanunu Md.12.

Sheet BELGE LISTESI
A1: 370 – KVK GEÇİCİ MD.14/1-a DEĞERLEMEden DOĞAN KAZANÇ | BELGE LİSTESİ | YMM TASDİK
A2: GİB KV Beyan Rehberi Mart 2026 (No:606) | KKM Dönüşüm | TCMB Kur | Banka Belgesi | 49 No.lu Tebliğ
A4: KATEGORİ 1 — ZORUNLU BELGELER (Tamamı Olmadan Tasdik Tamamlanmaz)
B5: No | C5: Belge / Bilgi | D5: Açıklama / YMM Kontrol | E5: Temin Yeri
B6: 1 | C6: ★ 31/12/2021 Bilançosu (Kesinleşmiş) — Yabancı Para Bakiyeleri | D6: 31/12/2021 tarihli bilanço — yabancı para hesapları (döviz tevdiat + kasa) açık bakiyeleri. YMM: Dönüşüm tutarı bu bakiyeleri aşmamalı. Aşma varsa orantılı ayrıştırma zorunlu. | E6: Kesinleşmiş Bilanço / Mizan
B7: 2 | C7: ★ Döviz Dönüşüm Dekontu — Dönüşüm Günü Banka Belgesi | D7: KKM hesabına dönüşümün gerçekleştiğini gösteren resmi banka dekontu. Dönüşüm tarihi, döviz miktarı, TL karşılığı ve uygulanan kur açıkça görünmeli. YMM: Dönüşüm tarihinin yasal süre içinde olduğu bu belgeden teyit edilir. | E7: Banka dekontu / Online bankacılık çıktısı
B8: 3 | C8: ★ KKM Hesap Açılış Belgesi (TL Mevduat / Katılım Hesabı Sözleşmesi) | D8: TL kur korumalı mevduat veya katılım hesabı sözleşmesi. Hesap türü, vade, başlangıç tutarı, kur garantisi koşulları görünmeli. YMM: Hesabın TL KKM niteliğinde olduğu bu belgeden teyit edilir. | E8: Banka sözleşmesi / KKM belgesi
B9: 4 | C9: ★ TCMB Resmi Döviz Kurları (31/12/2021 ve Dönüşüm Günü) | D9: Her iki tarih için TCMB resmi döviz alış kurları. tcmb.gov.tr → Döviz Kurları → İlgili tarihlerin kur tablosu. YMM: C tablosundaki kurların TCMB resmi kurlarıyla uyumlu olduğu teyit edilmeli. | E9: TCMB web sitesi (tcmb.gov.tr)
B10: 5 | C10: Dönüşüm Kazancı Hesaplama Tablosu (Bu Çalışma Kâğıdı C Bölümü) | D10: Her döviz bazında değerleme kazancı hesabı (bilanço kuru vs dönüşüm günü kuru). YMM: D.5 istisna tutarı ile beyanname 370 tutarının uyumlu olduğu teyit edilmeli. | E10: Bu çalışma kâğıdı — C ve D bölümleri
B11: 6 | C11: KV Beyannamesi Taslağı — 370. Satır | D11: 'Kazancın Bulunması Halinde İndirilecek' bölümünde. 370 tutarı D.5 ile birebir uyumlu olmalı. ★★ YİAKV: Beyannamedeki 370 tutarı YİAKV matrahından çıkarılmamış olmalı. | E11: GİB e-Beyanname sistemi
A13: KATEGORİ 2 — EK BELGELER
B14: No | C14: Belge / Bilgi | D14: Açıklama / YMM Kontrol | E14: Temin Yeri
B15: 7 | C15: Dönüşüm Tarihinin Yasal Süre İçinde Olduğunu Gösteren CB Kararı | D15: İlgili Cumhurbaşkanı Kararı — orijinal veya uzatma kararı. Dönüşüm tarihinin kararla belirlenen son tarih içinde olduğu kontrol edilmeli. | E15: Resmî Gazete / mevzuat.gov.tr
B16: 8 | C16: Muhasebe Yevmiye Kaydı — Kur Farkı Kazancı (646/679) | D16: Dönüşüm günü yevmiye kaydı: Döviz çıkışı + KKM açılışı + 646/679 kur farkı kaydı. C tablosu hesabıyla mutabık olmalı. | E16: Yevmiye defteri / Muhasebe ekstresi
B17: 9 | C17: 370 ve 371 Karşılaştırma Notu (İki İstisna Ayrıştırması) | D17: 370 (değerleme kazancı) ve 371 (faiz/kâr payı) tutarlarının ayrı ayrı belgelendiğini gösteren çapraz referans. Her iki istisnada da YİAKV düşülemez notu bulunmalı. | E17: Bu çalışma kâğıdı + 371 çalışma kâğıdı
A19: KATEGORİ 3 — YMM TASDİK KONTROL SORULARI
B20: No | C20: Kontrol Sorusu | D20: Beklenen Sonuç | E20: YMM Aksiyonu
B21: S1 | C21: ★ Yabancı para 31/12/2021 bilançosunda mevcut muydu? | D21: Bilanço teyidi zorunlu. Sonraki edinimler kapsam dışı. | E21: YMM kontrolü
B22: S2 | C22: ★ Dönüşüm tarihi yasal süre (CB Kararı) içinde mi? | D22: Dönüşüm dekontu tarihi ≤ Yasal son tarih. | E22: YMM kontrolü
B23: S3 | C23: Dönüşüm tutarı bilanço bakiyesini aşmıyor mu? | D23: Aşma → Orantılı ayrıştırma zorunlu. | E23: YMM kontrolü
B24: S4 | C24: ★ TCMB kurları resmi kaynaktan alındı mı? (Her iki tarih) | D24: tcmb.gov.tr — bilanço ve dönüşüm günü kurları. | E24: YMM kontrolü
B25: S5 | C25: Değerleme kazancı (D.3) muhasebe ile mutabık mı? | D25: 646/679 kur farkı tutarı ile uyumlu. | E25: YMM kontrolü
B26: S6 | C26: ★ 370 ve 371 doğru ayrıştırıldı mı? | D26: 370: Dönüşüm kazancı. 371: Faiz/kâr payı. Ayrı satırlar. | E26: YMM kontrolü
B27: S7 | C27: ★★ 370 istisnası YİAKV matrahından DÜŞÜLMEDI mi? | D27: YİAKV MATRAHINDA KALMALI — en kritik kontrol. | E27: YMM kontrolü
B28: S8 | C28: Beyanname 370 'Kazancın Bulunması Halinde' bölümünde mi? | D28: Zarar döneminde istisna uygulanamaz. | E28: YMM kontrolü
B29: S9 | C29: YMM Tasdik Raporu (49 No.lu Tebliğ) değerlendirildi mi? | D29: >=500.000 TL → YMM raporu. | E29: YMM kontrolü
A31: SON NOT: GİB KV Beyan Rehberi Mart 2026 (Yayın No:606) Bölüm 2.2.15 esas alınarak hazırlanmıştır. EN KRİTİK KONTROL: 370 tutarının YİAKV matrahından düşülmemesi — asgari kurumlar vergisi matrahında kalması zorunludur. 370 (değerleme kazancı) ve 371 (faiz/kâr payı) ayrı satırlar ve ayrı çalışma kâğıtları gerektirir. YMM müteselsil sorumluluk: SM-SMMM-YMM Kanunu Md.12.
