Workbook

Sheet VERİ GİRİŞİ
A1: 298 – GSYF & GSYO KAYNAKLI GELİRLERİN VERGİSEL DEĞERLENDİRİLMESİ | KVK Md. 5/1-a-3 | YMM TASDİK ÇALIŞMA KÂĞIDI
A2: Girişim Sermayesi Yatırım Fonu (GSYF) ve Ortaklığı (GSYO) — Gelir Türü Tespiti, Hukuki Nitelik Analizi ve İstisna Değerlendirmesi
A3: KULLANIM: Sarı zemin hücrelere veri giriniz. A0 kontrol bloğu eksiksiz doldurulmadan hesap bölümlerine geçilmemelidir.
A5: A. MÜKELLEF, YMM VE DÖNEM BİLGİLERİ
B6: Mükellef Ünvanı
B7: Vergi Kimlik Numarası
B8: Hesap Dönemi | D8: Tasdike konu hesap dönemi (örn. 2025)
B9: Beyanname Türü | D9: Kurumlar Vergisi Beyannamesi — 298 Kodlu Satır
B10: Çalışma Kâğıdı Hazırlayan
B11: Hazırlama Tarihi
A12: A0. GELİR TÜRÜ VE HUKUKİ NİTELİK UYGUNLUK KONTROLÜ — Tasdik Öncesi Zorunlu Sınıflama Kontrolü
A13: ⚠️ YMM UYARISI: GSYF/GSYO kaynaklı tüm gelirler otomatik olarak KVK 5/1-a iştirak kazancı istisnasına konu edilemez. Fon/ortaklık düzeyindeki kurumlar vergisi istisnası ile yatırımcı kurum nezdindeki gelir vergilemesi birbirinden ayrı değerlendirilmelidir. Gelirin hukuki niteliği tevsik belgesiyle desteklenmeden istisna tasdik raporuna alınamaz.
A14: Tasdik Sınıflama Kontrol Soruları | C14: Kullanıcı Seçimi | D14: Açıklama / Not
A15: A0.1 Yatırım aracı türü | C15: GSYF | D15: GSYF/GSYO'nun tam mükellef, Türkiye'de kurulu olduğu SPK lisansı veya fon bilgi formu ile belgelenmeli; aracı kurum kaydı tek başına yeterli değildir.
A16: A0.2 Gelirin hukuki niteliği | C16: Kâr payı / dağıtım | D16: Her gelir türü farklı vergi hükmüne tabidir: • Kâr payı/dağıtım → KVK 5/1-a kapsamı değerlendirilebilir • Fona iade kazancı → KVK 5/1-a (oran ve süre koşulu yok) • 3. kişiye satış → KVK 5/1-e (%75 istisna, 2 yıl aktif şartı) • Değer artışı → VUK 279 kapsamında ayrıca değerlendirmeli Gelir türü belirsizse istisna uygulanmamalıdır.
A17: A0.3 Uygulanacak istisna maddesi netleşti mi? | C17: EVET – 5/1-a (kâr payı/itfa) | D17: Fona iade: KVK 5/1-a. Üçüncü kişiye satış: KVK 5/1-e. Bu iki hüküm karıştırılmamalıdır; beyanname satırları farklıdır. Belirsizlik halinde YMM değerlendirme notu hazırlanmalıdır.
A18: A0.4 Fon/ortaklık – yatırımcı kurum ayrımı yapıldı mı? | C18: EVET | D18: GSYF/GSYO'nun kendi vergi rejimi (fonun KV istisnası) ile yatırımcı kurumun elde ettiği gelirin vergisel niteliği aynı şey değildir. Fon düzeyi istisna → yatırımcı kurumda otomatik istisna anlamına gelmez. Bu ayrım tasdik raporunda açıkça gerekçelendirilmelidir.
A19: A0.5 YİAKV etkisi ayrıca test edildi mi? | C19: EVET | D19: YİAKV etkisi gelirin hukuki niteliğine göre değişir; tek satır kesin hüküm verilemez. Klasik kâr payı (KVK 5/1-a) için genellikle düşülebilir; satış/itfa/değer artışı gelirleri için ayrı analiz gerekir. Dönem mevzuatı ayrıca kontrol edilmelidir.
A20: A0.6 Sınıflama Sonucu (Otomatik Kontrol) | C20: =IF(AND(C15<>"",C16<>"",C17<>"HAYIR – Belirsiz",C18="EVET"),"✅ OK – Sınıflama tamamlandı","⛔ HATA – Sınıflama eksik") -> ✅ OK – Sınıflama tamamlandı | D20: Tüm A0 kontrolleri tamamlanmadan bu çalışma kâğıdı tasdik dosyasına eklenemez. Sınıflama belirsizse YMM değerlendirme notu hazırlanmalıdır.
A21: 📌 KAPSAM NOTU: Bu çalışma kâğıdı, gelirin hukuki niteliğine göre sınıflama yapılmasını ve ardından vergisel sonucun değerlendirilmesini esas almaktadır. Gelir türü netleştirilmeden herhangi bir istisna veya vergi hükmü tasdik raporuna alınamaz. DENETÇİ NOTLARI sayfasındaki risk analizini inceleyiniz.
A23: B. GİRİŞİM SERMAYESİ YATIRIM FONU (GSYF) KATILMA PAYI GELİRLERİ — KVK Md. 5/1-a Alt Bent 3
B24: Kalem | C24: Tutar (TL) | D24: Açıklama
B25: B.1 | C25: GSYF Katılma Payı Sayısı / Fon Adı (Bilgi) | E25: Portföyde kaç GSYF varsa ayrı satır ekleyin
B26: B.2 | C26: GSYF-1: Katılma Payı Fona İade Kazancı (Brüt) | D26: 0 | E26: Fona iade bedelinden maliyet düşüldükten sonra kalan kazanç
B27: B.3 | C27: GSYF-2: Katılma Payı Fona İade Kazancı (Brüt) | D27: 0 | E27: İkinci GSYF varsa doldurun
B28: B.4 | C28: GSYF-3: Katılma Payı Fona İade Kazancı (Brüt) | D28: 0 | E28: Üçüncü GSYF varsa doldurun
B29: B.5 | C29: GSYF-1: Dönem İçi Alınan Kar Payı Tutarı | D29: 0 | E29: Fon tarafından dağıtılan kar payı (SPK Tebliği Md.25)
B30: B.6 | C30: GSYF-2: Dönem İçi Alınan Kar Payı Tutarı | D30: 0
B31: B.7 | C31: GSYF-3: Dönem İçi Alınan Kar Payı Tutarı | D31: 0
B32: B.8 | C32: GSYF Katılma Payları VUK 279 Dönem Sonu Değeri | D32: 0 | E32: Dönem sonu fon birim pay değeri × pay adedi
B33: B.9 | C33: GSYF Katılma Payları Maliyet Bedeli (Aktif Kaydı) | D33: 0 | E33: 24x/25x hesap bakiyesi — şirket hesap planına göre belirlenir; alış bedeli veya NAD esasına göre değerleme yöntemi fon portföy yapısına göre değişir
B34: B.10 | C34: GSYF Değerleme Kazancı (VUK Md.279 – Değer Artışı) | D34: =D32-D33 -> 0 | E34: B.8 – B.9 | İstisna kapsamındaki değer artışı
A36: C. GİRİŞİM SERMAYESİ YATIRIM ORTAKLIĞI (GSYO) HİSSE SENEDİ GELİRLERİ — KVK Md. 5/1-a Alt Bent 3
B37: Kalem | C37: Tutar (TL) | D37: Açıklama
B38: C.1 | C38: GSYO-1: Elde Tutulan Hisse Senedi Adedi | D38: 0 | E38: BİST'te işlem gören tam mükellef GSYO hissesi
B39: C.2 | C39: GSYO-1: Dönem İçi Alınan Kar Payı (Brüt) | D39: 0 | E39: GSYO'nun dağıttığı temettü — stopaj rejimi yatırım aracının niteliği, iktisap tarihi ve elde tutma süresine göre değişebilir; GVK Geçici 67 kapsamı ayrıca kontrol edilmelidir
B40: C.3 | C40: GSYO-2: Dönem İçi Alınan Kar Payı (Brüt) | D40: 0
B41: C.4 | C41: GSYO-3: Dönem İçi Alınan Kar Payı (Brüt) | D41: 0
B42: C.5 | C42: GSYO Hisse Maliyet Bedeli (Aktif Kaydı) | D42: 0 | E42: 24x/25x hesap bakiyesi — şirket hesap planına göre
B43: C.6 | C43: GSYO Hisse BİST Fiyatı × Adet (Piyasa Değeri) | D43: 0 | E43: Dönem sonu kapanış fiyatı × adet
...

Sheet HESAPLAMALAR & KONTROL
A1: 298 – GSYF & GSYO GELİRLERİ VERGİSEL DEĞERLENDİRME | HESAPLAMALAR VE DENETİM KONTROL PANELİ
A2: KVK Md. 5/1-a-3 | 1 Seri No.lu KV GT | KV Beyannamesi 298 Kodlu Satır — Tasdik Çalışma Kâğıdı
A4: TASDİK SINIFLAMA KONTROLÜ — VERİ GİRİŞİ BAĞLANTISI
A5: Tasdik Sınıflama Uygunluğu | C5: ='VERİ GİRİŞİ'!C20 -> ✅ OK – Sınıflama tamamlandı | D5: Bu hücre '✅ OK' olmadan çalışma kâğıdı tasdik dosyasına eklenemez. Hesap sonuçlarına dayanılamaz.
A6: YİAKV (KVK Md. 32/C) Etki Analizi | C6: =IF('VERİ GİRİŞİ'!C19="EVET","✅ TEST EDİLDİ","⚠ KONTROL GEREKİR") -> ✅ TEST EDİLDİ | D6: YİAKV etkisi gelirin hukuki niteliğine göre değişir; kesin hüküm verilemez. Klasik kâr payı (KVK 5/1-a) için genellikle YİAKV matrahından düşülebilir; satış/itfa/değer artışı gelirleri için ayrı analiz gerekir. Dönem mevzuatı ve gelir türü birlikte değerlendirilmelidir.
A7: Gelirin Hukuki Niteliği Tevsik Edildi mi? | C7: EVET | D7: Aracı kurum/portföy yönetim şirketi yazısı, fon dağıtım bildirimi veya itfa dekontu olmadan gelir niteliği tespiti yapılamaz.
A8: BÖLÜM 1 — GSYF KATILMA PAYI GELİRLERİ İSTİSNA HESABI
B9: Kod | C9: Açıklama | D9: Tutar (TL) | E9: Not
B10: G1.1 | C10: GSYF-1 Fona İade Kazancı | D10: ='VERİ GİRİŞİ'!D26 -> 0 | E10: Gelir türü tespit edilmişse KVK Md. 5/1-a/3 kapsamı değerlendirilebilir; fona iade kazancı için oran ve süre koşulu aranmamaktadır
B11: G1.2 | C11: GSYF-2 Fona İade Kazancı | D11: ='VERİ GİRİŞİ'!D27 -> 0
B12: G1.3 | C12: GSYF-3 Fona İade Kazancı | D12: ='VERİ GİRİŞİ'!D28 -> 0
B13: G1.4 | C13: GSYF Toplam Fona İade Kazancı (A) | D13: =D10+D11+D12 -> 0
B14: G1.5 | C14: GSYF-1 Kar Payı | D14: ='VERİ GİRİŞİ'!D29 -> 0
B15: G1.6 | C15: GSYF-2 Kar Payı | D15: ='VERİ GİRİŞİ'!D30 -> 0
B16: G1.7 | C16: GSYF-3 Kar Payı | D16: ='VERİ GİRİŞİ'!D31 -> 0
B17: G1.8 | C17: GSYF Toplam Kar Payı (B) | D17: =D14+D15+D16 -> 0
B18: G1.9 | C18: GSYF VUK 279 Değer Artış Kazancı (C) | D18: ='VERİ GİRİŞİ'!D34 -> 0 | E18: Değerleme farkı – istisna kapsamı
B19: G1.10 | C19: GSYF TOPLAM İSTİSNA (A+B+C) | D19: =D13+D17+D18 -> 0 | E19: Gelir niteliği doğrulandıysa KVK 5/1-a kapsamında istisna uygulanabilir
A21: BÖLÜM 2 — GSYO HİSSE SENEDİ GELİRLERİ İSTİSNA HESABI
B22: Kod | C22: Açıklama | D22: Tutar (TL) | E22: Not
B23: G2.1 | C23: GSYO-1 Kar Payı | D23: ='VERİ GİRİŞİ'!D39 -> 0 | E23: Tam mükellef GSYO hisse senedi — BİST işlem görme zorunlu; tam mükellef olduğu KAP/aracı kurum verisiyle teyit edilmeli
B24: G2.2 | C24: GSYO-2 Kar Payı | D24: ='VERİ GİRİŞİ'!D40 -> 0
B25: G2.3 | C25: GSYO-3 Kar Payı | D25: ='VERİ GİRİŞİ'!D41 -> 0
B26: G2.4 | C26: GSYO TOPLAM İSTİSNA (A+B+C toplamı) | D26: =D23+D24+D25 -> 0 | E26: Gelir niteliği doğrulandıysa KVK 5/1-a kapsamında istisna uygulanabilir
A28: BÖLÜM 3 — GENEL İSTİSNA ÖZETİ VE BEYANNAME KONTROLÜ
B29: Kod | C29: Açıklama | D29: Tutar (TL) | E29: Not
B30: Ö1 | C30: TOPLAM 298 KODU İSTİSNASI (GSYF + GSYO) | D30: =D19+D26 -> 0 | E30: KV Beyannamesi 298 kodlu satır — 'Zarar Olsa Dahi İndirilecek İstisna ve İndirimler' bölümü
B31: Ö2 | C31: KV Matrahı (VERİ GİRİŞİ D.6) | D31: ='VERİ GİRİŞİ'!D52 -> 0
B32: Ö3 | C32: İstisna Sonrası Beyanname Matrahı (Ö2 – Ö1) | D32: =D31-D30 -> 0 | E32: KV Beyannamesi matrah satırına girilecek tutar; beyanname öncesi YMM kontrolü zorunludur
A34: BÖLÜM 4 — YİAKV (ASGARİ KURUMLAR VERGİSİ — KVK Md. 32/C) ETKİ ANALİZİ
A35: YİAKV etkisi gelirin hukuki niteliğine göre ayrıca değerlendirilmelidir. Klasik kâr payı niteliğindeki gelirler için KVK 5/1-a kapsamında YİAKV matrahından düşülebilir; ancak satış/itfa/değer artışı gelirleri için ayrı analiz gerekir. Dönem mevzuatı teyidi zorunludur. Bu tablo bilgi amaçlıdır.
B36: Kod | C36: Açıklama | D36: Tutar (TL) | E36: Not
B37: Y1 | C37: YİAKV Matrahı (Ticari Bilanço Karı + KKEG) | D37: ='VERİ GİRİŞİ'!D47+'VERİ GİRİŞİ'!D48 -> 0 | E37: D.1 + D.2 referansları
B38: Y2 | C38: (–) 298 İstisna Tutarı | D38: =-D26 -> 0 | E38: Gelirin hukuki niteliğine göre ayrıca değerlendirilmelidir; klasik kâr payı için düşülebilir ancak diğer gelir türleri için ayrı analiz zorunludur
B39: Y3 | C39: YİAKV Matrahı (298 Sonrası) | D39: =D33+D34 -> 0 | E39: Diğer istisnalar/indirimler ayrıca düşülür
A41: BÖLÜM 5 — DENETİM VE TASDİK KONTROL LİSTESİ (K1–K10)
B42: K1 | C42: K1. Tam mükellef GSYF/GSYO statüsü SPK belgesiyle teyit edildi mi? | D42: ☐ UYGUN ☐ EKSİK ☐ RİSK | E42: SPK lisansı, fon bilgi formu veya KAP kaydı. Türkiye'de kurulu olma koşulu belgelenmeli; KVK 5/1-a son fıkra kapsamı teyit edilmelidir.
B43: K2 | C43: K2. GYF/GYO varsa KVK 5/1-d istisnası ve kâr dağıtım şartı (01.01.2025+) kontrol edildi mi? | D43: ☐ UYGUN ☐ EKSİK ☐ RİSK | E43: 7524 s.K. ile 01.01.2025 sonrası GYF/GYO'da kâr dağıtım şartı getirildi. Şartı sağlayan fondan alınan kâr payı 5/1-a'ya konu edilemez; ayrı değerlendirme zorunludur.
B44: K3 | C44: K3. VUK Md. 279 değerleme yöntemi fon portföy yapısına göre doğrulandı mı? | D44: ☐ UYGUN ☐ EKSİK ☐ RİSK | E44: Portföy ≥%51 Türkiye'de kurulu HS: Alış bedeli. Portföy <%51: NAD/borsa rayici. Fon bilgi formu ile portföy yapısı teyit edilmelidir.
B45: K4 | C45: K4. Fona iade kazancı doğru hesaplandı mı? (İade bedeli – Maliyet) | D45: ☐ UYGUN ☐ EKSİK ☐ RİSK | E45: Maliyet hesabı: Ortalama maliyet veya FIFO yöntemi uygulanmalı; yöntem tutarlılığı belgelenmeli.
...

Sheet MUHASEBE KAYITLARI
A1: 298 – KVK Md. 5/1-a-3 | MUHASEBE KAYITLARI ÇALIŞMA KÂĞIDI
A2: GSYF ve GSYO İşlemlerine İlişkin Muhasebe Kayıtları Rehberi — Yatırımın Muhasebe Sınıflamasına, TDHP Esaslarına ve Gelir Türüne Göre Uyarlanır. Muhasebe sorumluluğu mükellefte, tasdik sorumluluğu YMM'dedir.
A3: UYARI: Bu kayıtlar örnek ve rehber niteliğindedir. Hesap numaraları TDHP çerçevesinde şirket hesap planına göre belirlenir. Gelir türü (kâr payı / fona iade / satış / değer artışı) belirlenmeden kayıt seçilmemelidir.
A5: 📋 SENARYO REHBERİ: Gelir türüne göre ilgili kayıt bloğunu seçiniz. Birden fazla senaryo söz konusuysa her biri ayrı kayıt gerektir.
A6: SENARYO 1 — Kâr Payı/Dağıtım: Kayıt 4-5 | SENARYO 2 — Fona İade/İtfa: Kayıt 3 | SENARYO 3 — Alım ve Dönem Sonu Değerleme: Kayıt 1-2
A7: KAYIT 1 — [SENARYO 3: Alım ve Aktife Alma] GSYF KATILMA PAYI ALIMI VE AKTİFE KAYDI
B8: Tarih | C8: Hesap Adı / Açıklama | D8: Borç (TL) | E8: Alacak (TL) | F8: Açıklama
B9: Alım Tarihi | C9: 24x/11x İlgili finansal yatırım hesabı (240 Bağlı MK / 242 İştirakler / 110 — şirket sınıflamasına göre) | D9: ← Maliyet bedeli | F9: Maliyet bedeli ile aktife alınır (VUK 279 → alış bedeli; TÜİK portföy ≥%51 HS)
C10: 102 Bankalar | E10: ← Maliyet bedeli
C11: (Dipnot: 325/A kapsamında ise 10/1-g indirimine de dikkat)
A13: KAYIT 2 — [SENARYO 3: Değerleme] DÖNEM SONU GSYF DEĞERLEME KAYDI (VUK Md. 279)
B14: Tarih | C14: Hesap Adı / Açıklama | D14: Borç (TL) | E14: Alacak (TL) | F14: Açıklama
B15: Dönem sonu | C15: 24x/11x İlgili yatırım hesabı (şirket sınıflamasına göre) | D15: ← Değer artışı | F15: Dönem sonu fon NAD değeri – maliyet farkı
C16: 64x İlgili kazanç/gelir hesabı (642/645/649 — TDHP sınıflamasına göre) | E16: ← Değer artışı | F16: Değer artışı gelir yazılır – KVK 5/1-a-3 istisnasına konu edilir
C17: (VUK 279: portföy <% 51 HS ise borsa rayici / NAD değeri esas)
A19: KAYIT 3 — [SENARYO 2: Fona İade] GSYF KATILMA PAYI FONA İADE KAZANCI (KVK 5/1-a)
B20: Tarih | C20: Hesap Adı / Açıklama | D20: Borç (TL) | E20: Alacak (TL) | F20: Açıklama
B21: İade Tarihi | C21: 102 Bankalar | D21: ← İade bedeli | F21: Fona iade bedeli
C22: 24x/11x İlgili yatırım hesabı (şirket sınıflamasına göre) (Maliyet) | E22: ← Maliyet | F22: Maliyeti düşür
C23: 64x İlgili kazanç hesabı (645/649 — hesap planına göre) | E23: ← İade kazancı | F23: Fona iade kazancı — KVK 5/1-a/3 kapsamında istisna; süre ve oran koşulu yok
A25: KAYIT 4 — [SENARYO 1: Kâr Payı] GSYF KATILMA PAYINDAN KÂR PAYI TAHSİLATI
B26: Tarih | C26: Hesap Adı / Açıklama | D26: Borç (TL) | E26: Alacak (TL) | F26: Açıklama
B27: Kar Payı Tar. | C27: 102 Bankalar (veya 136 Diğer Çeşitli Alacaklar) | D27: ← Brüt kar payı | F27: Brüt kâr payı — stopaj rejimi iktisap tarihi ve türe göre değişir; aracı kurum bildirimi kontrol edilmelidir
C28: 64x İlgili gelir hesabı (640/642/649 — hesap planına göre) | E28: ← Brüt kar payı | F28: KVK 5/1-a kapsamında istisna tutarı
A30: KAYIT 5 — [SENARYO 1: Temettü] GSYO HİSSE SENEDİNDEN KÂR PAYI (TEMETTÜ) TAHSİLATI
B31: Tarih | C31: Hesap Adı / Açıklama | D31: Borç (TL) | E31: Alacak (TL) | F31: Açıklama
B32: Temettü Tar. | C32: 102 Bankalar | D32: ← Brüt temettü | F32: Brüt temettü — KVK 15/3 kapsamında GSYO bünyesinde kesinti uygulanabilir; stopaj durumu ayrıca teyit edilmeli
C33: 640/64x İlgili temettü/yatırım geliri hesabı | E33: ← Brüt temettü | F33: KVK 5/1-a kapsamında istisna edilir
A35: KAYIT 6 — KV BEYANNAMESİ: İSTİSNA TUTARININ BEYANNAME ETKİSİ
B36: Tarih | C36: Hesap Adı / Açıklama | D36: Borç (TL) | E36: Alacak (TL) | F36: Açıklama
B37: Dönem sonu | C37: 689 Diğer Olağandışı Gider ve Zararlar (veya ilgili gelir hesabı)
C38: NOT: KV beyannamesinde istisna tutarı 'Zarar Olsa Dahi İndirilecek İstisna ve İndirimler' bölümünde 298 kodu ile gösterilir. Muhasebe kaydı yapılmaz; beyanname notu niteliğindedir.
C39: İndirimler' bölümünde 298 kodu ile gösterilir. Ayrıca muhasebe kaydı olmaz.

Sheet DENETÇİ NOTLARI
A1: 298 – KVK Md. 5/1-a-3 | GSYF & GSYO GELİRLERİ | YMM MESLEKİ DEĞERLENDİRME VE TASDİK NOTLARI
A2: ANA DEĞERLENDİRME: GSYF/GSYO kaynaklı gelirlerin vergisel sonucu, gelirin hukuki niteliğine göre ayrıca değerlendirilmelidir. Fon/ortaklık düzeyindeki kurumlar vergisi istisnası ile yatırımcı kurum nezdindeki gelir vergilemesi aynı şey değildir. Bu ilke tasdik raporunun çekirdeğini oluşturur.
A4: I. HUKUK VE MEVZUAT DEĞERLENDİRMESİ (Ana Tasdik Tespiti)
A5: KVK Md. 5/1-a-3: Tam mükellef girişim sermayesi yatırım fonlarının katılma paylarından elde edilen kazançlar ile tam mükellef GSYO hisse senetlerinden elde edilen kazançlar kurumlar vergisinden istisnadır. KVK Md. 5/1-a-5: 3 ve 4 numaralı alt bentlerdeki istisna kazançlara kaynak oluşturan fon/ortaklıkların bu kazançları da istisna kapsamındadır. KVK Md. 5/1-a Son Fıkra: Diğer yatırım fonu ve ortaklık hisse senetlerinden elde edilen gelirler, kaynakları itibarıyla bu istisnadan yararlanamaz. GSYF/GSYO dışındaki yatırım araçlarında özel hüküm aranmalıdır. Tasdik Tespiti: İstisnanın uygulanabilmesi için: (i) Gelirin hukuki niteliğinin tevsik belgesiyle kanıtlanması, (ii) Fon/ortaklığın tam mükellef ve Türkiye'de kurulu GSYF/GSYO statüsünde olması, (iii)Fon/ortaklık düzeyi ile yatırımcı düzey ayrımının doğru yapılması zorunludur.
A6: KVK Madde 5/1-a Alt Bent 5: '(3) ve (4) numaralı alt bentlerde yer alan istisna kazançlarına kaynak oluşturan yatırım fonlarının katılma paylarının 213 sayılı VUK'un 279 uncu maddesi kapsamında değerlenmesinden kaynaklanan değer artış kazançları' → Dönem sonu değerleme farkı (gerçekleşmemiş kazanç) da istisna kapsamındadır.
A7: KVK Madde 5/1-a Son Fıkra: 'Diğer yatırım fonu katılma payları ile yatırım ortaklıklarının hisse senetlerinden elde edilen kâr payları bu istisnadan yararlanamaz.' → Sadece GSYF ve GSYO için özel istisna. Diğer MK/GYO ortaklıkları bu bentten yararlanamaz.
A9: II. YASAL DEĞIŞIKLIKLER VE GÜNCEL MEVZUAT
A10: 7456 Sayılı Kanun (15.07.2023): TL bazlı diğer yatırım fonlarına tanınan 5/1-a-4 ve 5/1-a-5 istisnası 15.07.2023 sonrası iktisaplar için kaldırıldı. GSYF ve GSYO korundu. Geçiş Hükmü: 15.07.2023 öncesi iktisap → istisna devam eder; sonrası iktisap → yalnızca GSYF/GSYO için istisna geçerlidir. Mükellefin portföy iktisap tarihleri ayrıca incelenmelidir.
A11: 7524 Sayılı Kanun (01.01.2025 Etkisi) — GYF/GYO ile İlişki: 7524 s.K. ile 01.01.2025 sonrası GYF ve GYO'larda KVK 5/1-d istisnası kâr dağıtım şartına bağlandı (%80 dağıtım zorunluluğu). Şartı sağlamayan GYF/GYO'dan alınan kâr payı 5/1-a'ya konu edilemez; ayrı değerlendirme zorunludur. 23 No.lu KVK GT (28.09.2024): GYF/GYO kâr paylarının 5/1-a uygulamasındaki çerçevesi detaylandırıldı. Portföyde GYF/GYO katılma payı varsa bu tebliğ ayrıca incelenmelidir.
A13: III. TASDİK RİSK ANALİZİ — KRİTİK RİSK VE GRİ ALANLAR
A14: 7524 s.K. ile 01.01.2025'ten itibaren: - GYF ve GYO'larda KVK 5/1-d istisnası kar dağıtım şartına bağlandı (%80 dağıtım zorunlu). - Kar dağıtım şartını SAĞLAYAN GYF/GYO'dan alınan kar payları: 5/1-a kapsamına GİRMEZ (çünkü kendisi zaten istisnadan yararlanıyor). - Kar dağıtım şartını SAĞLAYAMAYAN GYF/GYO'dan alınan kar payları: 5/1-a kapsamına GİRER. - GSYF ve GSYO'ya ilişkin 5/1-a/3 istisnası: Bu değişiklikten ETKİLENMEDİ.
A15: 23 No.lu KVK Genel Tebliği (28.09.2024 RG): - GYF/GYO'dan elde edilen kar paylarının 5/1-a uygulamasındaki yeni çerçevesini açıklar. - GSYF/GSYO için özel bir kısıtlama getirilmemiştir.
... A17: 🔴 KRİTİK RİSK — FON/ORTAKLIK DÜZEYİ İLE YATIRIMCI KURUM AYRIMI
A18: RİSK 1 | B18: Fon/ortaklık düzeyindeki kurumlar vergisi istisnası ile yatırımcı kurum nezdindeki gelir vergilemesi aynı şey değildir. GSYF/GSYO'nun kendi kazancının vergiden istisna olması, yatırımcı kurumun elde ettiği her türlü gelire otomatik olarak KVK 5/1-a uygulanacağı anlamına gelmez. Gelirin yatırımcı düzeyindeki niteliği (kâr payı, satış kazancı, itfa kazancı, değer artışı) ayrıca tespit edilmelidir.
A19: RİSK 2 | B19: Yatırımcı kurumun elde ettiği gelirin niteliği netleştirilmeden beyannameye istisna olarak alınmamalıdır. Gelir türü belirsizliği durumunda: • Portföy yönetim şirketi/aracı kurum yazılı görüşü alınmalı, • YMM değerlendirme notu hazırlanmalı, • Gerekirse özelge başvurusu yapılmalıdır.
A20: KONTROL | B20: A0 sınıflama bloğu 'OK' olmadan hesap sonuçları kullanılamaz. Sınıflama belirsizse 'HAYIR – Belirsiz' seçilerek YMM değerlendirme süreci başlatılmalıdır. Bu çalışma kâğıdı sınıflama tamamlanmadan tasdik dosyasına eklenemez.
A22: IV. DEĞERLEME (VUK Md. 279) UYGULAMASI VE RİSKLER
A23: Fon portföyü ≥%51 Türkiye'de kurulu şirket hisse senedinden oluşuyorsa: → GSYF katılma payları ALİŞ BEDELİ ile değerlenir. → Dönem sonu değerleme farkı oluşmaz; değer artışı geliri yazılmaz. → Bu durumda HESAPLAMALAR B.10 (değerleme kazancı) satırı sıfır kalır.
A24: Fon portföyü <%51 Türkiye'de kurulu şirket hisse senedinden oluşuyorsa: → Borsa rayici veya fon tarafından ilan edilen NAD değeri esas alınır. → Dönem sonu değer artışı gelir yazılarak KVK 5/1-a/5 kapsamında istisna edilir. → Değerleme yöntemi fon bilgi formundan teyit edilmeli ve belgelenmelidir.
A25: Özelge/İçtihat Riski: İdarenin çeşitli özelgelerinde fon değerleme yöntemi konusunda farklı görüşler bulunmaktadır. GİB özelge havuzu incelenerek emsal özelge araştırması yapılmalı; tartışmalı durumlarda ihtirazi kayıtla beyan veya özelge başvurusu değerlendirilmelidir.
A27: V. TARTIŞMALI KONULAR VE GÜNCEL RİSKLER
A28: Konu 1 — KVK 5/1-a ile 5/1-d Çakışması (01.01.2025+ GYF/GYO): 7524 s.K. değişikliği ile GYF/GYO'da kâr dağıtım şartı koşula bağlandı. Portföyde hem GSYF hem GYF/GYO varsa her birinin rejimi ayrı değerlendirilmeli; 5/1-a ve 5/1-d çakışması tasdik raporunda gerekçelendirilmelidir.
A29: Konu 2 — Katılma Payı Satışı (3. Kişi) vs. Fona İade Ayrımı: GSYF katılma payının üçüncü kişiye SATIŞI → KVK 5/1-e (%75 istisna, 2 yıl aktif şartı). Fona İADE → KVK 5/1-a (%100, süre ve oran koşulu yok). Bu ayrım beyanname satırlarını doğrudan etkiler; sözleşme ve dekont incelenmeli, tasdik raporunda açıkça belirtilmelidir.
A30: Konu 3 — Grup İçi GSYF'de Örtülü Kazanç Dağıtımı Riski (KVK Md. 13): Grup şirketlerince kurulan/yönetilen GSYF'lerde portföy yönetim ücretleri, performans primleri ve ilgili taraf işlemleri transfer fiyatlandırması riski taşıyabilir. YMM bu riski değerlendirmeli ve raporda gerekçelendirmelidir.
A31: Konu 4 — VUK 279 Değerleme Tutarsızlığı: Dönem başında gelir yazılan değer artışının dönem içinde değer düşüklüğüne dönüşmesi durumunda gider/zarar kaydının yapılıp yapılmayacağı tartışmalıdır. Tutarlı muhasebe politikası seçilmeli ve belgelenmelidir.
A32: VI. STOPAJ VE GVK GEÇİCİ 67 NOTU
A33: GVK Geçici 67 kapsamındaki stopaj etkisi; yatırım aracının niteliği, iktisap tarihi, elde tutma süresi ve gelir türüne göre değişir. 2025 yılında stopaj rejiminde güncellemeler yapılmıştır; dönem mevzuatı ayrıca kontrol edilmelidir. Aracı kurum stopaj bildirimi tasdik dosyasında yer almalıdır.
A34: VII. MEVZUAT DAYANAKLARI VE KAYNAK LİSTESİ
... A37: Yayınlar / Kaynak Makaleler: • Erdoğan Sağlam, 'Girişim Sermayesi Yatırım Fon ve Ortaklıklarının Vergilendirilmesi', T24 (28.03.2021) • İsmail Onay (Eski Hesap Uzmanı), 'İştirak Kazançları İstisnası', Gürel YMM (2023) • PwC Türkiye, 'Kurumlar Vergisi Genel Tebliği Yayımlandı', Vergi Bülteni 2024/55 • KPMG Vergi, 'Yurt İçi Asgari Kurumlar Vergisi Uygulaması' (2024) • Bilgener, 'GSYF Katılma Paylarına Yönelik Avantajlar ve Enflasyon Düzeltmesi' (2024) • BDO Türkiye, 'Yatırım Fon Payları Vergi İstisnasında Son Durum' (Ocak 2025)

Sheet BELGE LİSTESİ
A1: 298 – KVK Md. 5/1-a-3 GSYF & GSYO GELİRLERİ | TASDİK BELGE LİSTESİ VE DENETİM KANITI ENVANTERİ
A2: KVK Md. 17 / 3568 s.K. Kapsamında YMM Tasdik Dosyası — Zorunlu, Kritik Destek ve Destekleyici Belgeler
A3: KULLANIM: Her belgeyi temin edin ve UYGUN / EKSİK / RİSK olarak işaretleyin. Zorunlu belgeler (Kategori 1) eksik olmadan tasdik dosyası tamamlanamaz. Bu dosyanın en kritik belgesi: gelirin hukuki niteliğini gösteren PYŞ/aracı kurum yazısı.
B5: No | C5: Belge / Denetim Kanıtı | D5: İçerik ve YMM Tasdik Kontrol Notu | E5: Temin Yeri
A6: KATEGORİ 1 — ZORUNLU TASDİK BELGELERİ (Eksiklik Tasdik Kapsamından Çıkarılma Gerekçesi Oluşturur)
B7: 1 | C7: GSYF Fon Bilgi Formu / SPK İzin Belgesi | D7: Fon bilgi formu (KID), SPK izin belgesi veya KAP kaydı. GSYF statüsü, tam mükellef niteliği ve Türkiye'de kurulu olduğu belgelenmeli. Portföy yapısı (≥%51 HS mi?) değerleme yöntemini belirler. | E7: Portföy yönetim şirketi / SPK kamuyu aydınlatma platformu
B8: 2 | C8: GSYF Katılma Payı Maliyet Tablosu ve Hesap Dökümü (240/242) | D8: Her GSYF için alış tarihi, alış bedeli ve adet dökümü. Fona iade kazancı = İade bedeli – Maliyet. Muhasebe 24x/25x hesap ekstresiyle mutabakat yapılmalıdır. | E8: Muhasebe programı (240/242 hesap ekstreleri)
B9: 3 | C9: GSYF Dönem Sonu NAD (Net Aktif Değeri) Tablosu | D9: VUK Md. 279 değerlemesi için fon tarafından ilan edilen birim pay (NAD) değeri. Değer artış kazancı hesabında zorunludur. Portföy yapısına göre değerleme yöntemi teyit edilmelidir. | E9: Portföy yönetim şirketi / kamuya açık fon bilgi ekranı
B10: 4 | C10: GSYF Katılma Payı Fona İade Ekstresi / Banka Dekontu | D10: Fona iade bedeli, tarihi ve aracı kurum/banka bilgisi. Kazancın gerçekleştiğini belgeler; fona iade (5/1-a) ile satış (5/1-e) ayrımını kanıtlar. | E10: Aracı kurum / banka ekstresi
B11: 5 | C11: GSYO Hisse Senedi Portföy Tablosu ve BİST Fiyat Belgesi | D11: Tam mükellef GSYO statüsü ve BİST işlem görme belgesi. Dönem içi temettü ödemesi ve miktarı teyit edilmeli. KAP bildirimi veya aracı kurum yazısı. | E11: Aracı kurum / BİST KAP
B12: 6 | C12: GSYO Temettü Ödeme Belgesi / Banka Ekstresi | D12: Stopaj durumu: Rejim iktisap tarihi, elde tutma süresi ve gelir türüne göre değişir. Aracı kurum stopaj bildirimi veya GSYO'nun temettü bildirimi. Sabit %0 varsayımına dayanılamaz. | E12: GSYO'nun temettü bildirimi (KAP) / banka ekstresi
B13: 7 | C13: Dönem Sonu Bilanço ve Gelir Tablosu (VUK) | D13: Ticari bilanço karı, KKEG, diğer istisnalar ve KV matrahı. 298 istisnası beyanname üzerinde gösterilmeden önce matrah hesabının tamamlanmış olması gerekir. | E13: Muhasebe programı
A15: KATEGORİ 2 — KRİTİK DESTEK BELGELERİ (Tasdik Güvenilirliğini Artırır)
B16: 8 | C16: GSYF Yatırım Komitesi Kararı / Fon Bildirim Formu | D16: Portföy yöneticisinin pay alım/satım kararları; tarih ve gerekçe. Transfer fiyatlandırması riski değerlendirmesi için zorunludur. Grup içi GSYF varsa özellikle temin edilmelidir. | E16: Portföy yönetim şirketi
B17: 9 | C17: VUK 279 Değerleme Yöntemi İç Yazısı | D17: Şirketin hangi değerleme yöntemini uyguladığını belgeleyen iç not veya özelge. VUK Md. 279 kapsamındaki yöntem tutarlılığı teyit edilmeli; tartışmalı durumlarda emsal özelge araştırması yapılmalıdır. | E17: Muhasebe birimi / vergi müşaviri
B18: 10 | C18: KVK 5/1-d Durumu Analizi (GYF/GYO varsa) | D18: Portföyde GYF/GYO katılma payı varsa: Kâr dağıtım şartı sağlandı mı? 5/1-a veya 5/1-d rejimi hangisi uygulandı? 23 No.lu KV GT kapsamında değerlendirme yapılmalıdır. | E18: GYF/GYO'nun KAP bildirimi
B19: 11 | C19: YİAKV Hesaplama Notu | D19: YİAKV matrahı ve 298 istisnasının etkisi. Gelir türüne göre ayrı analiz yapılmalı; dönem mevzuatı teyit edilerek YMM tarafından imzalanmalıdır. | E19: Hesaplamalar sekmesi / vergi müşaviri
B20: 12 | C20: GVK Geçici 67 Stopaj Belgeleri | D20: GVK Geçici 67 stopaj belgesi — iktisap tarihi, elde tutma süresi ve gelir türüne göre. Aracı kurum stopaj bildirimi tasdik dosyasında yer almalıdır. Sabit oran varsayımı hatalı sonuç üretir. | E20: Aracı kurum stopaj bildirimi
B21: 13 | C21: Fon İçtüzüğü / İhraç Belgesi | D21: Fonun içtüzüğü, ihraç belgesi veya yatırımcı bilgi dokümanı. Gelir dağıtım hükümleri ve portföy kısıtlamaları; yatırımcı nezdindeki gelir rejimini belirleyen birincil kaynak. | E21: Portföy yönetim şirketi / SPK KAP
B22: 14 | C22: Katılma Payı Alım-Satım / İtfa Dekontları | D22: İtfa veya satış kaynaklı kazancın fona iade mi (5/1-a) yoksa 3. kişiye satış mı (5/1-e) olduğunu belgeler. Bu dosyanın en kritik ayrım belgesidir; eksikliği ciddi risk doğurur. | E22: Aracı kurum / banka
B23: 15 | C23: Dağıtım Bildirimi / Gelir Dağıtım Hesap Özeti | D23: Fonun dönemlik gelir dağıtımı: Kâr payı mı, sermaye iadesi mi, fon kazancı mı? Gelirin niteliğini ispatlayan temel belgedir. PYŞ veya KAP bildirimi yeterlidir. | E23: Portföy yönetim şirketi / KAP
B24: 16 | C24: Gelirin Hukuki Niteliğini Gösteren Aracı Kurum / PYŞ Yazısı | D24: Bu dosyanın en kritik belgesi. Elde edilen gelirin vergisel niteliğini (kâr payı / itfa / satış / değer artışı) yazılı olarak teyit eder. Sınıflama belirsizse PYŞ yazılı görüşü olmadan istisna uygulanmamalıdır. | E24: Portföy yönetim şirketi / aracı kurum
A26: KATEGORİ 3 — EK DENETİM SORULARI VE TASDİK KONTROL NOTLARI
B27: No | C27: Kontrol / Denetim Sorusu | D27: YMM Tasdik Notu
B28: S1 | C28: Mükellef, tam mükellef GSYF/GSYO'dan mı kazanç elde etti? | D28: Fonun/ortaklığın Türkiye'de kurulu ve tam mükellef statüsünde olduğu SPK belgesiyle teyit edilmeli. Dar mükellef araçtan elde edilen kazanç KVK 5/1-a kapsamına girmez.
B29: S2 | C29: GSYF portföy yapısı (≥%51 HS) VUK 279 değerleme yöntemini nasıl etkiliyor? | D29: ≥%51 HS: Alış bedeli → değerleme farkı yok. <%51: NAD/borsa rayici → değer artışı geliri yazılır, istisna kapsamı değerlendirilir. Fon bilgi formundan portföy yapısı teyit edilmelidir.
B30: S3 | C30: Katılma payı fona mı iade edildi yoksa üçüncü kişiye mi satıldı? | D30: Fona iade → KVK 5/1-a (%100, süre/oran koşulu yok). 3. kişi satışı → KVK 5/1-e (%75, 2 yıl aktif şartı). Bu ayrım tasdik raporunda açıkça gerekçelendirilmelidir.
B31: S4 | C31: Portföyde GYF/GYO katılma payı var mı? Kâr dağıtım şartı (7524 s.K.) sağlandı mı? | D31: 01.01.2025 sonrası: Kâr dağıtım şartını sağlayan GYF/GYO'dan alınan kâr payı 5/1-a kapsamında değerlendirilemez. Sağlayamayanın kâr payı ise değerlendirilebilir. 23 No.lu KV GT incelenmelidir.
B32: S5 | C32: YİAKV matrahında 298 istisnası gelir türüne göre doğru işlendi mi? | D32: Kâr payı niteliğindeki gelir için genellikle düşülebilir; satış/itfa/değer artışı için ayrı analiz. YİAKV hesabı dönem mevzuatıyla teyit edilmeli.
B33: S6 | C33: Muhasebe 64x hesabı ile beyanname 298 kodu mutabakatı tamamlandı mı? | D33: 640/642/645 hesap dökümü toplamı ile beyanname 298 satırı karşılaştırılmalı. Fark varsa gerekçesi yazılı olarak belgelenmelidir.
A35: TASDİK DOSYASI HAZIRLIK KONTROL ÖZETİ
A36: 298 — KVK Md. 5/1-a-3 GSYF & GSYO Gelirleri — Tasdik Hazırlık Kontrol Listesi □ A0 sınıflama bloğu tamamlandı ve 'OK' sonucu alındı □ GSYF/GSYO tam mükellef statüsü SPK belgesiyle teyit edildi □ Gelirin hukuki niteliği (kâr payı/itfa/satış/değer artışı) belirlendi □ Fona iade (5/1-a) ile 3. kişi satışı (5/1-e) ayrımı yapıldı □ VUK 279 değerleme yöntemi portföy yapısına göre doğrulandı □ Stopaj durumu GVK Geçici 67 kapsamında analiz edildi □ YİAKV etkisi gelir türüne göre hesaplandı □ Muhasebe 64x hesabı ile beyanname 298 kodu mutabakatı yapıldı □ Gelirin niteliğini gösteren PYŞ/aracı kurum yazısı temin edildi □ DENETÇİ NOTLARI sayfası dolduruldu
A38: ⚠️ TASDİK KURALI — KVK Md. 17 / 3568 s.K.: GSYF/GSYO kaynaklı gelirin hukuki niteliği portföy yönetim şirketi veya aracı kurum yazılı teyidiyle desteklenmeden istisna tasdik raporuna alınamaz. Sınıflama belirsizliği durumunda YMM değerlendirme notu hazırlanmalı; gerekirse ihtirazi kayıtla beyan veya özelge başvurusu değerlendirilmelidir.
