Workbook

Sheet VERİ GİRİŞİ
A1: 299 – DİĞER YATIRIM FONLARINDAN İŞTİRAK KAZANCI İSTİSNASI | KVK Md.5/1-a-4 | YMM TASDİK ÇALIŞMA KÂĞIDI
A2: KVK Md.5/1-a-4 | 7456 s.K. Mülga (15.07.2023) | GEÇİŞ UYGULAMASI: 15.07.2023 Öncesi İktisap | TL Esaslı Fon (Döviz/Altın/KKM Hariç) | Kâr Payı + Fon İadesi + VUK 279 Değerleme | Zarar Olsa Dahi İndirilecek — Beyanname Satır 299
A3: KRİTİK UYARILAR: (1) İktisap tarihi 15.07.2023'ten ÖNCE olmalı — sonrası vergiye tabi. (2) Portföyde döviz/altın/kıymetli maden OLMAMALI. (3) GSYF/GSYO için bu form DEĞİL — 298 kodu kullanılır. (4) Portföy ≥%51 hisse senedi → Alış bedeli → VUK 279 değerleme farkı İSTİSNA DIŞİ.
A4: RENK KODLARI: Sarı = Manuel giriş | Yeşil = Otomatik hesaplama | Kırmızı = Kritik uyarı / kapsam dışı | Dropdown = Listeden seçim
A6: A0. KAPSAM VE NİTELİK UYGUNLUK ÖN KONTROLÜ
B7: Kontrol Sorusu | E7: Yanıt | G7: YMM Tasdik Notu
A8: A0.1 ★ İstisna uygulanacak fon(lar)ın iktisap tarihi 15.07.2023'ten ÖNCE mi? | E8: EVET | F8: KRİTİK: 7456 s.K. (15.07.2023) ile bu bent mülga edilmiştir. 15.07.2023 sonrası iktisap edilen fonların kâr payı ve değerleme farkı VERGIYE TABİDİR. Karma tarihli alımlarda pay adedi bazında ayrıştırma zorunludur.
A9: A0.2 ★ Portföyde döviz/altın/kıymetli maden araçları YOK mu? | E9: EVET | F9: KRİTİK: KVK 5/1-a-4 yalnızca TL esaslı fonlar içindir. Portföyde yabancı para birimi, altın, kıymetli maden araçları olan fonlar kapsam dışıdır. Fon bilgi formu/izahnamesi ile portföy bileşimi teyit edilmelidir.
A10: A0.3 Bu form GSYF/GSYO için değil — doğru form kullanılıyor mu? | E10: EVET | F10: GSYF (Girişim Sermayesi YF) ve GSYO → Beyanname 298 kodu (KVK 5/1-a-3 kapsamı). Bu form (299) sadece diğer yatırım fonları içindir. GYF/GYO (Gayrimenkul) için ayrıca 5/1-d şartları değerlendirilmelidir.
A11: A0.4 VUK 279 değerleme yöntemi doğru belirlendi mi? (Portföy %51 kriteri) | E11: EVET | F11: Portföy ≥%51 hisse senedi: Alış bedeli → değerleme farkı OLUŞMAZ → C tablosu boş kalır. Portföy <%51 hisse senedi: Borsa rayici → değerleme farkı = istisna. Portföy bileşimi fon bilgi formundan her dönem teyit edilmelidir.
A12: A0.5 Karma tarihli alım ayrıştırması tam yapıldı mı? | E12: EVET | F12: Aynı fonda 15.07.2023 öncesi ve sonrası alım varsa: Pay adedi bazında ayrıştırma zorunludur. FIFO veya ağırlıklı ortalama maliyet yöntemi tutarlı biçimde uygulanmalıdır.
A13: A0.6 Muhasebe hesapları ile beyanname 299 tutarı uyumlu mu? | E13: EVET | F13: Üç kademe uyum: 118/640/645 hesap kartları = VERİ GİRİŞİ B+C toplamı = Beyanname 299. Uyumsuzluk varsa kayıt hatası veya kapsam dışı gelir karışmış olabilir.
A14: A0.7 YİAKV matrahından 299 istisnası DÜŞÜLEBİLİR mi? (5/1-a kapsamı — EVET) | E14: EVET | F14: NOT: KVK 5/1-a-4 (299) istisnası YİAKV matrahından DÜŞÜLEBİLİR (5/1-a kapsamı). Bu, 5/1-c (318) ve 5/1-e (361) istisnalarından önemli bir farktır. YİAKV çalışma kâğıdında 299 tutarı matrahtan doğru şekilde düşülmelidir.
A15: A0.8 YMM Tasdik Raporu gereksinimi değerlendirildi mi? (49 No.lu Tebliğ) | E15: EVET | F15: 49 No.lu Tebliğ (30.12.2025): Tek satır >=500.000 TL veya toplam >=1.000.000 TL → YMM raporu. Tam tasdik sözleşmesi olanlar ayrıca rapor düzenlemez.
A16: A0.9 Tasdik Uygunluk Sonucu | E16: =IF(AND(E8="EVET",E9="EVET",E10="EVET",E11="EVET",E12="EVET",E13="EVET",E14="EVET",E15="EVET"),"OK - Hesaplanabilir","HATA - Ön koşul eksik") -> OK - Hesaplanabilir | F16: ★ A0.1 (iktisap tarihi) ve A0.2 (portföy bileşimi) kritik. A0.5 karma ayrıştırmayı kontrol et.
A18: A. MÜKELLEF VE DÖNEM BİLGİLERİ
A19: Mükellef Unvanı | F19: İstisna uygulayan kurumun tam adı
A20: Vergi Kimlik Numarası | F20: 10 haneli VKN
A21: Hesap Dönemi | F21: Örn: 01.01.2025 – 31.12.2025
A22: Genel KV Oranı (%) | F22: 2025: %25 | Finans sektörü: %30
A24: B. KÂR PAYI + FON İADESİ KAZANCI (15.07.2023 Öncesi İktisap, TL Esaslı Fonlar)
A25: KAPSAM: Para piyasası, tahvil-bono, karma, serbest ve diğer TL esaslı yatırım fonu katılma payları. Her fon satırı: 15.07.2023 öncesi iktisap edilmiş paylardan elde edilen kâr payı ve fon iadesi kazancı. Portföyde döviz/altın olanlar kapsam dışıdır (D tablosuna alın).
B26: Fon Adı / Tanımlayıcı | C26: İktisap Tarihi | D26: Kâr Payı (TL) | E26: Fon İadesi Kaz. (TL) | F26: Toplam (TL) | G26: YMM Notu
B27: Fon-1 | F27: =IF(AND(D27>0,E27>=0),D27+E27,IF(D27>0,D27,IF(E27>0,E27,0))) -> 0 | G27: İktisap tarihi ve portföy bileşimi teyit edilmeli.
B28: Fon-2 | F28: =IF(AND(D28>0,E28>=0),D28+E28,IF(D28>0,D28,IF(E28>0,E28,0))) -> 0 | G28: İktisap tarihi ve portföy bileşimi teyit edilmeli.
B29: Fon-3 | F29: =IF(AND(D29>0,E29>=0),D29+E29,IF(D29>0,D29,IF(E29>0,E29,0))) -> 0 | G29: İktisap tarihi ve portföy bileşimi teyit edilmeli.
B30: Fon-4 | F30: =IF(AND(D30>0,E30>=0),D30+E30,IF(D30>0,D30,IF(E30>0,E30,0))) -> 0 | G30: İktisap tarihi ve portföy bileşimi teyit edilmeli.
B31: Fon-5 | F31: =IF(AND(D31>0,E31>=0),D31+E31,IF(D31>0,D31,IF(E31>0,E31,0))) -> 0 | G31: İktisap tarihi ve portföy bileşimi teyit edilmeli.
B32: Fon-6 | F32: =IF(AND(D32>0,E32>=0),D32+E32,IF(D32>0,D32,IF(E32>0,E32,0))) -> 0 | G32: İktisap tarihi ve portföy bileşimi teyit edilmeli.
B33: Fon-7 | F33: =IF(AND(D33>0,E33>=0),D33+E33,IF(D33>0,D33,IF(E33>0,E33,0))) -> 0 | G33: İktisap tarihi ve portföy bileşimi teyit edilmeli.
B34: Fon-8 | F34: =IF(AND(D34>0,E34>=0),D34+E34,IF(D34>0,D34,IF(E34>0,E34,0))) -> 0 | G34: İktisap tarihi ve portföy bileşimi teyit edilmeli.
B35: B — KÂR PAYI + FON İADESİ KAZANCI TOPLAMI | D35: =SUM(D27:D34) -> 0 | E35: =SUM(E27:E34) -> 0 | F35: =SUM(F27:F34) -> 0 | G35: → Beyanname 299 (B kısmı)
A37: C. VUK 279 DEĞERLEME FARKI KAZANCI (15.07.2023 Öncesi İktisap, Portföy <%51 Hisse)
A38: KAPSAM: Portföyünün <%51'i BIST hisse senedinden oluşan fonlar → Borsa rayiciyle değerlenir → Değerleme farkı istisna kapsamındadır. Portföy ≥%51 hisse: Alış bedeli → değerleme farkı YOKTUR (C tablosu boş). Portföy bileşimi fon bilgi formuyla dönem başı ve sonu kontrol edilmelidir.
B39: Fon Adı / Tanımlayıcı | C39: İktisap Tarihi | D39: Dönem Başı Değer (TL) | E39: Dönem Sonu VUK 279 (TL) | F39: Değerleme Farkı (TL) | G39: YMM Notu
B40: VUK-1 | F40: =IF(AND(E40>0,D40>=0),MAX(0,E40-D40),0) -> 0 | G40: Portföy %51 kriteri teyit edilmeli. Yalnızca artış istisna.
B41: VUK-2 | F41: =IF(AND(E41>0,D41>=0),MAX(0,E41-D41),0) -> 0 | G41: Portföy %51 kriteri teyit edilmeli. Yalnızca artış istisna.
B42: VUK-3 | F42: =IF(AND(E42>0,D42>=0),MAX(0,E42-D42),0) -> 0 | G42: Portföy %51 kriteri teyit edilmeli. Yalnızca artış istisna.
B43: VUK-4 | F43: =IF(AND(E43>0,D43>=0),MAX(0,E43-D43),0) -> 0 | G43: Portföy %51 kriteri teyit edilmeli. Yalnızca artış istisna.
B44: VUK-5 | F44: =IF(AND(E44>0,D44>=0),MAX(0,E44-D44),0) -> 0 | G44: Portföy %51 kriteri teyit edilmeli. Yalnızca artış istisna.
...

Sheet HESAPLAMALAR & KONTROL
A1: 299 – DİĞER YATIRIM FONLARI | HESAPLAMALAR VE DENETİM KONTROL PANELİ
A2: KVK Md.5/1-a-4 | 7456 s.K. Mülga (15.07.2023) | TL Esaslı Fon | Kâr Payı + Fon İadesi + VUK 279 | YİAKV'den DÜŞÜLEBİLİR | Beyanname Satır 299
A4: A. TASDİK ÖZETİ — VERİ GİRİŞİNDEN OTOMATİK
A5: A0 Tasdik Uygunluğu | D5: ='VERİ GİRİŞİ'!E16 -> OK - Hesaplanabilir | E5: A0.9 OK ise devam
A6: Kâr Payı + Fon İadesi Toplam (B Tablosu) | D6: ='VERİ GİRİŞİ'!F35 -> 0 | E6: B Toplamı
A7: VUK 279 Değerleme Farkı Toplam (C Tablosu) | D7: ='VERİ GİRİŞİ'!F46 -> 0 | E7: C Toplamı
A8: TOPLAM İSTİSNA (E.3 — Beyanname 299) | D8: ='VERİ GİRİŞİ'!F60 -> 0 | E8: B+C Toplamı → 299 Satırı
A9: Kapsam Dışı (D — Vergiye Tabi, Kontrol) | D9: ='VERİ GİRİŞİ'!D55 -> 0 | E9: Beyanname matrahında kalır
A11: B. FON TÜRÜ VE KAPSAM TABLOSU — 298 / 299 / Kapsam Dışı Ayrımı
B12: Fon Türü | D12: 299 Kapsamı? | F12: 298 mi? | G12: Açıklama
A13: Para Piyasası Fonu | C13: EVET (TL) | E13: HAYIR | G13: TL esaslı — 15.07.2023 öncesi iktisap şartıyla 299
A14: Tahvil-Bono Fonu | C14: EVET (TL) | E14: HAYIR | G14: TL esaslı — 15.07.2023 öncesi iktisap şartıyla 299
A15: Karma Fon (TL) | C15: EVET (TL) | E15: HAYIR | G15: Portföyde döviz/altın yoksa 299 kapsamında
A16: Hisse Senedi Fonu | C16: ★ VUK 279 Dikkat | E16: HAYIR | G16: ≥%51 hisse → Alış bedeli → Değerleme farkı yok
A17: GSYF (Girişim Sermayesi) | C17: HAYIR | E17: EVET | G17: KVK 5/1-a-3 kapsamı → 298 kodu
A18: GSYO | C18: HAYIR | E18: EVET | G18: KVK 5/1-a-3 kapsamı → 298 kodu
A19: Döviz/Altın Fonu | C19: HAYIR | E19: HAYIR | G19: Kapsam dışı — vergiye tabi
A20: KKM Fonu | C20: HAYIR | E20: HAYIR | G20: Kapsam dışı — vergiye tabi
A21: GYF/GYO (Gayrimenkul) | C21: ★ 5/1-d Koşullu | E21: HAYIR | G21: 5/1-d şartları ayrıca değerlendirilmeli
A23: C. DENETİM KONTROL LİSTESİ (K1–K10)
B24: Kontrol | D24: Açıklama ve Kanıt | F24: Sonuç | G24: YMM Aksiyonu
A25: K1 | B25: ★ İktisap tarihi her fon için ayrı ayrı 15.07.2023 öncesi mi? | D25: Banka/MKK alış dekontu ile her fon ayrı ayrı belgelenmelidir. Belgesiz hiçbir fon istisna kapsamında değerlendirilemez. | F25: Uygun / Eksik / Risk
A26: K2 | B26: ★ Portföy bileşimi: Döviz/altın/kıymetli maden YOK mu? | D26: Fon bilgi formu/izahnamesinden portföy bileşimi teyit edilmelidir. Yabancı para birimi, altın, kıymetli maden araçları içeren fonlar kapsam dışıdır. | F26: Uygun / Eksik / Risk
A27: K3 | B27: Fon türü doğru sınıflandırıldı mı? (298 / 299 / Kapsam Dışı ayrımı) | D27: GSYF/GSYO → 298. GYF/GYO → 5/1-d. Döviz/Altın fonlar → Kapsam dışı. Bu form (299) sadece TL esaslı diğer fonlar içindir. | F27: Uygun / Eksik / Risk
A28: K4 | B28: VUK 279 değerleme yöntemi portföy bileşimiyle uyumlu mu? | D28: ≥%51 BIST hisse senedi: Alış bedeli → Değerleme farkı yok → C tablosu boş. <%51 hisse: Borsa rayici → C tablosuna değerleme farkı işlenir. | F28: Uygun / Eksik / Risk
A29: K5 | B29: Kâr payı ve fon iadesi kazancı muhasebe hesaplarıyla uyumlu mu? | D29: 118 (maliyet), 640 (kâr payı), 645 (satış kazancı) hesap kartları ile VERİ GİRİŞİ B tablosu tutarlı olmalıdır. | F29: Uygun / Eksik / Risk
A30: K6 | B30: VUK 279 değerleme farkı muhasebe 649 hesabıyla uyumlu mu? | D30: Değerleme artışı 649 hesabına gelir kaydedilmeli. 649 toplamı (VUK 279 kısmı) ile C tablosu toplamı uyumlu olmalıdır. | F30: Uygun / Eksik / Risk
A31: K7 | B31: Beyanname 299 satırı E.3 tutarıyla birebir uyumlu mu? | D31: 3 kademe uyum: Muhasebe hesapları = VERİ GİRİŞİ E.3 = Beyanname 299. Fark varsa kaynak belgelere inilmeli ve açıklanmalıdır. | F31: Uygun / Eksik / Risk
A32: K8 | B32: Karma tarihli alım ayrıştırması doğru yapıldı mı? | D32: Aynı fonda 15.07.2023 öncesi ve sonrası alım: Pay adedi bazında ayrıştırma zorunlu. Kapsam içi kısım B tablosuna, kapsam dışı D tablosuna alınmalıdır. | F32: Uygun / Eksik / Risk
A33: K9 | B33: YİAKV matrahında 299 istisnası doğru konumlandırıldı mı? | D33: KVK 5/1-a-4 (299) istisnası YİAKV matrahından DÜŞÜLEBİLİR (5/1-a kapsamı). YİAKV çalışma kâğıdında 299 tutarı matrahtan doğru düşülmelidir. | F33: Uygun / Eksik / Risk
A34: K10 | B34: Beyanname 299 'Zarar Olsa Dahi' bölümünde doğru konumlandı mı? | D34: 299 satırı 'Zarar Olsa Dahi İndirilecek İstisna ve İndirimler' bölümündedir. 'Kazancın Bulunması Halinde' bölümüyle karıştırılmamalıdır. | F34: Uygun / Eksik / Risk
A36: D. BEYANNAME SATIR EŞLEŞTİRME
B37: Beyanname Satırı | D37: Tutar (TL) | F37: Açıklama
A38: Satır 299 | C38: ='VERİ GİRİŞİ'!F60 -> 0 | D38: KVK 5/1-a-4 — 15.07.2023 Öncesi İktisap TL Fon | Kâr Payı+Fon İadesi+VUK 279 | Zarar Olsa Dahi İndirilecek
A39: DİKKAT: 298 | C39: GSYF/GSYO Kazancı | D39: KVK 5/1-a-3 kapsamı (GSYF/GSYO) → 298 kodu. Bu forma dahil edilmez.
A40: DİKKAT: 300 | C40: Diğer Fon VUK 279 | D40: KVK 5/1-a-5 kapsamındaki VUK 279 → 300 kodu. 299 ile karıştırılmamalı.

Sheet MUHASEBE KAYITLARI
A1: 299 – DİĞER YATIRIM FONLARI | MUHASEBE KAYITLARI ÇALIŞMA KÂĞIDI
A2: KVK Md.5/1-a-4 | 15.07.2023 Öncesi İktisap | Kâr Payı + Fon İadesi + VUK 279
A3: NOT: Rehber niteliğindedir. Şirkete özgü muhasebe politikasına göre uyarlanmalıdır. Stopaj oranı kurumlar için %0'dır — brüt = net.
A5: KAYIT 1 — YATIRIM FONU SATIN ALIM KAYDI (Alış Tarihini Belgelemek Kritik)
A6: Fon Adı: [___] | Alış Tarihi: [GG.AA.YYYY] — 15.07.2023'ten ÖNCESİ olmali
B7: Tarih | C7: Hesap Adı / Kodu | D7: Muhasebe Notu | E7: Dr (TL) | F7: Kr (TL) | G7: Referans
A8: Dr | B8: [Alış Tarihi] | C8: 118 Diğer Menkul Kıymetler | D8: Fon katılma payı alış bedeli — İktisap tarihi mutlaka not edilmeli | E8: [Alış Bedeli] | F8: — | G8: Banka / aracı kurum dekontu
A9: Kr | B9: [Alış Tarihi] | C9: 102 Bankalar | D9: Ödeme | E9: — | F9: [Alış Bedeli] | G9: Banka dekontu
A10: ÖNEMLİ: İktisap tarihi 15.07.2023'ten önce olduğu banka dekontu veya MKK kaydıyla belgelenmelidir. Bu belge olmadan istisna uygulanamaz. Tarih muhasebe kayıt açıklamasına da yazılmalıdır.
A12: KAYIT 2 — KÂR PAYI GELİRİ (Fon Tarafından Dağıtılırsa)
B13: Tarih | C13: Hesap Adı / Kodu | D13: Muhasebe Notu | E13: Dr (TL) | F13: Kr (TL) | G13: Referans
A14: Dr | B14: [Kâr dağıtımı] | C14: 102 Bankalar | D14: Net kâr payı tahsilatı (Stopaj %0 — brüt = net) | E14: [Kâr Payı] | F14: — | G14: Banka dekontu
A15: Kr | B15: [Kâr dağıtımı] | C15: 640 İştiraklerden Temettü Gelirleri | D15: Fon kâr payı geliri — 5/1-a-4 istisnası | E15: — | F15: [Kâr Payı] | G15: KV 299 satırı
A16: NOT: Yatırım fonu kâr payı dağıtımında kurumlar için stopaj %0'dır. 640 hesabındaki tutar beyanname 299 satırı ile uyumlu olmalıdır.
A18: KAYIT 3 — FON İADESİ / SATIŞ KAYDI (Kazanç Tespiti)
B19: Tarih | C19: Hesap Adı / Kodu | D19: Muhasebe Notu | E19: Dr (TL) | F19: Kr (TL) | G19: Referans
A20: Dr | B20: [İade tarihi] | C20: 102 Bankalar | D20: Net iade bedeli tahsilatı | E20: [İade Bedeli] | F20: — | G20: Banka dekontu
A21: Kr | B21: [İade tarihi] | C21: 118 Diğer Menkul Kıymetler | D21: Maliyet değerinin çıkışı (VUK 279 değerleme sonrası bilanço değeri) | E21: — | F21: [Maliyet] | G21: 118 hesap kartı
A22: Kr | B22: [İade tarihi] | C22: 645 Menkul Kıymet Satış Kârı | D22: Fon iadesi kazancı — 5/1-a-4 istisnası | E22: — | F22: [Fark] | G22: KV 299 satırı
A23: NOT: İade kazancı (İade Bedeli − Maliyet) 645 hesabına gelir kaydedilir. Bu tutar VERİ GİRİŞİ B tablosundaki fon iadesi kazancı ile uyumlu olmalıdır.
A25: KAYIT 4 — DÖNEM SONU VUK 279 DEĞERLEME KAYDI (Portföy <%51 Hisse)
A26: Uygulama koşulu: Fonun portföyündeki hisse senedi oranı <%51 ise borsa rayiciyle değerleme yapılır.
B27: Tarih | C27: Hesap Adı / Kodu | D27: Muhasebe Notu | E27: Dr (TL) | F27: Kr (TL) | G27: Referans
A28: Dr | B28: 31.12.20XX | C28: 118 Diğer Menkul Kıymetler | D28: VUK 279 borsa rayici ile dönem sonu değerleme artışı | E28: [Artış] | F28: — | G28: VUK Md.279
A29: Kr | B29: 31.12.20XX | C29: 649 Diğer Olağandışı Gelir | D29: Değerleme artışı — 5/1-a-4 istisnası (15.07.2023 öncesi iktisap) | E29: — | F29: [Artış] | G29: KV 299 satırı
A30: VUK 279 AKIŞ: 649 hesabına gelir kaydı → KKEG tablosuna eklenir → Beyanname 299'da istisna düşülür. 649 toplamı (VUK 279 kısmı) ile VERİ GİRİŞİ C tablosu toplamı uyumlu olmalıdır. Portföy ≥%51 hisse ise bu kayıt YAPILMAZ.
A32: KAYIT 5 — BEYANNAME 299 MUTABAKAT NOTU
A33: BEYANNAME 299 AKIŞI: 1. B Tablosu (Kâr Payı + Fon İadesi): 640 + 645 hesap toplamı → VERİ GİRİŞİ B → Beyanname 299 B kısmı 2. C Tablosu (VUK 279): 649 hesap (VUK kısmı) toplamı → VERİ GİRİŞİ C → Beyanname 299 C kısmı 3. Toplam 299 = B + C → 'Zarar Olsa Dahi İndirilecek' bölümü 299. satır 3 KADEME UYUM KONTROLÜ: Muhasebe (640+645+649 VUK kısmı) = VERİ GİRİŞİ E.3 = Beyanname 299 YİAKV NOTU: 5/1-a-4 (299) istisnası YİAKV matrahından DÜŞÜLEBİLİR — 5/1-c (318) ve 5/1-e (361)'den farklı olarak bu kapsamda matrahtan çıkarılabilir.

Sheet DENETCİ NOTLARI
A1: 299 – DİĞER YATIRIM FONLARI | DENETÇİ NOTLARI VE MESLEKİ DEĞERLENDİRME
A2: KVK Md.5/1-a-4 | 7456 s.K. Mülga (15.07.2023) | Geçiş Uygulaması | TL Esaslı Fon | Kâr Payı+Fon İadesi+VUK 279 | YİAKV'den DÜŞÜLEBİLİR
A4: BÖLÜM 1 — YASAL DAYANAK, TARİHSEL ÇERÇEVE VE KAPSAM
A5: Kod | B5: Konu | C5: Mesleki Değerlendirme | D5: Mevzuat
A6: N1 | B6: KVK 5/1-a-4 İstisnasının Tarihsel Çerçevesi | C6: 7394 s.K. (15.04.2022): Diğer yatırım fonlarına istisna tanındı (TL esaslı, döviz/altın hariç). 7456 s.K. (15.07.2023): Bu bent mülga edildi. GEÇİŞ UYGULAMASI: 15.07.2023'ten önce iktisap edilen paylar için istisna DEVAM ETMEKTEDİR. Yeni iktisaplarda: Kazanç vergiye tabidir. Beyanname 299. Satır: 'Zarar Olsa Dahi İndirilecek' bölümündedir. | D6: KVK Md.5/1-a-4 | 7394 ve 7456 s.K.
A7: N2 | B7: İstisna Kapsamındaki Fon Türleri (TL Esaslı) | C7: KAPSAM İÇİ (Portföyde döviz/altın olmayan, TL esaslı, 15.07.2023 öncesi iktisap): ✓ MKYO (Menkul Kıymet Yatırım Ortaklığı) — KVK 5/1-a-1,2 iken bu bent 5/1-a-4 kapsar ✓ Para Piyasası Fonu, Tahvil-Bono Fonu, Karma Fon (TL), Serbest Fon (TL) ✓ Diğer TL esaslı fon türleri KAPSAM DIŞI: ✗ GSYF/GSYO → 298 kodu (KVK 5/1-a-3) ✗ Portföyde döviz/altın/kıymetli maden olan fonlar ✗ KKM (Kur Korumalı Mevduat) fonları ✗ 15.07.2023 sonrası iktisap | D7: KVK Md.5/1-a-4 | 7394 ve 7456 s.K.
A8: N3 | B8: ★ 15.07.2023 İktisap Tarihi — En Kritik Kontrol | C8: Bu tarih kesin sınırdır: ÖNCE iktisap → İstisna kapsamında (299 satırı) SONRA iktisap → Vergiye tabi (Beyanname matrahında) KARMA DURUM (Aynı Fonda Farklı Tarihli Alım): Pay adedi bazında ayrıştırma zorunludur. Her alım partisi için ayrı maliyet ve kazanç hesabı yapılmalıdır. FIFO veya ağırlıklı ortalama maliyet yöntemi tutarlı biçimde uygulanmalıdır. YMM notu: Banka/MKK dekontu olmadan hiçbir fon istisna kapsamında değerlendirilemez. | D8: 7456 s.K. | KVK Md.5/1-a-4
A9: N4 | B9: VUK 279 Değerleme — Portföy %51 Kriteri | C9: VUK Md.279 kapsamında değerleme: Portföy ≥%51 BIST hisse senedi → ALİŞ BEDELİ ile değerlenir → Değerleme farkı OLUŞMAZ → C tablosu boş Portföy <%51 hisse senedi → BORSA RAYİCİ ile değerlenir → Değerleme farkı C tablosuna işlenir Portföy bileşimi fon bilgi formu/izahnamesinden DÖNEM BAŞI VE SONU kontrol edilmelidir. Dönem içinde portföy bileşimi değişmişse: Hangi yöntemin geçerli olduğu ayrıca analiz edilmeli. YMM notu: Değerleme yönteminin yanlış belirlenmesi C tablosunu tamamen etkiler. | D9: VUK Md.279 | Fon Mevzuatı
A11: BÖLÜM 2 — YMM TASDİK DEĞERLENDİRMESİ
A12: Kod | B12: Konu | C12: Mesleki Değerlendirme | D12: Mevzuat
A13: N5 | B13: ★ YİAKV Matrahından DÜŞÜLEBİLİR (5/1-a Kapsamı — Kritik Fark) | C13: KVK 5/1-a-4 (299) istisnası YİAKV (KVK 32/C) matrahından DÜŞÜLEBİLİR. Bu kural önemli bir karşılaştırma noktasıdır: 5/1-a kapsamı (299) → YİAKV matrahından düşülebilir ✓ 5/1-c kapsamı (318) → YİAKV matrahından DÜŞÜLEMEZ ✗ 5/1-e kapsamı (361) → Ayrıca analiz gerekli ✗/? YMM notu: YİAKV çalışma kâğıdında 299 tutarının matrahtan doğru biçimde düşüldüğü teyit edilmelidir. | D13: KVK Md.32/C | YİAKV Tebliğleri
A14: N6 | B14: 298 / 299 / 300 Kod Karışıklığı Riski | C14: 298 (KVK 5/1-a-3): GSYF/GSYO kazancı — Girişim Sermayesi 299 (KVK 5/1-a-4): Diğer TL esaslı yatırım fonları (BU FORM) 300 (KVK 5/1-a-5): Diğer fon VUK 279 değerleme farkı (mülga — geçiş) Sık karıştırma: GSYF'yi 299'a veya diğer TL fonu 298'e yazmak. VUK 279 değerleme farkını 299 yerine 300'e yazmak (veya tersi). YMM notu: Fon türü teyidi belge bazında yapılmalı; kod karıştırma → tarhiyat riski. | D14: KVK Md.5/1-a-3,4,5
A15: N7 | B15: 49 No.lu Tebliğ — Tasdik Raporu | C15: 30.12.2025 tarihli 49 No.lu Tebliğ: Tek satır >=500.000 TL veya toplam >=1.000.000 TL → YMM tasdik raporu zorunlu. Tam tasdik sözleşmesi olanlar ayrıca rapor düzenlemez. YMM notu: Beyanname 299 satırı tutarını eşikle karşılaştırın. | D15: 49 No.lu Tebliğ (30.12.2025) | YMM Kanunu Md.12
A16: N8 | B16: Muhasebe-Beyanname 3 Kademe Uyum Kontrolü | C16: Uyum zinciri: 1. Muhasebe: 640 (kâr payı) + 645 (fon iadesi kazancı) + 649 (VUK 279 artış kısmı) 2. VERİ GİRİŞİ: B toplamı + C toplamı = E.3 3. Beyanname: 299. satır Bu üç tutarın birebir uyumlu olması tasdik dosyasının tamamlanma koşuludur. Uyumsuzluk varsa: Kapsam dışı gelir karışmış, karma tarihli ayrıştırma eksik veya VUK 279 yöntemi hatalı uygulanmış olabilir. | D16: KVK Md.5/1-a-4 | VUK Md.279
A17: N9 | B17: YMM Tasdik Dil Standardı | C17: KULLANIN: '...iktisap tarihi teyit edilen paylar için kazanç istisnadan yararlanabilecektir' '...portföy bileşimi dönem başı ve sonu itibariyle doğrulanmalıdır' '...VUK 279 yöntemi fon bilgi formuyla teyit edildiği ölçüde uygulanabilir' KULLANMAYIN: '...tüm fon geliri istisnadan yararlanır' | '...kesin istisna alır' | '...sorunsuz' KRİTİK RİSK ALANLARI: (1) İktisap tarihi belgesi | (2) Portföy bileşimi | (3) Karma tarihli ayrıştırma | (4) VUK 279 %51 kriteri | (5) 298/299/300 kod ayrımı | (6) YİAKV düşüm teyidi | D17: SM-SMMM-YMM Kanunu Md.12
A19: TARTIŞMALI ALAN — GEÇİŞ DÖNEMİ: Aynı fonda 15.07.2023 öncesi ve sonrası alım varsa ve fon iadesi (redemption) geliyorsa hangi payın iade edildiği (FIFO vs. Ağırlıklı Ortalama) istisna tutarını doğrudan etkiler. GİB'in karma tarihli durumlar için kapsamlı bir özelgesi henüz yayımlanmamıştır. Karma tarihli alımlarda ihtiyati yaklaşım ve yazılı belgeleme önerilir.

Sheet BELGE LISTESI
A1: 299 – DİĞER YATIRIM FONLARI İŞTİRAK KAZANCI | BELGE VE BİLGİ LİSTESİ | YMM TASDİK
A2: KVK Md.5/1-a-4 | 7456 s.K. Mülga | 15.07.2023 Öncesi İktisap | TL Esaslı Fon | Kâr Payı+Fon İadesi+VUK 279 | YİAKV'den Düşülebilir | 49 No.lu Tebliğ
A3: Kategori 1: Her fon için zorunlu belgeler. Kategori 2: Destekleyici belgeler. Kategori 3: YMM tasdik kontrol soruları (★ kritik).
A5: KATEGORİ 1 — ZORUNLU BELGELER (Her Fon İçin Ayrı Ayrı Temin Edilmeli)
B6: No | C6: Belge / Bilgi Adı | D6: Detay ve YMM Kontrol Noktaları | E6: Temin Yeri
B7: 1 | C7: Fon Alış Dekontu / MKK Hesap Ekstresi (İktisap Tarihi İspat) | D7: Her fon için 15.07.2023'ten ÖNCE iktisap edildiğini kanıtlayan belge. Banka alış dekontu veya MKK (Merkezi Kayıt Kuruluşu) hesap ekstresi. YMM notu: İktisap tarihi bulunmayan veya belgelenemeyenler istisna kapsamında değerlendirilemez. Tarih belirsizliği en büyük tarhiyat riskidir. | E7: Banka / aracı kurum alış dekontu / MKK portal ekstresi
B8: 2 | C8: Fon Bilgi Formu / İzahname (Portföy Bileşimi Teyidi) | D8: Portföyde döviz/altın/kıymetli maden araçları olmadığının teyidi (TL esaslı fon). VUK 279 değerleme yöntemi için portföy hisse oranı belirlenmesi (%51 kriteri). YMM notu: Fon bilgi formu dönem başı ve sonu itibariyle kontrol edilmelidir. Portföy bileşimi değişmişse hangi dönem için hangi yöntemin geçerli olduğu analiz edilmeli. | E8: KAP / fon yöneticisi / Borsa İstanbul / SPK veri sistemi
B9: 3 | C9: Muhasebe Hesap Kartları (118, 640, 645 Hesapları) | D9: 118 (maliyet): Fon katılma payı alış bedeli ve bilanço değeri. 640 (kâr payı): Fon tarafından dağıtılan kâr payı gelirleri. 645 (satış/iade kazancı): Fon iadesi/satışından elde edilen kazançlar. YMM notu: Bu hesapların B tablosu toplamıyla uyumu üç kademe kontrolün birinci adımıdır. | E9: Muhasebe programı — hesap ekstresi
B10: 4 | C10: VUK 279 Değerleme Tablosu (Portföy <%51 Hisse İçin) | D10: Dönem başı ve sonu birim pay değerleri ile değerleme farkı hesabı. 31.12 tarihli fon yöneticisi ilanı veya borsa rayici kullanılmalıdır. Sadece artışlar istisna kapsamındadır — düşüşler ayrıca analiz edilmelidir. YMM notu: 649 hesabı (VUK 279 kısmı) ile C tablosu toplamı uyumlu olmalıdır. | E10: Fon yöneticisi 31.12 ilanı / KAP / Borsa günlük veri
B11: 5 | C11: Fon İadesi / Satış Dekontu (Kazanç Tespiti İçin) | D11: İade tarihi, iade bedeli, pay adedi ve birim fiyat bilgileri. Kazanç = İade Bedeli − Alış Maliyeti (FIFO veya ortalama maliyet). YMM notu: İade bedeli ile 645 hesabı kazancı uyumlu olmalıdır. | E11: Banka / aracı kurum satış/iade dekontu
B12: 6 | C12: KV Beyannamesi Taslağı — 299. Satır (Nihai veya Taslak) | D12: Beyanname 299. satırındaki tutarın VERİ GİRİŞİ E.3 ile birebir uyumlu olduğu teyit edilmeli. 'Zarar Olsa Dahi İndirilecek' bölümünde 299 kodunda doğru konumlandırıldığı kontrol edilmeli. YMM notu: 299 > E.3 ise hata; 299 < E.3 ise neden az kullanıldığı açıklanmalı. | E12: GİB e-Beyanname sistemi / İnternet Vergi Dairesi
A14: KATEGORİ 2 — DESTEKLEYİCİ BELGELER (Duruma Göre Gereklidir)
B15: No | C15: Belge / Bilgi Adı | D15: Detay ve YMM Kontrol Noktaları | E15: Temin Yeri
B16: 7 | C16: Karma Tarihli Alım Ayrıştırma Tablosu (15.07.2023 Öncesi/Sonrası) | D16: Aynı fonda 15.07.2023 öncesi ve sonrası alım varsa: Pay adedi bazında ayrıştırma tablosu. Her alım partisi: Tarih, pay adedi, birim fiyat, maliyet. Kapsam içi kısım B/C tablosuna, kapsam dışı kısım D tablosuna alınmalıdır. YMM notu: FIFO veya ağırlıklı ortalama maliyet yöntemi seçimi tutarlı uygulanmalıdır. | E16: Muhasebe / yatırım hesabı ekstresi / aracı kurum raporu
B17: 8 | C17: Fon Türü Sınıflandırma ve 298/299/300 Kod Kontrol Tablosu | D17: Portföydeki tüm yatırım fonlarının türe göre sınıflandırması: GSYF/GSYO → 298 | TL esaslı diğer fonlar → 299 | VUK 279 diğer fon → 300. Her fonun hangi koda dahil edildiğini gösteren kontrol tablosu tasdik dosyasına eklenmelidir. | E17: Muhasebe / finans birimi / fon portföy listesi
B18: 9 | C18: Değerleme Düşüşü Analiz Notu (Fon Değeri Düştüyse) | D18: VUK 279 değerleme kaybı (dönem sonu < dönem başı) durumunda: Bu tutarın KKEG mi yoksa indirilebilir gider mi olduğu ayrıca değerlendirilmelidir. İstisna yalnızca artışlar için geçerlidir — düşüşler istisna dışındadır. | E18: YMM görüş notu / Güncel mukteza araştırması
B19: 10 | C19: YİAKV Matrah Hesaplama Tablosu (299 Tutarının Düşümü) | D19: KVK 5/1-a-4 (299) istisnası YİAKV matrahından DÜŞÜLEBİLİR. YİAKV çalışma kâğıdında 299 tutarının matrahtan doğru biçimde düşüldüğü teyit edilmelidir. YMM notu: Bu kontrol 5/1-c (318) ve 5/1-e (361) ile karıştırılmamalıdır. | E19: YİAKV çalışma kâğıdı / KVK 32/C Tebliğleri
B20: 11 | C20: KKEG Tablosu — Muhasebe-Beyanname Bağlantısı | D20: B tablosu (640+645) ve C tablosu (649 VUK kısmı) gelirlerinin KKEG akışındaki konumunun gösterildiği tablo. Yılsonu KKEG → Beyanname matrahı → 299 istisna → Net etki zincirinin belgelenmesi. | E20: Muhasebe çalışma kâğıdı / KKEG tablosu
A22: KATEGORİ 3 — YMM TASDİK KONTROL SORULARI (★ İşaretli Sorular Kritiktir)
B23: No | C23: Kontrol Sorusu | D23: Beklenen Sonuç / Tasdik Standardı | E23: YMM Aksiyonu
B24: S1 | C24: ★ Her fonun iktisap tarihi 15.07.2023'ten önce olduğu belgeyle teyit edildi mi? | D24: Banka/MKK dekontu mevcut olmalı. Belgesiz fon istisna kapsamında değerlendirilemez. Risk: Tarihin 15.07.2023 sonrası olması veya belge eksikliği → Tarhiyat. | E24: YMM kontrolü
B25: S2 | C25: ★ Portföyde döviz/altın/kıymetli maden araçları YOK mu? | D25: Fon bilgi formu/izahnamesi kontrol edilmeli. Bu varlıkları içeren fonlar kapsam dışıdır. Kapsam dışı fonlar D tablosuna alınmış olmalıdır. | E25: YMM kontrolü
B26: S3 | C26: Fon türü doğru sınıflandırıldı mı? (298 / 299 / 300 ayrımı) | D26: GSYF/GSYO → 298. GYF/GYO → 5/1-d analiz. Döviz/Altın fon → Kapsam dışı. VUK 279 diğer fon → 300 (mülga geçiş). Bu form 299 TL esaslı diğer fonlar içindir. | E26: YMM kontrolü
B27: S4 | C27: VUK 279 değerleme yöntemi portföy %51 kriteri ile uyumlu mu? | D27: ≥%51 BIST hisse: Alış bedeli → Değerleme farkı yok → C tablosu boş. <%51 hisse: Borsa rayici → C tablosuna değerleme farkı. Fon bilgi formu ile teyit edilmeli. | E27: YMM kontrolü
B28: S5 | C28: Muhasebe 640+645+649 toplamı beyanname 299 ile uyumlu mu? | D28: 3 kademe uyum: Muhasebe hesapları = VERİ GİRİŞİ E.3 = Beyanname 299. Fark varsa kapsam dışı gelir karışmış veya karma tarihli ayrıştırma eksik olabilir. | E28: YMM kontrolü
B29: S6 | C29: Karma tarihli alım ayrıştırması tam yapıldı mı? | D29: Aynı fonda 15.07.2023 öncesi/sonrası alım varsa pay adedi bazında ayrıştırma zorunlu. Kapsam içi kısım → B/C tablosu. Kapsam dışı kısım → D tablosu. | E29: YMM kontrolü
B30: S7 | C30: YİAKV matrahında 299 istisnası DÜŞÜLDܒ mü? (5/1-a kapsamı — düşülebilir) | D30: 299 istisnası YİAKV matrahından DÜŞÜLEBİLİR. YİAKV çalışma kâğıdında 299 tutarı matrahtan düşülmüşse doğrudur. Düşülmemişse gözden geçirilmeli. | E30: YMM kontrolü
B31: S8 | C31: Beyanname 299 'Zarar Olsa Dahi' bölümünde mi? Doğru konumlandı mı? | D31: 'Kazancın Bulunması Halinde' bölümüyle karıştırılmamalıdır. 299 satırı 'Zarar Olsa Dahi İndirilecek' bölümündedir. Yanlış bölüm: Tarhiyat riski. | E31: YMM kontrolü
A33: SON NOT (YMM TASDİK): 49 No.lu Tebliğ (30.12.2025): >=500.000 TL → YMM raporu zorunlu. Tam tasdik → ayrıca rapor yok. İktisap tarihi belgesi eksikliği en büyük tarhiyat riskidir. Portföy bileşimi her dönem teyit edilmelidir. 298/299/300 kod ayrımı titizlikle yapılmalıdır. YİAKV matrahından 299 istisnası DÜŞÜLEBİLİR (5/1-c'den farklı). YMM müteselsil sorumluluk: SM-SMMM-YMM Kanunu Md.12.
