Workbook

Sheet VERİ GİRİŞİ
A1: 319 – EMİSYON PRİMİ KAZANCI İSTİSNASI | KVK Md.5/1-ç | YMM TASDİK ÇALIŞMA KÂĞIDI
A2: KVK Md.5/1-ç | YALNIZCA Anonim Şirket | Kendi Paylarının Primli İhracı | %100 Tam İstisna | Zarar Olsa Dahi İndirilecek — Beyanname Satır 319 | YİAKV'den DÜŞÜLEBİLİR
A3: ★ KRİTİK BEYANNAME TEKNİĞİ: Emisyon primi 520 hesabına gider — gelir tablosuna GİRMEZ — ticari karda YOKTUR. Bu nedenle: (1) Önce KKEG olarak matrah artar, (2) Ardından 319 ile düşülür → Net vergi etkisi SIFIR. Bu iki işlem ZORUNLU ve EŞZAMANLI olmalıdır.
A4: KAPSAM DIŞI: AŞ'nin başkasına ait hisseleri elden çıkarmasından sağlanan kazanç (5/1-e/c). Sermaye azaltımı sırasında iptal edilen payların bedeli. Kâr dağıtımından kaynaklanan işlemler.
A6: A0. KAPSAM VE NİTELİK UYGUNLUK ÖN KONTROLÜ
B7: Kontrol Sorusu | E7: Yanıt | G7: YMM Tasdik Notu
A8: A0.1 ★ İstisna kullanan kurum ANONİM ŞİRKET mi? | E8: EVET | F8: KVK 5/1-ç'de 'anonim şirketlerin' ifadesi açık hükümdür. Ltd.Şti. için bu madde kapsamında açık bir istisna hükmü yoktur; tartışmalıdır. Ticaret sicil belgesi zorunludur.
A9: A0.2 ★ İstisna şirketin KENDİ paylarının primli ihracından mı? (Başkasına ait hisse satışı değil) | E9: EVET | F9: TEMEL KAPSAM SINIRI: AŞ'nin kendi hisselerini primli ihraç etmesi. Başkasına ait hisseleri satmak → 5/1-c veya 5/1-e. Pay senedi + sermaye artırım tescili ile belgelenmeli.
A10: A0.3 Pay ihracı kuruluş veya sermaye artırımı kapsamında mı? | E10: EVET | F10: KVK 5/1-ç: 'Kuruluşlarında VEYA sermayelerini artırdıkları sırada' ifadesi zorunludur. Sonradan çıkarılan primli paylar (sermaye artırımı olmaksızın) kapsam dışı tartışmalıdır.
A11: A0.4 Satış bedeli itibari değerin ÜSTÜNDE mi? (Gerçek primli ihraç) | E11: EVET | F11: Emisyon primi = Satış Bedeli − İtibari Değer > 0 olmalıdır. İtibari değere eşit veya altında ihraç → 319 istisnası uygulanmaz. C bölümündeki C.5 formülü ile kontrol edin.
A12: A0.5 ★ 520 hesabı kullanıldı mı? Emisyon primi gelir tablosuna GİRMEDİ mi? | E12: EVET | F12: KRİTİK MUHASEBE: Emisyon primi 520 (Hisse Senedi İhraç Primleri) hesabına kaydedilmelidir. Gelir tablosuna GİRMEMELİDİR. 520 yerine 649 veya 679'a kaydedilmişse muhasebe hatası var.
A13: A0.6 ★ KKEG ilavesi yapıldı mı? (519 satırı — 319 ile birlikte ZORUNLU) | E13: EVET | F13: KRİTİK BEYANNAME TEKNİĞİ: 520'ye giden tutar gelir tablosuna girmediğinden önce KKEG olarak matrah artırılmalı (519 satırı), ardından 319 ile düşülmelidir. KKEG yapılmadan sadece 319 yazılırsa beyanname HATALIDIR.
A14: A0.7 NSA (KVK 10/1-ı) hesabında emisyon primi tescil edilmeyen kısma DÂHİL EDİLMEDİ mi? | E14: EVET | F14: Emisyon primleri nakdi sermaye artışı indirim (NSA) hesabında dikkate ALINMAZ. Sadece tescil edilen sermaye artışı NSA'ya girer. NSA hesaplama tablosunda kontrol edilmelidir.
A15: A0.8 YMM Tasdik Raporu gereksinimi değerlendirildi mi? (49 No.lu Tebliğ) | E15: EVET | F15: 49 No.lu Tebliğ (30.12.2025): Tek satır >=500.000 TL veya toplam >=1.000.000 TL → YMM raporu. Tam tasdik sözleşmesi olanlar ayrıca rapor düzenlemez.
A16: A0.9 Tasdik Uygunluk Sonucu (A0.1-A0.8 tümü) | E16: =IF(AND(E8="EVET",E9="EVET",E10="EVET",E11="EVET",E12="EVET",E13="EVET",E14="EVET",E15="EVET"),"OK - Hesaplanabilir","HATA - Ön koşul eksik") -> OK - Hesaplanabilir | F16: ★ A0.2 (kendi payı), A0.5 (520 hesabı), A0.6 (KKEG zorunlu) kritik.
A18: A. GENEL BİLGİLER
A19: İstisna Kullanan Kurum (Anonim Şirket) | F19: Anonim şirket olmalı — tam unvan
A20: Vergi Kimlik Numarası | F20: 10 haneli VKN
A21: İşlemin Türü | F21: Kuruluş / Sermaye Artırımı
A22: Primli Pay İhraç Tarihi | F22: GG.AA.YYYY
A23: Hesap Dönemi | F23: Örn: 01.01.2025 – 31.12.2025
A24: Genel KV Oranı (%) | F24: 2025: %25 | Finans sektörü: %30
A26: B. MÜKELLEF VE KAPSAM KONTROLÜ — Üç Temel Şart
A27: 5/1-ç istisnası üç temel şartın KÜMÜLATİF sağlanmasını gerektirir: (1) Anonim şirket, (2) Kendi paylarının ihracı, (3) Kuruluş veya sermaye artırımı.
B28: Şart | D28: Durum | F28: Açıklama / YMM Notu
A29: B.1 ★ Anonim Şirket Statüsü | D29: EVET | F29: KVK 5/1-ç: 'Anonim şirketlerin' — açık hüküm. Ltd.Şti. için bu kapsamda açık hüküm yoktur. Ticaret sicil belgesi zorunludur.
A30: B.2 ★ Şirketin KENDİ Paylarının Primli İhracı | D30: EVET | F30: AŞ'nin başkasına ait hisseleri satması → Bu istisna KULLANILAMAZ. Pay senedi / ilmühaber + sermaye artırım tescil belgesi ile belgelenmelidir.
A31: B.3 Kuruluş veya Sermaye Artırımı Kapsamında İhraç | D31: EVET | F31: Genel kurul / yönetim kurulu (kayıtlı sermaye) kararıyla gerçekleşen primli ihraç. Ticaret siciline tescil zorunludur.
A33: C. EMİSYON PRİMİ HESABI — İstisna Tutarı
A34: EMİSYON PRİMİ = (Pay Başına Satış Bedeli − Pay Başına İtibari Değer) × İhraç Edilen Pay Adedi. Satış bedeli itibari değerin ÜSTÜNDE olmalıdır. Prim tutarı 520 (Hisse Senedi İhraç Primleri) hesabına kaydedilir — gelir tablosuna GİRMEZ.
B35: Hesap Kalemi | D35: Değer / Tutar (TL) | F35: Açıklama | G35: YMM Notu
A36: C.1 İhraç Edilen Pay Adedi | D36: Primli olarak satılan toplam pay adedi | F36: GK/YK kararındaki pay adediyle uyumlu olmalı
A37: C.2 Pay Başına İtibari Değer (TL) | D37: Hisse senedinin üzerinde yazılı nominal değer (örn: 1 TL) | F37: Ticaret sicili tescilindeki nominal değer esas alınır
A38: C.3 Pay Başına Satış Bedeli / İhraç Fiyatı (TL) | D38: Primli ihraç fiyatı — itibari değerin ÜSTÜNDE olmali | F38: GK/YK kararında belirlenen ihraç fiyatı
A39: C.4 Pay Başına Emisyon Primi (C.3 − C.2) | C39: =C38-C37 -> 0 | D39: Birimin prim tutarı (pozitif olmalı) | F39: Negatif ise istisna uygulanamaz
A40: C.5 Toplam Nominal Bedel (C.1 × C.2) | C40: =C36*C37 -> 0 | D40: Sermaye artırımının tescile esas kısmı | F40: 501 Ödenmemiş Sermaye ve 500 Sermaye ile uyumlu
A41: C.6 Toplam Tahsil Edilen Bedel (C.1 × C.3) | C41: =C36*C38 -> 0 | D41: Nakden tahsil edilen toplam tutar | F41: 102 Banka tahsilatı ile uyumlu olmalı
A42: C.7 EMİSYON PRİMİ = 319 İSTİSNA TUTARI (C.6 − C.5) | C42: =C41-C40 -> 0 | F42: Bu tutar KKEG ilavesi ve 319 satırıyla eşit olmalıdır
A43: C.8 TTK 519 Kanuni Yedek Akçe (Emisyon Priminden Ayrılacak Min. Tutar) | C43: =C42 -> 0 | D43: TTK Md.519/2: Emisyon priminin tamamı kanuni yedek akçeye eklenmeli | F43: Giderler düşüldükten sonra kalan kısım yedek akçeye aktarılır
A45: D. İHRAÇ GİDERLERİ VE KVK 5/3 KKEG ANALİZİ
...

Sheet HESAPLAMALAR & KONTROL
A1: 319 – EMİSYON PRİMİ KAZANCI | HESAPLAMALAR VE DENETİM KONTROL PANELİ
A2: KVK Md.5/1-ç | Anonim Şirket | Kendi Paylarının Primli İhracı | %100 İstisna | KKEG + 319 Zorunlu | YİAKV'den Düşülebilir
A4: A. TASDİK ÖZETİ — VERİ GİRİŞİNDEN OTOMATİK
A5: A0 Tasdik Uygunluğu | D5: ='VERİ GİRİŞİ'!E16 -> OK - Hesaplanabilir | E5: A0.9 OK ise devam
A6: AŞ Şartı (B.1) | D6: ='VERİ GİRİŞİ'!D29 -> EVET | E6: EVET zorunlu
A7: İhraç Edilen Pay Adedi | D7: ='VERİ GİRİŞİ'!C36 -> 0 | E7: C.1 değeri
A8: Pay Başına Emisyon Primi (C.4) | D8: ='VERİ GİRİŞİ'!C39 -> 0 | E8: Pozitif olmali
A9: Toplam Nominal Bedel (C.5) | D9: ='VERİ GİRİŞİ'!C40 -> 0 | E9: Sermaye tescil tutarı
A10: Toplam Tahsilat (C.6) | D10: ='VERİ GİRİŞİ'!C41 -> 0 | E10: Banka ile uyumlu
A11: EMİSYON PRİMİ = 319 İSTİSNA (C.7) | D11: ='VERİ GİRİŞİ'!C42 -> 0 | E11: C.7 = E.2 KKEG = E.4 319
A12: İhraç Giderleri KKEG Kısmı (D.3) | D12: ='VERİ GİRİŞİ'!C50 -> 0 | E12: KVK 5/3 — matrahtan düşülemez
A13: E.5 Net Vergi Etkisi (SIFIR OLMALI) | D13: ='VERİ GİRİŞİ'!C60 -> 0 | E13: SIFIR ise KKEG+319 doğru
A15: B. BEYANNAME TEKNİĞİ DOĞRULAMA — KKEG + 319 ÇİFT KAYIT
A16: KKEG tutarı (E.2) ile 319 tutarı (E.4) HER ZAMAN EŞİT OLMALIDIR. İkisi aynı emisyon primini temsil eder. E.5 (Net Etki) SIFIR vermezse beyanname hatalıdır.
B17: Kalem | D17: Tutar (TL) | F17: Beyanname Yeri
A18: KKEG İlavesi (519 Satırı) | D18: ='VERİ GİRİŞİ'!C57 -> 0 | E18: KV Beyannamesi — KKEG Tablosu
A19: 319 İstisnası | D19: ='VERİ GİRİŞİ'!C59 -> 0 | E19: KV Beyannamesi — 319 Satırı
A20: Net Etki (SIFIR OLMALI) | D20: ='VERİ GİRİŞİ'!C60 -> 0 | E20: KKEG − 319 = 0 ✓
A22: C. DENETİM KONTROL LİSTESİ (K1–K11)
B23: Kontrol | D23: Açıklama ve Kanıt | F23: Sonuç | G23: YMM Aksiyonu
A24: K1 | B24: ★ Kurum Anonim Şirket mi? (KVK 5/1-ç açık hükmü) | D24: Ticaret sicil gazetesi — AŞ ibaresi zorunlu. Ltd için açık hüküm yoktur. | F24: Uygun / Eksik / Risk
A25: K2 | B25: ★ İstisna şirketin KENDİ paylarının primli ihracından mı? | D25: Pay senedi + sermaye artırım tescil belgesi. Başkasına ait hisse satışı → 5/1-e/c. | F25: Uygun / Eksik / Risk
A26: K3 | B26: Satış bedeli itibari değerin üstünde mi? (Gerçek prim var mı?) | D26: C.4 = C.3 − C.2 > 0 olmalıdır. Negatif veya sıfır ise istisna uygulanamaz. | F26: Uygun / Eksik / Risk
A27: K4 | B27: ★ 520 hesabı kullanıldı mı? Emisyon primi gelir tablosuna GİRMEDİ mi? | D27: Muhasebe: 102 Banka Borç / 501 Sermaye Alacak + 520 Alacak. 520 yerine 649/679'a kaydedilmişse hata. | F27: Uygun / Eksik / Risk
A28: K5 | B28: ★ KKEG ilavesi yapıldı mı? (519 satırı — 319 ile aynı tutar) | D28: Beyanname KKEG tablosu (519 satırı): C.7 tutarında emisyon primi. Bu yapılmadan sadece 319 yazılırsa beyanname hatalıdır. | F28: Uygun / Eksik / Risk
A29: K6 | B29: ★ 319 tutarı KKEG tutarıyla EŞİT mi? E.5 = 0 mi? | D29: HESAPLAMALAR B bölümündeki E.5 kontrol satırı SIFIR vermelidir. Fark varsa hesap hatası var. | F29: Uygun / Eksik / Risk
A30: K7 | B30: İhraç giderleri KVK 5/3 kapsamında doğru ayrıştırıldı mı? | D30: D.3 = Toplam Gider × (Emisyon Primi / Toplam Tahsilat). Bu kısım KKEG olarak beyannamede ayrıca eklenir. | F30: Uygun / Eksik / Risk
A31: K8 | B31: TTK 519 kanuni yedek akçe ayrımı yapıldı mı? | D31: Emisyon priminin (giderler düşüldükten sonra) tamamı kanuni yedek akçeye eklenmeli. Genel kurul kararı zorunludur. | F31: Uygun / Eksik / Risk
A32: K9 | B32: NSA (KVK 10/1-ı) hesabında emisyon primi tescil edilmeyen kısma dahil edilmedi mi? | D32: Emisyon primleri NSA hesabına girmez. NSA hesaplama tablosunda bu kontrol zorunludur. | F32: Uygun / Eksik / Risk
A33: K10 | B33: YİAKV matrahından 319 istisnası DÜŞÜLDܒ mü? | D33: Emisyon primi istisnası (319) YİAKV matrahından DÜŞÜLEBİLİR. YİAKV çalışma kâğıdında teyit edilmeli. | F33: Uygun / Eksik / Risk
A34: K11 | B34: Birleşme/devir/bölünmede emisyon primleri doğru aktarıldı mı? | D34: KVK 18,19,20 kapsamında devir/bölünmede emisyon primlerinin devralan şirkete aynen aktarılması vergi avantajını korur. Devir sözleşmesi + bilanço kontrolü zorunludur. | F34: Uygun / Eksik / Risk
A36: D. BEYANNAME SATIR EŞLEŞTİRME
B37: Satır | D37: Tutar / Not | F37: Açıklama
A38: 319 | C38: ='VERİ GİRİŞİ'!C42 -> 0 | D38: KVK 5/1-ç — Emisyon Primi | %100 İstisna | Zarar Olsa Dahi İndirilecek
A39: KKEG | C39: ='VERİ GİRİŞİ'!C42 -> 0 | D39: Aynı tutar KKEG tablosuna da girilmeli (519 satırı) — ZORUNLU EŞLİK
A40: NSA | C40: Dahil Edilmez | D40: KVK 10/1-ı NSA hesabına emisyon primleri girmez — sadece tescil edilen sermaye artar

Sheet MUHASEBE KAYITLARI
A1: 319 – EMİSYON PRİMİ KAZANCI | MUHASEBE KAYITLARI ÇALIŞMA KÂĞIDI
A2: KVK Md.5/1-ç | %100 Tam İstisna | 520 Hesabı | KKEG + 319 Zorunlu | TTK 519 Yedek Akçe
A3: NOT: Rehber niteliğindedir. Şirkete özgü hesap planına göre uyarlanmalıdır. Emisyon primi gelir tablosuna GİRMEZ — 520 (Öz Kaynaklar) hesabına kaydedilir.
A5: KAYIT 1 — PRİMLİ PAY İHRACI (KENDİ PAYLARI — SERMAYE ARTIRIMI)
A6: Örnek: Nominal 1.500.000 TL sermaye artırımı, 500.000 TL emisyon primi → Toplam tahsilat 2.000.000 TL
B7: Tarih | C7: Hesap Adı / Kodu | D7: Muhasebe Notu | E7: Dr (TL) | F7: Kr (TL) | G7: Referans
A8: Dr | B8: İhraç tarihi | C8: 102 Bankalar | D8: Toplam tahsilatın bankaya girişi (nominal + prim) | E8: 2.000.000 | F8: — | G8: Banka dekontu
A9: Kr | B9: İhraç tarihi | C9: 501 Ödenmemiş Sermaye | D9: Taahhüt edilen sermaye artırımının kaydı | E9: — | F9: 1.500.000 | G9: GK/YK kararı
A10: Kr | B10: İhraç tarihi | C10: 520 Hisse Senedi İhraç Primleri | D10: EMİSYON PRİMİ — Öz Kaynaklar altında (GELİR TABLOSUNA GİRMEZ!) | E10: — | F10: 500.000 | G10: KVK 5/1-ç
A11: KRİTİK MUHASEBE NOTU: 520 hesabına kaydedilen emisyon primi GELİR TABLOSUNA GİRMEZ. Bu nedenle ticari karda görünmez. Tescil sonrası: 501 → 500 Sermaye aktarılır (Dr 501 / Kr 500).
A13: KAYIT 2 — İHRAÇ GİDERLERİ (KVK 5/3 KKEG AYIRIMI)
A14: Örnek: Toplam gider 100.000 TL, emisyon primi oranı %25 → KKEG: 25.000 TL, İndirilebilir: 75.000 TL
B15: Tarih | C15: Hesap Adı / Kodu | D15: Muhasebe Notu | E15: Dr (TL) | F15: Kr (TL) | G15: Referans
A16: Dr | B16: Gider tarihi | C16: 689 / 770 Genel Yönetim Giderleri | D16: Aracılık, tescil harcı, noter, gazete ilanı, hukuki vb. | E16: 100.000 | F16: — | G16: Fatura
A17: Kr | B17: Gider tarihi | C17: 102 Bankalar | D17: Ödeme | E17: — | F17: 100.000 | G17: Banka dekontu
A18: Beyanname | B18: — | C18: KKEG: İstisna kısmına isabet eden gider (25.000 TL) | D18: KVK 5/3: Bu kısım KKEG — beyanname KKEG tablosuna eklenir. KDV'si de indirim konusu yapılamaz (KDVK 30/d). | E18: 25.000 | F18: — | G18: KVK 5/3
A20: ★ KAYIT 3 — KRİTİK BEYANNAME TEKNİĞİ (KKEG + 319 ZORUNLU EŞLİK)
A21: BEYANNAME MEKANİZMASI — Emisyon priminin KV dışı tutulma yolu: ADIM 1: Ticari Kâr hesaplanır. Emisyon primi 520'ye gittiğinden ticari karda YOKTUR. ADIM 2: KKEG İLAVESİ (519 satırı): Emisyon primi tutarı beyannamede KKEG olarak matrahı artırır. → Bu adım olmadan sadece 319 yazılamaz! ADIM 3: 319 İSTİSNA DÜŞÜMÜ: 'Zarar Olsa Dahi İndirilecek' bölümünde aynı tutar düşülür. → KKEG ile 319 HER ZAMAN EŞİT OLMALIDIR. SONUÇ: KKEG ilavesi − 319 düşümü = SIFIR → Emisyon priminde KV ödenmez. ✓
A23: KAYIT 4 — TTK 519 KANUNİ YEDEK AKÇE AYRIMI
B24: Tarih | C24: Hesap Adı / Kodu | D24: Muhasebe Notu | E24: Dr (TL) | F24: Kr (TL) | G24: Referans
A25: Dr | B25: Dönem sonu | C25: 520 Hisse Senedi İhraç Primleri | D25: Emisyon priminin kanuni yedek akçeye aktarılması (giderler düşüldükten sonra) | E25: [Net Prim] | F25: — | G25: TTK Md.519/2
A26: Kr | B26: Dönem sonu | C26: 541 Yasal Yedekler (Kanuni Yedek Akçe) | D26: TTK 519: Emisyon priminin tamamı kanuni yedek akçeye eklenmeli | E26: — | F26: [Net Prim] | G26: GK kararı
A27: TTK Md.519/2: Emisyon primlerinin tamamı (giderler düşüldükten sonra) kanuni yedek akçeye eklenmeli. Bu aktarım için genel kurul kararı gerekebilir. Aktarım yapılmadan 520 bakiyesinde bırakmak TTK 519 ihlali riski taşır.

Sheet DENETCİ NOTLARI
A1: 319 – EMİSYON PRİMİ KAZANCI | DENETÇİ NOTLARI VE MESLEKİ DEĞERLENDİRME
A2: KVK Md.5/1-ç | Anonim Şirket | Kendi Paylarının Primli İhracı | %100 İstisna | KKEG+319 Zorunlu | YİAKV Düşülebilir | TTK 519 | NSA Dışında
A4: BÖLÜM 1 — YASAL DAYANAK VE TEMEL KAVRAMLAR
A5: Kod | B5: Konu | C5: Mesleki Değerlendirme | D5: Mevzuat
A6: N1 | B6: KVK 5/1-ç — Kanun Metni ve Kapsam | C6: KVK Md.5/1-ç (Tam metin): 'Anonim şirketlerin kuruluşlarında veya sermayelerini artırdıkları sırada çıkardıkları payların bedelinin itibarî değeri aşan kısmı.' EMİSYON PRİMİ = (Satış Bedeli − İtibari Değer) × Pay Adedi İstisna: %100 Tam İstisna — Zarar olsa dahi indirilecek. Muhasebe: 520 (Hisse Senedi İhraç Primleri) hesabına kaydedilir. YMM notu: Beyanname 319. satırına yazılır. | D6: KVK Md.5/1-ç
A7: N2 | B7: Kapsam Sınırları — Neyin İstisna OLMAYACAĞI | C7: KAPSAM DIŞI: ✗ AŞ'nin başkasına ait hisseleri satmasından sağlanan prim → 5/1-c veya 5/1-e kapsamı ✗ Sermaye azaltımı sırasında iptal edilen payların tutarı ✗ Kâr dağıtımından kaynaklanan işlemler ✗ İkincil piyasada hisse senedi alım-satımı (AŞ'nin kendi paylarını geri alıp satması tartışmalı) ✗ Borçlanma araçları ihraçlarındaki prim (tahvil primi — ayrı bir hüküm yoktur) YMM notu: 'Kendi paylarının primli ihracı' ifadesi belge ile doğrulanmalıdır. | D7: KVK Md.5/1-ç | Danıştay içtihatları
A8: N3 | B8: ★ Beyanname Tekniği — KKEG + 319 Birlikte Zorunlu | C8: EMİSYON PRİMİNİN KV SİSTEMİNDEKİ YERİ: 1. Emisyon primi → 520 hesabına gider → Gelir tablosuna GİRMEZ 2. Ticari karda görünmez → Beyanname düzeltme mekanizması zorunlu DOĞRU BEYANNAME AKIŞI: a) KKEG ilavesi (519 satırı): 520'ye giden tutar KKEG olarak matrahı artırır b) 319 istisnası: 'Zarar Olsa Dahi İndirilecek' bölümünde AYNI TUTAR düşülür c) Net etki: SIFIR → Emisyon priminde KV ödenmez HATA SENARYOSU: Sadece 319 yazılır, KKEG yapılmaz → Matrah yanlış → Tarhiyat riski! | D8: KVK Md.5/1-ç | GİB Özelgeleri | Danıştay
A9: N4 | B9: KVK 5/3 — İhraç Giderleri KKEG Analizi | C9: KVK 5/3: İstisna kazançlara ilişkin giderler KKEG'dir. İhraç giderlerinin emisyon primine isabet eden kısmı KKEG. Oran = Emisyon Primi / Toplam Tahsilat. Danıştay emsal kararı: İhraç giderlerinin KKEG sayılacağı teyit edilmiştir. KDV: İstisna işleme ait giderlerin KDV'si KDVK 30/d kapsamında indirim konusu yapılamaz. YMM notu: Gider ayrıştırma tablosu (D bölümü) tasdik dosyasına eklenmelidir. | D9: KVK Md.5/3 | KDVK Md.30/d | Danıştay
A11: BÖLÜM 2 — YMM TASDİK DEĞERLENDİRMESİ VE DİĞER ETKİLEŞİMLER
A12: Kod | B12: Konu | C12: Mesleki Değerlendirme | D12: Mevzuat
A13: N5 | B13: TTK 519 Kanuni Yedek Akçe Zorunluluğu | C13: TTK Md.519/2: Emisyon primlerinin giderler düşüldükten sonra kalan kısmının TAMAMI kanuni yedek akçeye eklenmeli. Genel kurul kararı gerekebilir. 520 bakiyesini yedek akçeye aktarmadan tutmak TTK 519 ihlali riski taşır. YMM notu: TTK uyumu KVK 5/1-ç istisnasının koşulu olmasa da tasdik dosyasında TTK 519 uyumu teyit edilmelidir. | D13: TTK Md.519/2
A14: N6 | B14: YİAKV'den DÜŞÜLEBİLİR (5/1-ç Kapsamı) | C14: KVK 32/C kapsamındaki YİAKV hesabında emisyon primi istisnası (319) MATRAHTAN DÜŞÜLEBİLİR. Bu, bazı diğer istisnalardan (5/1-c = 318 gibi) farklı bir durumdur. YİAKV çalışma kâğıdında 319 tutarı matrahtan doğru biçimde düşülmelidir. YMM notu: KPMG/7524 s.K. değerlendirmesi ve güncel GİB açıklamalarıyla teyit. | D14: KVK Md.32/C | YİAKV Tebliğleri
A15: N7 | B15: NSA (KVK 10/1-ı) — Emisyon Primleri Dahil Edilmez | C15: Nakdi Sermaye Artışı İndirimi (NSA) hesabında EMİSYON PRİMLERİ dikkate ALINMAZ. NSA'ya giren tutar: Ticaret siciline tescil edilen sermaye artışının nakdi kısmı. Emisyon primleri tescil edilen sermayeye değil, 520 hesabına gider. YMM notu: NSA hesaplama tablosunda emisyon priminin dahil edilmediği teyit edilmeli. | D15: KVK Md.10/1-ı | NSA Tebliğleri
A16: N8 | B16: Birleşme/Devir/Bölünmede Emisyon Primleri | C16: KVK 18, 19, 20 kapsamında birleşme/devir/bölünmede: Emisyon primlerinin devralan şirkete aynen aktarılması vergi avantajının devam etmesini sağlar. Aksi halde devir bilançosunda emisyon priminin farklı işlenmesi vergi riski doğurabilir. YMM notu: Devir/bölünme sözleşmesi + bilanço kontrolü zorunludur. | D16: KVK Md.18, 19, 20 | Danıştay
A17: N9 | B17: 49 No.lu Tebliğ — Tasdik Raporu + YMM Tasdik Dil Standardı | C17: 49 No.lu Tebliğ (30.12.2025): >=500.000 TL → YMM raporu. Tam tasdik → ayrıca rapor yok. KULLANIN: '...KVK 5/1-ç şartları sağlandığı ölçüde emisyon primi istisnası uygulanabilecektir' '...KKEG ilavesi ve 319 istisna düşümünün birlikte uygulandığı doğrulanmalıdır' KULLANMAYIN: '...otomatik olarak istisna uygulanır' | '...sorunsuz' | '...tüm primler kapsam içindedir' KRİTİK RİSK: KKEG yapılmadan sadece 319 → Tarhiyat. | D17: 49 No.lu Tebliğ | SM-SMMM-YMM K. Md.12
A19: ÖZELGE/DANIŞTAY: İzmir VDB (2011): Emisyon priminin KKEG + 319 tekniğiyle beyan edilmesi onaylanmıştır. Danıştay: İhraç giderlerinin KKEG sayıldığı teyit edilmiştir. Ltd şirketler için emisyon primi istisnasının uygulanabilirliği tartışmalıdır — özelge alınması tavsiye edilir.

Sheet BELGE LISTESI
A1: 319 – EMİSYON PRİMİ KAZANCI | BELGE VE BİLGİ LİSTESİ | YMM TASDİK
A2: KVK Md.5/1-ç | Anonim Şirket | Kendi Paylarının Primli İhracı | %100 İstisna | 520 Hesabı | KKEG+319 Zorunlu | TTK 519 | YİAKV Düşülebilir | NSA Dışında
A3: Kategori 1: Zorunlu belgeler. Kategori 2: Destekleyici. Kategori 3: YMM tasdik kontrol soruları (★ kritik).
A5: KATEGORİ 1 — ZORUNLU BELGELER (Tamamı Mevcut Olmadan Tasdik Tamamlanmaz)
B6: No | C6: Belge / Bilgi Adı | D6: Detay ve YMM Kontrol Noktaları | E6: Temin Yeri
B7: 1 | C7: Anonim Şirket Statüsünü İspat Eden Belge | D7: KVK 5/1-ç açık hükmü: 'Anonim şirketlerin...' — AŞ statüsü zorunludur. Ticaret sicil gazetesi veya güncel ticaret sicil tasdiknamesi. YMM notu: Ltd şirketler için bu kapsamda açık hüküm yoktur. Tartışmalı durumlarda özelge alınması tavsiye edilir. | E7: Ticaret sicil gazetesi / MERSİS / Ticaret sicil tasdiknamesi
B8: 2 | C8: Primli Pay İhraç Kararı (GK veya YK Kararı) | D8: Genel kurul veya yönetim kurulu (kayıtlı sermaye sisteminde) kararı. Primli ihraç fiyatı, itibari değer ve pay adedini açıkça göstermeli. YMM notu: İhraç fiyatının itibari değeri aştığı GK/YK kararında görünmeli. Karar olmadan primli ihraç belgelenemez. | E8: GK/YK karar metni / Yönetim kurulu toplantı tutanağı
B9: 3 | C9: Sermaye Artırım Tescil Belgesi (Ticaret Sicili) | D9: Tescil edilen nominal sermaye artışı tutarı görünmeli. Emisyon priminin tescil edilmediği (yalnızca nominal kısmın tescil edildiği) teyit edilmeli. YMM notu: NSA hesabında tescil edilen tutar esas alınır — emisyon primi tescil edilmez. | E9: Türkiye Ticaret Sicili Gazetesi / MERSİS tescil çıktısı
B10: 4 | C10: 520 Hesap Hareketi — Yevmiye ve Mizan | D10: 102 Bankalar Borç / 501 Ödenmemiş Sermaye + 520 Alacak kaydı. 520 hesabına kaydedildiği ve gelir tablosuna GİRMEDİĞİ teyit edilmeli. YMM notu: 520 yerine 649/679'a kaydedilmişse muhasebe hatası — düzeltme zorunlu. | E10: Yevmiye defteri + Mizan / 520 hesap ekstresi
B11: 5 | C11: KV Beyannamesi KKEG Tablosu (519 Satırı — Emisyon Primi) | D11: Emisyon priminin KKEG olarak beyanname matrahına eklendiği teyit edilmeli. KKEG tutarı = C.7 (Emisyon Primi) ile eşit olmalıdır. YMM notu: KKEG ilavesi yapılmadan sadece 319 yazılırsa beyanname HATALIDIR. Bu iki kaydın birlikte bulunması zorunludur. | E11: Onaylı KV beyannamesi — KKEG tablosu
B12: 6 | C12: KV Beyannamesi 319. Satır | D12: 'Zarar Olsa Dahi İndirilecek' bölümünde 319 satırında gösterilmeli. KKEG tutarıyla HER ZAMAN EŞİT olmali. YMM notu: HESAPLAMALAR B bölümü E.5 (Net Etki) SIFIR vermelidir. Sıfır vermiyorsa hata var. | E12: Onaylı KV beyannamesi — 319. satır
A14: KATEGORİ 2 — DESTEKLEYİCİ BELGELER (Duruma Göre Gereklidir)
B15: No | C15: Belge / Bilgi Adı | D15: Detay ve YMM Kontrol Noktaları | E15: Temin Yeri
B16: 7 | C16: İhraç Giderleri Listesi ve KVK 5/3 KKEG Analizi | D16: Aracılık komisyonu, tescil harcı, noter, gazete ilanı, danışmanlık vb. gider listesi. D.3 hesabı: Emisyon primine isabet eden kısım KKEG. KDV: İstisna kısma isabet eden KDV'nin indirimi tartışmalıdır (KDVK 30/d). YMM notu: KKEG gider analizi yazılı olarak tasdik dosyasına eklenmelidir. | E16: Fatura + Oran hesaplama tablosu (D bölümü)
B17: 8 | C17: TTK 519 Kanuni Yedek Akçe Ayrım Belgesi | D17: Emisyon priminin giderler düşüldükten sonra kanuni yedek akçeye aktarıldığını gösterir. Genel kurul kararı ve muhasebe aktarım kaydı. YMM notu: TTK 519 uyumu KVK istisnasının koşulu olmasa da tasdik dosyasında yer almalıdır. | E17: GK kararı + 520→541 muhasebe kaydı
B18: 9 | C18: NSA (KVK 10/1-ı) Hesaplama Tablosu | D18: Emisyon priminin NSA hesabına DAHİL EDİLMEDİĞİNİN teyidi. NSA'ya giren tutar: Tescil edilen nominal sermaye artışı (nakdi kısım). YMM notu: NSA tablosunda emisyon priminin ayrı tutulduğu gösterilmelidir. | E18: NSA hesaplama tablosu / KVK 10/1-ı çalışma kâğıdı
B19: 10 | C19: YİAKV Matrah Hesaplama Tablosu (319 Düşümü) | D19: Emisyon primi istisnası (319) YİAKV matrahından DÜŞÜLEBİLİR. YİAKV çalışma kâğıdında 319 tutarının matrahtan doğru biçimde düşüldüğü teyit edilmeli. | E19: YİAKV çalışma kâğıdı / KVK 32/C Tebliğleri
B20: 11 | C20: Birleşme/Devir/Bölünme Belgeleri (Emisyon Primlerinin Aktarımı) | D20: Birleşme, devir veya bölünme varsa: Emisyon primlerinin devralan şirkete aynen aktarıldığını gösteren devir bilanço ve sözleşmesi. YMM notu: Aktarım yapılmazsa vergi avantajı sona erebilir. | E20: Devir/bölünme sözleşmesi + Devre esas bilanço
A22: KATEGORİ 3 — YMM TASDİK KONTROL SORULARI (★ İşaretli Sorular Kritiktir)
B23: No | C23: Kontrol Sorusu | D23: Beklenen Sonuç / Tasdik Standardı | E23: YMM Aksiyonu
B24: S1 | C24: ★ Kurum gerçekten Anonim Şirket mi? (Ltd için açık hüküm yok) | D24: Ticaret sicil belgesi kontrol edilmeli. AŞ değilse tartışmalı — özelge alınması gerekebilir. | E24: YMM kontrolü
B25: S2 | C25: ★ İstisna şirketin KENDİ paylarının ihracından mı? (Başkasına ait hisse satışı değil) | D25: Pay senedi + sermaye artırım tescil belgesi. Başkasına ait hisse satışı → 5/1-e/c. | E25: YMM kontrolü
B26: S3 | C26: ★ 520 hesabı kullanıldı mı? Emisyon primi gelir tablosuna GİRMEDİ mi? | D26: Yevmiye + mizan: 520 hesabında görünmeli. 649/679'a kaydedilmişse muhasebe hatası. | E26: YMM kontrolü
B27: S4 | C27: ★ KKEG ilavesi yapıldı mı? (519 satırı — 319 ile aynı tutar) | D27: KV beyannamesi KKEG tablosu: Emisyon primi tutarı 519 satırında görünmeli. KKEG yapılmadan sadece 319 → Tarhiyat riski. | E27: YMM kontrolü
B28: S5 | C28: ★ KKEG tutarı = 319 tutarı mı? E.5 (Net Etki) SIFIR mu? | D28: HESAPLAMALAR B bölümü: E.2 = E.4 ve E.5 = 0 olmalıdır. Fark varsa hesap hatası. | E28: YMM kontrolü
B29: S6 | C29: İhraç giderleri KVK 5/3 kapsamında doğru ayrıştırıldı mı? | D29: D.3: Emisyon primine isabet eden kısım KKEG. İlgili KDV için KDVK 30/d analizi yapılmış mı? | E29: YMM kontrolü
B30: S7 | C30: TTK 519 kanuni yedek akçe aktarımı yapıldı mı? | D30: 520 → 541 aktarım kaydı ve GK kararı mevcut olmalı. TTK 519 uyumu kontrol edilmelidir. | E30: YMM kontrolü
B31: S8 | C31: NSA hesabında emisyon primi tescil edilmeyen kısma dahil edilmedi mi? | D31: NSA tablosu: Yalnızca tescil edilen sermaye artışı girer. Emisyon primleri girmez. | E31: YMM kontrolü
B32: S9 | C32: YİAKV matrahından 319 istisnası DÜŞÜLDܒ mü? | D32: Emisyon primi istisnası YİAKV matrahından düşülebilir. YİAKV çalışma kâğıdında teyit edilmeli. | E32: YMM kontrolü
A34: SON NOT (YMM TASDİK): 49 No.lu Tebliğ (30.12.2025): >=500.000 TL → YMM raporu. Tam tasdik → ayrıca rapor yok. En kritik hata: KKEG yapmadan sadece 319 yazmak → Tarhiyat riski. KKEG tutarı ile 319 tutarı HER ZAMAN EŞİT olmalıdır. YİAKV'den DÜŞÜLEBİLİR. NSA'ya dahil edilmez. TTK 519 uyumu kontrol edilmeli. YMM müteselsil sorumluluk: SM-SMMM-YMM Kanunu Md.12.
