Workbook

Sheet VERİ GİRİŞİ
A1: 353 – KURUCU SENETLERİ, İNTİFA SENETLERİ, RÜÇHAN HAKLARI VE GİRİŞİM SERMAYESİ YATIRIM FONU KATILMA PAYI SATIŞ KAZANCI | KVK Md.5/1-e | GİB REHBERİ MART 2026 (YAYIN NO:601) | YMM TASDİK ÇALIŞMA KÂĞIDI
A2: KVK Md.5/1-e | %75 → %50 (9160 s.CB Kararı, 27/11/2024) | 2 Yıl (730 Gün) Aktifinde | 4 Araç: Kurucu Senedi · İntifa Senedi · Rüçhan Hakkı · GSYF Katılma Payı | 549 Fon (5 Yıl) | Beyanname 353
A3: GİB REHBERİ MART 2026 — 9160 SAYILI CB KARARI İLE İSTİSNA ORAN DEĞİŞİMİ (TÜM 5/1-e ARAÇLARI İÇİN GEÇERLİ)
A4: %75 | B4: 27/11/2024 TARİHİNDEN ÖNCE gerçekleştirilen satışlarda uygulanır (Kurucu Senedi · İntifa Senedi · Rüçhan Hakkı · GSYF Katılma Payı)
A5: %50 | B5: 9160 SAYILI CB KARARI ile 27/11/2024 TARİHİNDEN İTİBAREN (bu tarih dahil) gerçekleştirilen satışlarda uygulanır
A6: ★ RÜÇHAN HAKKI — KRİTİK UYARI: TTK'ya göre rüçhan hakkı kullanım süresi en fazla 15 gündür. Bu nedenle 730 günlük (2 tam yıl) aktifinde bulundurma şartı PRATİKTE HİÇBİR ZAMAN sağlanamaz → İstisna uygulanamaz. ★ GSYF KATILMA PAYI: GİB Rehberi Bölüm B-I.5: 'KVK 5/1-a bendi kapsamında istisna kazançlarına kaynak oluşturan yatırım fonları' = Girişim Sermayesi Yatırım Fonları (GSYF). SPK'dan izinli GSYF. Diğer fonlar → 298/299 kapsamı.
A8: A0. KAPSAM VE NİTELİK UYGUNLUK ÖN KONTROLÜ — GİB Rehberi Mart 2026 Bölüm B-I
B9: Kontrol Sorusu | E9: Yanıt | G9: YMM Tasdik Notu
A10: A0.1 Satılan varlığın türü nedir? | E10: Kurucu Senedi | F10: Her araç türünün aktife giriş tarihi farklıdır. Rüçhan hakkı → 2 yıl şartı pratikte imkânsız.
A11: A0.2 Satış tarihi 27/11/2024 öncesi mi sonrası mı? (Oran belirleyici) | E11: 27/11/2024 SONRASI → %50 | F11: 9160 s. CB Kararı: 27/11/2024 tarihinden itibaren tüm 5/1-e araçları için oran %50 (GİB Rehberi Bölüm B-I.1).
A12: A0.3 ★ 2 Tam Yıl (730 Gün) Aktifinde Bulundurma şartı sağlandı mı? | E12: EVET | F12: Rüçhan hakkı için şart pratikte karşılanamaz (TTK max 15 gün kullanım). Diğerleri → muhasebe aktif tarihi esas.
A13: A0.4 ★ Rüçhan Hakkı ise: İstisna UYGULANAMAYACAĞINI teyit ettiniz mi? | E13: Uygulanmıyor | F13: Rüçhan hakkı → 730 gün dolmadan satılmak zorunda. Satış kazancı vergiye tabi kurum kazancıdır.
A14: A0.5 GSYF Katılma Payı ise: SPK'dan izinli Girişim Sermayesi Yatırım Fonu mu? | E14: Uygulanmıyor | F14: GİB Md.5: 'Girişim Sermayesi Yatırım Fonları' için istisna. Diğer fonlar → önce 298/299 analizi yapın.
A15: A0.6 ★ İstisna edilen kazanç süresi içinde 549 Özel Fonlar hesabına alınacak mı? | E15: EVET | F15: Satışı izleyen hesap döneminin başından KV beyan süresine kadar 549'a alınmalı. 5 yıl tutulacak.
A16: A0.7 Satış kazancı mı zarar mı? (Zarar → %75/%50 oranında KKEG — KVK 5/3) | E16: Kazanç | F16: Zarar durumunda 352 ile aynı kural: Zarar × İstisna Oranı = KKEG. Kalan kısım indirilebilir.
A17: A0.8 YİAKV matrahında 353 istisnasının etkisi analiz edildi mi? | E17: EVET | F17: KVK 5/1-e (353) istisnası YİAKV (KVK 32/C) matrahından DÜŞÜLEMEZ — matrahta kalır.
A18: A0.9 YMM Tasdik Raporu gereksinimi değerlendirildi mi? (49 No.lu Tebliğ) | E18: EVET | F18: >=500.000 TL → YMM raporu. KV beyannamesi ile birlikte veya 2 ay içinde elektronik. Tam tasdik → Ayrıca rapor yok.
A19: A0.10 Tasdik Uygunluk Sonucu | E19: =IF(AND(E12="EVET",E15="EVET"),"OK - Hesaplanabilir","HATA - Ön koşul eksik") -> OK - Hesaplanabilir | F19: ★ A0.3 (2 yıl), A0.4 (Rüçhan), A0.6 (549 fon) kritik.
A21: A. GENEL BİLGİLER
A22: Kurumun Unvanı | F22: Tam ticaret unvanı
A23: VKN | F23: 10 haneli VKN
A24: Satılan Varlığın Türü | F24: A0.1 ile uyumlu — Kurucu / İntifa / GSYF
A25: İhraç Eden Kuruluş | F25: Kurucu/İntifa senedini veya GSYF'yi ihraç eden şirket/fon
A26: Hesap Dönemi | F26: Örn: 01.01.2025 – 31.12.2025
A27: KV Oranı (%) | F27: 2025: %25 | Finans: %30
A28: Dosya Referansı | F28: YMM-2025/353-01
A30: B. ARAÇ TÜRÜ NİTELİK ANALİZİ — 4 TÜRÜN ÖZGÜN KOŞULLARI (GİB Rehberi Bölüm B-I.1-5)
A31: B.1 KURUCU SENEDİ — AŞ Kurucularına Tanınan Kâra İştirak Hakkı Belgesi (TTK Md.348)
B32: Parametre | D32: Değer / Seçim | F32: Açıklama | G32: GİB / TTK
A33: B.1.1 Kurucu senedinin aktife giriş tarihi (TTK tescil veya devir tarihi) | D33: GG.AA.YYYY — Kuruluşta TTK tescil tarihi veya devir tarihinde devir belgesi | F33: GİB Rehberi Md.1
A34: B.1.2 Kurucu senedinin izlendiği hesap | D34: 248 Diğer Mali Duran Varlıklar önerilir | F34: 110 veya 248 hesabı
A35: B.1.3 Kurucu senedi satış tarihi | D35: GG.AA.YYYY — Devir tarihi | F35: TTK Md.348
A36: B.1.4 Satış bedeli (TL) | D36: Yazılı devir sözleşmesindeki tutar | F36: Sözleşme
A37: B.1.5 Maliyet / Defter Değeri (TL) | D37: Muhasebe kartındaki kayıtlı değer | F37: 248/110 hesap kartı
A39: B.2 İNTİFA SENEDİ — Kâra ve/veya Tasfiye Payına İştirak Hakkı Belgesi (TTK Md.502)
B40: Parametre | D40: Değer / Seçim | F40: Açıklama | G40: TTK
A41: B.2.1 İntifa senedinin aktife giriş tarihi (düzenleme veya devir tarihi) | D41: GG.AA.YYYY — Düzenlendiği veya devir alındığı tarih | F41: TTK Md.502
A42: B.2.2 İntifa senedinin niteliği | D42: Kâra iştirak / Tasfiyeye iştirak / Her ikisi | F42: TTK Md.502
A43: B.2.3 İntifa senedinin izlendiği hesap | D43: 248 Diğer Mali Duran Varlıklar veya 110 Hisse Senetleri | F43: 248 veya 110 hesabı
A44: B.2.4 Satış tarihi / Satış bedeli (TL) | D44: GG.AA.YYYY — Devir sözleşmesindeki tutar | F44: Devir sözleşmesi
...

Sheet HESAPLAMALAR & KONTROL
A1: 353 – KURUCU / İNTİFA / RÜÇHAN / GSYF KATILMA PAYI | HESAPLAMALAR VE DENETİM
A2: GİB Rehberi Mart 2026 (Yayın No:601) | %75→%50 (27/11/2024) | 4 Araç Türü | Rüçhan: İstisna Yok | GSYF | Zarar KKEG | 549 Fon | Beyanname 353
A4: A. TASDİK ÖZETİ
A5: A0 Uygunluk | D5: ='VERİ GİRİŞİ'!E19 -> OK - Hesaplanabilir | E5: OK ise devam
A6: Araç Türü (A0.1) | D6: ='VERİ GİRİŞİ'!E10 -> Kurucu Senedi | E6: Kurucu/İntifa/GSYF/Rüçhan
A7: 2 Yıl Şartı (C.4) | D7: ='VERİ GİRİŞİ'!C69 -> HAYIR — Süre Yetersiz / Rüçhan: İstisna Yok | E7: EVET zorunlu — Rüçhan: HAYIR normal
A8: Elde Tutma (Gün) | D8: ='VERİ GİRİŞİ'!C68 -> 0 | E8: 730 gün eşiği
A9: İstisna Oranı (D.1) | D9: ='VERİ GİRİŞİ'!C75 -> 27/11/2024 SONRASI → %50 | E9: Seçilen oran
A10: Satış Kazancı/Zarari (E.4) | D10: ='VERİ GİRİŞİ'!C83 -> 0 | E10: Kazanç veya Zarar
A11: 353 İSTİSNA (E.6) | D11: ='VERİ GİRİŞİ'!C85 -> 0
A12: ZARAR KKEG (E.8+E.9) | D12: ='VERİ GİRİŞİ'!C87+'VERİ GİRİŞİ'!C88 -> 0 | E12: Zarar durumunda
A13: 549 Fon (F.1) | D13: ='VERİ GİRİŞİ'!C89 -> 0 | E13: 5 yıl tutulacak
A15: B. 4 ARAÇ TÜRÜ — PRATİK UYGULAMA VE KARŞILAŞTIRMA (GİB Rehberi Mart 2026)
B16: Araç Türü | C16: Aktife Giriş Tarihi | D16: 2 Yıl Şartı | E16: İstisna Oranı | F16: Pratikte Durum | G16: Beyanname
A17: Kurucu Senedi | B17: TTK tescil tarihi veya devir tarihi | C17: Mümkün — belge şart | D17: 27/11/2024- %75 | Sonrası %50 | E17: Nadir — belgesi zorunlu | F17: 353
A18: İntifa Senedi | B18: Düzenlendiği/devir alındığı tarih | C18: Mümkün — belge şart | D18: 27/11/2024- %75 | Sonrası %50 | E18: Nadir — belgesi zorunlu | F18: 353
A19: Rüçhan Hakkı | B19: Sermaye artırım kararı tarihi | C19: PRATİKTE İMKÂNSIZ (maks. 15 gün) | D19: Teorik: %75/%50 | E19: İSTİSNA HİÇBİR ZAMAN UYGULANAMAZ | F19: Yok — Vergiye Tabi
A20: GSYF Katılma Payı | B20: 118/248 muhasebe aktif kayıt tarihi | C20: Mümkün — 2 yıl tutulmalı | D20: 27/11/2024- %75 | Sonrası %50 | E20: SPK izinli GSYF şart | F20: 353
A22: C. GSYF KATILMA PAYI — 5/1-a-3 (298) / 5/1-a-4 (299) vs 5/1-e (353) KARAR TABLOSU (GİB Rehberi Md.5)
A23: YF katılma payı satışında kapsam kodu kritik. 353 seçilmeden önce bu analizi tamamlayın.
B24: Kriter | D24: 298 (KVK 5/1-a-3) | F24: 299 (KVK 5/1-a-4) | G24: 353 (KVK 5/1-e)
A25: Kapsam | C25: GSYF / GSYO hisseleri | D25: TL esaslı diğer fonlar (15.07.2023 öncesi iktisap) | E25: SPK izinli GSYF katılma payları (GİB Md.5)
A26: 2 Yıl Şartı | C26: YOK (Süre şartı aranmaz) | D26: YOK (Süre şartı aranmaz) | E26: VAR — 730 gün zorunlu
A27: Beyanname Bölümü | C27: Zarar Olsa Dahi İndirilecek | D27: Zarar Olsa Dahi İndirilecek | E27: Kazancın Bulunması Halinde
A28: İstisna Oranı | C28: %100 Tam İstisna | D28: %100 Tam İstisna | E28: 27/11/2024- %75 | Sonrası %50
A29: İktisap Tarihi Kısıtı | C29: Yok | D29: 15.07.2023 öncesi iktisap zorunlu | E29: Yok
A30: YİAKV Matrahı | C30: Düşülebilir (5/1-a kapsamı) | D30: Düşülebilir (5/1-a kapsamı) | E30: DÜŞÜLEMEZ (5/1-e)
A31: Öncelik Sırası | C31: 1. Tercih (GSYF/GSYO için) | D31: 2. Tercih (15.07.2023 öncesi TL fon) | E31: 3. Tercih (Kalan durumlar)
A33: D. DENETİM KONTROL LİSTESİ (K1–K14) — GİB REHBERİ MART 2026
B34: Kontrol | D34: Açıklama / GİB Rehberi | F34: Sonuç
A35: K1 | B35: ★ İstisna oranı doğru mu? 27/11/2024 öncesi/sonrası ayrımı yapıldı mı? | D35: 9160 s. CB Kararı: 27/11/2024+ → %50. Öncesi → %75. Tüm 4 araç için geçerli. | F35: Uygun/Eksik/Risk
A36: K2 | B36: ★ RÜÇHAN HAKKI: 2 yıl şartı karşılanamadığı teyit edildi — İstisna uygulanmadı mı? | D36: TTK max 15 gün kullanım süresi → 730 gün imkânsız. Rüçhan satış kazancı vergiye tabi. | F36: Uygun/Eksik/Risk
A37: K3 | B37: GSYF Katılma Payı: Önce 298/299 kapsam analizi yapıldı mı? | D37: 298 (GSYF/GSYO) veya 299 (15.07.2023 öncesi TL fon) → Daha avantajlı. 353 son tercih. | F37: Uygun/Eksik/Risk
A38: K4 | B38: ★ 2 Tam Yıl (730 Gün) Şartı — C.4 EVET veriyor mu? | D38: 730 günden 1 gün eksik → İstisna yok. Muhasebe aktif kayıt tarihi esas. | F38: Uygun/Eksik/Risk
A39: K5 | B39: Araç türüne göre aktife giriş tarihi doğru belirlendi mi? | D39: Kurucu/İntifa: TTK tescil/devir tarihi. GSYF: Muhasebe aktif kayıt tarihi. | F39: Uygun/Eksik/Risk
A40: K6 | B40: Araç türüne göre doğru muhasebe hesabı kullanılıyor mu? | D40: Kurucu/İntifa → 110 veya 248. GSYF → 118 veya 248. Tutarlı uygulanmalı. | F40: Uygun/Eksik/Risk
A41: K7 | B41: ★ Satış kazancı mı zarar mı? E.4 doğru belirlendi mi? | D41: Kazanç → E.6 = İstisna → Beyanname 353. Zarar → E.8+E.9 = KKEG → KKEG tablosu. | F41: Uygun/Eksik/Risk
A42: K8 | B42: Zarar varsa E.8 + E.9 KKEG tablosuna eklendi mi? | D42: KVK 5/3: Zarar × Oran ve Giderler × Oran KKEG. Beyanname KKEG tablosunda görünmeli. | F42: Uygun/Eksik/Risk
A43: K9 | B43: Satış bedeli fiili satış bedeli mi? Transfer fiyatlandırması? | D43: GİB Md.29: Fiili bedel esas. KVK Md.13: İlişkili kişi satışında emsal bedel. | F43: Uygun/Eksik/Risk
A44: K10 | B44: ★ Satış bedeli 2. takvim yılı sonuna kadar tahsil edilecek mi? | D44: Nakit veya Altın/DT/HB/BİST hisseleri (2 yıl içinde nakde). Tahsil edilmezse → Vergi ziyaı. | F44: Uygun/Eksik/Risk
...

Sheet MUHASEBE KAYITLARI
A1: 353 – KURUCU / İNTİFA / RÜÇHAN / GSYF KATILMA PAYI | MUHASEBE KAYITLARI
A2: GİB Rehberi Mart 2026 | %75/%50 Oran | 4 Araç Türü | Rüçhan: İstisna Yok | Zarar KKEG | 549 Fon
A3: NOT: Aşağıdaki kayıtlar örnek niteliğindedir. Araç türüne göre hesap adları değişmektedir.
A4: KAYIT 1 — GSYF KATILMA PAYI SATIŞI / KURUCU-İNTİFA SENEDİ SATIŞI (KAZANÇLA)
B5: Tarih | C5: Hesap | D5: Not | E5: Dr | F5: Kr | G5: Ref
A6: Dr | B6: [Satış Tarihi] | C6: 102 Bankalar / 120 Alıcılar | D6: Satış bedeli tahsilatı | E6: [Satış Bedeli] | F6: — | G6: Banka/Sözleşme
A7: Kr | B7: [Satış Tarihi] | C7: 118 / 248 / 110 (Araç Türüne Göre) | D7: GSYF: 118/248 | Kurucu/İntifa: 110/248 — defter değeriyle aktiften çıkış | E7: — | F7: [Defter Değeri] | G7: Hesap kartı
A8: Kr | B8: [Satış Tarihi] | C8: 645 MK Satış Kârı / 679 Diğer Olağandışı Kâr | D8: Satış kazancı (E.4) — KVK 5/1-e | %75 (27/11/2024 öncesi) / %50 (sonrası) → Beyanname 353 | E8: — | F8: [E.4 TL] | G8: KV 353
A9: ORAN NOTU: 27/11/2024 ÖNCESİ → %75. 27/11/2024 SONRASI → %50 (9160 s. CB Kararı). Hem GSYF katılma payı hem kurucu/intifa senedi için geçerli.
A10: KAYIT 2 — 549 ÖZEL FONLAR HESABINA ALMA (Satışı İzleyen Dönem KV Beyan Süresine Kadar)
B11: Tarih | C11: Hesap | D11: Not | E11: Dr | F11: Kr | G11: Ref
A12: Dr | B12: [KV Beyan] | C12: 645/679 Satış Kârı / Diğer Kâr | D12: İstisna edilen satış kazancının gelir hesabından çıkarılması | E12: [İstisna E.6] | F12: — | G12: E.6 tutarı
A13: Kr | B13: [KV Beyan] | C13: 549 Özel Fonlar | D13: KVK 5/1-e İstisna | %75/%50 | 5 yıl tutulacak (353 — Diğer MK Satış Kazancı İstisnası) | E13: — | F13: [İstisna E.6] | G13: 5 Yıl
A14: 5 YIL KURALI: 5 yıl içinde işletmeden çekilemez. Sermayeye ilave mümkün. Tasfiye = Otomatik çekim → Vergi ziyaı.
A15: KAYIT 3 — RÜÇHAN HAKKI SATIŞI (İSTİSNA UYGULANAMAZ — VERGİYE TABİ)
A16: RÜÇHAN HAKKI: 2 yıl (730 gün) aktifinde bulundurma şartı TTK'dan kaynaklı 15 günlük kullanım süresi nedeniyle karşılanamaz. Satış kazancı vergiye tabi kurum kazancıdır.
B17: Tarih | C17: Hesap | D17: Not | E17: Dr | F17: Kr | G17: Ref
A18: Dr | B18: [Satış Tarihi] | C18: 102 Bankalar | D18: Rüçhan hakkı satış bedeli — 2 yıl şartı karşılanamadı → İSTİSNA YOK | E18: [Satış Bed.] | F18: — | G18: Banka dekontu
A19: Kr | B19: [Satış Tarihi] | C19: 679 Diğer Olağandışı Kâr ve Gelirler | D19: Rüçhan hakkı satış kazancı — KVK 5/1-e istisnası UYGULANAMAZ — VERGIYE TABİ | E19: — | F19: [Kazanç] | G19: VERGİYE TABİ
A20: Beyanname 353 satırına istisna tutarı YAZILMAZ. Tüm kazanç KV matrahına dahil edilir. YMM notu dosyada bu husus açıkça belirtilmelidir.
A21: KAYIT 4 — ZARAR DURUMU VE KKEG (KVK 5/3 — TÜM ARAÇLAR İÇİN)
B22: Tarih | C22: Hesap | D22: Not | E22: Dr | F22: Kr | G22: Ref
A23: Dr | B23: [Satış Tarihi] | C23: 102 Bankalar | D23: Satış bedeli | E23: [Satış Bedeli] | F23: — | G23: Banka/Sözleşme
A24: Dr | B24: [Satış Tarihi] | C24: 689 Diğer Olağandışı Giderler | D24: Satış zararının KKEG olan kısmı (E.8 = Zarar × %75/%50) | E24: [E.8 KKEG] | F24: — | G24: KVK 5/3
A25: Dr | B25: [Satış Tarihi] | C25: 689 Diğer Olağandışı Giderler | D25: Satış giderlerinin KKEG olan kısmı (E.9 = Gider × %75/%50) | E25: [E.9 KKEG] | F25: — | G25: KVK 5/3
A26: Kr | B26: [Satış Tarihi] | C26: 118/248/110 | D26: Defter değeriyle aktiften çıkış | E26: — | F26: [Defter Değeri] | G26: Hesap kartı
A27: ZARAR KKEG: Zarar × İstisna Oranı (0.75 veya 0.50) = KKEG + Giderler × İstisna Oranı = KKEG. Kalan kısım gider olarak indirilebilir. 352 ile özdeş kural (KVK 5/3).

Sheet DENETCİ NOTLARI
A1: 353 – KURUCU / İNTİFA / RÜÇHAN / GSYF KATILMA PAYI | DENETÇİ NOTLARI
A2: GİB Rehberi Mart 2026 (Yayın No:601) | 9160 s. CB Kararı (27/11/2024) | TTK Rüçhan | GSYF Kapsam | Zarar KKEG | YMM Standardı
A3: Kod | B3: Konu | C3: Mesleki Değerlendirme / GİB Rehberi Mart 2026 | D3: Mevzuat / Kaynak
A4: N1 | B4: KVK 5/1-e — 353 Kapsamındaki Araçlar ve Güncel Oran (GİB Rehberi Bölüm B-I.1-5) | C4: KVK 5/1-e KAPSAMINDAKI ARAÇLAR (353): ① KURUCU SENETLERİ (TTK Md.348): AŞ kurucularına tanınan kâra iştirak hakkı veren senetler. Hisse senedi değil. ② İNTİFA SENETLERİ (TTK Md.502): Kâra ve/veya tasfiye payına iştirak hakkı veren senetler. Oy hakkı yok. ③ RÜÇHAN HAKLARI (TTK Md.461): Sermaye artırımında öncelikli yeni pay alma hakkı. ④ GİRİŞİM SERMAYESİ YATIRIM FONU (GSYF) KATILMA PAYLARI (GİB Md.5): KVK 5/1-a kapsamında istisna kazançlarına kaynak oluşturan yatırım fonları. SPK'dan izin alarak faaliyette bulunan girişim sermayesi fonlarının katılma payları. İSTİSNA ORAN DEĞİŞİMİ (GİB Rehberi Bölüm B-I.1): → 27/11/2024 ÖNCESİ: %75 istisna (KVK 5/1-e). → 27/11/2024 SONRASI: %50 istisna (9160 sayılı CB Kararı). Bu değişiklik kurucu senetleri, intifa senetleri, rüçhan hakları ve GSYF katılma paylarının tamamı için geçerlidir. BEYANNAME: 353 | Kazancın Bulunması Halinde | YİAKV matrahından DÜŞÜLEMEZ. | D4: KVK 5/1-e | 9160 s. CB Kararı | TTK Md.348,461,502 | GİB Rehberi Mart 2026
A5: N2 | B5: ★ Rüçhan Hakkı — 2 Yıl Şartı Pratikte Hiçbir Zaman Karşılanamaz | C5: RÜÇHAN HAKKI (GİB Rehberi Md.3): 'Anonim şirketler ile eshamlı komandit şirketlerin sermaye artırımına gitmeleri durumunda, bu şirketlerin hisse senetlerini aktifinde bulunduran kurumlar; yeni hisse senedi rüçhan hakkı kuponlarını başkalarına da satabilmektedirler. Söz konusu rüçhan haklarının satışından elde edilen kazançların %75'i (9160 s. CB Kararı gereğince 27/11/2024'ten itibaren %50'si) istisnadan yararlanabilir.' ANCAK — 2 YIL ŞARTI (GİB Rehberi Md.10): 'İstisna uygulamasına konu olacak ... rüçhan haklarının da en az iki tam yıl (730 gün) süreyle kurumun aktifinde yer alması... gerekmektedir.' TTK SORUNU: Rüçhan hakkının kullanım süresi azami 15 gündür (TTK Md.461). → 730 günlük aktifinde bulundurma şartı pratikte HİÇBİR ZAMAN sağlanamaz. → Rüçhan hakkı satış kazancı vergiye tabi kurum kazancıdır. → Beyanname 353 satırına istisna tutarı yazılamaz. YMM: Bu husus tasdik dosyasında açıkça belirtilmelidir. Rüçhan hakkı satışına istisna uygulamak en sık yapılan 353 hatasıdır. | D5: GİB Rehberi Md.3, 10 | TTK Md.461 | KVK 5/1-e
A6: N3 | B6: GSYF Katılma Payı — Kapsam Analizi: 298/299 vs 353 (GİB Rehberi Md.5) | C6: GİB Rehberi Md.5 — GSYF KATILMA PAYI TANIMI: 'Sermaye piyasası mevzuatına göre girişim sermayesi yatırım fonları, nitelikli yatırımcılardan katılma payı karşılığında toplanan para ya da iştirak paylarıyla, pay sahipleri hesabına, inançlı mülkiyet esaslarına göre, girişim sermayesi yatırımlarından oluşan portföyü işletmek amacıyla kurulan mal varlığı' KAPSAM ÖNCELİK SIRASI: 1. GSYF/GSYO → 298 (KVK 5/1-a-3): Zarar olsa dahi / 2 yıl şartı yok 2. TL esaslı diğer fonlar (15.07.2023 öncesi iktisap) → 299 (KVK 5/1-a-4): Daha avantajlı 3. Geriye kalan durumlar → 353 (KVK 5/1-e): 2 yıl şartı var, %75/%50 353 KULLANIM DURUMU: 15.07.2023 sonrası iktisap edilen veya 299 kapsamına girmeyen SPK izinli GSYF katılma payları için uygulanabilir. YMM: GSYF katılma payı satışında 298/299 analizi yapıldığı ve neden 353 seçildiği tasdik dosyasında mutlaka belgelenmelidir. | D6: GİB Rehberi Md.5 | KVK 5/1-a-3 (298) | KVK 5/1-a-4 (299) | KVK 5/1-e (353)
A7: N4 | B7: Kurucu ve İntifa Senetleri — Pratik Uygulama (GİB Rehberi Md.1) | C7: KURUCU SENETLERİ (TTK Md.348): Günümüzde son derece nadir. TTK'ya göre AŞ'lerde çıkarılabilir. Hisse senedi değil — kâra iştirak belgesi. Oy hakkı vermez. Aktife giriş tarihi: TTK tescil tarihi veya devir tarihinde devir belgesi. Muhasebe: 110 Hisse Senetleri veya 248 Diğer Mali Duran Varlıklar. İNTİFA SENETLERİ (TTK Md.502): Hisse senedi değil — kâra ve/veya tasfiye payına iştirak hakkı tanır. Sermaye payı temsil etmez. Oy hakkı yoktur. Genellikle bedelsiz devredilen paylar karşılığında verilir. Aktife giriş tarihi: Düzenlendiği veya devir alındığı tarih. Muhasebe: 248 veya 110 hesabında izlenebilir. YMM: Her iki araç için aktife giriş tarihi belgesi zorunludur. 2 yıl şartı sağlanabilir ancak belge eksikliği riski yüksektir. Belge eksikliğinde istisna reddedilir. | D7: TTK Md.348, 502 | KVK 5/1-e | GİB Rehberi Md.1
A8: N5 | B8: 49 No.lu Tebliğ + YMM Tasdik Dil Standardı (GİB Rehberi Bölüm C) | C8: 49 No.lu Tebliğ: >=500.000 TL → YMM raporu. KV beyannamesi ile birlikte veya 2 ay içinde elektronik. Tam tasdik → ayrıca rapor yok. KULLANIN — GSYF/Kurucu/İntifa (27/11/2024 SONRASI — %50): '...en az iki tam yıl süreyle kurum aktifinde yer alan [Araç Türü] satışından doğan kazancın 9160 sayılı Cumhurbaşkanı Kararı kapsamında %50'si olan [tutar] TL kurumlar vergisinden istisna edilmiş, söz konusu kazanç [tarih] tarihine kadar 549 Özel Fonlar hesabına alınmıştır.' KULLANMAYIN: '...rüçhan hakkı satışından istisna uygulanmıştır' → YANLIŞ! (2 yıl şartı karşılanamaz) '...%75 istisna uygulanmıştır' (27/11/2024 sonrası satış → %50) '...YF katılma payında 298/299 analizi yapılmaksızın 353 seçilmiştir' → Risk KRİTİK RİSK ALANLARI: (1) Rüçhan hakkı satışına 353 istisnası uygulamak — en sık hata. (2) 27/11/2024 sonrası satışta %75 oran kullanmak — yanlış oran. (3) GSYF katılma payında 298/299 kapsamını atlamak. (4) Fon kaydı yapmadan istisna uygulamak. (5) Zarar durumunda KKEG beyan etmemek. | D8: 49 No.lu Tebliğ | GİB Rehberi Mart 2026 Bölüm C | SM-SMMM-YMM K. Md.12
A9: GİB REHBERİ MART 2026 KAPANIŞ (353): 9160 s. CB Kararı ile 27/11/2024'ten itibaren oran %50. Rüçhan hakkında 2 yıl şartı pratikte karşılanamaz — en sık yapılan hata. GSYF katılma payında önce 298/299 analizi zorunlu. Zarar durumunda KKEG kuralı geçerli (KVK 5/3). YMM müteselsil sorumluluk: SM-SMMM-YMM K. Md.12.

Sheet BELGE LISTESI
A1: 353 – KURUCU / İNTİFA / RÜÇHAN / GSYF KATILMA PAYI | BELGE LİSTESİ | YMM TASDİK
A2: GİB Rehberi Mart 2026 (Yayın No:601) | %75→%50 (27/11/2024) | 4 Araç | Rüçhan: İstisna Yok | 549 Fon | 49 No.lu Tebliğ
A4: KATEGORİ 1 — ZORUNLU BELGELER (Tüm Araç Türleri İçin)
B5: No | C5: Belge / Bilgi | D5: Açıklama / YMM Kontrol | E5: Temin Yeri
B6: 1 | C6: ★ İstisna Oranını Belgeleyen Tarih Analizi (27/11/2024 Sınırı) | D6: Satış tarihi → 27/11/2024 öncesi = %75 | Sonrası = %50 (9160 s. CB Kararı). Bu çalışma kâğıdı D bölümü + satış sözleşmesi tarihi ile birlikte dosyada yer almalı. | E6: Bu çalışma kâğıdı D bölümü
B7: 2 | C7: ★ Araç Türünü Kanıtlayan Belge | D7: Kurucu Senedi: TTK tescil belgesi + kurucu senet metni. İntifa Senedi: TTK Md.502 kapsamında intifa senedi belgesi. GSYF: SPK'dan izinli fon belgesi veya MKK hesap ekstresi. | E7: Şirket sicil belgesi / Fon belgesi / MKK portal
B8: 3 | C8: ★ Aktifinde Bulundurma Süresini İspat Eden Belge (2 Yıl) | D8: 118/248/110 hesabında 730 gün kayıtlı olduğunu gösteren muhasebe ekstresi. Aktife giriş tarihi: Araç türüne göre B bölümündeki ilgili satır. | E8: Muhasebe hesap ekstresi (ilk kayıt tarihinden itibaren)
B9: 4 | C9: Satış Sözleşmesi / Devir Belgesi / Aracı Kurum Dekontu | D9: Satış bedeli, satış tarihi, alıcı bilgileri açık. GSYF: MKK dekontu veya aracı kurum satış belgesi. | E9: Devir sözleşmesi / Aracı kurum dekontu / Borsa kaydı
B10: 5 | C10: Satış Kazancı / Zarar Hesaplama Tablosu (E.4) | D10: E.4 = Satış Bedeli − Maliyet − Satış Giderleri. Kazanç → E.6 =%75/%50. Zarar → E.8+E.9 = KKEG. | E10: Bu çalışma kâğıdı E bölümü
B11: 6 | C11: ★ 549 Fon Hesabına Alınma Belgesi (Muhasebe Kaydı) | D11: İstisna tutarının (E.6) 549 hesabına kaydedildiğini gösteren yevmiye. Zamanlama kritik. | E11: Yevmiye defteri / 549 hesap ekstresi
B12: 7 | C12: KV Beyannamesi Taslağı — 353. Satır | D12: 353 tutarının E.6 ile uyumlu. 'Kazancın Bulunması Halinde' bölümünde. Zarar varsa 353 değil KKEG tablosu. | E12: GİB e-Beyanname sistemi
A14: KATEGORİ 2 — ARAÇ TÜRÜNE ÖZGÜ EK BELGELER
B15: No | C15: Belge / Bilgi | D15: Açıklama / YMM Kontrol | E15: Temin Yeri
B16: 8 | C16: GSYF Katılma Payı: 298/299 Kapsam Analiz Belgesi | D16: 298/299 analizi yapıldığı ve neden 353 seçildiği belgelenmelidir. 15.07.2023 sonrası iktisap veya 299 kapsamı dışı kalan fon → 353 seçim gerekçesi. | E16: Fon bilgi formu / İzahname / KAP fon portföy bilgisi
B17: 9 | C17: ★ Rüçhan Hakkı: Sermaye Artırım Kararı + İstisna UYGULANMADIĞI Notu | D17: Rüçhan hakkı → 2 yıl şartı karşılanamaz → İstisna yok → Satış kazancı vergiye tabi. Tasdik dosyasında bu husus açıkça belirtilmeli. | E17: Genel kurul kararı + Sermaye artırım tescil belgesi
B18: 10 | C18: Kurucu/İntifa Senedi: TTK Tescil ve Devir Belgesi | D18: Kurucu: AŞ kuruluş sözleşmesi + TTK tescil + Senet metni. İntifa: TTK Md.502 kapsamında GK kararı + düzenleme belgesi + devir tarihi. | E18: Ticaret sicil belgesi + Senet metni + Devir sözleşmesi
B19: 11 | C19: Zarar Durumu: KKEG Hesaplama Tablosu (E.8 + E.9) | D19: Zarar × İstisna Oranı = KKEG + Giderler × İstisna Oranı = KKEG. Beyanname KKEG tablosuna eklenen tutarlar ile uyum. | E19: Bu çalışma kâğıdı E.8+E.9 + Beyanname KKEG ekstresi
A21: KATEGORİ 3 — YMM TASDİK KONTROL SORULARI
B22: No | C22: Kontrol Sorusu | D22: Beklenen Sonuç | E22: YMM Aksiyonu
B23: S1 | C23: ★ İstisna oranı doğru mu? 27/11/2024 öncesi/sonrası ayrımı? | D23: 9160 s. CB Kararı: 27/11/2024+ → %50. Öncesi → %75. Tüm 4 araç için. | E23: YMM kontrolü
B24: S2 | C24: ★ RÜÇHAN HAKKI: İstisna uygulanmadığı ve kazancın vergiye tabi olduğu teyit edildi mi? | D24: 2 yıl şartı karşılanamaz. Beyanname 353 doldurulmaz. Tasdik dosyasında not düşülmeli. | E24: YMM kontrolü
B25: S3 | C25: GSYF Katılma Payı: Önce 298/299 analizi yapıldı mı? Neden 353 seçildiği belgelendi mi? | D25: 298 (GSYF/GSYO) veya 299 (TL esaslı, 15.07.2023 öncesi) → Daha avantajlı. | E25: YMM kontrolü
B26: S4 | C26: ★ 2 Tam Yıl (730 gün) şartı — C.4 EVET veriyor mu? | D26: 730 gün. 1 gün eksik → İstisna yok. Muhasebe aktif kayıt tarihi esas. | E26: YMM kontrolü
B27: S5 | C27: Araç türüne göre aktife giriş tarihi doğru belgesi ile ispat edildi mi? | D27: Kurucu/İntifa → TTK tescil/devir. GSYF → Muhasebe aktif tarihi. | E27: YMM kontrolü
B28: S6 | C28: ★ Satış kazancı mı zarar mı? Doğru kategoride işlem yapıldı mı? | D28: Kazanç → E.6 = İstisna → 353. Zarar → E.8+E.9 = KKEG tablosu. | E28: YMM kontrolü
B29: S7 | C29: Zarar varsa E.8 + E.9 KKEG tablosuna eklendi mi? | D29: KVK 5/3: Zarar × Oran + Gider × Oran = KKEG. | E29: YMM kontrolü
B30: S8 | C30: ★ Satış bedeli 2. takvim yılı sonuna kadar tahsil edilecek mi? | D30: Nakit veya Altın/DT/HB/BİST (2 yıl içinde nakde). Tahsil edilmezse → Vergi ziyaı. | E30: YMM kontrolü
B31: S9 | C31: ★ İstisna tutarı süresi içinde 549 hesabına alındı mı? | D31: Satışı izleyen dönem KV beyan süresi içinde. Fon kaydı yoksa istisna geçersiz. | E31: YMM kontrolü
B32: S10 | C32: Beyanname 353 'Kazancın Bulunması Halinde' bölümünde mi? | D32: Zarar varsa 353 kullanılmaz — KKEG tablosu. | E32: YMM kontrolü
B33: S11 | C33: YMM Tasdik Raporu (49 No.lu Tebliğ) değerlendirildi mi? | D33: >=500.000 TL → YMM raporu. | E33: YMM kontrolü
A35: SON NOT: GİB Rehberi Mart 2026 (Yayın No:601). Kritik güncellemeler: (1) 9160 s. CB Kararı: 27/11/2024+ → %50 oran (tüm 4 araç için). (2) Rüçhan hakkında 2 yıl şartı pratikte karşılanamaz — istisna uygulanamaz. (3) GSYF katılma payında önce 298/299 analizi zorunlu. (4) Zarar durumunda KVK 5/3 KKEG kuralı geçerli. (5) Fon kaydı yoksa istisna tamamen geçersiz. YMM müteselsil sorumluluk: SM-SMMM-YMM Kanunu Md.12.
