Workbook

Sheet VERİ GİRİŞİ
A1: 373 – KVK GEÇİCİ MADDE 14/1-b | VADE SONUNDA OLUŞAN KÂR PAYI VE FAİZ İSTİSNASI | KUR KORUMALI MEVDUAT (KKM) | YMM TASDİK
A2: KVK Geçici Md.14/1-b | KKM Hesabı Vadeye Ulaştığında Tahsil Edilen Kâr Payı ve Faiz | Beyanname 373 | ★ YİAKV MATRAHINDA DÜŞÜLEMEZ
A3: KVK GEÇİCİ MD.14 — DÖRT İSTİSNA KODU: 370 (1-a) Dönüşüm kur farkı — tek seferlik | 371 (1-b) Bankadan kur farkı tazminatı — nakit/dönemsel 372 (1-b) Dönem sonu (31/12) faiz/kâr payı tahakkuku — accrual | hesap hâlâ açık 373 (1-b) Vade sonu faiz/kâr payı tahsilatı — nakit | hesap vadeye ulaştı → BU DOSYA ★★ 372–373 MUTABAKAT: Yılı aşan vadeli hesaplarda mükerrerlik önlenmeli: Net 373 = Toplam Vade − Önceki Yıl 372
A4: ★★ YİAKV (KVK Md.32/C) KRİTİK: 373 kapsamındaki vade sonu kâr payı/faiz YİAKV matrahından DÜŞÜLEMEZ. 370+371+372+373 tamamı E.7 DÜŞÜLEMEZ listesindedir.
A6: A0. KAPSAM VE NİTELİK UYGUNLUK ÖN KONTROLÜ
B7: Kontrol Sorusu | F7: Yanıt | H7: YMM Tasdik Notu
A8: A0.1 Vadeye giren KKM hesabı KVK Geçici Md.14/1-a kapsamı dönüşümden mi açıldı? | F8: EVET | G8: 373, yalnızca 370 kapsamındaki dönüşümden açılan ve vadeye ulaşan KKM hesaplarına uygulanır.
A9: A0.2 ★ Dönem içinde vadeye ulaşan KKM hesabı var mı? Kâr payı/faiz tahsil edildi mi? | F9: EVET | G9: 373 = Vade bitiminde bankadan fiilen ALINAN kâr payı/faiz. Hesap hâlâ açıksa → 372 (tahakkuk).
A10: A0.3 ★ 372 ile MÜKERRERLİK kontrolü yapıldı mı? (C Sütun 6 dolduruldu mu?) | F10: EVET | G10: Önceki yıl 372 olan hesaplarda: Net 373 = Vade Toplam − Önceki 372. Aksi hâlde mükerrer istisna tarhiyat riski.
A11: A0.4 Vade sonu muhasebe kaydı doğru yapıldı mı? (102 Dr / 181 Kr + 642 Kr) | F11: EVET | G11: Vade: 102 Dr / Kr 181 (önceki yıl accrual kapatma) + Kr 642 (bu yılın yeni kısmı). Her iki alacak istisna kapsamında.
A12: A0.5 ★ 373 tutarının YİAKV matrahından DÜŞÜLMEDIĞI teyit edildi mi? | F12: EVET | G12: 370+371+372+373 tamamı YİAKV matrahından DÜŞÜLEMEZ. E.7'de dört satır da kontrol edilmeli.
A13: A0.6 Banka vade bildirimi/hesap özeti mevcut mu? | F13: EVET | G13: Vade sonunda bankadan alınan resmi bildiri: Vade tarihi, toplam kâr payı/faiz tutarı.
A14: A0.7 YMM Tasdik Raporu (49 No.lu Tebliğ) değerlendirildi mi? | F14: EVET | G14: >=500.000 TL → YMM raporu.
A15: A0.8 Tasdik Uygunluk Sonucu | F15: =IF(AND(F8="EVET",F9="EVET",F10="EVET",F12="EVET"),"OK - Hesaplanabilir","HATA - Ön koşul eksik") -> OK - Hesaplanabilir | G15: ★ A0.3 (mükerrerlik) ve A0.5 (YİAKV düşülemez) en kritik.
A17: A. GENEL BİLGİLER
A18: Kurumun Unvanı | G18: Tam ticaret unvanı
A19: VKN | G19: 10 haneli VKN
A20: Hesap Dönemi | G20: 01.01.2025 – 31.12.2025
A21: KV Oranı (%) | G21: 2025: %25 | Banka/Finans: %30
A22: Dosya Referansı | G22: YMM-2025/373-01
A23: 370/371/372 Referansı | G23: Aynı KKM hesabı — dört dosya çapraz mutabakat
A25: B. VADELİ KKM HESAP BİLGİLERİ VE 372–373 MUTABAKAT AÇIKLAMASI
A26: 372–373 MUTABAKAT KURALI (YILI AŞAN VADELİ HESAPLAR İÇİN): Örnek: Hesap açılış Mart 2024, Vade Eylül 2025, Toplam faiz 30.000 TL Aralık 2024 sonu (372): 14.500 TL tahakkuk → 2024 KV beyannamesi 372 satırı. Eylül 2025 vade (373): 30.000 − 14.500 = 15.500 TL net → 2025 KV beyannamesi 373 satırı. KURAL: Net 373 = Vade Toplam Kâr Payı/Faiz − Önceki Dönem(ler) 372 Tutarı. Mükerrerlik ÖNLENMELI.
B27: Parametre | E27: Değer / Tarih | G27: Açıklama | H27: Kaynak
A28: B.1 KKM Hesap Açılış Tarihi (370 ile aynı) | D28: 370 dönüşüm tarihi ile örtüşmeli. | G28: Banka sözleşmesi
A29: B.2 KKM Hesap Vade Tarihi (Bu Dönemde Kalan) | D29: Dönem içinde (01.01–31.12) vadeye ulaşan tarih. | G29: Banka sözleşmesi
A30: B.3 Kâr Payı / Faiz Türü | C30: TL Mevduat Faizi | D30: TL mevduat → Faiz (642). TL katılım → Kâr payı (644). | G30: Banka sözleşmesi
A31: B.4 Vade Sonu Toplam Kâr Payı/Faiz Tahsilat (Banka Bildirimi) | D31: Banka vade bildirimi / hesap özeti — tüm hesap süresi boyunca oluşan toplam. | G31: Banka vade bildirimi
A32: B.5 ★ Önceki Dönem(ler) 372 Tahakkuk Tutarı (Varsa — Bu Hesap İçin) | C32: 0 | D32: Bu hesap için önceki KV dönemlerinde 372 kapsamında istisna uygulanan toplam. Yoksa 0. | G32: Önceki dönem KV 372 satırı
A33: B.6 Bu Dönem Net 373 Tutarı (B.4 − B.5) | D33: Otomatik: C tablosunda hesaplanır. Burada sadece referans. | G33: Formül (C Sütun 7)
A34: B.7 ★ KKM Hesabının 31/12/2021 Bilanço Kaynaklı Olduğu Teyit Edildi mi? | C34: EVET | D34: 373 yalnızca 370 kapsamındaki dönüşümden açılan hesaplara uygulanır. | G34: KVK Geç.Md.14
A36: C. VADEYEGİREN KKM HESAP BAZINDA KÂR PAYI/FAİZ TABLOSU VE 372 MUTABAKAT
A37: SÜTUN 5 (lacivert çerçeve): Vade sonu toplam tahsilat — ANA GİRİŞ. SÜTUN 6 (turuncu çerçeve): Önceki yıl 372 tutarı — mükerrerlik önleme. SÜTUN 7: Net 373 = Col5 − Col6. SÜTUN 8: İstisna (= Net 373).
A38: KKM Hesap | B38: Açılış Tarihi | C38: Vade Tarihi | D38: Vade (Ay) | E38: Vade Sonu Toplam (TL) | F38: Önceki Yıl 372 (TL) | G38: Net 373 (TL) | H38: İstisna (TL)
G39: =IF(E39>0,MAX(E39-F39,0),0) -> 0 | H39: =G39 -> 0
G40: =IF(E40>0,MAX(E40-F40,0),0) -> 0 | H40: =G40 -> 0
G41: =IF(E41>0,MAX(E41-F41,0),0) -> 0 | H41: =G41 -> 0
G42: =IF(E42>0,MAX(E42-F42,0),0) -> 0 | H42: =G42 -> 0
G43: =IF(E43>0,MAX(E43-F43,0),0) -> 0 | H43: =G43 -> 0
G44: =IF(E44>0,MAX(E44-F44,0),0) -> 0 | H44: =G44 -> 0
...

Sheet HESAPLAMALAR & KONTROL
A1: 373 – KVK GEÇİCİ MD.14/1-b VADE SONU KÂR PAYI/FAİZ | HESAPLAMALAR VE DENETİM
A2: Vade Sonu Tahsilat | 372–373 Mükerrerlik Önleme | Beyanname 373 | YİAKV MATRAHINDA DÜŞÜLEMEZ
A4: A. TASDİK ÖZETİ
A5: A0 Uygunluğu | E5: ='VERİ GİRİŞİ'!F15 -> OK - Hesaplanabilir | F5: OK ise devam
A6: KKM Kaynaklı (B.7) | E6: ='VERİ GİRİŞİ'!C34 -> EVET | F6: EVET zorunlu
A7: Toplam Vade Tahsilat (D.1) | E7: ='VERİ GİRİŞİ'!D52 -> 0 | F7: Banka bildirimi
A8: 372 Mahsubu (D.2) | E8: ='VERİ GİRİŞİ'!D53 -> 0 | F8: Mükerrerlik önleme
A9: 373 NET İSTİSNA (D.3) | E9: ='VERİ GİRİŞİ'!D54 -> 0
A10: ★★ YİAKV'de DÜŞÜLEMEZ | E10: 370+371+372+373 — Dördü de E.7 | F10: Her zaman DÜŞÜLEMEZ
A12: B. 370–371–372–373 TAM KARŞILAŞTIRMA MATRİSİ — KVK GEÇİCİ MD.14
B13: Özellik | C13: 370 (1-a) | D13: 371 (1-b) | E13: 372 (1-b) | F13: 373 (1-b) | G13: Ortak
A14: Konu | C14: Kur farkı değerleme | D14: Kur farkı tazminat | E14: Faiz/kâr payı tahakkuk | F14: Faiz/kâr payı vade tahsil | G14: 4 ayrı mekanizma
A15: Zaman | C15: Dönüşüm — tek | D15: Ödeme dönemleri | E15: 31 Aralık | F15: Vade tarihi | G15: Her biri farklı dönem
A16: Muhasebe | C16: 646/679 | D16: 102/648 | E16: 181/642 | F16: 102/(181+642) | G16: Ticari kâra dahil
A17: Beyanname | C17: 370 | D17: 371 | E17: 372 | F17: 373 | G17: Kazancın Bulunması Halinde
A18: YİAKV | C18: DÜŞÜLEMEZ (E.7) | D18: DÜŞÜLEMEZ (E.7) | E18: DÜŞÜLEMEZ (E.7) | F18: DÜŞÜLEMEZ (E.7) | G18: Dördü birlikte E.7
A19: 372–373 İlişki | C19: — | D19: — | E19: Dönem sonu accrual | F19: Vade tahsilatı − 372 | G19: Net = Mükerrerlik yok
A21: C. DENETİM KONTROL LİSTESİ (K1–K12)
B22: Kontrol | D22: Açıklama | F22: Sonuç
A23: K1 | B23: ★ KKM hesabı 31/12/2021 bilanço kaynaklı dönüşümden mi açıldı? | D23: 370 çalışma kâğıdıyla çapraz teyit. B.7 EVET olmalı. | F23: =IF('VERİ GİRİŞİ'!C34="EVET","Uygun","Eksik") -> Uygun | G23: Uygun/Eksik/Risk
A24: K2 | B24: ★ Vade tarihi dönem içinde (01.01–31.12) mi? | D24: Sonraki dönemde vadeye girenler → Gelecek yıl 373. | F24: =IF('VERİ GİRİŞİ'!F9="EVET","Uygun","Eksik") -> Uygun | G24: Uygun/Eksik/Risk
A25: K3 | B25: ★ 372–373 MÜKERRERLİK kontrolü (C Sütun 6) yapıldı mı? | D25: Önceki yıl 372 tutarı mahsup edildi. Net 373 = Toplam − 372. EN KRİTİK. | F25: =IF('VERİ GİRİŞİ'!F10="EVET","Uygun","Risk") -> Uygun | G25: Uygun/Eksik/Risk
A26: K4 | B26: Vade tahsilat tutarları banka vade bildirimiyle mutabık mı? | D26: Her hesap satırı banka belgesinden doğrulanmalı. | F26: =IF('VERİ GİRİŞİ'!E47>0,"Uygun","Eksik") -> Eksik | G26: Uygun/Eksik/Risk
A27: K5 | B27: Kontrol: 372 + 373 = Toplam kâr payı/faiz mi? | D27: Çapraz: İki kodun toplamı banka toplam bildirim tutarına eşit. | F27: =IF(AND('VERİ GİRİŞİ'!E47>0,'VERİ GİRİŞİ'!G47='VERİ GİRİŞİ'!E47-'VERİ GİRİŞİ'!F47),"Uygun","Risk") -> Risk | G27: Uygun/Eksik/Risk
A28: K6 | B28: Vade sonu muhasebe kaydı doğru mu? (102 Dr / 181 Kr + 642 Kr) | D28: 181 kapatma (önceki yıl accrual) + 642 yeni kısım. | F28: =IF('VERİ GİRİŞİ'!F11="EVET","Uygun","Eksik") -> Uygun | G28: Uygun/Eksik/Risk
A29: K7 | B29: 370/371/372 çalışma kâğıtlarıyla çapraz mutabakat yapıldı mı? | D29: Dört dosya tutarlı — KKM hesap bilgileri örtüşüyor. | F29: =IF('VERİ GİRİŞİ'!F8="EVET","Uygun","Eksik") -> Uygun | G29: Uygun/Eksik/Risk
A30: K8 | B30: ★★ 373 istisnası YİAKV matrahından DÜŞÜLMEDI mi? | D30: 370+371+372+373 tamamı YİAKV matrahından DÜŞÜLEMEZ. E.7'de dört satır. | F30: =IF('VERİ GİRİŞİ'!F12="EVET","Uygun","Risk") -> Uygun | G30: Uygun/Eksik/Risk
A31: K9 | B31: Beyanname 373 'Kazancın Bulunması Halinde' bölümünde mi? | D31: Zarar döneminde uygulanamaz. | F31: =IF('VERİ GİRİŞİ'!F9="EVET","Uygun","Eksik") -> Uygun | G31: Uygun/Eksik/Risk
A32: K10 | B32: Dönem içinde birden fazla hesap vadeye girdi mi? Hepsi ayrı satırda mı? | D32: Her vadeye giren hesap C tablosunda ayrı satır ve ayrı 372 mahsubu. | F32: =IF('VERİ GİRİŞİ'!E47>0,"Uygun","Eksik") -> Eksik | G32: Uygun/Eksik/Risk
A33: K11 | B33: Hesap yenileme (rollover) yapıldıysa yeni hesap ayrıca değerlendirildi mi? | D33: Yenilenen hesap için yeni 371+372+373 analizi. | F33: =IF('VERİ GİRİŞİ'!F8="EVET","Uygun","Eksik") -> Uygun | G33: Uygun/Eksik/Risk
A34: K12 | B34: YMM Tasdik Raporu (49 No.lu Tebliğ) değerlendirildi mi? | D34: >=500.000 TL → YMM raporu. | F34: =IF('VERİ GİRİŞİ'!F14="EVET","Uygun","Eksik") -> Uygun | G34: Uygun/Eksik/Risk

Sheet MUHASEBE KAYITLARI
A1: 373 – KVK GEÇİCİ MD.14/1-b VADE SONU KÂR PAYI/FAİZ | MUHASEBE KAYITLARI
A2: Vade Tahsilatı | 372 Accrual Kapatma | 370–371–372–373 Muhasebe Tablosu
A4: KAYIT 1 — VADE SONU (AYNI YILDA AÇILIP KAPANAN HESAP — ÖNCEKİ YIL 372 YOK)
A5: Senaryo: KKM hesabı aynı dönemde açılıp vadeye giriyor (örn. Mart 2025 → Eylül 2025). Önceki yıl 372 yok.
B6: Tarih | C6: Hesap | D6: Not | E6: Dr | F6: Kr | H6: Ref
A7: Dr | B7: [Vade Tarihi] | C7: 102 Bankalar | D7: Vade sonu toplam kâr payı/faiz tahsilatı — tamamı bu dönem → Beyanname 373 | E7: [Tutar] | F7: — | H7: Banka bildirimi
A8: Kr | B8: [Vade Tarihi] | C8: 642 Faiz Gelirleri / 644 Kâr Payları | D8: Vade sonu kâr payı/faiz — KVK Geçici Md.14/1-b → Beyanname 373 (tamamı) | E8: — | F8: [Tutar] | H8: KV 373
A9: KAYIT 2 — VADE SONU (YILI AŞAN VADELİ HESAP — ÖNCEKİ YIL 372 VAR)
A10: Senaryo: Mart 2024 açılış, Eylül 2025 vade. 2024 yılı sonunda 372 (181/642) tahakkuku yapılmıştı.
B11: Tarih | C11: Hesap | D11: Not | E11: Dr | F11: Kr | H11: Ref
A12: Dr | B12: [Vade 2025] | C12: 102 Bankalar | D12: Vade sonu toplam kâr payı/faiz tahsilatı (2024 + 2025 toplam) | E12: [Toplam] | F12: — | H12: Banka bildirimi
A13: Kr | B13: [Vade 2025] | C13: 181 Gelir Tahakkukları | D13: Önceki yıl 372 tahakkukunun kapatılması (2024 tahakkuk tutarı) | E13: — | F13: [2024 x 372] | H13: 181 kapatma
A14: Kr | B14: [Vade 2025] | C14: 642 Faiz Gelirleri / 644 Kâr Payları | D14: Bu yılın (2025) kısmı → Beyanname 373 = Net tutar | E14: — | F14: [Net 373] | H14: KV 373
A15: 2025 Beyannamesi 373 = 642'ye yazılan tutar (Net = Toplam − 2024 x 372). 181 kapatma → 2025'te yeni gelir değil (2024'te 372 alındı). YİAKV'de düşülemez.
A16: KAYIT 3 — 370/371/372/373 TAM MUHASEBE TABLOSU
B17: Tarih | C17: Hesap | D17: Not | E17: Dr | F17: Kr | H17: Ref
A18: 370 | B18: [Dönüşüm] | C18: 646/679 | D18: Kur farkı değerleme → Tek seferlik → Beyanname 370 | E18: — | F18: [370] | H18: KV 370
A19: 371 | B19: [Ödeme] | C19: 102/648 | D19: Bankadan kur farkı koruma ödemesi → Dönemsel nakit → Beyanname 371 | E19: — | F19: [371] | H19: KV 371
A20: 372 | B20: [31.12] | C20: 181/642 | D20: Dönem sonu faiz/kâr payı tahakkuku → 31 Aralık → Beyanname 372 | E20: — | F20: [372] | H20: KV 372
A21: 373 | B21: [Vade] | C21: 102/(181+642) | D21: Vade sonu tahsilat (181 kapat + yeni 642) → Beyanname 373 | E21: — | F21: [373] | H21: KV 373
A22: YİAKV: 646+648+642(372)+642(373) → Ticari kâra dahil. 370+371+372+373 YİAKV MATRAHINDA DÜŞÜLEMEZ (E.7). Genel KV matrahından çıkarılır (her satır ayrı beyannamede). Toplamı: 370+371+372+373 = KVK Geçici Md.14 tam paketi.

Sheet DENETCİ NOTLARI
A1: 373 – KVK GEÇİCİ MD.14/1-b VADE SONU KÂR PAYI/FAİZ | DENETÇİ NOTLARI
A2: GİB KV Beyan Rehberi Mart 2026 (No:606) | KVK Geçici Md.14 | 372–373 Mükerrerlik | ★★ YİAKV DÜŞÜLEMEZ
A3: Kod | B3: Konu | C3: Mesleki Değerlendirme / Tasdik Standardı | D3: Mevzuat / Kaynak
A4: N1 | B4: KVK Geçici Md.14/1-b — 373 Vade Sonu Mekanizması | C4: 373 (VADE SONUNDA OLUŞAN KÂR PAYI VE FAİZ): KKM hesabı vadeye ulaştığında bankadan fiilen tahsil edilen kâr payı ve faiz geliri, KVK Geçici Madde 14/1-b kapsamında kurumlar vergisinden istisnadır. 372 ile TEMEL FARK: • 372: Hesap açık, dönem sonu 31 Aralık tahakkuku — muhasebe: 181 Dr / 642 Kr. • 373: Hesap vadeye ulaştı, kâr payı/faiz tahsil edildi — muhasebe: 102 Dr / (181+642) Kr. ÖNEMLI: Aynı KKM hesabından yılı aşan vadeli işlemlerde HER İKİSİ birlikte oluşabilir. Önceki yılın 372 tahakkuku ile bu yılın 373 vade tahsilatı ÇAKIŞABİLİR → mükerrerlik önlenmeli. BEYANNAME: 373 | Kazancın Bulunması Halinde İndirilecek | D4: KVK Geçici Md.14/1-b | GİB KV Beyan Reh. 2026 (No:606)
A5: N2 | B5: ★ 372–373 MÜKERRERLİK KURALI — EN KRİTİK YMM KONTROLÜ | C5: ÖRNEK (Yılı Aşan Vadeli Hesap): Hesap: Mart 2024 açılış | Eylül 2025 vade | Toplam kâr payı: 30.000 TL 2024 KV dönemi (31.12.2024): → Tahakkuk: 14.500 TL (10 ay) | Muhasebe: Dr 181 / Kr 642 → 2024 beyannamesi 372 satırı: 14.500 TL ✓ 2025 KV dönemi (Vade: Eylül 2025): → Banka 30.000 TL öder → Muhasebe: Dr 102 / Kr 181 (14.500 kapatma) + Kr 642 (15.500 yeni) → 2025 beyannamesi 373 satırı: 15.500 TL (NET — önceki 372 mahsup edildi) ✓ ÇAPRAZ KONTROL: 372 (14.500) + 373 (15.500) = 30.000 TL (banka toplam bildirimi) ✓ HATA: 373'e 30.000 TL yazılırsa → 14.500 TL mükerrer istisna → Tarhiyat + Vergi ziyaı cezası. | D5: KVK Geçici Md.14/1-b | 1 Seri No.lu KVK GT
A6: N3 | B6: ★★ YİAKV ile İlişki — 370+371+372+373 Tamamı DÜŞÜLEMEZ | C6: YİAKV (KVK Md.32/C) MATRAHINDA: • 370 → DÜŞÜLEMEZ | • 371 → DÜŞÜLEMEZ • 372 → DÜŞÜLEMEZ | • 373 → DÜŞÜLEMEZ YİAKV çalışma kâğıdı E.7 satırı: 'KKM Kur Farkı Değerleme + Tazminat + Dönem Sonu + Vade Kâr Payı/Faiz İstisnası (KVK Geçici Md.14) → YİAKV'de DÜŞÜLEMEZ ✗ | Beyanname 370/371/372/373' YMM, dört kodun tamamının asgari vergi matrahında kaldığını teyit etmelidir. Toplu olarak da, ayrı ayrı da YİAKV matrahından düşülemez. | D6: KVK Md.32/C | YİAKV Reh. (No:607) | GİB KV Beyan Reh. (No:606)
A7: N4 | B7: Hesap Yenileme, Aynı Yılda Birden Fazla Vade, Erken Kapatma | C7: HESAP YENİLEME (ROLLOVER): Vadeye giren hesabın kâr payı/faizi → 373 istisnası. Yenilenen yeni hesap için yeni 371/372/373 döngüsü başlar. Yeni hesabın da 31/12/2021 kaynaklı olduğu teyit edilmeli. AYNI YILDA BİRDEN FAZLA VADE: Her vadeye giren hesap C tablosunda ayrı satır. Her hesap için önceki yıl 372 mahsubu ayrı ayrı hesaplanır. ERKEN KAPATMA: Vade öncesi kapatmada genellikle ceza faizi uygulanır. Fiilen tahsil edilen kâr payı/faiz → 373 kapsamında değerlendirilebilir. 372+373 ÇAPRAZ KONTROL: Her hesap için: 372 (tüm dönem) + 373 (net vade) = Banka toplam bildirimi. Bu eşitlik sağlanamıyorsa muhasebe veya beyanname hatası var demektir. | D7: KVK Geçici Md.14/1-b | VUK Md.280/281
A8: N5 | B8: 49 No.lu Tebliğ + YMM Tasdik Dil Standardı | C8: KULLANIN (Önceki Yıl 372 Olan Hesap İçin): '...31/12/2021 tarihli bilançoda kayıtlı yabancı paranın TL kur korumalı mevduat hesabına dönüştürülmesi sonucunda açılan KKM hesabı [Vade Tarihi] tarihinde vadeye ulaşmış; vade süresince oluşan toplam [Brüt Tutar] TL kâr payı/faizin önceki dönemde 372 istisnasına konu edilen [372 Tutarı] TL düşülerek kalan [Net 373] TL KVK Geçici Madde 14/1-b kapsamında kurumlar vergisinden istisna edilmiş ve yurt içi asgari kurumlar vergisi matrahından indirilmemiştir.' KULLANIN (Önceki Yıl 372 Olmayan Hesap İçin): '...Vade süresinde oluşan toplam [Tutar] TL kâr payı/faizin tamamı 373 kapsamında istisnaya tabidir.' KULLANMAYINlar: '...Toplam vade kâr payının tamamı 373'e yazılmıştır.' (Önceki 372 mahsubu yapılmamış) '...373 tutarı YİAKV matrahından düşülmüştür.' (YANLIŞ) KRİTİK RİSKLER: (1) 372 mahsubu yapılmadan 373'e toplam yazmak — MÜKERRERLIK. (2) 373'ü YİAKV matrahından düşmek. (3) Vade tarihinin dönem dışında olduğunu gözden kaçırmak. | D8: 49 No.lu Tebliğ | KVK Geçici Md.14 | SM-SMMM-YMM K. Md.12
A9: GİB KV BEYAN REHBERİ MART 2026 (No:606) KAPANIŞ (373): KVK Geçici Md.14 paketi tamamlandı — 370/371/372/373 dört kod, dört ayrı mekanizma, dört ayrı beyanname satırı. 372–373 mükerrerlik YMM'nin en kritik kontrolüdür. Dördü de YİAKV matrahından DÜŞÜLEMEZ. YMM müteselsil sorumluluk: SM-SMMM-YMM Kanunu Md.12.

Sheet BELGE LISTESI
A1: 373 – KVK GEÇİCİ MD.14/1-b VADE SONU KÂR PAYI/FAİZ | BELGE LİSTESİ | YMM TASDİK
A2: GİB KV Beyan Rehberi Mart 2026 (No:606) | Banka Vade Bildirimi | 372 Mükerrerlik Önleme
A4: KATEGORİ 1 — ZORUNLU BELGELER
B5: No | C5: Belge | D5: Açıklama | E5: Temin
B6: 1 | C6: ★ Banka Vade Bildirimi / Hesap Özeti — Toplam Kâr Payı/Faiz | D6: Vade sonunda bankadan alınan resmi bildiri: Vade tarihi ve toplam kâr payı/faiz tutarı. C tablosu Sütun 5'in dayanağıdır. Her hesap için ayrı banka belgesi zorunludur. | E6: Banka şubesi/internet bankacılığı
B7: 2 | C7: ★ Önceki Dönem KV Beyannamesi 372 Satırı (Bu Hesap İçin) | D7: Önceki yılda bu hesap için 372 kapsamında istisna uygulanan tutar. C tablosu Sütun 6 (mükerrerlik önleme) için zorunlu kaynak. YMM: 372 + 373 = Toplam kâr payı/faiz (banka bildirimi) eşitliği kontrol edilmeli. | E7: Önceki dönem KV beyannamesi 372 satırı
B8: 3 | C8: ★ 370/371/372 Çalışma Kâğıtları — Çapraz Mutabakat | D8: Dört dosyanın KKM hesap bilgileri tutarlı. B.7 (31/12/2021 kaynaklı) dört dosyada teyit. | E8: 370/371/372 çalışma kâğıtları
B9: 4 | C9: Muhasebe Yevmiyesi — Vade Tahsilat Kaydı (102 Dr / 181 Kr + 642 Kr) | D9: Vade muhasebe kaydı: 102 borç / 181 alacak (önceki yıl accrual kapatma) + 642 alacak (yeni kısım). C Sütun 7 (net 373) ile 642'ye yazılan tutar uyumlu olmalı. | E9: Yevmiye defteri
B10: 5 | C10: KV Beyannamesi Taslağı — 373. Satır | D10: 'Kazancın Bulunması Halinde' bölümü. ★★ YİAKV matrahından çıkarılmamış. | E10: GİB e-Beyanname sistemi
A12: KATEGORİ 2 — EK BELGELER
B13: No | C13: Belge | D13: Açıklama | E13: Temin
B14: 6 | C14: 181 Hesap Ekstresi — Önceki Yıl Tahakkuk Kapanışı | D14: 181 kapatılan tutar = Sütun 6 tutarı (mükerrerlik kontrol belgesi). | E14: 181 hesap ekstresi
B15: 7 | C15: KKM Hesap Sözleşmesi | D15: Kâr payı/faiz oranı ve vade koşulları — hesap doğrulaması için. | E15: Banka sözleşmesi
B16: 8 | C16: Hesap Yenileme Belgesi (Varsa) | D16: Rollover için yenileme sözleşmesi — yeni hesabın kapsam analizi. | E16: Banka belgesi
A18: KATEGORİ 3 — YMM TASDİK KONTROL SORULARI
B19: No | C19: Kontrol Sorusu | D19: Beklenen Sonuç | E19: YMM Aksiyonu
B20: S1 | C20: ★ KKM hesabı 31/12/2021 bilanço kaynaklı dönüşümden mi açıldı? | D20: 370 çapraz teyit. B.7 EVET. | E20: YMM kontrolü
B21: S2 | C21: ★ Vade tarihi dönem içinde (01.01–31.12) mi? | D21: Sonraki dönemde vadeye girenler → Gelecek yıl 373. | E21: YMM kontrolü
B22: S3 | C22: ★ 372–373 MÜKERRERLİK (C Sütun 6) kontrolü yapıldı mı? | D22: Önceki yıl 372 mahsup edildi. Net 373 doğru hesaplandı. | E22: YMM kontrolü
B23: S4 | C23: Vade tahsilat tutarları banka bildirimiyle mutabık mı? | D23: Her hesap satırı banka belgesinden doğrulanmalı. | E23: YMM kontrolü
B24: S5 | C24: 372+373 = Banka toplam bildirimi eşitliği sağlandı mı? | D24: Çapraz kontrol: İki kodun toplamı banka tutarına eşit. | E24: YMM kontrolü
B25: S6 | C25: Vade muhasebe kaydı doğru? (102/181+642) | D25: 181 kapatma + 642 yeni kısım. | E25: YMM kontrolü
B26: S7 | C26: 370/371/372 dosyalarıyla çapraz mutabakat tamam mı? | D26: Dört dosya tutarlı. | E26: YMM kontrolü
B27: S8 | C27: ★★ 373 istisnası YİAKV matrahından DÜŞÜLMEDI mi? | D27: 370+371+372+373 tamamı YİAKV E.7'de DÜŞÜLEMEZ. | E27: YMM kontrolü
B28: S9 | C28: Beyanname 373 'Kazancın Bulunması Halinde' bölümünde mi? | D28: Zarar döneminde uygulanamaz. | E28: YMM kontrolü
B29: S10 | C29: YMM Tasdik Raporu (49 No.lu Tebliğ) değerlendirildi mi? | D29: >=500.000 TL → YMM raporu. | E29: YMM kontrolü
A31: SON NOT: GİB KV Beyan Rehberi Mart 2026 (No:606) esas alınmıştır. 373, 370+371+372 ile KVK Geçici Md.14 paketini tamamlar. 372–373 mükerrerlik (Sütun 6 mahsubu) en kritik YMM kontrol noktasıdır. Dördü de YİAKV matrahından DÜŞÜLEMEZ (E.7). YMM müteselsil: SM-SMMM-YMM Kanunu Md.12.
