Workbook

Sheet VERİ GİRİŞİ
A1: 384 – KVK GEÇİCİ MADDE 14/4 | KÂR PAYI VE FAİZ İSTİSNASI | PARAGRAF 4 — GENEL / VADESİZ / DÖNEMSELİ KAPSAR | 383–384 MÜKERRERLİK | YMM TASDİK
A2: KVK Geçici Md.14/4 (Paragraf 4) | Genel Kâr Payı/Faiz İstisnası (Dönem Sonu Kısıtı Yok) | Beyanname 384 | ★ YİAKV MATRAHINDA DÜŞÜLEMEZ | 383–384 Mükerrerlik Önlenmeli
A3: 383 – 384 AYRIMI (PARAGRAF 4 İÇİNDE): 383 (Md.14/4): 'Dönem Sonu DEĞERLEMESİNDEN DOĞAN kâr payı ve faiz' → 31 Aralık tahakkuk esaslı | 181/642. 384 (Md.14/4): 'Kâr payı ve faiz istisnası' → Dönem sonu sınırı YOK — doğrudan ödeme, vade sonu, dönemsel tahsilat kapsar | 102/642. ★★ 383–384 MÜKERRERLİK: 383 tahakkuku yapılan araç için vade/tahsilat döneminde → 383'ün önceki yıl kısmı 384'ten çıkarılır. (372-373, 376-377, 380-381 kuralının Paragraf 4 eşdeğeri)
A4: ★★ YİAKV (KVK Md.32/C) KRİTİK: 384 kapsamındaki kâr payı/faiz istisnası YİAKV matrahından DÜŞÜLEMEZ. KVK Geçici Md.14 tüm kodları E.7 DÜŞÜLEMEZ listesindedir.
A6: A0. KAPSAM VE NİTELİK UYGUNLUK ÖN KONTROLÜ
B7: Kontrol Sorusu | F7: Yanıt | H7: YMM Tasdik Notu
A8: A0.1 KVK Geçici Md.14/4 kapsamında işlem gerçekleştirildi mi? | F8: EVET | G8: 384, KVK Geçici Md.14/4 kapsamı araçlardan elde edilen kâr payı ve faize uygulanır. Paragraf 4 kapsam analizi zorunludur.
A9: A0.2 ★ Bu kâr payı/faiz 383 (dönem sonu tahakkuk) kapsamında DEĞİL mi? | F9: EVET | G9: 383: 31 Aralık tahakkuk (dönem sonu değerleme). 384: Doğrudan ödeme/vade/dönemsel kâr payı/faiz. Aynı tutarın hem 383 hem 384'e yazılması mükerrerlik oluşturur.
A10: A0.3 Tahsilat/Ödeme Türü belirlendi mi? | F10: Vade Sonu Tahsilatı | G10: 384'ün kapsamı: Vade sonu + Dönemsel tahsilat + Doğrudan ödeme — 383'ten farklı tüm tahsilatlar.
A11: A0.4 ★ 383–384 MÜKERRERLİK kontrolü yapıldı mı? | F11: EVET | G11: Önceki yılda 383 tahakkuku yapılmış araç vadeye giriyorsa: Net 384 = Toplam − Önceki Yıl 383 Tahakkuku. (372-373, 376-377, 380-381 kuralının P4 eşdeğeri)
A12: A0.5 Paragraf 1/2/3 ile mükerrerlik analizi yapıldı mı? | F12: EVET | G12: Paragraf 4 araçlarının 373/377/381 kapsamına girmediği teyit edilmeli.
A13: A0.6 ★ 384 tutarının YİAKV matrahından DÜŞÜLMEDIĞI teyit edildi mi? | F13: EVET | G13: KVK Geçici Md.14 tüm kodları YİAKV matrahından DÜŞÜLEMEZ. E.7'de 384 de kontrol edilmeli.
A14: A0.7 YMM Tasdik Raporu (49 No.lu Tebliğ) değerlendirildi mi? | F14: EVET | G14: >=500.000 TL → YMM raporu.
A15: A0.8 Tasdik Uygunluk Sonucu | F15: =IF(AND(F8="EVET",F9="EVET",F11="EVET",F13="EVET"),"OK - Hesaplanabilir","HATA - Ön koşul eksik") -> OK - Hesaplanabilir | G15: ★ A0.2 (383 ayrımı), A0.4 (383-384 mükerrerlik), A0.6 (YİAKV) kritik.
A17: A. GENEL BİLGİLER
A18: Kurumun Unvanı | G18: Tam ticaret unvanı
A19: VKN | G19: 10 haneli VKN
A20: Hesap Dönemi | G20: 01.01.2025 – 31.12.2025
A21: KV Oranı (%) | G21: 2025: %25 | Banka/Finans: %30
A22: Dosya Referansı | G22: YMM-2025/384-01
A23: 383 Çalışma Kâğıdı Referansı | G23: Dönem sonu tahakkuk (383) ile mükerrerlik önleme zorunlu
A25: B. 383–384 MUTABAKAT AÇIKLAMASI VE ARAÇ BİLGİLERİ
A26: 383–384 MUTABAKAT KURALI (YILI AŞAN VADELİ PARAGRAF 4 ARAÇLARI): Örnek: P4 araç açılış Mart 2024 | Vade Eylül 2025 | Toplam kâr payı: 30.000 TL Aralık 2024 sonu (383): 14.500 TL tahakkuk → 2024 KV beyannamesi 383 satırı. Eylül 2025 vade (384): 30.000 − 14.500 = 15.500 TL net → 2025 KV beyannamesi 384 satırı. KURAL: Net 384 = Toplam − Önceki Yıl 383 Tahakkuku. Çapraz: 383 + 384 = Toplam kâr payı/faiz.
B27: Parametre | E27: Değer / Tarih | G27: Açıklama | H27: Kaynak
A28: B.1 Paragraf 4 TL Araç Türü | C28: TL Mevduat | D28: KVK Geçici Md.14/4 kapsamı TL araç türü. | G28: Araç sözleşmesi
A29: B.2 384 Tahsilat Türü | C29: Vade Sonu Tahsilatı | D29: 384'ün 383'ten farklı kapsamı: Vade/dönemsel/doğrudan tahsilat. | G29: Ödeme belgesi
A30: B.3 Tahsilat/Ödeme Tarihi (veya Dönem) | D30: Kâr payı/faizin tahsil edildiği tarih veya dönem. | G30: Banka belgesi
A31: B.4 Toplam Kâr Payı/Faiz (Bu Araç İçin Banka Bildirimi) | D31: Tüm araç süresi boyunca oluşan toplam kâr payı/faiz. | G31: Banka bildirimi
A32: B.5 ★ Önceki Dönem(ler) 383 Tahakkuk Tutarı (Bu Araç İçin) | D32: Bu araç için önceki KV dönemlerinde 383 kapsamında istisna uygulanan toplam. Yoksa 0. | G32: Önceki dönem KV 383 satırı
A33: B.6 Net 384 Tutarı (B.4 − B.5) | C33: =G47 -> 0 | D33: C tablosunda otomatik hesaplanır. Çapraz: 383+384 = B.4. | G33: Formül (C Sütun 7)
A34: B.7 ★ Paragraf 4 Kapsamı Teyit Edildi mi? | C34: EVET | D34: Paragraf 4 kapsam analizi belgesi hazırlandı. | G34: Paragraf 4 analizi
A36: C. PARAGRAF 4 ARACI BAZINDA KÂR PAYI/FAİZ VE 383 MUTABAKAT TABLOSU
A37: SÜTUN 5 (yeşil çerçeve): Toplam kâr payı/faiz — ANA VERİ. SÜTUN 6 (turuncu çerçeve): Önceki yıl 383 tutarı — mükerrerlik önleme. SÜTUN 7 = Net 384. SÜTUN 8 = İstisna.
A38: Araç Adı/No | B38: Açılış/Dönem | C38: Tahsilat Türü | D38: Tahsilat Tarihi | E38: Toplam Kâr Payı/Faiz (TL) | F38: Önceki Yıl 383 (TL) | G38: Net 384 (TL) | H38: İstisna (TL)
G39: =IF(E39>0,MAX(E39-F39,0),0) -> 0 | H39: =G39 -> 0
G40: =IF(E40>0,MAX(E40-F40,0),0) -> 0 | H40: =G40 -> 0
G41: =IF(E41>0,MAX(E41-F41,0),0) -> 0 | H41: =G41 -> 0
G42: =IF(E42>0,MAX(E42-F42,0),0) -> 0 | H42: =G42 -> 0
G43: =IF(E43>0,MAX(E43-F43,0),0) -> 0 | H43: =G43 -> 0
G44: =IF(E44>0,MAX(E44-F44,0),0) -> 0 | H44: =G44 -> 0
...

Sheet HESAPLAMALAR & KONTROL
A1: 384 – KVK GEÇİCİ MD.14/4 KÂR PAYI VE FAİZ | HESAPLAMALAR VE DENETİM
A2: Paragraf 4 Genel Kâr Payı/Faiz | 383-384 Mükerrerlik | Beyanname 384 | YİAKV MATRAHINDA DÜŞÜLEMEZ
A4: A. TASDİK ÖZETİ
A5: A0 Uygunluğu | E5: ='VERİ GİRİŞİ'!F15 -> OK - Hesaplanabilir | F5: OK ise devam
A6: Tahsilat Türü (A0.3) | E6: ='VERİ GİRİŞİ'!F10 -> Vade Sonu Tahsilatı | F6: Vade/Dönemsel/Doğrudan
A7: Toplam Kâr Payı/Faiz (D.1) | E7: ='VERİ GİRİŞİ'!D52 -> 0 | F7: Banka bildirimi
A8: 383 Mahsubu (D.2) | E8: ='VERİ GİRİŞİ'!D53 -> 0 | F8: Mükerrerlik önleme
A9: 384 NET İSTİSNA (D.3) | E9: ='VERİ GİRİŞİ'!D54 -> 0 | F9: Kazancın bulunması halinde
A10: ★★ YİAKV'de DÜŞÜLEMEZ | E10: Tüm KVK Geçici Md.14 kodları E.7 | F10: Her zaman DÜŞÜLEMEZ
A12: B. 373 / 377 / 381 / 384 — VADE VE GENEL KÂR PAYI/FAİZ DÖRT PARAGRAF KARŞILAŞTIRMASI
B13: Özellik | C13: 373 (Md.14/1-b) P1 | D13: 377 (Md.14/2) P2 | E13: 381 (Md.14/3) P3 | F13: 384 (Md.14/4) P4 | G13: Ortak | H13: YİAKV
A14: Dayanak | C14: P1: Aktif yab.para/altın → TL KKM | D14: P2: Borç → TL araç | E14: P3: Altın → TL araç | F14: P4: Özel kapsam araç | G14: Vade/genel kâr payı | H14: Dördü DÜŞÜLEMEZ
A15: Muhasebe | C15: 102/(181+642) | D15: 102/(181+642) | E15: 102/(181+642) | F15: 102/(181+642) veya 102/642 | G15: Benzer mekanizma | H15: E.7
A16: Mükerrerlik | C16: 372-373 | D16: 376-377 | E16: 380-381 | F16: 383-384 (YENİ) | G16: Önceki tahakkuk mahsubu | H16: Her çift
A17: Önceki Tahakkuk | C17: 372 mahsubu | D17: 376 mahsubu | E17: 380 mahsubu | F17: 383 mahsubu | G17: Net = Toplam − Önceki | H17: Çapraz eşitlik
A19: C. DENETİM KONTROL LİSTESİ (K1–K12)
B20: Kontrol | D20: Açıklama | F20: Sonuç
A21: K1 | B21: ★ Paragraf 4 kapsamı analizi yapıldı ve belgelendi mi? | D21: GİB Beyan Reh. No:606 + CB Kararları referans alındı. | G21: =IF('VERİ GİRİŞİ'!F8="EVET","Uygun","Eksik") -> Uygun
A22: K2 | B22: ★ Bu kâr payı/faiz 383 (dönem sonu tahakkuk) kapsamında değil mi? | D22: 383 = 31 Aralık accrual. 384 = Genel kâr payı/faiz. Ayrım açık olmalı. | G22: =IF('VERİ GİRİŞİ'!F9="EVET","Uygun","Eksik") -> Uygun
A23: K3 | B23: ★ 383–384 MÜKERRERLİK kontrolü (C Sütun 6) yapıldı mı? | D23: Önceki yıl 383 mahsup edildi. Net 384 doğru hesaplandı. EN KRİTİK. | G23: =IF('VERİ GİRİŞİ'!F11="EVET","Uygun","Eksik") -> Uygun
A24: K4 | B24: Kâr payı/faiz tutarları banka bildirimiyle mutabık mı? | D24: Her araç satırı banka belgesinden doğrulanmış. | G24: =IF('VERİ GİRİŞİ'!E47>0,"Uygun","Eksik") -> Eksik
A25: K5 | B25: ÇAPRAZ: 383 + 384 = Toplam kâr payı/faiz mi? | D25: İki kodun toplamı banka toplam bildirimine eşit olmalı. | G25: =IF(AND(E7>0,E7=E8+E9),"Uygun",IF(E7=0,"Eksik","Risk")) -> Eksik
A26: K6 | B26: Vade sonu muhasebe kaydı doğru mu? (102 / 181 Kr + 642 Kr) | D26: Önceki 383 181 kapatma + 642 yeni kısım. | G26: =IF(E7>0,"Uygun","Eksik") -> Eksik
A27: K7 | B27: 373/377/381 (Paragraf 1/2/3) ile mükerrerlik analizi yapıldı mı? | D27: Paragraf 4 araçları → 384. Diğer paragraflara karıştırma yok. | G27: =IF('VERİ GİRİŞİ'!F12="EVET","Uygun","Eksik") -> Uygun
A28: K8 | B28: ★★ 384 istisnası YİAKV matrahından DÜŞÜLMEDI mi? | D28: KVK Geçici Md.14 tüm kodları YİAKV E.7'de DÜŞÜLEMEZ. | G28: =IF('VERİ GİRİŞİ'!F13="EVET","Uygun","Risk") -> Uygun
A29: K9 | B29: Beyanname 384 'Kazancın Bulunması Halinde' bölümünde mi? | D29: Zarar döneminde uygulanamaz. | G29: =IF(E9>0,"Uygun","Eksik") -> Eksik
A30: K10 | B30: Tahsilat türü doğru belirlendi mi? (Vade/Dönemsel/Doğrudan) | D30: B.2 tahsilat türü seçimi yapıldı. | G30: =IF(E6<>"","Uygun","Eksik") -> Uygun
A31: K11 | B31: Birden fazla Paragraf 4 aracı varsa her biri ayrı satırda mı? | D31: Her araç C tablosunda ayrı satır ve ayrı 383 mahsubu. | G31: =IF(COUNTA('VERİ GİRİŞİ'!A39:A46)>0,"Uygun","Eksik") -> Eksik
A32: K12 | B32: YMM Tasdik Raporu (49 No.lu Tebliğ) değerlendirildi mi? | D32: >=500.000 TL → YMM raporu. | G32: =IF('VERİ GİRİŞİ'!F14="EVET","Uygun","Eksik") -> Uygun

Sheet MUHASEBE KAYITLARI
A1: 384 – KVK GEÇİCİ MD.14/4 KÂR PAYI VE FAİZ | MUHASEBE KAYITLARI
A2: Vade Tahsilatı | 383 Accrual Kapatma | 373/377/381/384 Karşılaştırma
A4: KAYIT 1 — VADE SONU (AYNI YILDA AÇILIP KAPANAN P4 ARACI — ÖNCEKİ YIL 383 YOK)
B5: Tarih | C5: Hesap | D5: Not | E5: Dr | F5: Kr | H5: Ref
A6: Dr | B6: [Tahsilat Tarihi] | C6: 102 Bankalar | D6: Kâr payı/faiz tahsilatı — tamamı bu dönem → Beyanname 384 | E6: [Tutar] | F6: — | H6: Banka belgesi
A7: Kr | B7: [Tahsilat Tarihi] | C7: 642 Faiz Gelirleri / 644 Kâr Payları | D7: KVK Geçici Md.14/4 → Beyanname 384 (tamamı) | E7: — | F7: [Tutar] | H7: KV 384
A8: KAYIT 2 — VADE SONU (YILI AŞAN VADELİ P4 ARACI — ÖNCEKİ YIL 383 VAR)
A9: 383 (dönem sonu tahakkuk) yapılmış araç vadeye giriyorsa: 181 kapatma + yeni 642 kısmı.
B10: Tarih | C10: Hesap | D10: Not | E10: Dr | F10: Kr | H10: Ref
A11: Dr | B11: [Tahsilat Tarihi] | C11: 102 Bankalar | D11: Toplam kâr payı/faiz tahsilatı (önceki 383 + bu yıl yeni) | E11: [Toplam] | F11: — | H11: Banka belgesi
A12: Kr | B12: [Tahsilat Tarihi] | C12: 181 Gelir Tahakkukları | D12: Önceki yıl 383 tahakkukunun kapatılması | E12: — | F12: [383 Tutar] | H12: 181 kapatma
A13: Kr | B13: [Tahsilat Tarihi] | C13: 642 Faiz Gelirleri | D13: Bu yılın yeni kısmı → Beyanname 384 (Net) | E13: — | F13: [Net 384] | H13: KV 384
A14: ÇAPRAZ: 383 (2024) + 384 (2025 Net) = Toplam kâr payı/faiz. C tablosu Sütun 6 mükerrerlik önler.
A15: KAYIT 3 — 373 / 377 / 381 / 384 DÖRT PARAGRAF YAN YANA
B16: Tarih | C16: Hesap | D16: Not | E16: Dr | F16: Kr | H16: Ref
A17: 373 | B17: [Vade] | C17: 102/(181+642) | D17: P1 AKT: KKM vade kâr payı/faiz → 373 | E17: — | F17: [373] | H17: KV 373
A18: 377 | B18: [Vade] | C18: 102/(181+642) | D18: P2 PAS: Borç araç vade kâr payı/faiz → 377 | E18: — | F18: [377] | H18: KV 377
A19: 381 | B19: [Vade] | C19: 102/(181+642) | D19: P3 ALT: Altın araç vade kâr payı/faiz → 381 | E19: — | F19: [381] | H19: KV 381
A20: 384 | B20: [Vade/Dönem] | C20: 102/(181+642) | D20: P4: Genel kâr payı/faiz → 384 (BU) | E20: — | F20: [384] | H20: KV 384
A21: YİAKV: 373+377+381+384 dördünün de geliri YİAKV MATRAHINDA DÜŞÜLEMEZ (E.7). Aynı araç için yalnızca biri uygulanabilir. 383-384 çapraz kontrol: 383 (tahakkuk) + 384 (net) = Toplam kâr payı/faiz banka bildirimi.

Sheet DENETCİ NOTLARI
A1: 384 – KVK GEÇİCİ MD.14/4 KÂR PAYI VE FAİZ | DENETÇİ NOTLARI
A2: GİB KV Beyan Rehberi Mart 2026 (No:606) | 373/377/381 Karşılaştırması | 383-384 Mükerrerlik | ★★ YİAKV
A3: Kod | B3: Konu | C3: Mesleki Değerlendirme / Tasdik Standardı | D3: Mevzuat / Kaynak
A4: N1 | B4: KVK Geçici Md.14/4 — 383 vs 384 Ayrımı ve Genel Kâr Payı/Faiz Mekanizması | C4: 384 (PARAGRAF 4 — KÂR PAYI VE FAİZ İSTİSNASI) TANIMI: 383'ten FARK: • 383 'Dönem sonu DEĞERLEMESİNDEN DOĞAN kâr payı ve faiz' → 31 Aralık tahakkuk, 181/642 • 384 'Kâr payı ve faiz istisnası' → Genel, zamana sınırsız, doğrudan ödeme/vade/dönemsel 384 KAPSAMINA GIREN TAHSİLAT TÜRLERİ: ① Vade sonu kâr payı/faiz tahsilatı (araç vadeye ulaştığında) ② Dönemsel kâr payı/faiz ödemeleri (aylık, üç aylık, yıllık) ③ Doğrudan tahsilat (belirli bir tarih ön koşulu olmaksızın) ④ 383 (dönem sonu tahakkuku) dışında kalan her türlü P4 kâr payı/faizi 383–384 MÜKERRERLİK KURALI: Önceki yıl 383 tahakkuku yapılmışsa: Net 384 = Toplam − 383 Tahakkuku Çapraz: 383 + 384 = Toplam kâr payı/faiz (banka bildirimi toplamı) BEYANNAME: 384 | Kazancın Bulunması Halinde İndirilecek | D4: KVK Geçici Md.14/4 | GİB KV Beyan Reh. 2026 (No:606)
A5: N2 | B5: ★ 383–384 MÜKERRERLİK KURALI — Paragraf 4'ün Kritik Hesap Dengesi | C5: 383-384 MÜKERRERLİK SENARYOsu (372-373, 376-377, 380-381 kuralının P4 eşdeğeri): P4 Araç: Mart 2024 açılış | Eylül 2025 vade | Toplam kâr payı: 30.000 TL 2024 KV (31.12.2024): → Dönem sonu tahakkuk (383): 14.500 TL | Dr 181 / Kr 642 → 2024 beyannamesi 383: 14.500 TL ✓ 2025 KV (Eylül 2025 vade): → Tahsilat: 30.000 TL → Dr 102 / Kr 181 (14.500 kapatma) + Kr 642 (15.500 yeni) → 2025 beyannamesi 384: 15.500 TL (NET) ✓ ÇAPRAZ: 383 (14.500) + 384 (15.500) = 30.000 TL (banka bildirimi) ✓ HATA: 384'e 30.000 TL yazılırsa → 14.500 TL mükerrer istisna → Tarhiyat. | D5: KVK Geçici Md.14/4 | 383 Çalışma Kâğıdı
A6: N3 | B6: ★★ YİAKV ile İlişki — KVK Geçici Md.14 Tüm Kodları DÜŞÜLEMEZ | C6: KVK GEÇİCİ MD.14 KAPSAMININ TAMAMININ YİAKV MATRAHINDA DÜŞÜLEMEZLİĞİ: Paragraf 1: 370|371|372|373|374 → BEŞİ DE DÜŞÜLEMEZ Paragraf 2: 375|376|377|378 → DÖRDÜ DE DÜŞÜLEMEZ Paragraf 3: 379|380|381|382 → DÖRDÜ DE DÜŞÜLEMEZ Paragraf 4: 383|384|... → HEPSI DÜŞÜLEMEZ YİAKV E.7 (Güncellenmeli — 384 eklenmeli): 'KVK Geçici Md.14 (Tüm Paragraflar 1-4, Kodlar 370-384+) → DÜŞÜLEMEZ ✗ | Beyanname 370/.../383/384' YMM, 384'ün eklenmesiyle E.7'yi güncellemelidir. | D6: KVK Md.32/C | YİAKV Reh. (No:607) | GİB KV Beyan Reh. (No:606)
A7: N4 | B7: Paragraf 4 Kâr Payı/Faiz Zinciri: 383 → 384 | C7: PARAGRAF 4 ZİNCİRİ (383-384): 383 (Md.14/4): Paragraf 4 dönem sonu faiz/kâr payı tahakkuku (31 Aralık accrual) 384 (Md.14/4): Paragraf 4 genel kâr payı/faiz (vade, dönemsel, doğrudan) Paralel zincirler: P1: 372 (dönem sonu) → 373 (vade) P2: 376 (dönem sonu) → 377 (vade) P3: 380 (dönem sonu) → 381 (vade) P4: 383 (dönem sonu) → 384 (vade/genel) ← BU 384 = 373, 377, 381'in Paragraf 4 karşılığı (ama adı daha genel). ÖZELGE: Paragraf 4 kapsamı tartışmalıysa GİB özelgesi alınmalıdır. | D7: KVK Geçici Md.14/4 | VUK Md.280/281
A8: N5 | B8: 49 No.lu Tebliğ + YMM Tasdik Dil Standardı | C8: KULLANIN (Önceki Yıl 383 Olan Araç İçin): '...KVK Geçici Madde 14/4 kapsamındaki [Araç Türü] hesabından elde edilen toplam [Brüt Tutar] TL kâr payı/faizin önceki dönemde 383 istisnasına konu edilen [383 Tutarı] TL düşülerek kalan [Net 384] TL, KVK Geçici Madde 14/4 kapsamında kurumlar vergisinden istisna edilmiş ve yurt içi asgari kurumlar vergisi matrahından indirilmemiştir.' KULLANMAYIN: '...384 tutarı YİAKV matrahından düşülmüştür.' (YANLIŞ) '...Toplam kâr payının tamamı 384'e yazılmıştır.' (383 mahsubu yapılmamış) '...383 ve 384 aynı araç için birlikte uygulanabilir.' (Mükerrerlik açıklaması eksik) KRİTİK RİSKLER: (1) 383 mahsubu yapılmadan 384'e toplam yazmak — MÜKERRERLİK. (2) 384'ü YİAKV matrahından düşmek. (3) Paragraf 4 kapsam analizi yapmadan 384 uygulamak. (4) 373/377/381 araçlarını 384'e yazmak (paragraf karışıklığı). | D8: 49 No.lu Tebliğ | KVK Geçici Md.14/4 | SM-SMMM-YMM K. Md.12
A9: GİB KV BEYAN REHBERİ MART 2026 (No:606) KAPANIŞ (384): 384 = 373, 377, 381'in Paragraf 4 karşılığı (daha genel adlandırma). 383 (dönem sonu tahakkuk) + 384 (genel kâr payı/faiz) = Paragraf 4 tam kâr payı/faiz paketi. 383-384 mükerrerlik (Sütun 6 mahsubu) kritik. KVK Geçici Md.14 tüm kodları YİAKV E.7'de DÜŞÜLEMEZ. YMM müteselsil sorumluluk: SM-SMMM-YMM Kanunu Md.12.

Sheet BELGE LISTESI
A1: 384 – KVK GEÇİCİ MD.14/4 KÂR PAYI VE FAİZ | BELGE LİSTESİ | YMM TASDİK
A2: GİB KV Beyan Rehberi Mart 2026 (No:606) | Araç/Banka Bildirimi | 383 Mükerrerlik | Paragraf 4
A4: KATEGORİ 1 — ZORUNLU BELGELER
B5: No | C5: Belge | D5: Açıklama | E5: Temin
B6: 1 | C6: ★ Banka/Araç Kâr Payı/Faiz Bildirimi (Toplam Tutar) | D6: Tahsilat/ödeme dönemine ait kâr payı/faiz bildirimi. C tablosu Sütun 5'in dayanağıdır. | E6: Banka/araç belgesi
B7: 2 | C7: ★ Önceki Dönem KV Beyannamesi 383 Satırı (Bu Araç İçin) | D7: Önceki yılda bu araç için 383 kapsamında istisna uygulanan tutar. C Sütun 6 (mükerrerlik önleme) için zorunlu. 383+384=Toplam kâr payı/faiz eşitliği kontrol edilmeli. | E7: Önceki dönem KV beyannamesi 383 satırı
B8: 3 | C8: ★ Paragraf 4 Kapsam Analizi Belgesi | D8: KVK Geçici Md.14/4 kapsamını gösteren YMM tarafından hazırlanan kapsam analizi notu. | E8: YMM tarafından hazırlanır
B9: 4 | C9: Muhasebe Yevmiyesi — Tahsilat Kaydı (102 Dr / 181 Kr + 642 Kr) | D9: Tahsilat kaydı: 102 borç / 181 alacak (önceki 383 kapatma) + 642 alacak (yeni kısım). | E9: Yevmiye defteri
B10: 5 | C10: KV Beyannamesi Taslağı — 384. Satır | D10: 'Kazancın Bulunması Halinde' bölümü. ★★ YİAKV matrahından çıkarılmamış. | E10: GİB e-Beyanname
A12: KATEGORİ 2 — EK BELGELER
B13: No | C13: Belge | D13: Açıklama | E13: Temin
B14: 6 | C14: GİB Özelgesi (Paragraf 4 Kapsam Belirsizliğinde) | D14: Paragraf 4 kapsamı tartışmalıysa GİB özelgesi alınmalıdır. | E14: GİB özelge sistemi
B15: 7 | C15: 181 Hesap Ekstresi — 383 Accrual Kapatma | D15: 181 kapatılan tutar = Sütun 6 — mükerrerlik kontrol belgesi. | E15: 181 hesap ekstresi
A17: KATEGORİ 3 — YMM TASDİK KONTROL SORULARI
B18: No | C18: Kontrol Sorusu | D18: Beklenen Sonuç | E18: YMM Aksiyonu
B19: S1 | C19: ★ Paragraf 4 kapsam analizi yapıldı ve belgelendi mi? | D19: GİB Beyan Reh. + CB Kararları referans. | E19: YMM kontrolü
B20: S2 | C20: ★ Bu kâr payı/faiz 383 (dönem sonu tahakkuk) kapsamında değil mi? | D20: 383 vs 384 ayrımı açık. | E20: YMM kontrolü
B21: S3 | C21: ★ 383-384 MÜKERRERLİK (C Sütun 6) kontrolü yapıldı mı? | D21: Önceki yıl 383 mahsup edildi. | E21: YMM kontrolü
B22: S4 | C22: Tahsilat tutarları banka bildirimiyle mutabık mı? | D22: Her satır belgeyle doğrulanmalı. | E22: YMM kontrolü
B23: S5 | C23: 383 + 384 = Toplam kâr payı/faiz eşitliği sağlandı mı? | D23: Çapraz kontrol — banka bildirimi toplamına eşit. | E23: YMM kontrolü
B24: S6 | C24: Vade muhasebe kaydı doğru? (102 / 181 Kr + 642 Kr) | D24: 181 kapatma + 642 yeni kısım. | E24: YMM kontrolü
B25: S7 | C25: 373/377/381 ile doğru ayrıştırıldı mı? | D25: P4 araçları → 384. Diğer paragraflara karıştırma yok. | E25: YMM kontrolü
B26: S8 | C26: ★★ 384 istisnası YİAKV matrahından DÜŞÜLMEDI mi? | D26: Tüm KVK Geçici Md.14 kodları YİAKV E.7'de DÜŞÜLEMEZ. | E26: YMM kontrolü
B27: S9 | C27: Beyanname 384 'Kazancın Bulunması Halinde' bölümünde mi? | D27: Zarar döneminde uygulanamaz. | E27: YMM kontrolü
B28: S10 | C28: YMM Tasdik Raporu (49 No.lu Tebliğ) değerlendirildi mi? | D28: >=500.000 TL → YMM raporu. | E28: YMM kontrolü
A30: GİB KV Beyan Rehberi Mart 2026 (No:606) esas alınmıştır. 384 = 373, 377, 381'in Paragraf 4 karşılığı (genel kâr payı/faiz formülasyonu). 383 (dönem sonu tahakkuk) + 384 (genel kâr payı/faiz) = Paragraf 4 tam paketi. 383-384 mükerrerlik (C Sütun 6 mahsubu) en kritik kontrol. KVK Geçici Md.14 tüm kodları YİAKV E.7'de DÜŞÜLEMEZ. YMM müteselsil sorumluluk: SM-SMMM-YMM Kanunu Md.12.
