Workbook

Sheet ANA KONTROL
A1: KVK Md.32/A İNDİRİMLİ KURUMLAR VERGİSİ | YMM TASDİK ÇALIŞMA KÂĞIDI Çok YTB Belge Bazlı Takip | Yatırım + İşletme Dönemi | Tevsi Götürü/Gerçek | Çok Yıllı Kümülatif İzleme
A2: KVK Md.32/A | YKT = Yatırım × YKT% | İndirimli KV = Normal KV × (1-İndirim%) | Her YTB Ayrı İzlenir | Tamamlama Sonrası Kalan YKT: YDO | 49 No.lu Tebliğ: Tutar Sınırı Olmaksızın YMM
A3: KRİTİK İLKE: Her YTB ayrı izlenir. Kullanılan YKT belge bazında takip edilir. İndirimli KV otomatik olarak tüm kurum kazancına uygulanamaz — kazancın ilgili belge kapsamındaki yatırımdan elde edildiği teyit edilmelidir. Çapraz kullanım riski her dönem ayrıca değerlendirilmelidir.
A5: A. MÜKELLEF VE DÖNEM BİLGİLERİ
A6: Mükellef Unvanı
A7: VKN
A8: Hesap Dönemi
A9: Hazırlayan YMM
A11: B. YTB MASTER TAKİP TABLOSU — Belge Bazlı Özet (Her YTB Sayfasından Otomatik)
A12: Bu tablo, birden fazla YTB'nin tek ekranda izlendiği master görünümdür. Kümülatif kullanılan ve kalan YKT her belgede ayrı ayrı izlenmektedir. Çapraz kullanım riski: Bir YTB'nin YKT'si başka bir YTB'ye mahsup edilemez.
B13: Parametre | C13: YTB-1 | D13: YTB-2 | E13: YTB-3 | F13: YTB-4 | G13: YTB-5 | H13: TOPLAM/NOT
A14: YTB Numarası | C14: ='YTB-1'!C19 -> 0 | D14: ='YTB-2'!C19 -> 0 | E14: ='YTB-3'!C19 -> 0 | F14: ='YTB-4'!C19 -> 0 | G14: ='YTB-5'!C19 -> 0
A15: YTB Tarihi | C15: ='YTB-1'!C20 -> 0 | D15: ='YTB-2'!C20 -> 0 | E15: ='YTB-3'!C20 -> 0 | F15: ='YTB-4'!C20 -> 0 | G15: ='YTB-5'!C20 -> 0
A16: Yatırım Türü | C16: ='YTB-1'!C22 -> Komple Yeni | D16: ='YTB-2'!C22 -> Komple Yeni | E16: ='YTB-3'!C22 -> Komple Yeni | F16: ='YTB-4'!C22 -> Komple Yeni | G16: ='YTB-5'!C22 -> Komple Yeni
A17: Bölge | C17: ='YTB-1'!C21 -> 3 | D17: ='YTB-2'!C21 -> 3 | E17: ='YTB-3'!C21 -> 3 | F17: ='YTB-4'!C21 -> 3 | G17: ='YTB-5'!C21 -> 3
A18: YKT Oranı % | C18: ='YTB-1'!C24 -> 0 | D18: ='YTB-2'!C24 -> 0 | E18: ='YTB-3'!C24 -> 0 | F18: ='YTB-4'!C24 -> 0 | G18: ='YTB-5'!C24 -> 0
A19: İndirim Oranı % | C19: ='YTB-1'!C26 -> 0 | D19: ='YTB-2'!C26 -> 0 | E19: ='YTB-3'!C26 -> 0 | F19: ='YTB-4'!C26 -> 0 | G19: ='YTB-5'!C26 -> 0
A20: İndirimli KV Oranı % | C20: ='YTB-1'!C28 -> 25 | D20: ='YTB-2'!C28 -> 25 | E20: ='YTB-3'!C28 -> 25 | F20: ='YTB-4'!C28 -> 25 | G20: ='YTB-5'!C28 -> 25
A21: Toplam Yatırım Tutarı (TL) | C21: ='YTB-1'!C23 -> 0 | D21: ='YTB-2'!C23 -> 0 | E21: ='YTB-3'!C23 -> 0 | F21: ='YTB-4'!C23 -> 0 | G21: ='YTB-5'!C23 -> 0 | H21: =SUM(C21:G21) -> 0
A22: Hesaplanan Toplam YKT (TL) | C22: ='YTB-1'!C25 -> 0 | D22: ='YTB-2'!C25 -> 0 | E22: ='YTB-3'!C25 -> 0 | F22: ='YTB-4'!C25 -> 0 | G22: ='YTB-5'!C25 -> 0 | H22: =SUM(C22:G22) -> 0
A23: Önceki Dönemler Kullanılan YKT (TL) | C23: ='YTB-1'!C78 -> 0 | D23: ='YTB-2'!C78 -> 0 | E23: ='YTB-3'!C78 -> 0 | F23: ='YTB-4'!C78 -> 0 | G23: ='YTB-5'!C78 -> 0 | H23: =SUM(C23:G23) -> 0
A24: Dönem Başı Kalan YKT (TL) | C24: ='YTB-1'!C79 -> 0 | D24: ='YTB-2'!C79 -> 0 | E24: ='YTB-3'!C79 -> 0 | F24: ='YTB-4'!C79 -> 0 | G24: ='YTB-5'!C79 -> 0 | H24: =SUM(C24:G24) -> 0
A25: Cari Dönem Yatırım Dön. Kullanım (TL) | C25: ='YTB-1'!C47 -> 0 | D25: ='YTB-2'!C47 -> 0 | E25: ='YTB-3'!C47 -> 0 | F25: ='YTB-4'!C47 -> 0 | G25: ='YTB-5'!C47 -> 0 | H25: =SUM(C25:G25) -> 0
A26: Cari Dönem İşletme Dön. Kullanım (TL) | C26: ='YTB-1'!C65 -> 0 | D26: ='YTB-2'!C65 -> 0 | E26: ='YTB-3'!C65 -> 0 | F26: ='YTB-4'!C65 -> 0 | G26: ='YTB-5'!C65 -> 0 | H26: =SUM(C26:G26) -> 0
A27: Cari Dönem Toplam YKT Kullanımı (TL) | C27: ='YTB-1'!C84 -> 0 | D27: ='YTB-2'!C84 -> 0 | E27: ='YTB-3'!C84 -> 0 | F27: ='YTB-4'!C84 -> 0 | G27: ='YTB-5'!C84 -> 0 | H27: =SUM(C27:G27) -> 0
A28: Dönem Sonu Kalan YKT / Devir (TL) | C28: ='YTB-1'!C86 -> 0 | D28: ='YTB-2'!C86 -> 0 | E28: ='YTB-3'!C86 -> 0 | F28: ='YTB-4'!C86 -> 0 | G28: ='YTB-5'!C86 -> 0 | H28: =SUM(C28:G28) -> 0
A29: Cari Dönem KV Tasarrufu (TL) | C29: ='YTB-1'!C83 -> 0 | D29: ='YTB-2'!C83 -> 0 | E29: ='YTB-3'!C83 -> 0 | F29: ='YTB-4'!C83 -> 0 | G29: ='YTB-5'!C83 -> 0 | H29: =SUM(C29:G29) -> 0
A30: YKT Durum Göstergesi | C30: ='YTB-1'!C88 -> YKT Giriş Eksik | D30: ='YTB-2'!C88 -> YKT Giriş Eksik | E30: ='YTB-3'!C88 -> YKT Giriş Eksik | F30: ='YTB-4'!C88 -> YKT Giriş Eksik | G30: ='YTB-5'!C88 -> YKT Giriş Eksik
A31: Dönem Durumu (Yatırım/İşletme) | C31: ='YTB-1'!C29 -> Yatırım Döneminde | D31: ='YTB-2'!C29 -> Yatırım Döneminde | E31: ='YTB-3'!C29 -> Yatırım Döneminde | F31: ='YTB-4'!C29 -> Yatırım Döneminde | G31: ='YTB-5'!C29 -> Yatırım Döneminde
A33: C. DÖNEM KV TASARRUFU VE BEYANNAME MUTABAKATI
A34: Aşağıdaki değerler KONSOLİDASYON sayfasından otomatik aktarılır. GİB e-Beyanname EKler / İndirimli KV Tablosu ile mutabık olmalıdır. Her YTB için GİB sistemine ayrı satır açılmalıdır.
B35: Beyanname Kalemi | D35: Tutar (TL) | H35: Not
A36: Toplam 32/A İndirimli KV Matrahı | D36: =KONSOLİDASYON!D28 -> 0
A37: Toplam Normal KV (Hesaplanan) | D37: =KONSOLİDASYON!D29 -> 0
A38: Toplam İndirimli KV (Alınmayan) | D38: =KONSOLİDASYON!D30 -> 0
A39: Toplam KV Tasarrufu = Kullanılan YKT | D39: =KONSOLİDASYON!D31 -> 0
A40: Toplam Kalan YKT (Sonraki Yıla Devir) | D40: =KONSOLİDASYON!D32 -> 0
A42: ÇAPRAZ KULLANIM UYARISI: Yukarıdaki toplam KV tasarrufu belge bazında ayrıştırılmış değerlerin toplamıdır. Hiçbir YTB'nin YKT'si başka bir YTB hesabına mahsup edilemez. Bu ilke GİB beyanname sistemi ve tasdik dosyasında belge bazında izlenmektedir.

Sheet YTB-1
A1: KVK Md.32/A İNDİRİMLİ KURUMLAR VERGİSİ | YTB-1 BELGE BAZLI ÇALIŞMA KÂĞIDI | Yatırım Dönemi + İşletme Dönemi + YKT Kümülatif Takip
A2: BELGE BAZLI ÇALIŞMA İLKESİ: Bu sayfa yalnızca bu YTB'ye ait verileri içerir. Başka YTB'lerle çapraz kullanım yapılamaz. İndirimli KV; kazancın ilgili yatırımdan elde edildiği teyit edildikten sonra uygulanır.
A3: YTB-1 — Sarı hücreler manuel giriş. Yeşil hücreler otomatik hesaplama. Tevsi yatırımda kazanç yöntemi (Götürü/Gerçek) C bölümünden seçilir. F bölümü çok yıllı kümülatif takibi sağlar.
A5: A0. YTB-1 — KAPSAM, NİTELİK VE KAZANÇ UYGUNLUK KONTROLÜ
B6: Kontrol Sorusu | E6: Yanıt | G6: YMM Tasdik Notu
A7: A0.1 Bu YTB geçerli mi? Dönemde aktif ve revize/iptal olmamış mı? | E7: EVET | F7: YTB geçerliliği T.C. Sanayi ve Teknoloji Bakanlığı sisteminden sorgulanmalıdır. Revize YTB'de değişen koşullar dönem hesabını etkiler.
A8: A0.2 Bu YTB kapsamındaki yatırım KVK 32/A'dan yararlanabilecek sektörde mi? | E8: EVET | F8: Finans/sigortacılık, iş ortaklıkları, taahhüt, YİD/Yİ, rödovans kapsamları hariçtir. Bu sektörlerde 32/A uygulanamaz.
A9: A0.3 ★ İndirimli KV uygulanacak kazanç, bu YTB kapsamındaki yatırımdan elde edilen kazanç mı? (KRİTİK) | E9: EVET | F9: EN KRİTİK KONTROL: 32/A'da en sık hata budur. YTB var → tüm kurum kazancına indirimli vergi YANLIŞTIR. İşletme döneminde: Sadece bu yatırımdan elde edilen kazanç. Yatırım döneminde: Diğer faaliyet kazancına bölge oranı limiti dahilinde.
A10: A0.4 Yatırım dönemi / işletme dönemi ayrımı doğru belirlendi mi? | E10: EVET | F10: Tamamlama vizesi öncesi: Yatırım dönemi (B bölümü). Tamamlama vizesi sonrası: İşletme dönemi (D bölümü). Karma dönem: Her ikisi de (B + D birlikte).
A11: A0.5 Önceki dönemlerde kullanılan YKT tutarları doğru devredildi mi? | E11: EVET | F11: F.2 satırı (Önceki Dönemler Kümülatif YKT): GİB beyanname sisteminden alınmalıdır. Hatalı devir tutarı tüm hesabı bozar.
A12: A0.6 ★ Bu YTB'nin YKT'si başka bir YTB hesabına mahsup edilmiyor mu? (ÇAPRAZ KULLANIM) | E12: EVET | F12: KRİTİK: Her YTB'nin YKT'si o belgeye özgüdür. Çapraz mahsup yasaktır. 5 YTB varsa 5 ayrı YKT hesabı ve takibi zorunludur. Bu sayfadaki hesaplar yalnızca bu YTB'ye aittir.
A13: A0.7 YİAKV ve diğer matrah düzeltmeleri değerlendirildi mi? | E13: EVET | F13: KVK 32/C YİAKV hesabında 32/A'nın alınmayan vergi etkisi analiz edilmelidir. 32/A matrahının YİAKV hesabıyla ilişkisi dönem tebliğleriyle doğrulanmalıdır.
A14: A0.8 YMM Raporu zorunluluğu değerlendirildi mi? (49 No.lu Tebliğ) | E14: EVET | F14: 49 No.lu Tebliğ (30.12.2025): KVK 32/A için TUTAR SINIRI OLMAKSIZIN YMM tasdik raporu zorunlu. Tam tasdik sözleşmesi olanlar ayrıca rapor düzenlemez.
A15: A0.9 Tasdik Uygunluk Sonucu (A0.1-A0.8 tümü kontrol edildi) | E15: =IF(AND(E7="EVET",E8="EVET",E9="EVET",E10="EVET",E11="EVET",E12="EVET",E13="EVET",E14="EVET"),"OK - Hesaplanabilir","HATA - Ön koşul eksik") -> OK - Hesaplanabilir | F15: Özellikle A0.3 (kazanç uygunluğu) ve A0.6 (çapraz kullanım) kritik.
A17: A. YTB-1 KİMLİK BİLGİLERİ VE TEŞVİK PARAMETRELERİ
B18: Parametre | C18: Değer/Giriş | E18: Açıklama | G18: YMM Notu
A19: A.1 YTB Numarası | D19: Örn. 2023-C3-12345 | F19: Bakanlık sisteminden doğrulanmalı.
A20: A.2 YTB Düzenleme Tarihi | D20: GG.AA.YYYY | F20: Belge tarihine göre dönem oranları belirlenir.
A21: A.3 Yatırım Bölgesi (1-6) | C21: 3 | D21: 1,2,3,4,5,6 — Listeden seçin | F21: Bölge; YKT oranı ve limit oranını belirler.
A22: A.4 Yatırım Türü | C22: Komple Yeni | D22: Komple Yeni,Tevsi,Modernizasyon,Ürün Çeşitlendirme,Entegrasyon | F22: Tevsi: C bölümü ek hesabı gerektirir.
A23: A.5 YTB Kapsamı Toplam Yatırım Tutarı (TL) | D23: YTB'de onaylanan tutar | F23: Revize edilmişse güncel tutarı kullanın.
A24: A.6 YKT Oranı % (Teşvik Belgesindeki) | D24: % örn. 30 | F24: İmalat + 2017-2022: +15 puan ek uygulanabilir.
A25: A.7 Hesaplanan Toplam YKT (= A.5 × A.6/100) | C25: =C23*C24/100 -> 0 | D25: Otomatik | F25: Toplam devlet desteği = Kullanılabilecek azami YKT tutarı.
A26: A.8 Vergi İndirim Oranı % (Teşvik Belgesindeki) | D26: % örn. 70 | F26: Normal KV üzerinden indirim yapılacak oran.
A27: A.9 Normal KV Oranı % (Dönem) | C27: 25 | D27: 2025: %25 | F27: Gerekirse güncelleyin.
A28: A.10 İndirimli KV Oranı % (= A.9 × (1 - A.8/100)) | C28: =C27*(1-C26/100) -> 25 | D28: Otomatik | F28: A.8=%100 ise indirimli KV=%0.
A29: A.11 YTB Dönem Durumu | C29: Yatırım Döneminde | D29: Yatırım Döneminde,İşletme Döneminde,Her İkisi (Karma) | F29: Tamamlama vizesi alınmadıysa Yatırım. Alındıysa İşletme.
A30: A.12 Tamamlama Vizesi Tarihi (Varsa) | D30: GG.AA.YYYY veya boş | F30: Vize tarihi = işletme döneminin başlangıcı.
A32: B. YATIRIM DÖNEMİ — Diğer Faaliyetlerden İndirimli KV (Tamamlama Öncesi)
A33: Yatırım döneminde DİĞER FAALİYET kazancına indirimli KV uygulanabilir. Azami limit: MIN(YKT × Bölge Oranı, Gerçekleşen Harcama). Bölge oranları: 2.Bölge=%10 | 3.=%20 | 4.=%30 | 5.=%50 | 6.=%80. 1.Bölge genellikle diğer faaliyet için mümkün değildir.
B34: Hesap Kalemi | C34: Değer (TL) | E34: Açıklama | G34: YMM Notu
A35: B.1 Dönem Başı Kümülatif Fiili Harcama | E35: Önceki KV beyannamesi EKler / İndirimli KV Tablosundan | G35: Arazi/arsa/royalti hariç.
A36: B.2 Bu Dönem Fiili Yatırım Harcaması | E36: Dönem içinde YTB kapsamı yapılan harcama | G36: Fatura bazlı, muhasebe ile uyumlu olmalı.
A37: B.3 Kümülatif Harcama (B.1 + B.2) | C37: =C35+C36 -> 0 | E37: Azami matrah hesabında kullanılır | G37: Negatif olamaz.
A38: B.4 Bölge Limit Oranı % (Yatırım Döneminde) | E38: 2=%10 | 3=%20 | 4=%30 | 5=%50 | 6=%80 | 1=%0 | G38: YTB bölgesiyle uyumlu olmalı.
A39: B.5 YKT × Bölge Oranı Limiti (A.7 × B.4 / 100) | C39: =C25*C38/100 -> 0 | E39: Yatırım döneminde kullanılabilecek azami YKT | G39: Bu limiti aşan kısım işletme döneminde.
A40: B.6 Azami Yatırım Dön. YKT Limiti = MIN(B.5, B.3) | C40: =IF(MIN(C39,C37)>0,MIN(C39,C37),0) -> 0 | E40: İki sınırdan küçük olan | G40: Gerçekleşen harcama da limittir.
A41: B.7 Önceki Dönemler Yatırım Dön. Kullanılan YKT (Kümülatif) | E41: GİB EKler / İndirimli KV Tablosundan | G41: Her dönem güncellenmeli.
A42: B.8 Bu Dönem Azami Yatırım Dön. YKT (B.6 - B.7) | C42: =MAX(0,C40-C41) -> 0 | E42: Kalan yatırım dönem kapasitesi | G42: Bu tutardan fazla kullanım mümkün değil.
A43: B.9 Bu Dönem Diğer Faaliyet KV Matrahı | E43: KKEG eklenmiş, önceki yıl zararları düşülmüş KV matrahı | G43: Beyanname ara hesabıyla doğrulanmalı.
...

Sheet YTB-2
A1: KVK Md.32/A İNDİRİMLİ KURUMLAR VERGİSİ | YTB-2 BELGE BAZLI ÇALIŞMA KÂĞIDI | Yatırım Dönemi + İşletme Dönemi + YKT Kümülatif Takip
A2: BELGE BAZLI ÇALIŞMA İLKESİ: Bu sayfa yalnızca bu YTB'ye ait verileri içerir. Başka YTB'lerle çapraz kullanım yapılamaz. İndirimli KV; kazancın ilgili yatırımdan elde edildiği teyit edildikten sonra uygulanır.
A3: YTB-2 — Sarı hücreler manuel giriş. Yeşil hücreler otomatik hesaplama. Tevsi yatırımda kazanç yöntemi (Götürü/Gerçek) C bölümünden seçilir. F bölümü çok yıllı kümülatif takibi sağlar.
A5: A0. YTB-2 — KAPSAM, NİTELİK VE KAZANÇ UYGUNLUK KONTROLÜ
B6: Kontrol Sorusu | E6: Yanıt | G6: YMM Tasdik Notu
A7: A0.1 Bu YTB geçerli mi? Dönemde aktif ve revize/iptal olmamış mı? | E7: EVET | F7: YTB geçerliliği T.C. Sanayi ve Teknoloji Bakanlığı sisteminden sorgulanmalıdır. Revize YTB'de değişen koşullar dönem hesabını etkiler.
A8: A0.2 Bu YTB kapsamındaki yatırım KVK 32/A'dan yararlanabilecek sektörde mi? | E8: EVET | F8: Finans/sigortacılık, iş ortaklıkları, taahhüt, YİD/Yİ, rödovans kapsamları hariçtir. Bu sektörlerde 32/A uygulanamaz.
A9: A0.3 ★ İndirimli KV uygulanacak kazanç, bu YTB kapsamındaki yatırımdan elde edilen kazanç mı? (KRİTİK) | E9: EVET | F9: EN KRİTİK KONTROL: 32/A'da en sık hata budur. YTB var → tüm kurum kazancına indirimli vergi YANLIŞTIR. İşletme döneminde: Sadece bu yatırımdan elde edilen kazanç. Yatırım döneminde: Diğer faaliyet kazancına bölge oranı limiti dahilinde.
A10: A0.4 Yatırım dönemi / işletme dönemi ayrımı doğru belirlendi mi? | E10: EVET | F10: Tamamlama vizesi öncesi: Yatırım dönemi (B bölümü). Tamamlama vizesi sonrası: İşletme dönemi (D bölümü). Karma dönem: Her ikisi de (B + D birlikte).
A11: A0.5 Önceki dönemlerde kullanılan YKT tutarları doğru devredildi mi? | E11: EVET | F11: F.2 satırı (Önceki Dönemler Kümülatif YKT): GİB beyanname sisteminden alınmalıdır. Hatalı devir tutarı tüm hesabı bozar.
A12: A0.6 ★ Bu YTB'nin YKT'si başka bir YTB hesabına mahsup edilmiyor mu? (ÇAPRAZ KULLANIM) | E12: EVET | F12: KRİTİK: Her YTB'nin YKT'si o belgeye özgüdür. Çapraz mahsup yasaktır. 5 YTB varsa 5 ayrı YKT hesabı ve takibi zorunludur. Bu sayfadaki hesaplar yalnızca bu YTB'ye aittir.
A13: A0.7 YİAKV ve diğer matrah düzeltmeleri değerlendirildi mi? | E13: EVET | F13: KVK 32/C YİAKV hesabında 32/A'nın alınmayan vergi etkisi analiz edilmelidir. 32/A matrahının YİAKV hesabıyla ilişkisi dönem tebliğleriyle doğrulanmalıdır.
A14: A0.8 YMM Raporu zorunluluğu değerlendirildi mi? (49 No.lu Tebliğ) | E14: EVET | F14: 49 No.lu Tebliğ (30.12.2025): KVK 32/A için TUTAR SINIRI OLMAKSIZIN YMM tasdik raporu zorunlu. Tam tasdik sözleşmesi olanlar ayrıca rapor düzenlemez.
A15: A0.9 Tasdik Uygunluk Sonucu (A0.1-A0.8 tümü kontrol edildi) | E15: =IF(AND(E7="EVET",E8="EVET",E9="EVET",E10="EVET",E11="EVET",E12="EVET",E13="EVET",E14="EVET"),"OK - Hesaplanabilir","HATA - Ön koşul eksik") -> OK - Hesaplanabilir | F15: Özellikle A0.3 (kazanç uygunluğu) ve A0.6 (çapraz kullanım) kritik.
A17: A. YTB-2 KİMLİK BİLGİLERİ VE TEŞVİK PARAMETRELERİ
B18: Parametre | C18: Değer/Giriş | E18: Açıklama | G18: YMM Notu
A19: A.1 YTB Numarası | D19: Örn. 2023-C3-12345 | F19: Bakanlık sisteminden doğrulanmalı.
A20: A.2 YTB Düzenleme Tarihi | D20: GG.AA.YYYY | F20: Belge tarihine göre dönem oranları belirlenir.
A21: A.3 Yatırım Bölgesi (1-6) | C21: 3 | D21: 1,2,3,4,5,6 — Listeden seçin | F21: Bölge; YKT oranı ve limit oranını belirler.
A22: A.4 Yatırım Türü | C22: Komple Yeni | D22: Komple Yeni,Tevsi,Modernizasyon,Ürün Çeşitlendirme,Entegrasyon | F22: Tevsi: C bölümü ek hesabı gerektirir.
A23: A.5 YTB Kapsamı Toplam Yatırım Tutarı (TL) | D23: YTB'de onaylanan tutar | F23: Revize edilmişse güncel tutarı kullanın.
A24: A.6 YKT Oranı % (Teşvik Belgesindeki) | D24: % örn. 30 | F24: İmalat + 2017-2022: +15 puan ek uygulanabilir.
A25: A.7 Hesaplanan Toplam YKT (= A.5 × A.6/100) | C25: =C23*C24/100 -> 0 | D25: Otomatik | F25: Toplam devlet desteği = Kullanılabilecek azami YKT tutarı.
A26: A.8 Vergi İndirim Oranı % (Teşvik Belgesindeki) | D26: % örn. 70 | F26: Normal KV üzerinden indirim yapılacak oran.
A27: A.9 Normal KV Oranı % (Dönem) | C27: 25 | D27: 2025: %25 | F27: Gerekirse güncelleyin.
A28: A.10 İndirimli KV Oranı % (= A.9 × (1 - A.8/100)) | C28: =C27*(1-C26/100) -> 25 | D28: Otomatik | F28: A.8=%100 ise indirimli KV=%0.
A29: A.11 YTB Dönem Durumu | C29: Yatırım Döneminde | D29: Yatırım Döneminde,İşletme Döneminde,Her İkisi (Karma) | F29: Tamamlama vizesi alınmadıysa Yatırım. Alındıysa İşletme.
A30: A.12 Tamamlama Vizesi Tarihi (Varsa) | D30: GG.AA.YYYY veya boş | F30: Vize tarihi = işletme döneminin başlangıcı.
A32: B. YATIRIM DÖNEMİ — Diğer Faaliyetlerden İndirimli KV (Tamamlama Öncesi)
A33: Yatırım döneminde DİĞER FAALİYET kazancına indirimli KV uygulanabilir. Azami limit: MIN(YKT × Bölge Oranı, Gerçekleşen Harcama). Bölge oranları: 2.Bölge=%10 | 3.=%20 | 4.=%30 | 5.=%50 | 6.=%80. 1.Bölge genellikle diğer faaliyet için mümkün değildir.
B34: Hesap Kalemi | C34: Değer (TL) | E34: Açıklama | G34: YMM Notu
A35: B.1 Dönem Başı Kümülatif Fiili Harcama | E35: Önceki KV beyannamesi EKler / İndirimli KV Tablosundan | G35: Arazi/arsa/royalti hariç.
A36: B.2 Bu Dönem Fiili Yatırım Harcaması | E36: Dönem içinde YTB kapsamı yapılan harcama | G36: Fatura bazlı, muhasebe ile uyumlu olmalı.
A37: B.3 Kümülatif Harcama (B.1 + B.2) | C37: =C35+C36 -> 0 | E37: Azami matrah hesabında kullanılır | G37: Negatif olamaz.
A38: B.4 Bölge Limit Oranı % (Yatırım Döneminde) | E38: 2=%10 | 3=%20 | 4=%30 | 5=%50 | 6=%80 | 1=%0 | G38: YTB bölgesiyle uyumlu olmalı.
A39: B.5 YKT × Bölge Oranı Limiti (A.7 × B.4 / 100) | C39: =C25*C38/100 -> 0 | E39: Yatırım döneminde kullanılabilecek azami YKT | G39: Bu limiti aşan kısım işletme döneminde.
A40: B.6 Azami Yatırım Dön. YKT Limiti = MIN(B.5, B.3) | C40: =IF(MIN(C39,C37)>0,MIN(C39,C37),0) -> 0 | E40: İki sınırdan küçük olan | G40: Gerçekleşen harcama da limittir.
A41: B.7 Önceki Dönemler Yatırım Dön. Kullanılan YKT (Kümülatif) | E41: GİB EKler / İndirimli KV Tablosundan | G41: Her dönem güncellenmeli.
A42: B.8 Bu Dönem Azami Yatırım Dön. YKT (B.6 - B.7) | C42: =MAX(0,C40-C41) -> 0 | E42: Kalan yatırım dönem kapasitesi | G42: Bu tutardan fazla kullanım mümkün değil.
A43: B.9 Bu Dönem Diğer Faaliyet KV Matrahı | E43: KKEG eklenmiş, önceki yıl zararları düşülmüş KV matrahı | G43: Beyanname ara hesabıyla doğrulanmalı.
...

Sheet YTB-3
A1: KVK Md.32/A İNDİRİMLİ KURUMLAR VERGİSİ | YTB-3 BELGE BAZLI ÇALIŞMA KÂĞIDI | Yatırım Dönemi + İşletme Dönemi + YKT Kümülatif Takip
A2: BELGE BAZLI ÇALIŞMA İLKESİ: Bu sayfa yalnızca bu YTB'ye ait verileri içerir. Başka YTB'lerle çapraz kullanım yapılamaz. İndirimli KV; kazancın ilgili yatırımdan elde edildiği teyit edildikten sonra uygulanır.
A3: YTB-3 — Sarı hücreler manuel giriş. Yeşil hücreler otomatik hesaplama. Tevsi yatırımda kazanç yöntemi (Götürü/Gerçek) C bölümünden seçilir. F bölümü çok yıllı kümülatif takibi sağlar.
A5: A0. YTB-3 — KAPSAM, NİTELİK VE KAZANÇ UYGUNLUK KONTROLÜ
B6: Kontrol Sorusu | E6: Yanıt | G6: YMM Tasdik Notu
A7: A0.1 Bu YTB geçerli mi? Dönemde aktif ve revize/iptal olmamış mı? | E7: EVET | F7: YTB geçerliliği T.C. Sanayi ve Teknoloji Bakanlığı sisteminden sorgulanmalıdır. Revize YTB'de değişen koşullar dönem hesabını etkiler.
A8: A0.2 Bu YTB kapsamındaki yatırım KVK 32/A'dan yararlanabilecek sektörde mi? | E8: EVET | F8: Finans/sigortacılık, iş ortaklıkları, taahhüt, YİD/Yİ, rödovans kapsamları hariçtir. Bu sektörlerde 32/A uygulanamaz.
A9: A0.3 ★ İndirimli KV uygulanacak kazanç, bu YTB kapsamındaki yatırımdan elde edilen kazanç mı? (KRİTİK) | E9: EVET | F9: EN KRİTİK KONTROL: 32/A'da en sık hata budur. YTB var → tüm kurum kazancına indirimli vergi YANLIŞTIR. İşletme döneminde: Sadece bu yatırımdan elde edilen kazanç. Yatırım döneminde: Diğer faaliyet kazancına bölge oranı limiti dahilinde.
A10: A0.4 Yatırım dönemi / işletme dönemi ayrımı doğru belirlendi mi? | E10: EVET | F10: Tamamlama vizesi öncesi: Yatırım dönemi (B bölümü). Tamamlama vizesi sonrası: İşletme dönemi (D bölümü). Karma dönem: Her ikisi de (B + D birlikte).
A11: A0.5 Önceki dönemlerde kullanılan YKT tutarları doğru devredildi mi? | E11: EVET | F11: F.2 satırı (Önceki Dönemler Kümülatif YKT): GİB beyanname sisteminden alınmalıdır. Hatalı devir tutarı tüm hesabı bozar.
A12: A0.6 ★ Bu YTB'nin YKT'si başka bir YTB hesabına mahsup edilmiyor mu? (ÇAPRAZ KULLANIM) | E12: EVET | F12: KRİTİK: Her YTB'nin YKT'si o belgeye özgüdür. Çapraz mahsup yasaktır. 5 YTB varsa 5 ayrı YKT hesabı ve takibi zorunludur. Bu sayfadaki hesaplar yalnızca bu YTB'ye aittir.
A13: A0.7 YİAKV ve diğer matrah düzeltmeleri değerlendirildi mi? | E13: EVET | F13: KVK 32/C YİAKV hesabında 32/A'nın alınmayan vergi etkisi analiz edilmelidir. 32/A matrahının YİAKV hesabıyla ilişkisi dönem tebliğleriyle doğrulanmalıdır.
A14: A0.8 YMM Raporu zorunluluğu değerlendirildi mi? (49 No.lu Tebliğ) | E14: EVET | F14: 49 No.lu Tebliğ (30.12.2025): KVK 32/A için TUTAR SINIRI OLMAKSIZIN YMM tasdik raporu zorunlu. Tam tasdik sözleşmesi olanlar ayrıca rapor düzenlemez.
A15: A0.9 Tasdik Uygunluk Sonucu (A0.1-A0.8 tümü kontrol edildi) | E15: =IF(AND(E7="EVET",E8="EVET",E9="EVET",E10="EVET",E11="EVET",E12="EVET",E13="EVET",E14="EVET"),"OK - Hesaplanabilir","HATA - Ön koşul eksik") -> OK - Hesaplanabilir | F15: Özellikle A0.3 (kazanç uygunluğu) ve A0.6 (çapraz kullanım) kritik.
A17: A. YTB-3 KİMLİK BİLGİLERİ VE TEŞVİK PARAMETRELERİ
B18: Parametre | C18: Değer/Giriş | E18: Açıklama | G18: YMM Notu
A19: A.1 YTB Numarası | D19: Örn. 2023-C3-12345 | F19: Bakanlık sisteminden doğrulanmalı.
A20: A.2 YTB Düzenleme Tarihi | D20: GG.AA.YYYY | F20: Belge tarihine göre dönem oranları belirlenir.
A21: A.3 Yatırım Bölgesi (1-6) | C21: 3 | D21: 1,2,3,4,5,6 — Listeden seçin | F21: Bölge; YKT oranı ve limit oranını belirler.
A22: A.4 Yatırım Türü | C22: Komple Yeni | D22: Komple Yeni,Tevsi,Modernizasyon,Ürün Çeşitlendirme,Entegrasyon | F22: Tevsi: C bölümü ek hesabı gerektirir.
A23: A.5 YTB Kapsamı Toplam Yatırım Tutarı (TL) | D23: YTB'de onaylanan tutar | F23: Revize edilmişse güncel tutarı kullanın.
A24: A.6 YKT Oranı % (Teşvik Belgesindeki) | D24: % örn. 30 | F24: İmalat + 2017-2022: +15 puan ek uygulanabilir.
A25: A.7 Hesaplanan Toplam YKT (= A.5 × A.6/100) | C25: =C23*C24/100 -> 0 | D25: Otomatik | F25: Toplam devlet desteği = Kullanılabilecek azami YKT tutarı.
A26: A.8 Vergi İndirim Oranı % (Teşvik Belgesindeki) | D26: % örn. 70 | F26: Normal KV üzerinden indirim yapılacak oran.
A27: A.9 Normal KV Oranı % (Dönem) | C27: 25 | D27: 2025: %25 | F27: Gerekirse güncelleyin.
A28: A.10 İndirimli KV Oranı % (= A.9 × (1 - A.8/100)) | C28: =C27*(1-C26/100) -> 25 | D28: Otomatik | F28: A.8=%100 ise indirimli KV=%0.
A29: A.11 YTB Dönem Durumu | C29: Yatırım Döneminde | D29: Yatırım Döneminde,İşletme Döneminde,Her İkisi (Karma) | F29: Tamamlama vizesi alınmadıysa Yatırım. Alındıysa İşletme.
A30: A.12 Tamamlama Vizesi Tarihi (Varsa) | D30: GG.AA.YYYY veya boş | F30: Vize tarihi = işletme döneminin başlangıcı.
A32: B. YATIRIM DÖNEMİ — Diğer Faaliyetlerden İndirimli KV (Tamamlama Öncesi)
A33: Yatırım döneminde DİĞER FAALİYET kazancına indirimli KV uygulanabilir. Azami limit: MIN(YKT × Bölge Oranı, Gerçekleşen Harcama). Bölge oranları: 2.Bölge=%10 | 3.=%20 | 4.=%30 | 5.=%50 | 6.=%80. 1.Bölge genellikle diğer faaliyet için mümkün değildir.
B34: Hesap Kalemi | C34: Değer (TL) | E34: Açıklama | G34: YMM Notu
A35: B.1 Dönem Başı Kümülatif Fiili Harcama | E35: Önceki KV beyannamesi EKler / İndirimli KV Tablosundan | G35: Arazi/arsa/royalti hariç.
A36: B.2 Bu Dönem Fiili Yatırım Harcaması | E36: Dönem içinde YTB kapsamı yapılan harcama | G36: Fatura bazlı, muhasebe ile uyumlu olmalı.
A37: B.3 Kümülatif Harcama (B.1 + B.2) | C37: =C35+C36 -> 0 | E37: Azami matrah hesabında kullanılır | G37: Negatif olamaz.
A38: B.4 Bölge Limit Oranı % (Yatırım Döneminde) | E38: 2=%10 | 3=%20 | 4=%30 | 5=%50 | 6=%80 | 1=%0 | G38: YTB bölgesiyle uyumlu olmalı.
A39: B.5 YKT × Bölge Oranı Limiti (A.7 × B.4 / 100) | C39: =C25*C38/100 -> 0 | E39: Yatırım döneminde kullanılabilecek azami YKT | G39: Bu limiti aşan kısım işletme döneminde.
A40: B.6 Azami Yatırım Dön. YKT Limiti = MIN(B.5, B.3) | C40: =IF(MIN(C39,C37)>0,MIN(C39,C37),0) -> 0 | E40: İki sınırdan küçük olan | G40: Gerçekleşen harcama da limittir.
A41: B.7 Önceki Dönemler Yatırım Dön. Kullanılan YKT (Kümülatif) | E41: GİB EKler / İndirimli KV Tablosundan | G41: Her dönem güncellenmeli.
A42: B.8 Bu Dönem Azami Yatırım Dön. YKT (B.6 - B.7) | C42: =MAX(0,C40-C41) -> 0 | E42: Kalan yatırım dönem kapasitesi | G42: Bu tutardan fazla kullanım mümkün değil.
A43: B.9 Bu Dönem Diğer Faaliyet KV Matrahı | E43: KKEG eklenmiş, önceki yıl zararları düşülmüş KV matrahı | G43: Beyanname ara hesabıyla doğrulanmalı.
...

Sheet YTB-4
A1: KVK Md.32/A İNDİRİMLİ KURUMLAR VERGİSİ | YTB-4 BELGE BAZLI ÇALIŞMA KÂĞIDI | Yatırım Dönemi + İşletme Dönemi + YKT Kümülatif Takip
A2: BELGE BAZLI ÇALIŞMA İLKESİ: Bu sayfa yalnızca bu YTB'ye ait verileri içerir. Başka YTB'lerle çapraz kullanım yapılamaz. İndirimli KV; kazancın ilgili yatırımdan elde edildiği teyit edildikten sonra uygulanır.
A3: YTB-4 — Sarı hücreler manuel giriş. Yeşil hücreler otomatik hesaplama. Tevsi yatırımda kazanç yöntemi (Götürü/Gerçek) C bölümünden seçilir. F bölümü çok yıllı kümülatif takibi sağlar.
A5: A0. YTB-4 — KAPSAM, NİTELİK VE KAZANÇ UYGUNLUK KONTROLÜ
B6: Kontrol Sorusu | E6: Yanıt | G6: YMM Tasdik Notu
A7: A0.1 Bu YTB geçerli mi? Dönemde aktif ve revize/iptal olmamış mı? | E7: EVET | F7: YTB geçerliliği T.C. Sanayi ve Teknoloji Bakanlığı sisteminden sorgulanmalıdır. Revize YTB'de değişen koşullar dönem hesabını etkiler.
A8: A0.2 Bu YTB kapsamındaki yatırım KVK 32/A'dan yararlanabilecek sektörde mi? | E8: EVET | F8: Finans/sigortacılık, iş ortaklıkları, taahhüt, YİD/Yİ, rödovans kapsamları hariçtir. Bu sektörlerde 32/A uygulanamaz.
A9: A0.3 ★ İndirimli KV uygulanacak kazanç, bu YTB kapsamındaki yatırımdan elde edilen kazanç mı? (KRİTİK) | E9: EVET | F9: EN KRİTİK KONTROL: 32/A'da en sık hata budur. YTB var → tüm kurum kazancına indirimli vergi YANLIŞTIR. İşletme döneminde: Sadece bu yatırımdan elde edilen kazanç. Yatırım döneminde: Diğer faaliyet kazancına bölge oranı limiti dahilinde.
A10: A0.4 Yatırım dönemi / işletme dönemi ayrımı doğru belirlendi mi? | E10: EVET | F10: Tamamlama vizesi öncesi: Yatırım dönemi (B bölümü). Tamamlama vizesi sonrası: İşletme dönemi (D bölümü). Karma dönem: Her ikisi de (B + D birlikte).
A11: A0.5 Önceki dönemlerde kullanılan YKT tutarları doğru devredildi mi? | E11: EVET | F11: F.2 satırı (Önceki Dönemler Kümülatif YKT): GİB beyanname sisteminden alınmalıdır. Hatalı devir tutarı tüm hesabı bozar.
A12: A0.6 ★ Bu YTB'nin YKT'si başka bir YTB hesabına mahsup edilmiyor mu? (ÇAPRAZ KULLANIM) | E12: EVET | F12: KRİTİK: Her YTB'nin YKT'si o belgeye özgüdür. Çapraz mahsup yasaktır. 5 YTB varsa 5 ayrı YKT hesabı ve takibi zorunludur. Bu sayfadaki hesaplar yalnızca bu YTB'ye aittir.
A13: A0.7 YİAKV ve diğer matrah düzeltmeleri değerlendirildi mi? | E13: EVET | F13: KVK 32/C YİAKV hesabında 32/A'nın alınmayan vergi etkisi analiz edilmelidir. 32/A matrahının YİAKV hesabıyla ilişkisi dönem tebliğleriyle doğrulanmalıdır.
A14: A0.8 YMM Raporu zorunluluğu değerlendirildi mi? (49 No.lu Tebliğ) | E14: EVET | F14: 49 No.lu Tebliğ (30.12.2025): KVK 32/A için TUTAR SINIRI OLMAKSIZIN YMM tasdik raporu zorunlu. Tam tasdik sözleşmesi olanlar ayrıca rapor düzenlemez.
A15: A0.9 Tasdik Uygunluk Sonucu (A0.1-A0.8 tümü kontrol edildi) | E15: =IF(AND(E7="EVET",E8="EVET",E9="EVET",E10="EVET",E11="EVET",E12="EVET",E13="EVET",E14="EVET"),"OK - Hesaplanabilir","HATA - Ön koşul eksik") -> OK - Hesaplanabilir | F15: Özellikle A0.3 (kazanç uygunluğu) ve A0.6 (çapraz kullanım) kritik.
A17: A. YTB-4 KİMLİK BİLGİLERİ VE TEŞVİK PARAMETRELERİ
B18: Parametre | C18: Değer/Giriş | E18: Açıklama | G18: YMM Notu
A19: A.1 YTB Numarası | D19: Örn. 2023-C3-12345 | F19: Bakanlık sisteminden doğrulanmalı.
A20: A.2 YTB Düzenleme Tarihi | D20: GG.AA.YYYY | F20: Belge tarihine göre dönem oranları belirlenir.
A21: A.3 Yatırım Bölgesi (1-6) | C21: 3 | D21: 1,2,3,4,5,6 — Listeden seçin | F21: Bölge; YKT oranı ve limit oranını belirler.
A22: A.4 Yatırım Türü | C22: Komple Yeni | D22: Komple Yeni,Tevsi,Modernizasyon,Ürün Çeşitlendirme,Entegrasyon | F22: Tevsi: C bölümü ek hesabı gerektirir.
A23: A.5 YTB Kapsamı Toplam Yatırım Tutarı (TL) | D23: YTB'de onaylanan tutar | F23: Revize edilmişse güncel tutarı kullanın.
A24: A.6 YKT Oranı % (Teşvik Belgesindeki) | D24: % örn. 30 | F24: İmalat + 2017-2022: +15 puan ek uygulanabilir.
A25: A.7 Hesaplanan Toplam YKT (= A.5 × A.6/100) | C25: =C23*C24/100 -> 0 | D25: Otomatik | F25: Toplam devlet desteği = Kullanılabilecek azami YKT tutarı.
A26: A.8 Vergi İndirim Oranı % (Teşvik Belgesindeki) | D26: % örn. 70 | F26: Normal KV üzerinden indirim yapılacak oran.
A27: A.9 Normal KV Oranı % (Dönem) | C27: 25 | D27: 2025: %25 | F27: Gerekirse güncelleyin.
A28: A.10 İndirimli KV Oranı % (= A.9 × (1 - A.8/100)) | C28: =C27*(1-C26/100) -> 25 | D28: Otomatik | F28: A.8=%100 ise indirimli KV=%0.
A29: A.11 YTB Dönem Durumu | C29: Yatırım Döneminde | D29: Yatırım Döneminde,İşletme Döneminde,Her İkisi (Karma) | F29: Tamamlama vizesi alınmadıysa Yatırım. Alındıysa İşletme.
A30: A.12 Tamamlama Vizesi Tarihi (Varsa) | D30: GG.AA.YYYY veya boş | F30: Vize tarihi = işletme döneminin başlangıcı.
A32: B. YATIRIM DÖNEMİ — Diğer Faaliyetlerden İndirimli KV (Tamamlama Öncesi)
A33: Yatırım döneminde DİĞER FAALİYET kazancına indirimli KV uygulanabilir. Azami limit: MIN(YKT × Bölge Oranı, Gerçekleşen Harcama). Bölge oranları: 2.Bölge=%10 | 3.=%20 | 4.=%30 | 5.=%50 | 6.=%80. 1.Bölge genellikle diğer faaliyet için mümkün değildir.
B34: Hesap Kalemi | C34: Değer (TL) | E34: Açıklama | G34: YMM Notu
A35: B.1 Dönem Başı Kümülatif Fiili Harcama | E35: Önceki KV beyannamesi EKler / İndirimli KV Tablosundan | G35: Arazi/arsa/royalti hariç.
A36: B.2 Bu Dönem Fiili Yatırım Harcaması | E36: Dönem içinde YTB kapsamı yapılan harcama | G36: Fatura bazlı, muhasebe ile uyumlu olmalı.
A37: B.3 Kümülatif Harcama (B.1 + B.2) | C37: =C35+C36 -> 0 | E37: Azami matrah hesabında kullanılır | G37: Negatif olamaz.
A38: B.4 Bölge Limit Oranı % (Yatırım Döneminde) | E38: 2=%10 | 3=%20 | 4=%30 | 5=%50 | 6=%80 | 1=%0 | G38: YTB bölgesiyle uyumlu olmalı.
A39: B.5 YKT × Bölge Oranı Limiti (A.7 × B.4 / 100) | C39: =C25*C38/100 -> 0 | E39: Yatırım döneminde kullanılabilecek azami YKT | G39: Bu limiti aşan kısım işletme döneminde.
A40: B.6 Azami Yatırım Dön. YKT Limiti = MIN(B.5, B.3) | C40: =IF(MIN(C39,C37)>0,MIN(C39,C37),0) -> 0 | E40: İki sınırdan küçük olan | G40: Gerçekleşen harcama da limittir.
A41: B.7 Önceki Dönemler Yatırım Dön. Kullanılan YKT (Kümülatif) | E41: GİB EKler / İndirimli KV Tablosundan | G41: Her dönem güncellenmeli.
A42: B.8 Bu Dönem Azami Yatırım Dön. YKT (B.6 - B.7) | C42: =MAX(0,C40-C41) -> 0 | E42: Kalan yatırım dönem kapasitesi | G42: Bu tutardan fazla kullanım mümkün değil.
A43: B.9 Bu Dönem Diğer Faaliyet KV Matrahı | E43: KKEG eklenmiş, önceki yıl zararları düşülmüş KV matrahı | G43: Beyanname ara hesabıyla doğrulanmalı.
...

Sheet YTB-5
A1: KVK Md.32/A İNDİRİMLİ KURUMLAR VERGİSİ | YTB-5 BELGE BAZLI ÇALIŞMA KÂĞIDI | Yatırım Dönemi + İşletme Dönemi + YKT Kümülatif Takip
A2: BELGE BAZLI ÇALIŞMA İLKESİ: Bu sayfa yalnızca bu YTB'ye ait verileri içerir. Başka YTB'lerle çapraz kullanım yapılamaz. İndirimli KV; kazancın ilgili yatırımdan elde edildiği teyit edildikten sonra uygulanır.
A3: YTB-5 — Sarı hücreler manuel giriş. Yeşil hücreler otomatik hesaplama. Tevsi yatırımda kazanç yöntemi (Götürü/Gerçek) C bölümünden seçilir. F bölümü çok yıllı kümülatif takibi sağlar.
A5: A0. YTB-5 — KAPSAM, NİTELİK VE KAZANÇ UYGUNLUK KONTROLÜ
B6: Kontrol Sorusu | E6: Yanıt | G6: YMM Tasdik Notu
A7: A0.1 Bu YTB geçerli mi? Dönemde aktif ve revize/iptal olmamış mı? | E7: EVET | F7: YTB geçerliliği T.C. Sanayi ve Teknoloji Bakanlığı sisteminden sorgulanmalıdır. Revize YTB'de değişen koşullar dönem hesabını etkiler.
A8: A0.2 Bu YTB kapsamındaki yatırım KVK 32/A'dan yararlanabilecek sektörde mi? | E8: EVET | F8: Finans/sigortacılık, iş ortaklıkları, taahhüt, YİD/Yİ, rödovans kapsamları hariçtir. Bu sektörlerde 32/A uygulanamaz.
A9: A0.3 ★ İndirimli KV uygulanacak kazanç, bu YTB kapsamındaki yatırımdan elde edilen kazanç mı? (KRİTİK) | E9: EVET | F9: EN KRİTİK KONTROL: 32/A'da en sık hata budur. YTB var → tüm kurum kazancına indirimli vergi YANLIŞTIR. İşletme döneminde: Sadece bu yatırımdan elde edilen kazanç. Yatırım döneminde: Diğer faaliyet kazancına bölge oranı limiti dahilinde.
A10: A0.4 Yatırım dönemi / işletme dönemi ayrımı doğru belirlendi mi? | E10: EVET | F10: Tamamlama vizesi öncesi: Yatırım dönemi (B bölümü). Tamamlama vizesi sonrası: İşletme dönemi (D bölümü). Karma dönem: Her ikisi de (B + D birlikte).
A11: A0.5 Önceki dönemlerde kullanılan YKT tutarları doğru devredildi mi? | E11: EVET | F11: F.2 satırı (Önceki Dönemler Kümülatif YKT): GİB beyanname sisteminden alınmalıdır. Hatalı devir tutarı tüm hesabı bozar.
A12: A0.6 ★ Bu YTB'nin YKT'si başka bir YTB hesabına mahsup edilmiyor mu? (ÇAPRAZ KULLANIM) | E12: EVET | F12: KRİTİK: Her YTB'nin YKT'si o belgeye özgüdür. Çapraz mahsup yasaktır. 5 YTB varsa 5 ayrı YKT hesabı ve takibi zorunludur. Bu sayfadaki hesaplar yalnızca bu YTB'ye aittir.
A13: A0.7 YİAKV ve diğer matrah düzeltmeleri değerlendirildi mi? | E13: EVET | F13: KVK 32/C YİAKV hesabında 32/A'nın alınmayan vergi etkisi analiz edilmelidir. 32/A matrahının YİAKV hesabıyla ilişkisi dönem tebliğleriyle doğrulanmalıdır.
A14: A0.8 YMM Raporu zorunluluğu değerlendirildi mi? (49 No.lu Tebliğ) | E14: EVET | F14: 49 No.lu Tebliğ (30.12.2025): KVK 32/A için TUTAR SINIRI OLMAKSIZIN YMM tasdik raporu zorunlu. Tam tasdik sözleşmesi olanlar ayrıca rapor düzenlemez.
A15: A0.9 Tasdik Uygunluk Sonucu (A0.1-A0.8 tümü kontrol edildi) | E15: =IF(AND(E7="EVET",E8="EVET",E9="EVET",E10="EVET",E11="EVET",E12="EVET",E13="EVET",E14="EVET"),"OK - Hesaplanabilir","HATA - Ön koşul eksik") -> OK - Hesaplanabilir | F15: Özellikle A0.3 (kazanç uygunluğu) ve A0.6 (çapraz kullanım) kritik.
A17: A. YTB-5 KİMLİK BİLGİLERİ VE TEŞVİK PARAMETRELERİ
B18: Parametre | C18: Değer/Giriş | E18: Açıklama | G18: YMM Notu
A19: A.1 YTB Numarası | D19: Örn. 2023-C3-12345 | F19: Bakanlık sisteminden doğrulanmalı.
A20: A.2 YTB Düzenleme Tarihi | D20: GG.AA.YYYY | F20: Belge tarihine göre dönem oranları belirlenir.
A21: A.3 Yatırım Bölgesi (1-6) | C21: 3 | D21: 1,2,3,4,5,6 — Listeden seçin | F21: Bölge; YKT oranı ve limit oranını belirler.
A22: A.4 Yatırım Türü | C22: Komple Yeni | D22: Komple Yeni,Tevsi,Modernizasyon,Ürün Çeşitlendirme,Entegrasyon | F22: Tevsi: C bölümü ek hesabı gerektirir.
A23: A.5 YTB Kapsamı Toplam Yatırım Tutarı (TL) | D23: YTB'de onaylanan tutar | F23: Revize edilmişse güncel tutarı kullanın.
A24: A.6 YKT Oranı % (Teşvik Belgesindeki) | D24: % örn. 30 | F24: İmalat + 2017-2022: +15 puan ek uygulanabilir.
A25: A.7 Hesaplanan Toplam YKT (= A.5 × A.6/100) | C25: =C23*C24/100 -> 0 | D25: Otomatik | F25: Toplam devlet desteği = Kullanılabilecek azami YKT tutarı.
A26: A.8 Vergi İndirim Oranı % (Teşvik Belgesindeki) | D26: % örn. 70 | F26: Normal KV üzerinden indirim yapılacak oran.
A27: A.9 Normal KV Oranı % (Dönem) | C27: 25 | D27: 2025: %25 | F27: Gerekirse güncelleyin.
A28: A.10 İndirimli KV Oranı % (= A.9 × (1 - A.8/100)) | C28: =C27*(1-C26/100) -> 25 | D28: Otomatik | F28: A.8=%100 ise indirimli KV=%0.
A29: A.11 YTB Dönem Durumu | C29: Yatırım Döneminde | D29: Yatırım Döneminde,İşletme Döneminde,Her İkisi (Karma) | F29: Tamamlama vizesi alınmadıysa Yatırım. Alındıysa İşletme.
A30: A.12 Tamamlama Vizesi Tarihi (Varsa) | D30: GG.AA.YYYY veya boş | F30: Vize tarihi = işletme döneminin başlangıcı.
A32: B. YATIRIM DÖNEMİ — Diğer Faaliyetlerden İndirimli KV (Tamamlama Öncesi)
A33: Yatırım döneminde DİĞER FAALİYET kazancına indirimli KV uygulanabilir. Azami limit: MIN(YKT × Bölge Oranı, Gerçekleşen Harcama). Bölge oranları: 2.Bölge=%10 | 3.=%20 | 4.=%30 | 5.=%50 | 6.=%80. 1.Bölge genellikle diğer faaliyet için mümkün değildir.
B34: Hesap Kalemi | C34: Değer (TL) | E34: Açıklama | G34: YMM Notu
A35: B.1 Dönem Başı Kümülatif Fiili Harcama | E35: Önceki KV beyannamesi EKler / İndirimli KV Tablosundan | G35: Arazi/arsa/royalti hariç.
A36: B.2 Bu Dönem Fiili Yatırım Harcaması | E36: Dönem içinde YTB kapsamı yapılan harcama | G36: Fatura bazlı, muhasebe ile uyumlu olmalı.
A37: B.3 Kümülatif Harcama (B.1 + B.2) | C37: =C35+C36 -> 0 | E37: Azami matrah hesabında kullanılır | G37: Negatif olamaz.
A38: B.4 Bölge Limit Oranı % (Yatırım Döneminde) | E38: 2=%10 | 3=%20 | 4=%30 | 5=%50 | 6=%80 | 1=%0 | G38: YTB bölgesiyle uyumlu olmalı.
A39: B.5 YKT × Bölge Oranı Limiti (A.7 × B.4 / 100) | C39: =C25*C38/100 -> 0 | E39: Yatırım döneminde kullanılabilecek azami YKT | G39: Bu limiti aşan kısım işletme döneminde.
A40: B.6 Azami Yatırım Dön. YKT Limiti = MIN(B.5, B.3) | C40: =IF(MIN(C39,C37)>0,MIN(C39,C37),0) -> 0 | E40: İki sınırdan küçük olan | G40: Gerçekleşen harcama da limittir.
A41: B.7 Önceki Dönemler Yatırım Dön. Kullanılan YKT (Kümülatif) | E41: GİB EKler / İndirimli KV Tablosundan | G41: Her dönem güncellenmeli.
A42: B.8 Bu Dönem Azami Yatırım Dön. YKT (B.6 - B.7) | C42: =MAX(0,C40-C41) -> 0 | E42: Kalan yatırım dönem kapasitesi | G42: Bu tutardan fazla kullanım mümkün değil.
A43: B.9 Bu Dönem Diğer Faaliyet KV Matrahı | E43: KKEG eklenmiş, önceki yıl zararları düşülmüş KV matrahı | G43: Beyanname ara hesabıyla doğrulanmalı.
...

Sheet KONSOLİDASYON
A1: KVK Md.32/A İNDİRİMLİ KURUMLAR VERGİSİ | KONSOLİDASYON | 5 YTB Birleşik Hesap | Vergi Avantajı ↔ YKT Tüketimi | KV Beyanname Mutabakatı
A2: Her YTB'nin yatırım + işletme dönemi hesapları ayrı ayrı gösterilir. Toplam KV tasarrufu = Toplam kullanılan YKT ilişkisi bu sayfada kontrol edilir. Çapraz kullanım: Hiçbir YTB'nin değeri başka bir YTB sütununa aktarılmaz.
A4: A. YTB BAZINDA DÖNEM HESAP MATRİSİ
B5: Hesap Kalemi | C5: YTB-1 | D5: YTB-2 | E5: YTB-3 | F5: YTB-4 | G5: YTB-5 | H5: 5 YTB TOPLAM
A6: Toplam YKT (A.7) | C6: ='YTB-1'!C25 -> 0 | D6: ='YTB-2'!C25 -> 0 | E6: ='YTB-3'!C25 -> 0 | F6: ='YTB-4'!C25 -> 0 | G6: ='YTB-5'!C25 -> 0 | H6: =SUM(C6:G6) -> 0
A7: Önceki Kümülatif Kullanılan YKT (F.2) | C7: ='YTB-1'!C78 -> 0 | D7: ='YTB-2'!C78 -> 0 | E7: ='YTB-3'!C78 -> 0 | F7: ='YTB-4'!C78 -> 0 | G7: ='YTB-5'!C78 -> 0 | H7: =SUM(C7:G7) -> 0
A8: Dönem Başı Kalan YKT (F.3) | C8: ='YTB-1'!C79 -> 0 | D8: ='YTB-2'!C79 -> 0 | E8: ='YTB-3'!C79 -> 0 | F8: ='YTB-4'!C79 -> 0 | G8: ='YTB-5'!C79 -> 0 | H8: =SUM(C8:G8) -> 0
A9: — Yatırım Dön. Matrahı (B.10) | C9: ='YTB-1'!C44 -> 0 | D9: ='YTB-2'!C44 -> 0 | E9: ='YTB-3'!C44 -> 0 | F9: ='YTB-4'!C44 -> 0 | G9: ='YTB-5'!C44 -> 0 | H9: =SUM(C9:G9) -> 0
A10: — Yatırım Dön. Normal KV (B.11) | C10: ='YTB-1'!C45 -> 0 | D10: ='YTB-2'!C45 -> 0 | E10: ='YTB-3'!C45 -> 0 | F10: ='YTB-4'!C45 -> 0 | G10: ='YTB-5'!C45 -> 0 | H10: =SUM(C10:G10) -> 0
A11: — Yatırım Dön. İndirimli KV (B.12) | C11: ='YTB-1'!C46 -> 0 | D11: ='YTB-2'!C46 -> 0 | E11: ='YTB-3'!C46 -> 0 | F11: ='YTB-4'!C46 -> 0 | G11: ='YTB-5'!C46 -> 0 | H11: =SUM(C11:G11) -> 0
A12: — Yatırım Dön. KV Tasarrufu/YKT (B.13) | C12: ='YTB-1'!C47 -> 0 | D12: ='YTB-2'!C47 -> 0 | E12: ='YTB-3'!C47 -> 0 | F12: ='YTB-4'!C47 -> 0 | G12: ='YTB-5'!C47 -> 0 | H12: =SUM(C12:G12) -> 0
A13: — İşletme Dön. Matrahı (D.1) | C13: ='YTB-1'!C62 | D13: ='YTB-2'!C62 | E13: ='YTB-3'!C62 | F13: ='YTB-4'!C62 | G13: ='YTB-5'!C62 | H13: =SUM(C13:G13) -> 0
A14: — İşletme Dön. Normal KV (D.2) | C14: ='YTB-1'!C63 -> 0 | D14: ='YTB-2'!C63 -> 0 | E14: ='YTB-3'!C63 -> 0 | F14: ='YTB-4'!C63 -> 0 | G14: ='YTB-5'!C63 -> 0 | H14: =SUM(C14:G14) -> 0
A15: — İşletme Dön. İndirimli KV (D.3) | C15: ='YTB-1'!C64 -> 0 | D15: ='YTB-2'!C64 -> 0 | E15: ='YTB-3'!C64 -> 0 | F15: ='YTB-4'!C64 -> 0 | G15: ='YTB-5'!C64 -> 0 | H15: =SUM(C15:G15) -> 0
A16: — İşletme Dön. KV Tasarrufu/YKT (D.4) | C16: ='YTB-1'!C65 -> 0 | D16: ='YTB-2'!C65 -> 0 | E16: ='YTB-3'!C65 -> 0 | F16: ='YTB-4'!C65 -> 0 | G16: ='YTB-5'!C65 -> 0 | H16: =SUM(C16:G16) -> 0
A17: ★ Toplam 32/A Matrahı (F.4) | C17: ='YTB-1'!C80 -> 0 | D17: ='YTB-2'!C80 -> 0 | E17: ='YTB-3'!C80 -> 0 | F17: ='YTB-4'!C80 -> 0 | G17: ='YTB-5'!C80 -> 0 | H17: =SUM(C17:G17) -> 0
A18: ★ Toplam Normal KV (F.5) | C18: ='YTB-1'!C81 -> 0 | D18: ='YTB-2'!C81 -> 0 | E18: ='YTB-3'!C81 -> 0 | F18: ='YTB-4'!C81 -> 0 | G18: ='YTB-5'!C81 -> 0 | H18: =SUM(C18:G18) -> 0
A19: ★ Toplam İndirimli KV (F.6) | C19: ='YTB-1'!C82 -> 0 | D19: ='YTB-2'!C82 -> 0 | E19: ='YTB-3'!C82 -> 0 | F19: ='YTB-4'!C82 -> 0 | G19: ='YTB-5'!C82 -> 0 | H19: =SUM(C19:G19) -> 0
A20: ★ KV Tasarrufu = Kullanılan YKT (F.7) | C20: ='YTB-1'!C83 -> 0 | D20: ='YTB-2'!C83 -> 0 | E20: ='YTB-3'!C83 -> 0 | F20: ='YTB-4'!C83 -> 0 | G20: ='YTB-5'!C83 -> 0 | H20: =SUM(C20:G20) -> 0
A21: YKT Tüketimi Kontrol (F.9 — SIFIR OLMALI) | C21: ='YTB-1'!C85 -> 0 | D21: ='YTB-2'!C85 -> 0 | E21: ='YTB-3'!C85 -> 0 | F21: ='YTB-4'!C85 -> 0 | G21: ='YTB-5'!C85 -> 0 | H21: =SUM(C21:G21) -> 0
A22: Dönem Sonu Kalan YKT / Devir (F.10) | C22: ='YTB-1'!C86 -> 0 | D22: ='YTB-2'!C86 -> 0 | E22: ='YTB-3'!C86 -> 0 | F22: ='YTB-4'!C86 -> 0 | G22: ='YTB-5'!C86 -> 0 | H22: =SUM(C22:G22) -> 0
A23: YKT Durum | C23: ='YTB-1'!C88 -> YKT Giriş Eksik | D23: ='YTB-2'!C88 -> YKT Giriş Eksik | E23: ='YTB-3'!C88 -> YKT Giriş Eksik | F23: ='YTB-4'!C88 -> YKT Giriş Eksik | G23: ='YTB-5'!C88 -> YKT Giriş Eksik
A25: B. KV BEYANNAME 32/A — MUTABAKAT TABLOSU
A26: GİB e-Beyanname EKler / İndirimli KV Tablosu: Her YTB için ayrı satır açılmalıdır. Bu tablo GİB sistemiyle birebir uyumlu olmalıdır. ★ KRITIK: KV Tasarrufu (Alınmayan Vergi) = Kullanılan YKT → Bu denklem sağlanmadan tasdik tamamlanmaz.
B27: Beyanname Kalemi | D27: Tutar (TL) | H27: Kaynak/Not
A28: Toplam İndirimli KV Matrahı (5 YTB) | D28: =H17 -> 0
A29: Toplam Normal KV (Hesaplanan) | D29: =H18 -> 0
A30: Toplam İndirimli KV (Alınmayan Vergi) | D30: =H19 -> 0
A31: ★ Toplam KV Tasarrufu = Kullanılan YKT | D31: =H20 -> 0
A32: Kalan YKT (Tüm YTB — Sonraki Yıla Devir) | D32: =H22 -> 0
A34: ÇAPRAZ KULLANIM KONTROLÜ: Yukarıdaki toplamlar belge bazlı ayrıştırılmış değerlerdir. Hiçbir YTB'nin YKT'si başka bir YTB hesabına mahsup edilmemiştir. YKT Tüketimi Kontrol satırlarının (F.9) tümü sıfır olduğunda matematiksel tutarlılık sağlanmıştır.

Sheet DENETCİ NOTLARI
A1: KVK Md.32/A İNDİRİMLİ KURUMLAR VERGİSİ | DENETÇİ NOTLARI | YMM MESLEKİ DEĞERLENDİRME
A2: KVK Md.32/A | Belge Bazlı Takip | Yatırım+İşletme Dönemi | Tevsi Kazanç | Çok Yıllı YKT İzleme
A4: BÖLÜM 1 — TEMEL İLKELER VE KRİTİK UYARILAR (Her YTB İçin Geçerli)
A5: Kod | B5: Konu | C5: Mesleki Değerlendirme | D5: Mevzuat
A6: N1 | B6: Her YTB Ayrı İzlenmelidir | C6: Bu dosyanın temel ilkesi: Her yatırım teşvik belgesi bağımsız olarak izlenir. Tek toplam ekranı yeterli değildir. Belge no, YKT oranı, indirim oranı, toplam YKT, kullanılan YKT, kalan YKT her belgede ayrı ayrı takip edilmelidir. ÇAPRAZ KULLANIM YASAĞI: Bir YTB'nin YKT'si başka bir YTB hesabına mahsup edilemez. Bu hata vergi incelemesinde en büyük risklerden biridir. | D6: KVK Md.32/A | 1 No.lu KV GT
A7: N2 | B7: ★ İndirimli KV Kazanç Uygunluğu (En Kritik Kural) | C7: EN SIK YAPILAN HATA: 'YTB var → tüm kurum kazancına indirimli KV uygula.' Bu her zaman doğru değildir: İşletme Döneminde: Sadece o YTB kapsamındaki yatırımdan elde edilen kazanca uygulanır. Yatırım Döneminde: Diğer faaliyet kazancına bölge oranı limiti (maks %10-%80) dahilinde ve gerçekleşen harcama tutarını aşmamak kaydıyla uygulanır. YMM tasdikinde: Kazancın ilgili yatırımdan elde edildiği ayrıca teyit edilmeli ve belgelenmelidir. | D7: KVK Md.32/A/1-2 | 1 No.lu KV GT 32.2
A8: N3 | B8: Yatırım Dönemi / İşletme Dönemi Ayrımı Zorunludur | C8: Yatırım Dönemi (Tamamlama Vizesi Öncesi): • Diğer faaliyet kazancına belirli oranlarla indirimli KV uygulanabilir • Azami limit: MIN(YKT × Bölge Oranı, Kümülatif Gerçekleşen Harcama) İşletme Dönemi (Tamamlama Vizesi Sonrası): • Sadece ilgili yatırımdan elde edilen kazanca uygulanır • Diğer faaliyet kazancına uygulanamaz Karma Dönem: Tamamlamanın dönem ortasında gerçekleştiği durumda her iki hesap ayrı yapılmalıdır. | D8: KVK Md.32/A/1 | 1 No.lu KV GT
A9: N4 | B9: Tevsi Yatırımda Kazanç Ayrıştırması Zorunludur | C9: Tevsi yatırımlarda kazanç tespit yöntemi seçilmesi ve tutarlı uygulanması zorunludur: GERÇEK USUL: Kazanç ayrı hesaplarda (maliyet merkezi/proje) izleniyorsa bu kazanç kullanılır. İzleme yapılmıyorsa bu yöntem seçilemez. GÖTÜRÜ USUL: Ayrı izleme yoksa → İndirimli KV Matrahı = Dönem Kazancı × (YTB ATİK / Toplam ATİK). ATİK yeniden değerlenmiş değerle dikkate alınır. Devam eden yatırımlar dahildir. YMM notu: Seçilen yöntem dönem içinde değiştirilemez. Değişim açıklanmalıdır. | D9: KVK Md.32/A | 1 No.lu KV GT 32.3.3
A10: N5 | B10: Kümülatif YKT Takibi ve Çok Yıllı Perspektif | C10: 32/A dosyası tek dönem değil, belgenin tüm ömrü boyunca kullanılacak çok yıllı izleme aracıdır. Her dönem: F.2 (önceki dönemler kümülatif) bir önceki dönem GİB beyanname tablosundan alınır. Sonraki yıla devir: F.10 (kalan YKT) + YDO endekslemesi (E bölümü) GİB sistemi: EKler / İndirimli KV Tablosu ve Ek Bilgiler — her YTB için ayrı satır. YMM notu: Beyanname tablosu ile bu çalışma kâğıdının tam mutabakatı zorunludur. | D10: KVK Md.32/A/4 | 1 No.lu KV GT
A12: BÖLÜM 2 — YMM TASDİK STANDARDI VE UYARILAR
A13: Kod | B13: Konu | C13: Mesleki Değerlendirme | D13: Mevzuat
A14: N6 | B14: ★ KV Tasarrufu = YKT Tüketimi Denkliği | C14: Bu denklem her dönem sağlanmadıkça tasdik dosyası eksik sayılır: Sağlanan Vergi Avantajı (KV Tasarrufu) = Katkıdan Tüketilen Tutar (Kullanılan YKT) Matematiksel ifade: Normal KV − İndirimli KV = Kullanılan YKT F.9 kontrolü (= F.7 − F.8) sıfır vermelidir. Vermiyorsa: • Vergi oranları hatalı girilmiş olabilir • YKT hesabında mantık hatası olabilir • Matrah tutarları yanlış aktarılmış olabilir | D14: KVK Md.32/A | 1 No.lu KV GT
A15: N7 | B15: 49 No.lu Tebliğ — Tasdik Raporu Zorunluluğu | C15: 30.12.2025 tarihli 49 No.lu SMMM ve YMM Kanunu Genel Tebliği: KVK 32/A için TUTAR SINIRI OLMAKSIZIN YMM tasdik raporu zorunludur. Tam tasdik sözleşmesi olanlar ayrıca rapor düzenlemez. Raporun içeriği: Belge bazlı YKT hesabı, dönem ayrımı, kazanç uygunluğu teyidi, beyanname mutabakatı. YMM müteselsil sorumluluk: SM-SMMM-YMM Kanunu Md.12. | D15: 49 No.lu Tebliğ (30.12.2025) | YMM Kanunu Md.12
A16: N8 | B16: YDO Endekslemesi — Kalan YKT | C16: Tamamlama vizesini izleyen yıllarda kalan YKT, VUK hükümlerine göre YDO ile artırılır. 2024 için: YDO = %63,93 (VUK 574 No.lu Tebliğ) 2025/1 Geçici Vergi: YDO = %3,30 (GİB 68 No.lu Sirküler) Yanlış endeks oranı = Hatalı YKT bakiyesi = Tasdik hatası. Her dönem GİB sirküleri ile teyit edilmelidir. | D16: KVK Md.32/A/4 | VUK Tebliğleri | GİB Sirkülerleri
A17: N9 | B17: YİAKV ve Diğer Matrah Düzeltmeleri | C17: KVK 32/C kapsamındaki yurt içi asgari KV hesabında 32/A'nın 'alınmayan vergi' etkisi analiz edilmelidir. İndirimli KV uygulamasının YİAKV matrahıyla ilişkisi dönem tebliğleriyle doğrulanmalıdır. YMM notu: Her YTB için ayrıca YİAKV etkisi hesaplanmalı ve konsolidasyona yansıtılmalıdır. | D17: KVK Md.32/C | YİAKV Tebliğleri
A19: BÖLÜM 3 — YMM TASDİK DİL STANDARDI
A20: KULLANIN: '...ilgili yatırımdan elde edilen kazanca indirimli KV uygulanabilecektir' '...belge bazında teyit edilmesi ve izlenmesi gerekmektedir' '...dönem itibarıyla değerlendirilmelidir' | '...analiz edilmelidir' KULLANMAYIN: '...indirimli vergi uygulanır' | '...tüm kazanca uygulanabilir' | '...sorunsuz geçti' KRİTİK RİSK ALANLARI: (1) Kazancın YTB kapsamında olduğunun teyidi | (2) Çapraz kullanım önleme | (3) Dönem ayrımı | (4) Tevsi yöntemi tutarlılığı | (5) Kümülatif YKT mutabakatı

Sheet BELGE LISTESI
A1: KVK Md.32/A İNDİRİMLİ KURUMLAR VERGİSİ | BELGE VE BİLGİ LİSTESİ | YMM TASDİK
A2: KVK Md.32/A | Belge Bazlı | Yatırım+İşletme Dönemi | Tevsi | YKT Kümülatif | 49 No.lu Tebliğ: Tutar Sınırı Yok
A3: Kategori 1: Her YTB için zorunlu belgeler. Kategori 2: Yatırım türüne göre ek belgeler. Kategori 3: YMM tasdik kontrol soruları.
A5: KATEGORİ 1 — ZORUNLU BELGELER (Her YTB İçin Ayrı Ayrı Temin Edilmeli)
B6: No | C6: Belge / Bilgi Adı | D6: Detay ve YMM Kontrol Noktaları | E6: Temin Yeri
B7: 1 | C7: Yatırım Teşvik Belgesi (YTB) — Güncel ve Onaylı Suret (Her YTB İçin Ayrı) | D7: YTB numarası, tarihi, bölgesi, yatırım türü ve tutarı, YKT oranı, indirim oranı açık olmalıdır. Revize/tadil YTB varsa güncel suret esas alınır. T.C. Sanayi ve Teknoloji Bakanlığı sisteminden (SAYEZ) doğrulanmalıdır. YMM notu: Belgedeki YKT oranı ile çalışma kâğıdı A.6 mutabık olmalı. | E7: T.C. Sanayi ve Teknoloji Bakanlığı (SAYEZ) / YTB sahibi
B8: 2 | C8: Önceki Dönemler YKT Kullanım Özeti — Belge Bazında Devir Tablosu | D8: Her YTB için belge bazında: Toplam YKT, önceki tüm dönemlerde kullanılan kümülatif YKT, dönem başı kalan YKT. Bu tablo F.2 satırının dayanağıdır. YMM notu: Bu tablo olmadan çok yıllı takip metodolojik olarak zayıftır. Her dönem güncellenerek imzalanmalı ve denetim dosyasına eklenmeli. | E8: Önceki dönem çalışma kâğıtları / YMM tasdik dosyaları
B9: 3 | C9: GİB Beyanname EKler / İndirimli KV Tablosu (Tüm Geçmiş Dönemler) | D9: Her YTB için GİB e-Beyanname sistemi 'İndirimli KV Tablosu' satırları. Kümülatif kullanılan YKT ve kalan YKT bu tablodan doğrulanır. YMM notu: Bu çalışma kâğıdı F.2 ile GİB tablosu tam mutabık olmalı. | E9: GİB Dijital Vergi Dairesi / KV Beyannamesi Ekler
B10: 4 | C10: YTB Kapsamındaki Yatırım Harcama Dökümleri (Fatura + Ödeme) | D10: Makine-teçhizat, inşaat, yazılım ve diğer YTB kapsamı harcamalar. Arazi, arsa, royalti ve amortismana tabi olmayan harcamalar YTB matrahına dahil edilmez. Harcama → fatura → ödeme → muhasebe uyum zinciri kurulmalıdır. | E10: Tedarikçi faturaları / Banka ödeme dekontları / Muhasebe
B11: 5 | C11: Tamamlama Vizesi (Tamamlanmış Yatırımlar İçin) | D11: İşletme dönemine geçişin resmî teyidi. Vize tarihi işletme dönemi başlangıcını belirler. Vizesiz yatırım için işletme dönemi indirimli KV uygulanamaz. YMM notu: Vize tarihini beyanname dönemleriyle eşleştirin. | E11: T.C. Sanayi ve Teknoloji Bakanlığı
B12: 6 | C12: Sabit Kıymet Tablosu / ATİK Listesi (Götürü Usul Tevsi İçin) | D12: Dönem sonu YTB kapsamındaki ATİK tutarı ve toplam ATİK tutarı (devam eden dahil). Sabit kıymetler yeniden değerlenmiş değerle alınır. Götürü usul oranı = YTB ATİK / Toplam ATİK. YMM notu: Bu oran doğrudan indirimli KV matrahını etkiler. | E12: Muhasebe programı — sabit kıymet modülü
B13: 7 | C13: Dönem KV Beyannamesi (Taslak veya Nihai) + EKler/İndirimli KV Tablosu | D13: Beyanname 'Alınmayan Vergi' satırı ile F.7 (KV Tasarrufu) mutabık olmalı. GİB 'Ek Bilgiler' kulakçığı: Kalan YKT tutarı (F.10) bu bölüme girilmeli. YMM notu: Beyanname = çalışma kâğıdı = GİB tablosu üçlü mutabakatı zorunludur. | E13: GİB e-Beyanname sistemi / Mali müşavir çalışma dosyası
B14: 8 | C14: Mizan / Vergi Hesap Mutabakat Tablosu | D14: Dönem kurumlar vergisi matrahı, indirimli KV uygulaması ve 'alınmayan vergi' tutarının mizan kayıtlarıyla uyumu. 371 (Dönem KV Karşılığı) ve ilgili hesap dökümleri. YMM notu: Mizan ile beyanname ve bu çalışma kâğıdının tam uyumu zorunludur. | E14: Muhasebe programı — mizanlar / vergi hesapları
A16: KATEGORİ 2 — DESTEKLEYİCİ BELGELER (Yatırım Türüne ve Duruma Göre)
B17: No | C17: Belge / Bilgi Adı | D17: Detay ve YMM Kontrol Noktaları | E17: Temin Yeri
B18: 9 | C18: Yatırım Döneminde Diğer Faaliyet Harcama/Limit Hesap Tablosu | D18: Yatırım döneminde diğer faaliyet limiti hesabı: MIN(YKT × Bölge Oranı, Kümülatif Harcama). B.3, B.4, B.6 satırlarının dayanağı. Bölge oranı YTB'den alınmalı. | E18: Muhasebe programı / Proje yönetim sistemi
B19: 10 | C19: Tevsi — Gerçek Usul Kazanç Tespit Belgeleri (Gerçek Usul Seçilmişse) | D19: Yatırımdan elde edilen kazancın ayrı hesaplarda izlendiğini gösteren muhasebe dökümleri. Maliyet/proje merkezleri, ayrı hasılat ve maliyet takibi zorunludur. Ayrı izleme yoksa gerçek usul seçilemez. | E19: Muhasebe — maliyet merkezi / proje hesapları
B20: 11 | C20: Revize / Tadil YTB ve Ek Oran Belgesi (+15 Puan) | D20: İmalat sanayii kapsamında (+15 puan) veya revize YTB söz konusuysa güncelleme belgesi. US-97 kodu (15-37) teyidi: TÜİK sektör sınıflandırması ile uyumlu olmalıdır. | E20: T.C. Sanayi ve Teknoloji Bakanlığı / TÜİK
B21: 12 | C21: YDO Teyit Belgesi (GİB Sirküleri / VUK Tebliği) | D21: Tamamlama sonrası dönemlerde kalan YKT'ye uygulanacak YDO oranını gösteren resmi kaynak. 2024: %63,93 (VUK 574) | 2025/1: %3,30 (68 No.lu KV Sirküleri). | E21: GİB Sirküleri / VUK Tebliği / Nexia, KPMG vb. özet
B22: 13 | C22: Belge Bazında Çapraz Kullanım Kontrol Tablosu | D22: Birden fazla YTB varsa: Her YTB'nin YKT'sinin başka bir YTB ile çakışmadığını gösteren tablo. Her YTB sütun bazında bağımsız izlenmeli. Bu tablo olmadan çok YTB dosyası metodolojik olarak savunulamaz. | E22: YMM çalışma kâğıdı / Bu dosya ANA KONTROL sayfası
B23: 14 | C23: YİAKV Matrah Hesaplama Tablosu (KVK 32/C Etkisi) | D23: 32/A 'alınmayan vergi' tutarının YİAKV matrahına etkisi. KVK 32/C kapsamında analiz zorunludur. | E23: YİAKV çalışma kâğıdı / KVK 32/C Tebliğleri
B24: 15 | C24: Ertelenmiş Vergi Analizi (TMS 12) | D24: İndirimli KV uygulamasının yarattığı ertelenmiş vergi alacağı/yükümlülüğü. TMS 12 çerçevesinde muhasebeleştirilmiş ve notlarda açıklanmış olmalıdır. | E24: Bağımsız denetim çalışma kâğıtları / Muhasebe
A25: KATEGORİ 3 — YMM TASDİK KONTROL SORULARI (Her YTB İçin Ayrı Uygulayın)
B26: No | C26: Kontrol Sorusu | D26: Beklenen Sonuç / Tasdik Standardı | E26: YMM Aksiyonu
B27: S1 | C27: ★ İndirimli KV uygulanacak kazanç, bu YTB kapsamındaki yatırımdan mı elde edildi? | D27: İşletme döneminde: Sadece ilgili yatırımdan elde edilen kazanç. Yatırım döneminde: Diğer faaliyet kazancı + bölge oranı limiti dahilinde. Bu teyit yapılmadan tasdik tamamlanmaz. | E27: YMM kontrolü
B28: S2 | C28: ★ Çapraz kullanım var mı? Bu YTB'nin YKT'si başka bir YTB hesabına mahsup edildi mi? | D28: HAYIR cevabı beklenir. Her YTB ayrı izlenmelidir. Çapraz kullanım durumunda tüm YKT hesabı geçersiz sayılabilir. | E28: YMM kontrolü
B29: S3 | C29: Önceki dönemler kümülatif YKT (F.2) GİB tablosuyla mutabık mı? | D29: F.2 satırı = GİB beyanname EKler / İndirimli KV Tablosu kümülatif tutarı. Fark varsa kaynak belgelere inilmeli ve açıklanmalıdır. | E29: YMM kontrolü
B30: S4 | C30: YKT Tasarruf ↔ Tüketim denkliği kontrol edildi mi? (F.9 = SIFIR mu?) | D30: F.9 = F.7 − F.8 = SIFIR olmalıdır. Aksi halde hesap hatası var. Bu kontrol olmadan tasdik dosyası eksik sayılır. | E30: YMM kontrolü
B31: S5 | C31: Dönem ayrımı (Yatırım/İşletme) doğru uygulandı mı? Tamamlama vizesi doğrulandı mı? | D31: Tamamlama vizesi tarihi → işletme dönemi başlangıcı. Karma dönem varsa her ikisi de ayrı hesaplanmalıdır. | E31: YMM kontrolü
B32: S6 | C32: Tevsi yatırımda kazanç tespit yöntemi tutarlı uygulandı mı? | D32: Gerçek usul: Ayrı hesap izlemesi belgelenmeli. Götürü usul: ATİK oranı yeniden değerlenmiş değerle doğru hesaplanmalı. Yöntem değişikliği açıklanmalıdır. | E32: YMM kontrolü
B33: S7 | C33: YDO endekslemesi doğru dönem oranıyla yapıldı mı? | D33: E.2 YDO oranı = GİB sirküleri ile doğrulanmış olmalı. Yanlış oran = Hatalı YKT bakiyesi = Tasdik hatası. | E33: YMM kontrolü
B34: S8 | C34: GİB sistemi: Kalan YKT Ek Bilgiler bölümüne girildi mi? İndirimli KV Tablosu eksiksiz mi? | D34: Her YTB için ayrı GİB İndirimli KV Tablosu satırı açılmalı. Kalan YKT Ek Bilgiler bölümünden girilmeli. | E34: YMM kontrolü
A36: SON NOT (YMM TASDİK): 49 No.lu Tebliğ (30.12.2025): KVK 32/A için TUTAR SINIRI OLMAKSIZIN YMM tasdik raporu zorunludur. Her YTB için GİB İndirimli KV Tablosu ayrı doldurulmalı. KV Tasarrufu = Kullanılan YKT denkliği sağlanmadan tasdik tamamlanmış sayılmaz. Çapraz kullanım riski her dönem kontrol edilmeli. Bu dosya çok yıllı izleme aracıdır — tek dönem bakışı metodolojik hata oluşturur.
