Workbook

Sheet VERİ GİRİŞİ
A1: YURT İÇİ ASGARİ KURUMLAR VERGİSİ (YİAKV) ÇALIŞMA KÂĞIDI | KVK Md.32/C | 7524 SAYILI KANUN | YMM TASDİK KÂĞIDI
A2: VERİ GİRİŞİ SAYFASI — Sarı alanları doldurun. Hesaplamalar YİAKV HESAPLAMA sayfasına otomatik yansır.
A3: KAPSAM: 2025 yılı ve izleyen dönemler | Geçici vergi dahil | GİB Rehberleri: No:607 (YİAKV) | No:606 (KV Beyan) | No:605 (KV Oran) | No:589 (%5 İndirim)
A5: A. MÜKELLEF BİLGİLERİ
A6: Mükellef Unvanı | F6: Tam ticaret unvanı — beyannamedeki ile aynı
A7: Vergi Kimlik Numarası | F7: 10 haneli VKN
A8: Hesap Dönemi | F8: Örn: 01.01.2025 – 31.12.2025
A9: Kuruluş Tarihi | F9: GG.AA.YYYY — Yeni şirket 3 hesap dönemi muafiyet kontrolü için
A10: Faaliyet Konusu | F10: İmalat / İhracat / Hizmet / Karma
A11: Dosya Referansı | F11: YMM-2025/AV-01
A12: YMM Adı Soyadı | F12: Tasdiki yapan YMM
A13: Tasdik Tarihi | F13: GG.AA.YYYY
A15: B. YİAKV MÜKELLEFİYET ÖN KONTROL
A16: Mükellefin YİAKV kapsamında olup olmadığını belirleyin — GİB Rehberi Bölüm 1.2
B17: Kontrol Sorusu | E17: Yanıt | F17: Açıklama
A18: B.1 ★ Mükellef kurumlar vergisinden muaf mı? | D18: HAYIR | E18: Muaf kurumlar YİAKV kapsamı dışındadır.
A19: B.2 ★ İlk defa faaliyete başlayan şirket mi? (3 hesap dönemi muafiyet) | D19: HAYIR | E19: 2025'te kurulduysa 2025-26-27 muaf. 2024'te → 2025-26. 2023'te → 2025.
A20: B.3 Birleşme/devir/tür değişikliği/bölünme yoluyla mı kuruldu? | D20: HAYIR | E20: Bu yollarla kurulan şirket 'ilk defa' sayılmaz.
A21: B.4 Hasılat esasına göre vergilendirilen kurum mu? (GVK Md.113) | D21: HAYIR | E21: Hasılat esaslı mükellefler kapsam dışı.
A22: B.5 02.08.2024 öncesi alınmış YTB var mı? | D22: HAYIR | E22: Eski YTB → 32/A alınmayan vergi asgari vergiden düşülür.
A23: B.6 02.08.2024 sonrası alınan YTB var mı? | D23: HAYIR | E23: Yeni YTB alınmayan vergi asgari vergiden DÜŞÜLEMEZ.
A24: B.7 YİAKV UYGULAMA SONUCU | D24: =IF(OR(D18="EVET-YİAKV Uygulanmaz",D19="EVET-YİAKV Uygulanmaz",D21="EVET-YİAKV Uygulanmaz"),"KAPSAM DIŞI","KAPSAM İÇİ — YİAKV Hesaplanacak") -> KAPSAM İÇİ — YİAKV Hesaplanacak | E24: Kapsam içiyse → YİAKV HESAPLAMA sayfasına geçin.
A26: C. TEMEL MALİ VERİLER
A27: UYARI: Enflasyon düzeltmesi uygulandıysa düzeltilmiş bilanço değerleri kullanılmalıdır (VUK Mük.Md.298/Geçici Md.33).
B28: Kalem | D28: Tutar (TL) | F28: Kaynak / YMM Notu
A29: C.1 Ticari Bilanço Kârı (+) / Zararı (-) | D29: Mizan / Bilanço | E29: Enflasyon düzeltmesi dahil — formülün başlangıç noktası
A30: C.2 Kanunen Kabul Edilmeyen Giderler (KKEG) | D30: Muavin Defter | E30: BSMV, gecikme faizi, özel gider vb. — eksiksiz liste
A31: C.3 Geçmiş Yıl Zararları (GYZ) — BİLGİ AMAÇLI | D31: Beyanname | E31: YİAKV matrahından DÜŞÜLEMEZ — Danıştay 3.D. E:2024/5700
A32: C.4 TİCARİ KAZANÇ TABANI = C.1 + C.2 (YİAKV için — GİB Rehberi Md.2.4) | C32: =C29+C30 -> 0 | D32: Bu tutar > 0 ise YİAKV hesaplanır | ≤ 0 ise YİAKV hesaplanmaz
A34: D. YİAKV MATRAHTAN DÜŞÜLEBİLECEK İSTİSNA VE İNDİRİMLER (GİB Rehberi Bölüm 3.1)
A35: Beyannamede kullandığınız tutarı girin. Yalnızca bu kalemler YİAKV matrahından düşülür.
B36: İstisna / İndirim Kalemi | D36: Kullanılan Tutar (TL) | F36: YMM Kontrol Notu
A37: D.1 İştirak Kazançları İstisnası (KVK 5/1-a) | D37: Beyanname 301 | E37: Yurt içi iştirak kâr payları. ★ YENİ (7524 s.K. Md.32): 5/1-d fon/ort. %50 dağıtım şartını SAĞLIYORSA → bu fondan alınan kâr payı 5/1-a istisnasına KONU EDİLEMEZ. Dağıtım şartı SAĞLANAMIYORSA → 5/1-a kapsamında istisna uygulanabilir. (KV Beyan Rehberi 2026 — Yayın No:606)
A38: D.2 Emisyon Primi Kazancı (KVK 5/1-ç) | D38: Beyanname 302 | E38: Hisse ihraç primleri
A39: D.3 Yat.Fon/Ort. — Taşınmaz HARİÇ Kazancı (KVK 5/1-d) ★ KOŞULLU: %50 Dağıtım Şartı (7524 s.K. Md.32 — 1/1/2025+) | D39: Beyanname 305-308 | E39: ★ 1/1/2025'ten itibaren KOŞULLU: ✓ Dağıtım şartı SAĞLANIYORSA: Taşınmaz dışı kazanç düşülür. ✗ Dağıtım şartı SAĞLANAMIYORSA: Tüm kazanç (taşınmaz dahil) DÜŞÜLEMEZ. Dağıtım: KV beyan ayını izleyen 2. ayın sonu. Beyanname 305-308. GYO taşınmaz gelirleri her durumda DÜŞÜLEMEZ (E.3 bölümü).
A40: D.4 Risturn Kazancı (KVK 5/1-i) | D40: Beyanname 309 | E40: Kooperatif risturnları
A41: D.5 Sat-Kirala-Geri Al İstisnası (KVK 5/1-j) | D41: Beyanname 310-312 | E41: SKG
A42: D.6 Varlık Kiralama (Sukuk) İstisnası (KVK 5/1-k) | D42: Beyanname 313-315 | E42: VKŞ — Sukuk
A43: D.7 TUGS — Türk Uluslararası Gemi Sicili (4490 s.K. Md.12) | D43: Beyanname 315 | E43: TUGS kayıtlı gemi işletme/devir
A44: D.8 Serbest Bölge Kazanç İstisnası (3218 s.K. Geçici Md.) | D44: Beyanname 350 | E44: SB faaliyet lisanslı kazanç
...

Sheet YİAKV HESAPLAMA
A1: YİAKV HESAPLAMA VE DENETİM TABLOSU | KVK Md.32/C | 7524 SAYILI KANUN | GİB REHBERİ NİSAN 2026
A2: ='VERİ GİRİŞİ'!C6&" | Hesap Dönemi: "&'VERİ GİRİŞİ'!C8&" | Dosya Ref: "&'VERİ GİRİŞİ'!C11 -> | Hesap Dönemi: | Dosya Ref:
A4: I. YİAKV HESAPLAMA TABLOSU — GİB REHBERİ NİSAN 2026
A5: No | B5: Hesap Kalemi | C5: Referans | D5: Tutar (TL) | E5: Etki | F5: Formül / Açıklama | G5: YMM Denetim Notu
A6: 1 | B6: Ticari Bilanço Kârı / Zararı | C6: VERİ GİRİŞİ C.1 | D6: ='VERİ GİRİŞİ'!C29 -> 0 | E6: + | F6: Mizan/Bilanço | G6: KVK 32/C Formül Başlangıcı
A7: 2 | B7: (+) Kanunen Kabul Edilmeyen Giderler | C7: VERİ GİRİŞİ C.2 | D7: ='VERİ GİRİŞİ'!C30 -> 0 | E7: + | F7: KKEG toplamı | G7: BSMV, gecikme faizi vb.
A8: 3 | B8: TİCARİ KAZANÇ TABANI (1+2) | C8: Auto | D8: =D6+D7 -> 0 | E8: = | F8: (1)+(2) | G8: Sıfırdan büyükse YİAKV hesaplanır
A9: 4 | B9: (-) İştirak Kazançları (KVK 5/1-a) | C9: VERİ GİRİŞİ D.1 | D9: =-'VERİ GİRİŞİ'!C37 -> 0 | E9: − | F9: Düşülür | G9: Beyanname 301
A10: 5 | B10: (-) Emisyon Primi (KVK 5/1-ç) | C10: VERİ GİRİŞİ D.2 | D10: =-'VERİ GİRİŞİ'!C38 -> 0 | E10: − | F10: Düşülür | G10: Beyanname 302
A11: 6 | B11: (-) Yat.Fon/Ort. — Taşınmaz HARİÇ (KVK 5/1-d) | C11: VERİ GİRİŞİ D.3 | D11: =-'VERİ GİRİŞİ'!C39 -> 0 | E11: − | F11: Düşülür | G11: GYO taşınmaz DÜŞÜLEMEZ
A12: 7 | B12: (-) Risturn (KVK 5/1-i) | C12: VERİ GİRİŞİ D.4 | D12: =-'VERİ GİRİŞİ'!C40 -> 0 | E12: − | F12: Düşülür | G12: Beyanname 309
A13: 8 | B13: (-) Sat-Kirala-Geri Al (KVK 5/1-j) | C13: VERİ GİRİŞİ D.5 | D13: =-'VERİ GİRİŞİ'!C41 -> 0 | E13: − | F13: Düşülür | G13: Beyanname 310-312
A14: 9 | B14: (-) Varlık Kiralama (Sukuk) (KVK 5/1-k) | C14: VERİ GİRİŞİ D.6 | D14: =-'VERİ GİRİŞİ'!C42 -> 0 | E14: − | F14: Düşülür | G14: Beyanname 313-315
A15: 10 | B15: (-) TUGS Gemi Sicili (4490 s.K. Md.12) | C15: VERİ GİRİŞİ D.7 | D15: =-'VERİ GİRİŞİ'!C43 -> 0 | E15: − | F15: Düşülür | G15: Beyanname 315
A16: 11 | B16: (-) Serbest Bölge Kazanç İstisnası (3218 s.K.) | C16: VERİ GİRİŞİ D.8 | D16: =-'VERİ GİRİŞİ'!C44 -> 0 | E16: − | F16: Düşülür | G16: SB faaliyet kazancı
A17: 12 | B17: (-) Teknokent Kazanç İstisnası (4691 s.K. Geçici Md.2) | C17: VERİ GİRİŞİ D.9 | D17: =-'VERİ GİRİŞİ'!C45 -> 0 | E17: − | F17: Düşülür | G17: TGB girişimci
A18: 13 | B18: (-) Ar-Ge ve Tasarım İndirimi (5746; 6550 Geçici Md.1/c) | C18: VERİ GİRİŞİ D.10 | D18: =-'VERİ GİRİŞİ'!C46 -> 0 | E18: − | F18: İndirilir | G18: Ar-Ge/Tasarım Merkezi
A19: 14 | B19: (-) Girişim Sermayesi Fonu İndirimi (KVK 10/1-g) | C19: VERİ GİRİŞİ D.11 | D19: =-'VERİ GİRİŞİ'!C47 -> 0 | E19: − | F19: İndirilir | G19: GS Fonu
A20: 15 | B20: (-) Engelliler Korumalı İşyeri İndirimi (KVK 10/1-h) | C20: VERİ GİRİŞİ D.12 | D20: =-'VERİ GİRİŞİ'!C48 -> 0 | E20: − | F20: İndirilir | G20: 5378 s.K.
A21: 16 | B21: ASGARİ VERGİ MATRAHI | C21: Auto | D21: =D8+SUM(D9:D20) -> 0 | E21: = | F21: (3)−İzin Verilen İstisna/İndirimler | G21: GİB Rehberi Bölüm 3.1
A22: 17 | B22: HAM ASGARİ VERGİ (×%10) | C22: Auto | D22: =IF(D21>0,D21*0.1,0) -> 0 | E22: ×%10 | F22: Matrah × %10 | G22: Negatif matrahta 0
A23: 18 | B23: (-) İhracat 5 Puan — Alınmayan Vergi (KVK 32/6) | C23: VERİ GİRİŞİ F.1 | D23: =-'VERİ GİRİŞİ'!E73 -> 0 | E23: − | F23: Vergiden düşer | G23: İhracat matrahı × %5
A24: 19 | B24: (-) Üretim 1 Puan — Alınmayan Vergi (KVK 32/7) | C24: VERİ GİRİŞİ F.2 | D24: =-'VERİ GİRİŞİ'!E74 -> 0 | E24: − | F24: Vergiden düşer | G24: Üretim matrahı × %1
A25: 20 | B25: (-) Halka Arz 2 Puan — Alınmayan Vergi (KVK 32/8) | C25: VERİ GİRİŞİ F.3 | D25: =-'VERİ GİRİŞİ'!E75 -> 0 | E25: − | F25: Vergiden düşer | G25: ≥%20 BİST halka arz
A26: 21 | B26: (-) Eski YTB 32/A Alınmayan Vergi (02.08.2024 ÖNCESİ) | C26: VERİ GİRİŞİ F.4 | D26: =-'VERİ GİRİŞİ'!E76 -> 0 | E26: − | F26: Vergiden düşer | G26: YENİ YTB DÜŞÜLEMEZ
A27: 22 | B27: NİHAİ ASGARİ KURUMLAR VERGİSİ BARAJI | C27: Auto | D27: =MAX(0,D22+SUM(D23:D26)) -> 0 | E27: = | F27: Ham Asgari − İndirim Oranı Avantajları | G27: GİB Rehberi Md.2.6/2.7
A29: II. KARŞILAŞTIRMA VE ÖDENECEK VERGİ TESPİTİ
A30: A | B30: Genel Hükümlere Göre Hesaplanan KV | D30: ='VERİ GİRİŞİ'!C82 -> 0 | E30: Beyanname Hesaplanan KV
A31: B | B31: Nihai Asgari Kurumlar Vergisi Baraji | D31: =D27 -> 0 | E31: Hesaplama Tablosu No.22
A32: → | B32: ÖDENECEK VERGİ = MAX (A, B) | D32: =MAX(D30,D31) -> 0 | E32: =IF(D30>=D31,"✓ Genel KV Uygulanır — YİAKV Ek Yük Yok","★ YİAKV Devreye Girdi — Fark Ödenmeli") -> ✓ Genel KV Uygulanır — YİAKV Ek Yük Yok
A33: Δ | B33: YİAKV EK VERGİ YÜKÜ (Fark) | D33: =MAX(0,D31-D30) -> 0 | E33: 0 → YİAKV ek yük yok | Pozitif → Bu tutar ilave vergi ödenir
A35: III. TEVKİFAT VE GEÇİCİ VERGİ MAHSUBU (GİB Rehberi Md.2.8)
B36: Kalem | D36: Tutar (TL) | F36: Açıklama
A37: Tevkif Suretiyle Ödenen KV | D37: ='VERİ GİRİŞİ'!C83 -> 0
A38: Ödenen Geçici Vergiler | D38: ='VERİ GİRİŞİ'!C84 -> 0
A39: TOPLAM MAHSUP | D39: =SUM(D37:D38) -> 0
A40: NİHAİ ÖDENECEK YİAKV (Mahsup Sonrası) | D40: =MAX(0,D32-D39) -> 0
A42: IV. YMM DENETİM KONTROL LİSTESİ (K1–K14)
B43: Kontrol | D43: Açıklama | F43: Sonuç
A44: K1 | B44: ★ Mükellef YİAKV kapsamında mı? (3 muafiyet hali kontrol edildi mi?) | D44: KV muaf | Yeni şirket | Hasılat esaslı — VERİ GİRİŞİ B bölümü. | F44: Uygun / Eksik / Risk
...

Sheet İSTİSNA & İNDİRİM MATRİSİ
A1: YİAKV İSTİSNA VE İNDİRİM MATRİSİ — GİB REHBERİ NİSAN 2026 | KV BEYAN REHBERİ MART 2026 (No:606)
A2: HIZLI BAŞVURU — Hangi istisnalar YİAKV matrahından düşülür/düşülemez?
A3: Sıra | B3: İstisna / İndirim (Kanun Maddesi) | C3: Genel KV | D3: YİAKV Matrahı | E3: Beyanname
A4: 1 | B4: İştirak Kazançları (KVK 5/1-a) | C4: Düşülür ✓ | D4: Düşülür ✓ | E4: 301
A5: 2 | B5: Emisyon Primi (KVK 5/1-ç) | C5: Düşülür ✓ | D5: Düşülür ✓ | E5: 302
A6: 3 | B6: Yat.Fon/Ort. — Taşınmaz HARİÇ (KVK 5/1-d) | C6: Düşülür ✓ | D6: KOŞULLU ★ (1/1/2025+) ✓ %50 Dağıtım SAĞLANIYORSA: Taşınmaz Dışı → Düşülür ✗ Dağıtım SAĞLANAMIYORSA: TÜM KAZANÇ DÜŞÜLEMEZ (7524 s.K. Md.32 | KV Beyan Reh. No:606) | E6: 305-308
A7: 4 | B7: Risturn (KVK 5/1-i) | C7: Düşülür ✓ | D7: Düşülür ✓ | E7: 309
A8: 5 | B8: Sat-Kirala-Geri Al (KVK 5/1-j) | C8: Düşülür ✓ | D8: Düşülür ✓ | E8: 310-312
A9: 6 | B9: Varlık Kiralama/Sukuk (KVK 5/1-k) | C9: Düşülür ✓ | D9: Düşülür ✓ | E9: 313-315
A10: 7 | B10: TUGS Gemi Sicili (4490 s.K. Md.12) | C10: Düşülür ✓ | D10: Düşülür ✓ | E10: 315
A11: 8 | B11: Serbest Bölge Kazanç İstisnası (3218 s.K.) | C11: Düşülür ✓ | D11: Düşülür ✓ | E11: 350
A12: 9 | B12: Teknokent Kazanç İstisnası (4691 s.K. Geçici Md.2) | C12: Düşülür ✓ | D12: Düşülür ✓ | E12: 350
A13: 10 | B13: Ar-Ge ve Tasarım İndirimi (5746 s.K.; 6550 Geçici Md.1/c) | C13: İndirilir ✓ | D13: İndirilir ✓ | E13: 283/284
A14: 11 | B14: Girişim Sermayesi Fonu (KVK 10/1-g) | C14: İndirilir ✓ | D14: İndirilir ✓ | E14: 285
A15: 12 | B15: Engelliler Korumalı İşyeri (KVK 10/1-h) | C15: İndirilir ✓ | D15: İndirilir ✓ | E15: 286
A16: — İZİN VERİLENLER (Üstte) — DÜŞÜLEMEYENLER (Altta) —
A17: 13 | B17: Yurt Dışı İştirak/Şube/İnşaat Kaz. (KVK 5/1-b,c,g,h) | C17: Düşülür ✓ | D17: DÜŞÜLEMEZ ✗ | E17: 303/304/322
A18: 14 | B18: GYO/Fon — Taşınmaz Gelirleri (KVK 5/1-d taşınmaz kısım) | C18: Düşülür ✓ | D18: DÜŞÜLEMEZ ✗ | E18: 305-308
A19: 15 | B19: Taşınmaz/İştirak/Fon Satış Kazancı (KVK 5/1-e) | C19: Düşülür ✓ | D19: DÜŞÜLEMEZ ✗ | E19: 351-359
A20: 16 | B20: Banka Borçlu Taşınmaz/İştirak Satışı (KVK 5/1-f) | C20: Düşülür ✓ | D20: DÜŞÜLEMEZ ✗ | E20: 321
A21: 17 | B21: Eğitim/Öğretim Kazanç İstisnası (KVK 5/1-ı) | C21: Düşülür ✓ | D21: DÜŞÜLEMEZ ✗ | E21: 339
A22: 18 | B22: Yabancı Fon Yönetici Şirketi (KVK 5/A) + Patent Box (KVK 5/B) | C22: Düşülür ✓ | D22: DÜŞÜLEMEZ ✗ | E22: 323/324
A23: 19 | B23: KKM İstisnalar — Tüm Kodlar (KVK Geçici Md.14) P1: 370/371/372/373/374 (Aktif) | P2: 375/376/377/378 (Pasif) P3: 379/380/381/382 (Altın) | P4: 383/384/385 | C23: Düşülür ✓ | D23: DÜŞÜLEMEZ ✗ | E23: 370–385
A24: 20 | B24: Ürün Senedi Kazancı (GVK Geçici Md.76 / 5300 s.K.) | C24: Düşülür ✓ | D24: DÜŞÜLEMEZ ✗ | E24: 349
A25: 21 | B25: Araştırma Altyapıları Ar-Ge (6550 s.K. Geçici Md.1/a) | C25: Düşülür ✓ | D25: DÜŞÜLEMEZ ✗ | E25: 350
A26: 22 | B26: Sponsorluk + Bağış/Yardımlar — Tümü (KVK 10/1-b,c,ç,d,e,f) | C26: İndirilir ✓ | D26: DÜŞÜLEMEZ ✗ | E26: 260-270
A27: 23 | B27: Yurt Dışı Yazılım/Müh./Eğ./Sağ. İndirimi (KVK 10/1-ğ) | C27: İndirilir ✓ | D27: DÜŞÜLEMEZ ✗ | E27: 280
A28: 24 | B28: Nakdi Sermaye Artışı Faiz İndirimi (KVK 10/1-ı) | C28: İndirilir ✓ | D28: DÜŞÜLEMEZ ✗ | E28: 283
... A31: 27 | B31: ÇVÖA İstisnaları (Uluslararası Anlaşmalar) | C31: Düşülür ✓ | D31: DÜŞÜLEMEZ ✗ | E31: Diğer
A32: — ÖZEL: İNDİRİM ORANI KAYNAKLIYLAR (Asgari Vergiden Düşülür) —
A33: 28 | B33: İhracat 5 Puan / Üretim 1 Puan / Halka Arz 2 Puan (KVK 32/6-7-8) | C33: Mat. indirim | D33: ★ ASGARİ VERGİDEN DÜŞÜLÜR | E33: KVK 32
A34: 29 | B34: 02.08.2024 ÖNCESİ YTB — KVK 32/A Alınmayan Vergi | C34: Mat. indirim | D34: ★ ASGARİ VERGİDEN DÜŞÜLÜR | E34: KVK 32/A
A35: 30 | B35: 02.08.2024 SONRASI YTB — KVK 32/A Alınmayan Vergi | C35: Mat. indirim | D35: ✗ ASGARİ VERGİDEN DE DÜŞÜLEMEZ | E35: KVK 32/A
A36: ★ 5/1-d KOŞULLU DÜZENLEME (7524 s.K. Md.32 — 1/1/2025+): GYO/fon ve ortaklıklar taşınmaz gelirlerinin %50'sini dağıtmazsa hem taşınmaz hem taşınmaz dışı kazançlar için istisna yoktur. Bu durumda D.3 ve E.3 satırlarının ikisi de DÜŞÜLEMEZ olur. 5/1-d dağıtım şartı sağlandığında alınan kar payları 5/1-a istisnasına konu edilemez. (KV Beyan Rehberi Mart 2026 — Yayın No:606)

Sheet DENETÇİ NOTLARI
A1: YİAKV DENETÇİ NOTLARI VE YMM TASDİK STANDARDI | KVK Md.32/C
A2: GİB Rehberleri: Yayın No:607 (YİAKV Nis.2026) | No:606 (KV Beyan Mar.2026) | No:605 (KV Oran Mar.2026) | No:589 (%5 İndirim Şub.2026) | 7524 Sayılı Kanun
A3: Kod | B3: Konu | C3: Mesleki Değerlendirme / Tasdik Standardı | D3: Mevzuat / Kaynak
A4: N1 | B4: YİAKV — Temel Kural, Formül ve Yürürlük | C4: YİAKV TEMEL KURALI (KVK Md.32/C — 7524 Sayılı Kanun Md.36): Hesaplanan KV < Ticari Bilanço Kârı + KKEG × %10 ise aradaki fark YİAKV olarak ödenir. HESAPLAMA FORMÜLÜ: ① Ticari Bilanço Kârı/Zararı + KKEG = Kazanç Tabanı ② Kazanç Tabanı − İzin Verilen İstisna/İndirimler = Asgari Vergi Matrahı ③ Asgari Vergi Matrahı × %10 = Ham Asgari Vergi ④ Ham Asgari Vergi − İndirim Oranı Kaynaklı Alınmayan Vergiler = Nihai Asgari Vergi ⑤ MAX(Genel KV, Nihai Asgari Vergi) = Ödenecek KV YÜRÜRLÜK: 2025 yılı I. Geçici Vergi döneminden itibaren. MUAFİYETLER: KV muafları | İlk 3 hesap dönemi | Hasılat esaslı mükellefler. Birleşme/devir/tür değiş./bölünme yoluyla kurulanlar muafiyet kapsamı dışı. | D4: KVK Md.32/C | 7524 s.K. Md.36 | GİB Rehberi Nisan 2026
A5: N2 | B5: Matrahtan Düşülemeyen İstisnalar — En Sık Yapılan Hatalar | C5: YİAKV MATRAHINDA KALACAK (DÜŞÜLEMEZ) İSTİSNA VE İNDİRİMLER: ① KVK 5/1-e: Taşınmaz/İştirak/Fon Satış Kazancı (351-359) ② KVK 5/1-b,c,g,h: Yurt dışı iştirak/şube/inşaat kazançları ③ KVK 5/A: Yabancı fon yönetici şirketi (323) | KVK 5/B: Patent Box (324) ④ KVK Geçici Md.14 TÜM ON ALTI KOD — DÜŞÜLEMEZ: Paragraf 1 (Aktif): 370 Kur farkı değerleme | 371 Kur farkı tazminat | 372 Dönem sonu faiz/kâr payı tahakkuku | 373 Vade sonu faiz/kâr payı | 374 Vade sonu diğer kazançlar Paragraf 2 (Pasif/Borç): 375 Borç kur farkı | 376 Dönem sonu tahakkuk | 377 Vade sonu faiz/kâr payı | 378 Vade sonu diğer kazançlar Paragraf 3 (Altın Hesabı): 379 Altın dönüşüm kazancı | 380 Dönem sonu tahakkuk | 381 Vade sonu faiz/kâr payı | 382 Vade sonu diğer kazançlar Paragraf 4: 383 Dönem sonu tahakkuk | 384 Kâr payı ve faiz | 385 Vade sonu kazanç ⑤ GVK Geçici Md.76: Ürün senedi kazancı (349) ⑥ KVK 10/1-ı: Nakdi sermaye artışı faiz indirimi ⑦ KVK 10/1-b,c,ç,d,e,f: Tüm bağış ve sponsorluklar ⑧ Yatırım indirimi (devreden dahil) ⑨ ÇVÖA kapsamı istisnaları (386 — Beyanname ayrı satır) YMM NOT: Bu istisnaları yanlışlıkla matrahtan düşmek YİAKV'nin EN SIK YAPILAN HATASIDIR. ★ KVK Geçici Md.14 için: Tüm 16 kod birden E.7 satırında — herhangi birini düşmek hata. ★ ÇVÖA istisnaları (386): YİAKV etkisi anlaşma/gelir türüne göre ayrıca analiz edilmeli. | D5: KVK Md.32/C | GİB Rehberi Bölüm 3.3
A6: N3 | B6: GYZ, Enflasyon Düzeltmesi, TMS-VUK Farkları | C6: GEÇMİŞ YIL ZARARLARI (GYZ): GYZ YİAKV matrahından düşülemez. GYZ sadece genel KV matrahını etkiler. (Danıştay 3.D. E:2024/5700 doğrultusunda) ENFLASYON DÜZELTMESİ: VUK Mük.Md.298 / Geçici Md.33 uygulandığında düzeltilmiş değerler kullanılır. TMS/TFRS ile VUK ARASINDA DEĞERLEME FARKLARI: Bu farklar istisna/indirim niteliğinde değil — YİAKV kapsamı dışı (GİB Rehberi Md.3.2). Özellikle: Örtülü sermaye kur farkı geliri, kıdem tazm. karşılık iptali, GVK Mük.121 vergi indirimi hakkı gelir kaydı — YİAKV kapsamı dışı. ÇVÖA İSTİSNALARI: Türkiye'nin vergi alma hakkı olmadığı ÇVÖA kazançları YİAKV matrahına dahil edilmez. | D6: VUK Mük.Md.298 | GİB Rehberi Md.2.5, 3.2 | Danıştay 3.D.
A7: N4 | B7: İndirim Oranı Kaynaklı Alınmayan Vergiler | C7: HAM ASGARİ VERGİDEN DÜŞÜLECEK TUTARLAR: İHRACAT 5 PUAN: İhracat matrahı = KV matrahı × (İhracat kazancı / Ticari bilanço kârı) Alınmayan vergi = İhracat matrahı × %5 ÜRETİM 1 PUAN (Sanayi Sicil + Fiili Üretim): Üretim matrahı = KV matrahı × (Üretim kazancı / Ticari bilanço kârı) Alınmayan vergi = Üretim matrahı × %1 HALKA ARZ 2 PUAN (≥%20 BİST): Alınmayan vergi = İlgili matrah × %2 YTB — KVK 32/A: 02.08.2024 ÖNCESİ YTB → Alınmayan vergi asgari vergiden DÜŞÜLÜR 02.08.2024 SONRASI YTB → ASGARİ VERGİDEN DE DÜŞÜLEMEZ Yatırım tutarında bu tarihten sonraki revize artışlar dahil edilmez. | D7: KVK 32/6-7-8 | KVK 32/A | GİB Rehberi Md.2.6-2.7
A8: N5 | B8: YMM Tasdik Dil Standardı | C8: YİAKV YOK — KULLANIN: '...KVK Md.32/C kapsamında yapılan hesaplamada [mükellef]'in [dönem] dönemine ait ticari bilanço kârına KKEG eklenmesiyle bulunan [X] TL üzerinden %10 oranında hesaplanan [Y] TL nihai asgari kurumlar vergisi, genel hükümlere göre hesaplanan [Z] TL kurumlar vergisinin altında kaldığından, yurt içi asgari kurumlar vergisi nedeniyle ilave vergi yükü doğmamıştır.' YİAKV DEVREYE GİRDİ — KULLANIN: '...hesaplanan [Z] TL kurumlar vergisi, nihai asgari vergi baraji [Y] TL'nin altında kaldığından; aradaki [Y-Z] TL fark tutar yurt içi asgari kurumlar vergisi olarak tahakkuk ettirilmiştir.' KULLANMAYIN: '...GYZ asgari vergiden düşülmüştür...' | '...5/1-e istisnası matrahtan indirilmiştir...' '...yeni YTB alınmayan vergi mahsup edilmiştir...' (02.08.2024+ YTB düşülemez) | D8: 49 No.lu Tebliğ | KVK Md.32/C | SM-SMMM-YMM K. Md.12
A9: N6 | B9: ★ GYO/Fon 5/1-d Dağıtım Şartı + 5/1-a Bağlantısı + %5 İndirim Limiti + YİD/KÖİ Oranı | C9: ★ 5/1-d DAĞITIM ŞARTI (7524 s.K. Md.32 — 1/1/2025 tarihinden itibaren): GYO/GKO/fon ve ortaklıklar (emeklilik fonları HARİÇ) istisna kazançlarından yararlanabilmek için taşınmaz gelirlerinin en az %50'sini, elde edildiği KV beyan ayını izleyen 2. ayın sonuna kadar kar payı olarak DAĞITMAK ZORUNDADIR. SONUÇLAR: ✓ Dağıtım şartı SAĞLANIYORSA: Taşınmaz dışı kazançlar (D.3) YİAKV matrahından düşülür. ✗ Dağıtım şartı SAĞLANAMIYORSA: Hem taşınmaz HEM taşınmaz dışı kazançların tamamı için istisna KALKAR → YİAKV matrahından HİÇBİR TUTAR düşülemez. ★ 5/1-a İŞTİRAK KAZANCI VE 5/1-d BAĞLANTISI (KV Beyan Rehberi 2026 — Yayın No:606): • 5/1-d %50 dağıtım şartını SAĞLAYAN fon/ort.'dan alınan kâr payı → 5/1-a (İştirak Kazançları) istisnasına KONU EDİLEMEZ (D.1). • 5/1-d dağıtım şartını SAĞLAYAMAYAN fon/ort.'dan alınan kâr payı → 5/1-a kapsamında istisna uygulanabilir. ★ %5 VERGİ İNDİRİMİ ÜST LİMİTİ (Yayın No:589 — Şubat 2026): 1/1/2026'dan itibaren verilecek KV beyannamelerinde hesaplanan %5 indirim tutarı 12.000.000 TL'yi aşamaz (332 Seri No.lu GV GT). Dar mükellefler de yararlanabilir. ★ YAP-İŞLET-DEVRET / KAMU-ÖZEL İŞBİRLİĞİ ŞİRKETLERİ (Yayın No:605): 3996 s.K. (YİD) ve 6428 s.K. (KÖİ) kapsamındaki şirketler 2025 yılı ve izleyen dönemlerde %30 KV oranına tabidir. Bu mükelleflerin dosyalarında oran %30 girilmeli. | D9: 7524 s.K. Md.32 | KVK Md.5/1-a, 5/1-d KV Beyan Rehberi Mart 2026 (No:606) KV Oran Rehberi Mart 2026 (No:605) %5 Vergi İndirimi Reh. Şubat 2026 (No:589) 332 Seri No.lu GV Genel Tebliği
A10: 49 No.lu Tebliğ: >=500.000 TL → YMM raporu. Tam tasdik → ayrıca rapor yok. YİAKV 2025 ve sonrası tüm KV tasdiklerinde DENETİM ODAĞI haline gelmiştir. Bu çalışma kâğıdı her KV tasdik dosyasında bulunmalıdır. YMM müteselsil sorumluluk: SM-SMMM-YMM K. Md.12.

Sheet BELGE LİSTESİ
A1: YİAKV TASDİK DOSYASI BELGE LİSTESİ | KVK Md.32/C | GİB REHBERİ NİSAN 2026
A3: KATEGORİ 1 — ZORUNLU ANA BELGELER
B4: No | C4: Belge / Bilgi | D4: Açıklama / YMM Kontrol | E4: Temin Yeri
B5: 1 | C5: ★ Kurumlar Vergisi Beyannamesi (e-Beyanname çıktısı) | D5: Hesaplanan KV, matrah ve istisna satırları — YİAKV hesaplamasıyla uyum. | E5: GİB e-Beyanname sistemi
B6: 2 | C6: ★ Kesinleşmiş Mizan ve Bilanço (Enflasyon Düzeltmeli — Uygulanıyorsa) | D6: Ticari bilanço kârı/zararının kaynağı. Düzeltme uygulandıysa düzeltilmiş bilanço zorunlu. | E6: Muhasebe programı
B7: 3 | C7: ★ KKEG Dökümü (Kanunen Kabul Edilmeyen Giderler Listesi) | D7: BSMV, gecikme faizi, özel gider, tüm KKEG kalemleri — eksiksiz liste. | E7: Muhasebe ekstresi — 689/770
B8: 4 | C8: ★ YİAKV Hesaplama Tablosu (Bu Çalışma Kâğıdı — YİAKV HESAPLAMA Sayfası) | D8: GİB Rehberi Nisan 2026 formülüne uygun tam hesaplama. Her satır için referans belirtilmeli. | E8: Bu dosya — YİAKV HESAPLAMA
B9: 5 | C9: ★ İstisna/İndirim Ayrıştırma Analizi (Bu Dosya — İSTİSNA & İNDİRİM MATRİSİ) | D9: Hangi istisnaların YİAKV matrahından düşüldüğü — kalem kalem teyit. | E9: Bu dosya — Matris Sayfası
A11: KATEGORİ 2 — MUAFİYET VE ÖZEL DURUM BELGELERİ
B12: No | C12: Belge / Bilgi | D12: Açıklama / YMM Kontrol | E12: Temin Yeri
B13: 6 | C13: Kuruluş Belgesi / Ticaret Sicil Gazetesi (Yeni Şirket Muafiyet Kontrolü) | D13: 3 hesap dönemi muafiyeti. Birleşme/devir/bölünme ile kurulma kontrolü. | E13: Ticaret Sicil Gazetesi
B14: 7 | C14: Yatırım Teşvik Belgesi (YTB) + 02.08.2024 Tarih Analizi | D14: Eski YTB → Asgari vergiden düşülür. Yeni YTB → Düşülemez. Revize geçmişi incelenmeli. | E14: Sanayi ve Teknoloji Bakanlığı
B15: 8 | C15: Sanayi Sicil Belgesi + Fiili Üretim Kanıtı (1 Puan İçin) | D15: Aktif sanayi sicil belgesi + fiili üretim belgesi. | E15: Sanayi Sicil Belgesi — güncel
B16: 9 | C16: Ar-Ge/Tasarım Merkezi Belgesi + Dönem Harcama Listesi | D16: Sanayi Bakanlığı onaylı merkez belgesi. Harcama listesi D.10 ile uyumlu. | E16: Ar-Ge/Tasarım Merkezi Belgesi
B17: 10 | C17: TGB Kiracı Belgesi / SB Faaliyet Lisansı (Teknokent / SB İstisnası İçin) | D17: TGB kiracı teyidi (4691) veya SB faaliyet lisansı (3218). | E17: TGB Yönetici / SB Bölge Müd.
A19: KATEGORİ 3 — YMM TASDİK KONTROL SORULARI
B20: No | C20: Kontrol Sorusu | D20: Beklenen Sonuç | E20: YMM Aksiyonu
B21: S1 | C21: ★ Mükellef YİAKV kapsamında mı? 3 muafiyet hali kontrol edildi mi? | D21: KV muaf | Yeni şirket | Hasılat esaslı. | E21: YMM kontrolü
B22: S2 | C22: ★ Matrahtan düşülemeyen istisnalar matrahta bırakıldı mı? | D22: 5/1-e, KKM, Ürün Senedi, Patent Box vb. | E22: YMM kontrolü
B23: S3 | C23: ★ GYZ asgari vergi matrahından düşülmedi mi? | D23: GYZ sadece genel KV matrahını etkiler. | E23: YMM kontrolü
B24: S4 | C24: Enflasyon düzeltmesi uygulandıysa düzeltilmiş değerler kullanıldı mı? | D24: VUK Mük.Md.298/Geçici Md.33. | E24: YMM kontrolü
B25: S5 | C25: GYO/Fon taşınmaz gelir ayrıştırması yapıldı mı? (5/1-d) | D25: Taşınmaz gelirleri matrahta kalmalı. | E25: YMM kontrolü
B26: S6 | C26: TMS-VUK değerleme farkları vb. kapsam dışı tutarlar temizlendi mi? | D26: GİB Rehberi Md.3.2. | E26: YMM kontrolü
B27: S7 | C27: İhracat/Üretim/Halka Arz alınmayan vergi doğru hesaplandı mı? | D27: Matrah oranlaması + puan uygulaması. | E27: YMM kontrolü
B28: S8 | C28: YTB tarihi 02.08.2024 öncesi/sonrası ayrıştırması yapıldı mı? | D28: Eski → Düşülür. Yeni → Düşülemez. | E28: YMM kontrolü
B29: S9 | C29: Ödenecek vergi MAX(Genel KV, Nihai Asgari Vergi) ile belirlendi mi? | D29: Her iki hesabın büyüğü ödenir. | E29: YMM kontrolü
B30: S10 | C30: YMM Tasdik Raporu (49 No.lu Tebliğ) değerlendirildi mi? | D30: >=500.000 TL → YMM raporu. | E30: YMM kontrolü
A32: SON NOT: GİB Rehberi Nisan 2026 (Yayın No:607) esas alınarak hazırlanmıştır. YİAKV, 2025 yılı I. Geçici Vergi döneminden itibaren uygulanmaktadır. Temel kural: Ödenecek KV = MAX(Genel KV, Nihai Asgari Vergi). Kritik hatalar: GYZ'yi matrahtan düşmek | 5/1-e ve KKM istisnasını yanlış sınıflandırmak | Yeni YTB alınmayan vergiyi asgari vergiden düşmek. Bu çalışma kâğıdı her KV tasdik dosyasında yer almalıdır. YMM müteselsil sorumluluk: SM-SMMM-YMM Kanunu Md.12.
